WARNING 2024-12-31 20:29:40,740 log.py log log_response 248: Method Not Allowed: /api/v1/login
DEBUG 2024-12-31 20:29:55,886 VideoView.py VideoView upload_video 34: 'Request' object has no attribute 'user_id'
ERROR 2024-12-31 20:29:55,887 log.py log log_response 248: Internal Server Error: /api/v1/upload_video
DEBUG 2024-12-31 20:30:33,364 VideoView.py VideoView upload_video 34: 'Request' object has no attribute 'user_id'
ERROR 2024-12-31 20:30:33,364 log.py log log_response 248: Internal Server Error: /api/v1/upload_video
WARNING 2024-12-31 20:33:37,856 log.py log log_response 248: Unauthorized: /api/v1/upload_video
WARNING 2024-12-31 20:40:58,799 log.py log log_response 248: Unauthorized: /api/v1/upload_video
DEBUG 2024-12-31 20:41:09,565 VideoView.py VideoView upload_video 35: 'str' object has no attribute '_meta'
ERROR 2024-12-31 20:41:09,565 log.py log log_response 248: Internal Server Error: /api/v1/upload_video
DEBUG 2024-12-31 20:43:07,580 VideoView.py VideoView upload_video 35: 'str' object has no attribute '_meta'
ERROR 2024-12-31 20:43:07,580 log.py log log_response 248: Internal Server Error: /api/v1/upload_video
DEBUG 2024-12-31 20:43:37,907 VideoView.py VideoView upload_video 35: 'str' object has no attribute '_meta'
ERROR 2024-12-31 20:43:37,907 log.py log log_response 248: Internal Server Error: /api/v1/upload_video
DEBUG 2024-12-31 20:46:07,000 VideoView.py VideoView upload_video 35: 'str' object has no attribute '_meta'
ERROR 2024-12-31 20:46:07,001 log.py log log_response 248: Internal Server Error: /api/v1/upload_video
DEBUG 2024-12-31 20:51:37,707 VideoView.py VideoView upload_video 35: 'NoneType' object has no attribute 'user_id'
ERROR 2024-12-31 20:51:37,708 log.py log log_response 248: Internal Server Error: /api/v1/upload_video
DEBUG 2024-12-31 20:52:04,966 VideoView.py VideoView upload_video 35: 'str' object has no attribute 'user_id'
ERROR 2024-12-31 20:52:04,966 log.py log log_response 248: Internal Server Error: /api/v1/upload_video
DEBUG 2024-12-31 20:52:17,392 VideoView.py VideoView upload_video 35: name 'instance' is not defined
ERROR 2024-12-31 20:52:17,393 log.py log log_response 248: Internal Server Error: /api/v1/upload_video
WARNING 2025-01-01 08:04:04,541 log.py log log_response 248: Unauthorized: /api/v1/upload_video
WARNING 2025-01-01 08:05:47,171 log.py log log_response 248: Method Not Allowed: /api/v1/login
WARNING 2025-01-01 08:06:20,567 log.py log log_response 248: Unauthorized: /api/v1/upload_video
WARNING 2025-01-01 08:11:23,970 log.py log log_response 248: Unauthorized: /api/v1/upload_video
DEBUG 2025-01-01 08:11:35,617 VideoView.py VideoView upload_video 35: name 'instance' is not defined
ERROR 2025-01-01 08:11:35,617 log.py log log_response 248: Internal Server Error: /api/v1/upload_video
DEBUG 2025-01-01 08:12:29,605 VideoView.py VideoView upload_video 35: 'TemporaryUploadedFile' object has no attribute 'get'
ERROR 2025-01-01 08:12:29,607 log.py log log_response 248: Internal Server Error: /api/v1/upload_video
DEBUG 2025-01-01 08:13:27,437 serializer.py serializer create 151: 4973185-hd_1920_1080_30fps.mp4
DEBUG 2025-01-01 08:13:28,986 VideoView.py VideoView upload_video 35: 'TemporaryUploadedFile' object has no attribute 'get'
ERROR 2025-01-01 08:13:28,988 log.py log log_response 248: Internal Server Error: /api/v1/upload_video
DEBUG 2025-01-01 08:14:53,357 serializer.py serializer create 151: 4973185-hd_1920_1080_30fps.mp4
DEBUG 2025-01-01 08:15:01,249 VideoView.py VideoView upload_video 35: NOT NULL constraint failed: api_videos.duration
ERROR 2025-01-01 08:15:01,250 log.py log log_response 248: Internal Server Error: /api/v1/upload_video
DEBUG 2025-01-01 08:15:35,585 serializer.py serializer create 151: 4973185-hd_1920_1080_30fps.mp4
DEBUG 2025-01-01 08:15:47,943 VideoView.py VideoView upload_video 35: NOT NULL constraint failed: api_videos.views
ERROR 2025-01-01 08:15:47,945 log.py log log_response 248: Internal Server Error: /api/v1/upload_video
DEBUG 2025-01-01 08:16:30,884 serializer.py serializer create 151: 4973185-hd_1920_1080_30fps.mp4
DEBUG 2025-01-01 08:16:42,421 VideoView.py VideoView upload_video 35: NOT NULL constraint failed: api_videos.isPublished
ERROR 2025-01-01 08:16:42,422 log.py log log_response 248: Internal Server Error: /api/v1/upload_video
DEBUG 2025-01-01 08:17:06,179 serializer.py serializer create 151: 4973185-hd_1920_1080_30fps.mp4
DEBUG 2025-01-01 08:17:15,704 VideoView.py VideoView upload_video 35: int() argument must be a string, a bytes-like object or a real number, not 'DeferredAttribute'
ERROR 2025-01-01 08:17:15,705 log.py log log_response 248: Internal Server Error: /api/v1/upload_video
DEBUG 2025-01-01 08:21:29,765 serializer.py serializer create 151: 4973185-hd_1920_1080_30fps.mp4
DEBUG 2025-01-01 08:21:41,614 VideoView.py VideoView upload_video 35: int() argument must be a string, a bytes-like object or a real number, not 'DeferredAttribute'
ERROR 2025-01-01 08:21:41,615 log.py log log_response 248: Internal Server Error: /api/v1/upload_video
DEBUG 2025-01-01 08:22:56,214 serializer.py serializer create 151: 4973185-hd_1920_1080_30fps.mp4
DEBUG 2025-01-01 08:23:09,288 VideoView.py VideoView upload_video 35: int() argument must be a string, a bytes-like object or a real number, not 'DeferredAttribute'
ERROR 2025-01-01 08:23:09,289 log.py log log_response 248: Internal Server Error: /api/v1/upload_video
DEBUG 2025-01-01 08:24:37,784 serializer.py serializer create 151: 4973185-hd_1920_1080_30fps.mp4
DEBUG 2025-01-01 08:24:49,948 VideoView.py VideoView upload_video 35: int() argument must be a string, a bytes-like object or a real number, not 'DeferredAttribute'
ERROR 2025-01-01 08:24:49,950 log.py log log_response 248: Internal Server Error: /api/v1/upload_video
DEBUG 2025-01-01 08:26:16,870 serializer.py serializer create 151: 4973185-hd_1920_1080_30fps.mp4
DEBUG 2025-01-01 08:26:16,872 serializer.py serializer create 153: 10
DEBUG 2025-01-01 08:26:31,909 serializer.py serializer create 151: 4973185-hd_1920_1080_30fps.mp4
DEBUG 2025-01-01 08:26:31,910 serializer.py serializer create 153: <class 'int'>
DEBUG 2025-01-01 08:26:49,126 serializer.py serializer create 151: 4973185-hd_1920_1080_30fps.mp4
DEBUG 2025-01-01 08:26:49,129 serializer.py serializer create 153: <class 'str'>
DEBUG 2025-01-01 08:27:02,195 serializer.py serializer create 151: 4973185-hd_1920_1080_30fps.mp4
DEBUG 2025-01-01 08:27:02,197 serializer.py serializer create 153: 10
DEBUG 2025-01-01 08:27:14,740 VideoView.py VideoView upload_video 35: int() argument must be a string, a bytes-like object or a real number, not 'DeferredAttribute'
ERROR 2025-01-01 08:27:14,742 log.py log log_response 248: Internal Server Error: /api/v1/upload_video
DEBUG 2025-01-01 08:32:42,255 serializer.py serializer create 151: 4973185-hd_1920_1080_30fps.mp4
DEBUG 2025-01-01 08:32:42,256 serializer.py serializer create 153: 10
DEBUG 2025-01-01 08:32:54,792 VideoView.py VideoView upload_video 35: int() argument must be a string, a bytes-like object or a real number, not 'DeferredAttribute'
ERROR 2025-01-01 08:32:54,793 log.py log log_response 248: Internal Server Error: /api/v1/upload_video
DEBUG 2025-01-01 08:33:42,915 serializer.py serializer create 151: 4973185-hd_1920_1080_30fps.mp4
DEBUG 2025-01-01 08:33:42,917 serializer.py serializer create 153: 10
DEBUG 2025-01-01 08:33:54,743 VideoView.py VideoView upload_video 35: int() argument must be a string, a bytes-like object or a real number, not 'DeferredAttribute'
ERROR 2025-01-01 08:33:54,745 log.py log log_response 248: Internal Server Error: /api/v1/upload_video
DEBUG 2025-01-01 08:36:35,906 serializer.py serializer create 151: 4973185-hd_1920_1080_30fps.mp4
DEBUG 2025-01-01 08:36:35,909 serializer.py serializer create 153: 10
ERROR 2025-01-01 09:07:57,960 log.py log log_response 248: Internal Server Error: /api/v1/signup
Traceback (most recent call last):
  File "/home/rushikeshkadam/code_space/videoView/server/venv/lib/python3.10/site-packages/django/core/handlers/exception.py", line 55, in inner
    response = get_response(request)
  File "/home/rushikeshkadam/code_space/videoView/server/venv/lib/python3.10/site-packages/django/core/handlers/base.py", line 197, in _get_response
    response = wrapped_callback(request, *callback_args, **callback_kwargs)
  File "/home/rushikeshkadam/code_space/videoView/server/venv/lib/python3.10/site-packages/django/views/decorators/csrf.py", line 65, in _view_wrapper
    return view_func(request, *args, **kwargs)
  File "/home/rushikeshkadam/code_space/videoView/server/venv/lib/python3.10/site-packages/django/views/generic/base.py", line 104, in view
    return self.dispatch(request, *args, **kwargs)
  File "/home/rushikeshkadam/code_space/videoView/server/venv/lib/python3.10/site-packages/rest_framework/views.py", line 509, in dispatch
    response = self.handle_exception(exc)
  File "/home/rushikeshkadam/code_space/videoView/server/venv/lib/python3.10/site-packages/rest_framework/views.py", line 469, in handle_exception
    self.raise_uncaught_exception(exc)
  File "/home/rushikeshkadam/code_space/videoView/server/venv/lib/python3.10/site-packages/rest_framework/views.py", line 480, in raise_uncaught_exception
    raise exc
  File "/home/rushikeshkadam/code_space/videoView/server/venv/lib/python3.10/site-packages/rest_framework/views.py", line 506, in dispatch
    response = handler(request, *args, **kwargs)
  File "/home/rushikeshkadam/code_space/videoView/server/venv/lib/python3.10/site-packages/rest_framework/decorators.py", line 50, in handler
    return func(*args, **kwargs)
  File "/home/rushikeshkadam/code_space/videoView/server/videoView/api/Views/UserViews.py", line 37, in signup
    user,token=serializer.save()
  File "/home/rushikeshkadam/code_space/videoView/server/venv/lib/python3.10/site-packages/rest_framework/serializers.py", line 208, in save
    self.instance = self.create(validated_data)
  File "/home/rushikeshkadam/code_space/videoView/server/videoView/api/serializer.py", line 43, in create
    coverImage_img=cloudinary.uploader.upload(image2)
  File "/home/rushikeshkadam/code_space/videoView/server/venv/lib/python3.10/site-packages/cloudinary/uploader.py", line 45, in upload
    return call_cacheable_api("upload", params, file=file, **options)
  File "/home/rushikeshkadam/code_space/videoView/server/venv/lib/python3.10/site-packages/cloudinary/uploader.py", line 462, in call_cacheable_api
    result = call_api(action, params, http_headers, return_error, unsigned, file, timeout, **options)
  File "/home/rushikeshkadam/code_space/videoView/server/venv/lib/python3.10/site-packages/cloudinary/uploader.py", line 527, in call_api
    raise Error(result["error"]["message"])
cloudinary.exceptions.Error: Missing required parameter - file
ERROR 2025-01-01 09:11:17,008 log.py log log_response 248: Internal Server Error: /api/v1/signup
Traceback (most recent call last):
  File "/home/rushikeshkadam/code_space/videoView/server/venv/lib/python3.10/site-packages/django/core/handlers/exception.py", line 55, in inner
    response = get_response(request)
  File "/home/rushikeshkadam/code_space/videoView/server/venv/lib/python3.10/site-packages/django/core/handlers/base.py", line 197, in _get_response
    response = wrapped_callback(request, *callback_args, **callback_kwargs)
  File "/home/rushikeshkadam/code_space/videoView/server/venv/lib/python3.10/site-packages/django/views/decorators/csrf.py", line 65, in _view_wrapper
    return view_func(request, *args, **kwargs)
  File "/home/rushikeshkadam/code_space/videoView/server/venv/lib/python3.10/site-packages/django/views/generic/base.py", line 104, in view
    return self.dispatch(request, *args, **kwargs)
  File "/home/rushikeshkadam/code_space/videoView/server/venv/lib/python3.10/site-packages/rest_framework/views.py", line 509, in dispatch
    response = self.handle_exception(exc)
  File "/home/rushikeshkadam/code_space/videoView/server/venv/lib/python3.10/site-packages/rest_framework/views.py", line 469, in handle_exception
    self.raise_uncaught_exception(exc)
  File "/home/rushikeshkadam/code_space/videoView/server/venv/lib/python3.10/site-packages/rest_framework/views.py", line 480, in raise_uncaught_exception
    raise exc
  File "/home/rushikeshkadam/code_space/videoView/server/venv/lib/python3.10/site-packages/rest_framework/views.py", line 506, in dispatch
    response = handler(request, *args, **kwargs)
  File "/home/rushikeshkadam/code_space/videoView/server/venv/lib/python3.10/site-packages/rest_framework/decorators.py", line 50, in handler
    return func(*args, **kwargs)
  File "/home/rushikeshkadam/code_space/videoView/server/videoView/api/Views/UserViews.py", line 37, in signup
    user,token=serializer.save()
  File "/home/rushikeshkadam/code_space/videoView/server/venv/lib/python3.10/site-packages/rest_framework/serializers.py", line 208, in save
    self.instance = self.create(validated_data)
  File "/home/rushikeshkadam/code_space/videoView/server/videoView/api/serializer.py", line 43, in create
    coverImage_img=cloudinary.uploader.upload(image2)
  File "/home/rushikeshkadam/code_space/videoView/server/venv/lib/python3.10/site-packages/cloudinary/uploader.py", line 45, in upload
    return call_cacheable_api("upload", params, file=file, **options)
  File "/home/rushikeshkadam/code_space/videoView/server/venv/lib/python3.10/site-packages/cloudinary/uploader.py", line 462, in call_cacheable_api
    result = call_api(action, params, http_headers, return_error, unsigned, file, timeout, **options)
  File "/home/rushikeshkadam/code_space/videoView/server/venv/lib/python3.10/site-packages/cloudinary/uploader.py", line 527, in call_api
    raise Error(result["error"]["message"])
cloudinary.exceptions.Error: Missing required parameter - file
ERROR 2025-01-01 09:14:14,624 log.py log log_response 248: Internal Server Error: /api/v1/signup
Traceback (most recent call last):
  File "/home/rushikeshkadam/code_space/videoView/server/venv/lib/python3.10/site-packages/django/core/handlers/exception.py", line 55, in inner
    response = get_response(request)
  File "/home/rushikeshkadam/code_space/videoView/server/venv/lib/python3.10/site-packages/django/core/handlers/base.py", line 197, in _get_response
    response = wrapped_callback(request, *callback_args, **callback_kwargs)
  File "/home/rushikeshkadam/code_space/videoView/server/venv/lib/python3.10/site-packages/django/views/decorators/csrf.py", line 65, in _view_wrapper
    return view_func(request, *args, **kwargs)
  File "/home/rushikeshkadam/code_space/videoView/server/venv/lib/python3.10/site-packages/django/views/generic/base.py", line 104, in view
    return self.dispatch(request, *args, **kwargs)
  File "/home/rushikeshkadam/code_space/videoView/server/venv/lib/python3.10/site-packages/rest_framework/views.py", line 509, in dispatch
    response = self.handle_exception(exc)
  File "/home/rushikeshkadam/code_space/videoView/server/venv/lib/python3.10/site-packages/rest_framework/views.py", line 469, in handle_exception
    self.raise_uncaught_exception(exc)
  File "/home/rushikeshkadam/code_space/videoView/server/venv/lib/python3.10/site-packages/rest_framework/views.py", line 480, in raise_uncaught_exception
    raise exc
  File "/home/rushikeshkadam/code_space/videoView/server/venv/lib/python3.10/site-packages/rest_framework/views.py", line 506, in dispatch
    response = handler(request, *args, **kwargs)
  File "/home/rushikeshkadam/code_space/videoView/server/venv/lib/python3.10/site-packages/rest_framework/decorators.py", line 50, in handler
    return func(*args, **kwargs)
  File "/home/rushikeshkadam/code_space/videoView/server/videoView/api/Views/UserViews.py", line 37, in signup
    user,token=serializer.save()
  File "/home/rushikeshkadam/code_space/videoView/server/venv/lib/python3.10/site-packages/rest_framework/serializers.py", line 208, in save
    self.instance = self.create(validated_data)
  File "/home/rushikeshkadam/code_space/videoView/server/videoView/api/serializer.py", line 44, in create
    coverImage_img=cloudinary.uploader.upload(image2)
  File "/home/rushikeshkadam/code_space/videoView/server/venv/lib/python3.10/site-packages/cloudinary/uploader.py", line 45, in upload
    return call_cacheable_api("upload", params, file=file, **options)
  File "/home/rushikeshkadam/code_space/videoView/server/venv/lib/python3.10/site-packages/cloudinary/uploader.py", line 462, in call_cacheable_api
    result = call_api(action, params, http_headers, return_error, unsigned, file, timeout, **options)
  File "/home/rushikeshkadam/code_space/videoView/server/venv/lib/python3.10/site-packages/cloudinary/uploader.py", line 527, in call_api
    raise Error(result["error"]["message"])
cloudinary.exceptions.Error: Missing required parameter - file
ERROR 2025-01-01 09:15:29,295 log.py log log_response 248: Internal Server Error: /api/v1/signup
Traceback (most recent call last):
  File "/home/rushikeshkadam/code_space/videoView/server/venv/lib/python3.10/site-packages/django/core/handlers/exception.py", line 55, in inner
    response = get_response(request)
  File "/home/rushikeshkadam/code_space/videoView/server/venv/lib/python3.10/site-packages/django/core/handlers/base.py", line 197, in _get_response
    response = wrapped_callback(request, *callback_args, **callback_kwargs)
  File "/home/rushikeshkadam/code_space/videoView/server/venv/lib/python3.10/site-packages/django/views/decorators/csrf.py", line 65, in _view_wrapper
    return view_func(request, *args, **kwargs)
  File "/home/rushikeshkadam/code_space/videoView/server/venv/lib/python3.10/site-packages/django/views/generic/base.py", line 104, in view
    return self.dispatch(request, *args, **kwargs)
  File "/home/rushikeshkadam/code_space/videoView/server/venv/lib/python3.10/site-packages/rest_framework/views.py", line 509, in dispatch
    response = self.handle_exception(exc)
  File "/home/rushikeshkadam/code_space/videoView/server/venv/lib/python3.10/site-packages/rest_framework/views.py", line 469, in handle_exception
    self.raise_uncaught_exception(exc)
  File "/home/rushikeshkadam/code_space/videoView/server/venv/lib/python3.10/site-packages/rest_framework/views.py", line 480, in raise_uncaught_exception
    raise exc
  File "/home/rushikeshkadam/code_space/videoView/server/venv/lib/python3.10/site-packages/rest_framework/views.py", line 506, in dispatch
    response = handler(request, *args, **kwargs)
  File "/home/rushikeshkadam/code_space/videoView/server/venv/lib/python3.10/site-packages/rest_framework/decorators.py", line 50, in handler
    return func(*args, **kwargs)
  File "/home/rushikeshkadam/code_space/videoView/server/videoView/api/Views/UserViews.py", line 37, in signup
    user,token=serializer.save()
  File "/home/rushikeshkadam/code_space/videoView/server/venv/lib/python3.10/site-packages/rest_framework/serializers.py", line 208, in save
    self.instance = self.create(validated_data)
  File "/home/rushikeshkadam/code_space/videoView/server/videoView/api/serializer.py", line 44, in create
    coverImage_img=cloudinary.uploader.upload(image2)
  File "/home/rushikeshkadam/code_space/videoView/server/venv/lib/python3.10/site-packages/cloudinary/uploader.py", line 45, in upload
    return call_cacheable_api("upload", params, file=file, **options)
  File "/home/rushikeshkadam/code_space/videoView/server/venv/lib/python3.10/site-packages/cloudinary/uploader.py", line 462, in call_cacheable_api
    result = call_api(action, params, http_headers, return_error, unsigned, file, timeout, **options)
  File "/home/rushikeshkadam/code_space/videoView/server/venv/lib/python3.10/site-packages/cloudinary/uploader.py", line 527, in call_api
    raise Error(result["error"]["message"])
cloudinary.exceptions.Error: Missing required parameter - file
ERROR 2025-01-01 09:17:04,575 log.py log log_response 248: Internal Server Error: /api/v1/signup
Traceback (most recent call last):
  File "/home/rushikeshkadam/code_space/videoView/server/venv/lib/python3.10/site-packages/django/core/handlers/exception.py", line 55, in inner
    response = get_response(request)
  File "/home/rushikeshkadam/code_space/videoView/server/venv/lib/python3.10/site-packages/django/core/handlers/base.py", line 197, in _get_response
    response = wrapped_callback(request, *callback_args, **callback_kwargs)
  File "/home/rushikeshkadam/code_space/videoView/server/venv/lib/python3.10/site-packages/django/views/decorators/csrf.py", line 65, in _view_wrapper
    return view_func(request, *args, **kwargs)
  File "/home/rushikeshkadam/code_space/videoView/server/venv/lib/python3.10/site-packages/django/views/generic/base.py", line 104, in view
    return self.dispatch(request, *args, **kwargs)
  File "/home/rushikeshkadam/code_space/videoView/server/venv/lib/python3.10/site-packages/rest_framework/views.py", line 509, in dispatch
    response = self.handle_exception(exc)
  File "/home/rushikeshkadam/code_space/videoView/server/venv/lib/python3.10/site-packages/rest_framework/views.py", line 469, in handle_exception
    self.raise_uncaught_exception(exc)
  File "/home/rushikeshkadam/code_space/videoView/server/venv/lib/python3.10/site-packages/rest_framework/views.py", line 480, in raise_uncaught_exception
    raise exc
  File "/home/rushikeshkadam/code_space/videoView/server/venv/lib/python3.10/site-packages/rest_framework/views.py", line 506, in dispatch
    response = handler(request, *args, **kwargs)
  File "/home/rushikeshkadam/code_space/videoView/server/venv/lib/python3.10/site-packages/rest_framework/decorators.py", line 50, in handler
    return func(*args, **kwargs)
  File "/home/rushikeshkadam/code_space/videoView/server/videoView/api/Views/UserViews.py", line 36, in signup
    user,token=serializer.save()
  File "/home/rushikeshkadam/code_space/videoView/server/venv/lib/python3.10/site-packages/rest_framework/serializers.py", line 208, in save
    self.instance = self.create(validated_data)
  File "/home/rushikeshkadam/code_space/videoView/server/videoView/api/serializer.py", line 54, in create
    if coverImage_img:
UnboundLocalError: local variable 'coverImage_img' referenced before assignment
WARNING 2025-01-01 09:17:25,317 log.py log log_response 248: Unauthorized: /api/v1/signup
WARNING 2025-01-01 13:52:39,733 log.py log log_response 248: Not Found: /api/v1/get_all_video
WARNING 2025-01-01 13:53:37,249 log.py log log_response 248: Method Not Allowed: /api/v1/login
WARNING 2025-01-01 13:53:49,683 log.py log log_response 248: Not Found: /api/v1/get_all_video
WARNING 2025-01-01 13:53:55,286 log.py log log_response 248: Not Found: /api/v1/get_all_video
ERROR 2025-01-01 13:54:11,699 log.py log log_response 248: Internal Server Error: /api/v1/get_all_videos
Traceback (most recent call last):
  File "/home/rushikeshkadam/code_space/videoView/server/venv/lib/python3.10/site-packages/django/core/handlers/exception.py", line 55, in inner
    response = get_response(request)
  File "/home/rushikeshkadam/code_space/videoView/server/venv/lib/python3.10/site-packages/django/core/handlers/base.py", line 220, in _get_response
    response = response.render()
  File "/home/rushikeshkadam/code_space/videoView/server/venv/lib/python3.10/site-packages/django/template/response.py", line 114, in render
    self.content = self.rendered_content
  File "/home/rushikeshkadam/code_space/videoView/server/venv/lib/python3.10/site-packages/rest_framework/response.py", line 74, in rendered_content
    ret = renderer.render(self.data, accepted_media_type, context)
  File "/home/rushikeshkadam/code_space/videoView/server/venv/lib/python3.10/site-packages/rest_framework/renderers.py", line 100, in render
    ret = json.dumps(
  File "/home/rushikeshkadam/code_space/videoView/server/venv/lib/python3.10/site-packages/rest_framework/utils/json.py", line 25, in dumps
    return json.dumps(*args, **kwargs)
  File "/usr/lib/python3.10/json/__init__.py", line 238, in dumps
    **kw).encode(obj)
  File "/usr/lib/python3.10/json/encoder.py", line 199, in encode
    chunks = self.iterencode(o, _one_shot=True)
  File "/usr/lib/python3.10/json/encoder.py", line 257, in iterencode
    return _iterencode(o, 0)
  File "/home/rushikeshkadam/code_space/videoView/server/venv/lib/python3.10/site-packages/rest_framework/utils/encoders.py", line 67, in default
    return super().default(obj)
  File "/usr/lib/python3.10/json/encoder.py", line 179, in default
    raise TypeError(f'Object of type {o.__class__.__name__} '
TypeError: Object of type ApiResponse is not JSON serializable
ERROR 2025-01-01 13:54:52,558 log.py log log_response 248: Internal Server Error: /api/v1/get_all_videos
Traceback (most recent call last):
  File "/home/rushikeshkadam/code_space/videoView/server/venv/lib/python3.10/site-packages/django/core/handlers/exception.py", line 55, in inner
    response = get_response(request)
  File "/home/rushikeshkadam/code_space/videoView/server/venv/lib/python3.10/site-packages/django/core/handlers/base.py", line 220, in _get_response
    response = response.render()
  File "/home/rushikeshkadam/code_space/videoView/server/venv/lib/python3.10/site-packages/django/template/response.py", line 114, in render
    self.content = self.rendered_content
  File "/home/rushikeshkadam/code_space/videoView/server/venv/lib/python3.10/site-packages/rest_framework/response.py", line 74, in rendered_content
    ret = renderer.render(self.data, accepted_media_type, context)
  File "/home/rushikeshkadam/code_space/videoView/server/venv/lib/python3.10/site-packages/rest_framework/renderers.py", line 100, in render
    ret = json.dumps(
  File "/home/rushikeshkadam/code_space/videoView/server/venv/lib/python3.10/site-packages/rest_framework/utils/json.py", line 25, in dumps
    return json.dumps(*args, **kwargs)
  File "/usr/lib/python3.10/json/__init__.py", line 238, in dumps
    **kw).encode(obj)
  File "/usr/lib/python3.10/json/encoder.py", line 199, in encode
    chunks = self.iterencode(o, _one_shot=True)
  File "/usr/lib/python3.10/json/encoder.py", line 257, in iterencode
    return _iterencode(o, 0)
  File "/home/rushikeshkadam/code_space/videoView/server/venv/lib/python3.10/site-packages/rest_framework/utils/encoders.py", line 67, in default
    return super().default(obj)
  File "/usr/lib/python3.10/json/encoder.py", line 179, in default
    raise TypeError(f'Object of type {o.__class__.__name__} '
TypeError: Object of type Videos is not JSON serializable
WARNING 2025-01-01 14:03:47,620 log.py log log_response 248: Not Found: /api/v1/get_all_video/:id
WARNING 2025-01-01 14:04:30,305 log.py log log_response 248: Not Found: /api/v1/get_all_video
ERROR 2025-01-01 14:04:32,033 log.py log log_response 248: Internal Server Error: /api/v1/get_all_videos
Traceback (most recent call last):
  File "/home/rushikeshkadam/code_space/videoView/server/venv/lib/python3.10/site-packages/django/core/handlers/exception.py", line 55, in inner
    response = get_response(request)
  File "/home/rushikeshkadam/code_space/videoView/server/venv/lib/python3.10/site-packages/django/core/handlers/base.py", line 197, in _get_response
    response = wrapped_callback(request, *callback_args, **callback_kwargs)
  File "/home/rushikeshkadam/code_space/videoView/server/venv/lib/python3.10/site-packages/django/views/decorators/csrf.py", line 65, in _view_wrapper
    return view_func(request, *args, **kwargs)
  File "/home/rushikeshkadam/code_space/videoView/server/venv/lib/python3.10/site-packages/django/views/generic/base.py", line 104, in view
    return self.dispatch(request, *args, **kwargs)
  File "/home/rushikeshkadam/code_space/videoView/server/venv/lib/python3.10/site-packages/rest_framework/views.py", line 509, in dispatch
    response = self.handle_exception(exc)
  File "/home/rushikeshkadam/code_space/videoView/server/venv/lib/python3.10/site-packages/rest_framework/views.py", line 469, in handle_exception
    self.raise_uncaught_exception(exc)
  File "/home/rushikeshkadam/code_space/videoView/server/venv/lib/python3.10/site-packages/rest_framework/views.py", line 480, in raise_uncaught_exception
    raise exc
  File "/home/rushikeshkadam/code_space/videoView/server/venv/lib/python3.10/site-packages/rest_framework/views.py", line 506, in dispatch
    response = handler(request, *args, **kwargs)
  File "/home/rushikeshkadam/code_space/videoView/server/venv/lib/python3.10/site-packages/rest_framework/decorators.py", line 50, in handler
    return func(*args, **kwargs)
  File "/home/rushikeshkadam/code_space/videoView/server/videoView/api/Views/VideoView.py", line 43, in get_all_videos
    return Response(ApiResponse.success(200,"fetched all videos",response=serializer.data).__dict__,status=200)
  File "/home/rushikeshkadam/code_space/videoView/server/venv/lib/python3.10/site-packages/rest_framework/serializers.py", line 795, in data
    ret = super().data
  File "/home/rushikeshkadam/code_space/videoView/server/venv/lib/python3.10/site-packages/rest_framework/serializers.py", line 245, in data
    raise AssertionError(msg)
AssertionError: When a serializer is passed a `data` keyword argument you must call `.is_valid()` before attempting to access the serialized `.data` representation.
You should either call `.is_valid()` first, or access `.initial_data` instead.
ERROR 2025-01-01 14:05:27,014 log.py log log_response 248: Internal Server Error: /api/v1/get_all_videos
Traceback (most recent call last):
  File "/home/rushikeshkadam/code_space/videoView/server/venv/lib/python3.10/site-packages/django/core/handlers/exception.py", line 55, in inner
    response = get_response(request)
  File "/home/rushikeshkadam/code_space/videoView/server/venv/lib/python3.10/site-packages/django/core/handlers/base.py", line 197, in _get_response
    response = wrapped_callback(request, *callback_args, **callback_kwargs)
  File "/home/rushikeshkadam/code_space/videoView/server/venv/lib/python3.10/site-packages/django/views/decorators/csrf.py", line 65, in _view_wrapper
    return view_func(request, *args, **kwargs)
  File "/home/rushikeshkadam/code_space/videoView/server/venv/lib/python3.10/site-packages/django/views/generic/base.py", line 104, in view
    return self.dispatch(request, *args, **kwargs)
  File "/home/rushikeshkadam/code_space/videoView/server/venv/lib/python3.10/site-packages/rest_framework/views.py", line 509, in dispatch
    response = self.handle_exception(exc)
  File "/home/rushikeshkadam/code_space/videoView/server/venv/lib/python3.10/site-packages/rest_framework/views.py", line 469, in handle_exception
    self.raise_uncaught_exception(exc)
  File "/home/rushikeshkadam/code_space/videoView/server/venv/lib/python3.10/site-packages/rest_framework/views.py", line 480, in raise_uncaught_exception
    raise exc
  File "/home/rushikeshkadam/code_space/videoView/server/venv/lib/python3.10/site-packages/rest_framework/views.py", line 506, in dispatch
    response = handler(request, *args, **kwargs)
  File "/home/rushikeshkadam/code_space/videoView/server/venv/lib/python3.10/site-packages/rest_framework/decorators.py", line 50, in handler
    return func(*args, **kwargs)
  File "/home/rushikeshkadam/code_space/videoView/server/videoView/api/Views/VideoView.py", line 45, in get_all_videos
    return Response(ApiResponse.success(200,"fetched all videos",response=serializer.data).__dict__,status=200)
  File "/home/rushikeshkadam/code_space/videoView/server/venv/lib/python3.10/site-packages/rest_framework/serializers.py", line 795, in data
    ret = super().data
  File "/home/rushikeshkadam/code_space/videoView/server/venv/lib/python3.10/site-packages/rest_framework/serializers.py", line 245, in data
    raise AssertionError(msg)
AssertionError: When a serializer is passed a `data` keyword argument you must call `.is_valid()` before attempting to access the serialized `.data` representation.
You should either call `.is_valid()` first, or access `.initial_data` instead.
ERROR 2025-01-01 14:06:05,383 log.py log log_response 248: Internal Server Error: /api/v1/get_all_videos
Traceback (most recent call last):
  File "/home/rushikeshkadam/code_space/videoView/server/venv/lib/python3.10/site-packages/django/core/handlers/exception.py", line 55, in inner
    response = get_response(request)
  File "/home/rushikeshkadam/code_space/videoView/server/venv/lib/python3.10/site-packages/django/core/handlers/base.py", line 220, in _get_response
    response = response.render()
  File "/home/rushikeshkadam/code_space/videoView/server/venv/lib/python3.10/site-packages/django/template/response.py", line 114, in render
    self.content = self.rendered_content
  File "/home/rushikeshkadam/code_space/videoView/server/venv/lib/python3.10/site-packages/rest_framework/response.py", line 74, in rendered_content
    ret = renderer.render(self.data, accepted_media_type, context)
  File "/home/rushikeshkadam/code_space/videoView/server/venv/lib/python3.10/site-packages/rest_framework/renderers.py", line 100, in render
    ret = json.dumps(
  File "/home/rushikeshkadam/code_space/videoView/server/venv/lib/python3.10/site-packages/rest_framework/utils/json.py", line 25, in dumps
    return json.dumps(*args, **kwargs)
  File "/usr/lib/python3.10/json/__init__.py", line 238, in dumps
    **kw).encode(obj)
  File "/usr/lib/python3.10/json/encoder.py", line 199, in encode
    chunks = self.iterencode(o, _one_shot=True)
  File "/usr/lib/python3.10/json/encoder.py", line 257, in iterencode
    return _iterencode(o, 0)
  File "/home/rushikeshkadam/code_space/videoView/server/venv/lib/python3.10/site-packages/rest_framework/utils/encoders.py", line 67, in default
    return super().default(obj)
  File "/usr/lib/python3.10/json/encoder.py", line 179, in default
    raise TypeError(f'Object of type {o.__class__.__name__} '
TypeError: Object of type Videos is not JSON serializable
ERROR 2025-01-01 14:06:58,123 log.py log log_response 248: Internal Server Error: /api/v1/get_all_videos
Traceback (most recent call last):
  File "/home/rushikeshkadam/code_space/videoView/server/venv/lib/python3.10/site-packages/django/core/handlers/exception.py", line 55, in inner
    response = get_response(request)
  File "/home/rushikeshkadam/code_space/videoView/server/venv/lib/python3.10/site-packages/django/core/handlers/base.py", line 197, in _get_response
    response = wrapped_callback(request, *callback_args, **callback_kwargs)
  File "/home/rushikeshkadam/code_space/videoView/server/venv/lib/python3.10/site-packages/django/views/decorators/csrf.py", line 65, in _view_wrapper
    return view_func(request, *args, **kwargs)
  File "/home/rushikeshkadam/code_space/videoView/server/venv/lib/python3.10/site-packages/django/views/generic/base.py", line 104, in view
    return self.dispatch(request, *args, **kwargs)
  File "/home/rushikeshkadam/code_space/videoView/server/venv/lib/python3.10/site-packages/rest_framework/views.py", line 509, in dispatch
    response = self.handle_exception(exc)
  File "/home/rushikeshkadam/code_space/videoView/server/venv/lib/python3.10/site-packages/rest_framework/views.py", line 469, in handle_exception
    self.raise_uncaught_exception(exc)
  File "/home/rushikeshkadam/code_space/videoView/server/venv/lib/python3.10/site-packages/rest_framework/views.py", line 480, in raise_uncaught_exception
    raise exc
  File "/home/rushikeshkadam/code_space/videoView/server/venv/lib/python3.10/site-packages/rest_framework/views.py", line 506, in dispatch
    response = handler(request, *args, **kwargs)
  File "/home/rushikeshkadam/code_space/videoView/server/venv/lib/python3.10/site-packages/rest_framework/decorators.py", line 50, in handler
    return func(*args, **kwargs)
  File "/home/rushikeshkadam/code_space/videoView/server/videoView/api/Views/VideoView.py", line 45, in get_all_videos
    return Response(ApiResponse.success(200,"fetched all videos",response=serializer.data).__dict__,status=200)
  File "/home/rushikeshkadam/code_space/videoView/server/venv/lib/python3.10/site-packages/rest_framework/serializers.py", line 795, in data
    ret = super().data
  File "/home/rushikeshkadam/code_space/videoView/server/venv/lib/python3.10/site-packages/rest_framework/serializers.py", line 245, in data
    raise AssertionError(msg)
AssertionError: When a serializer is passed a `data` keyword argument you must call `.is_valid()` before attempting to access the serialized `.data` representation.
You should either call `.is_valid()` first, or access `.initial_data` instead.
ERROR 2025-01-01 14:10:22,089 log.py log log_response 248: Internal Server Error: /api/v1/get_all_videos
Traceback (most recent call last):
  File "/home/rushikeshkadam/code_space/videoView/server/venv/lib/python3.10/site-packages/django/core/handlers/exception.py", line 55, in inner
    response = get_response(request)
  File "/home/rushikeshkadam/code_space/videoView/server/venv/lib/python3.10/site-packages/django/core/handlers/base.py", line 197, in _get_response
    response = wrapped_callback(request, *callback_args, **callback_kwargs)
  File "/home/rushikeshkadam/code_space/videoView/server/venv/lib/python3.10/site-packages/django/views/decorators/csrf.py", line 65, in _view_wrapper
    return view_func(request, *args, **kwargs)
  File "/home/rushikeshkadam/code_space/videoView/server/venv/lib/python3.10/site-packages/django/views/generic/base.py", line 104, in view
    return self.dispatch(request, *args, **kwargs)
  File "/home/rushikeshkadam/code_space/videoView/server/venv/lib/python3.10/site-packages/rest_framework/views.py", line 509, in dispatch
    response = self.handle_exception(exc)
  File "/home/rushikeshkadam/code_space/videoView/server/venv/lib/python3.10/site-packages/rest_framework/views.py", line 469, in handle_exception
    self.raise_uncaught_exception(exc)
  File "/home/rushikeshkadam/code_space/videoView/server/venv/lib/python3.10/site-packages/rest_framework/views.py", line 480, in raise_uncaught_exception
    raise exc
  File "/home/rushikeshkadam/code_space/videoView/server/venv/lib/python3.10/site-packages/rest_framework/views.py", line 506, in dispatch
    response = handler(request, *args, **kwargs)
  File "/home/rushikeshkadam/code_space/videoView/server/venv/lib/python3.10/site-packages/rest_framework/decorators.py", line 50, in handler
    return func(*args, **kwargs)
  File "/home/rushikeshkadam/code_space/videoView/server/videoView/api/Views/VideoView.py", line 45, in get_all_videos
    return Response(ApiResponse.success(200,"fetched all videos",response=serializer.data).__dict__,status=200)
  File "/home/rushikeshkadam/code_space/videoView/server/venv/lib/python3.10/site-packages/rest_framework/serializers.py", line 571, in data
    ret = super().data
  File "/home/rushikeshkadam/code_space/videoView/server/venv/lib/python3.10/site-packages/rest_framework/serializers.py", line 253, in data
    self._data = self.get_initial()
  File "/home/rushikeshkadam/code_space/videoView/server/venv/lib/python3.10/site-packages/rest_framework/serializers.py", line 421, in get_initial
    for field in self.fields.values()
  File "/home/rushikeshkadam/code_space/videoView/server/venv/lib/python3.10/site-packages/django/utils/functional.py", line 47, in __get__
    res = instance.__dict__[self.name] = self.func(instance)
  File "/home/rushikeshkadam/code_space/videoView/server/venv/lib/python3.10/site-packages/rest_framework/serializers.py", line 372, in fields
    for key, value in self.get_fields().items():
  File "/home/rushikeshkadam/code_space/videoView/server/venv/lib/python3.10/site-packages/rest_framework/serializers.py", line 1103, in get_fields
    field_class, field_kwargs = self.build_field(
  File "/home/rushikeshkadam/code_space/videoView/server/venv/lib/python3.10/site-packages/rest_framework/serializers.py", line 1249, in build_field
    return self.build_unknown_field(field_name, model_class)
  File "/home/rushikeshkadam/code_space/videoView/server/venv/lib/python3.10/site-packages/rest_framework/serializers.py", line 1367, in build_unknown_field
    raise ImproperlyConfigured(
django.core.exceptions.ImproperlyConfigured: Field name `isPublish` is not valid for model `Videos` in `api.serializer.AllVideoSerializer`.
ERROR 2025-01-01 14:11:03,222 log.py log log_response 248: Internal Server Error: /api/v1/get_all_videos
Traceback (most recent call last):
  File "/home/rushikeshkadam/code_space/videoView/server/venv/lib/python3.10/site-packages/django/core/handlers/exception.py", line 55, in inner
    response = get_response(request)
  File "/home/rushikeshkadam/code_space/videoView/server/venv/lib/python3.10/site-packages/django/core/handlers/base.py", line 197, in _get_response
    response = wrapped_callback(request, *callback_args, **callback_kwargs)
  File "/home/rushikeshkadam/code_space/videoView/server/venv/lib/python3.10/site-packages/django/views/decorators/csrf.py", line 65, in _view_wrapper
    return view_func(request, *args, **kwargs)
  File "/home/rushikeshkadam/code_space/videoView/server/venv/lib/python3.10/site-packages/django/views/generic/base.py", line 104, in view
    return self.dispatch(request, *args, **kwargs)
  File "/home/rushikeshkadam/code_space/videoView/server/venv/lib/python3.10/site-packages/rest_framework/views.py", line 509, in dispatch
    response = self.handle_exception(exc)
  File "/home/rushikeshkadam/code_space/videoView/server/venv/lib/python3.10/site-packages/rest_framework/views.py", line 469, in handle_exception
    self.raise_uncaught_exception(exc)
  File "/home/rushikeshkadam/code_space/videoView/server/venv/lib/python3.10/site-packages/rest_framework/views.py", line 480, in raise_uncaught_exception
    raise exc
  File "/home/rushikeshkadam/code_space/videoView/server/venv/lib/python3.10/site-packages/rest_framework/views.py", line 506, in dispatch
    response = handler(request, *args, **kwargs)
  File "/home/rushikeshkadam/code_space/videoView/server/venv/lib/python3.10/site-packages/rest_framework/decorators.py", line 50, in handler
    return func(*args, **kwargs)
  File "/home/rushikeshkadam/code_space/videoView/server/videoView/api/Views/VideoView.py", line 45, in get_all_videos
    return Response(ApiResponse.success(200,"fetched all videos",response=serializer.data).__dict__,status=200)
  File "/home/rushikeshkadam/code_space/videoView/server/venv/lib/python3.10/site-packages/rest_framework/serializers.py", line 795, in data
    ret = super().data
  File "/home/rushikeshkadam/code_space/videoView/server/venv/lib/python3.10/site-packages/rest_framework/serializers.py", line 249, in data
    self._data = self.to_representation(self.instance)
  File "/home/rushikeshkadam/code_space/videoView/server/venv/lib/python3.10/site-packages/rest_framework/serializers.py", line 713, in to_representation
    return [
  File "/home/rushikeshkadam/code_space/videoView/server/venv/lib/python3.10/site-packages/rest_framework/serializers.py", line 714, in <listcomp>
    self.child.to_representation(item) for item in iterable
  File "/home/rushikeshkadam/code_space/videoView/server/venv/lib/python3.10/site-packages/rest_framework/serializers.py", line 523, in to_representation
    for field in fields:
  File "/home/rushikeshkadam/code_space/videoView/server/venv/lib/python3.10/site-packages/rest_framework/serializers.py", line 384, in _readable_fields
    for field in self.fields.values():
  File "/home/rushikeshkadam/code_space/videoView/server/venv/lib/python3.10/site-packages/django/utils/functional.py", line 47, in __get__
    res = instance.__dict__[self.name] = self.func(instance)
  File "/home/rushikeshkadam/code_space/videoView/server/venv/lib/python3.10/site-packages/rest_framework/serializers.py", line 372, in fields
    for key, value in self.get_fields().items():
  File "/home/rushikeshkadam/code_space/videoView/server/venv/lib/python3.10/site-packages/rest_framework/serializers.py", line 1103, in get_fields
    field_class, field_kwargs = self.build_field(
  File "/home/rushikeshkadam/code_space/videoView/server/venv/lib/python3.10/site-packages/rest_framework/serializers.py", line 1249, in build_field
    return self.build_unknown_field(field_name, model_class)
  File "/home/rushikeshkadam/code_space/videoView/server/venv/lib/python3.10/site-packages/rest_framework/serializers.py", line 1367, in build_unknown_field
    raise ImproperlyConfigured(
django.core.exceptions.ImproperlyConfigured: Field name `isPublish` is not valid for model `Videos` in `api.serializer.AllVideoSerializer`.
ERROR 2025-01-01 14:20:30,271 log.py log log_response 248: Internal Server Error: /api/v1/get_all_videos
Traceback (most recent call last):
  File "/home/rushikeshkadam/code_space/videoView/server/venv/lib/python3.10/site-packages/django/core/handlers/exception.py", line 55, in inner
    response = get_response(request)
  File "/home/rushikeshkadam/code_space/videoView/server/venv/lib/python3.10/site-packages/django/core/handlers/base.py", line 197, in _get_response
    response = wrapped_callback(request, *callback_args, **callback_kwargs)
  File "/home/rushikeshkadam/code_space/videoView/server/venv/lib/python3.10/site-packages/django/views/decorators/csrf.py", line 65, in _view_wrapper
    return view_func(request, *args, **kwargs)
  File "/home/rushikeshkadam/code_space/videoView/server/venv/lib/python3.10/site-packages/django/views/generic/base.py", line 104, in view
    return self.dispatch(request, *args, **kwargs)
  File "/home/rushikeshkadam/code_space/videoView/server/venv/lib/python3.10/site-packages/rest_framework/views.py", line 509, in dispatch
    response = self.handle_exception(exc)
  File "/home/rushikeshkadam/code_space/videoView/server/venv/lib/python3.10/site-packages/rest_framework/views.py", line 469, in handle_exception
    self.raise_uncaught_exception(exc)
  File "/home/rushikeshkadam/code_space/videoView/server/venv/lib/python3.10/site-packages/rest_framework/views.py", line 480, in raise_uncaught_exception
    raise exc
  File "/home/rushikeshkadam/code_space/videoView/server/venv/lib/python3.10/site-packages/rest_framework/views.py", line 506, in dispatch
    response = handler(request, *args, **kwargs)
  File "/home/rushikeshkadam/code_space/videoView/server/venv/lib/python3.10/site-packages/rest_framework/decorators.py", line 50, in handler
    return func(*args, **kwargs)
  File "/home/rushikeshkadam/code_space/videoView/server/videoView/api/Views/VideoView.py", line 45, in get_all_videos
    return Response(ApiResponse.success(200,"fetched all videos",response=serializer.data).__dict__,status=200)
  File "/home/rushikeshkadam/code_space/videoView/server/venv/lib/python3.10/site-packages/rest_framework/serializers.py", line 795, in data
    ret = super().data
  File "/home/rushikeshkadam/code_space/videoView/server/venv/lib/python3.10/site-packages/rest_framework/serializers.py", line 249, in data
    self._data = self.to_representation(self.instance)
  File "/home/rushikeshkadam/code_space/videoView/server/venv/lib/python3.10/site-packages/rest_framework/serializers.py", line 713, in to_representation
    return [
  File "/home/rushikeshkadam/code_space/videoView/server/venv/lib/python3.10/site-packages/rest_framework/serializers.py", line 714, in <listcomp>
    self.child.to_representation(item) for item in iterable
  File "/home/rushikeshkadam/code_space/videoView/server/venv/lib/python3.10/site-packages/rest_framework/serializers.py", line 538, in to_representation
    ret[field.field_name] = field.to_representation(attribute)
  File "/home/rushikeshkadam/code_space/videoView/server/venv/lib/python3.10/site-packages/rest_framework/serializers.py", line 523, in to_representation
    for field in fields:
  File "/home/rushikeshkadam/code_space/videoView/server/venv/lib/python3.10/site-packages/rest_framework/serializers.py", line 384, in _readable_fields
    for field in self.fields.values():
  File "/home/rushikeshkadam/code_space/videoView/server/venv/lib/python3.10/site-packages/django/utils/functional.py", line 47, in __get__
    res = instance.__dict__[self.name] = self.func(instance)
  File "/home/rushikeshkadam/code_space/videoView/server/venv/lib/python3.10/site-packages/rest_framework/serializers.py", line 372, in fields
    for key, value in self.get_fields().items():
  File "/home/rushikeshkadam/code_space/videoView/server/venv/lib/python3.10/site-packages/rest_framework/serializers.py", line 1103, in get_fields
    field_class, field_kwargs = self.build_field(
  File "/home/rushikeshkadam/code_space/videoView/server/venv/lib/python3.10/site-packages/rest_framework/serializers.py", line 1249, in build_field
    return self.build_unknown_field(field_name, model_class)
  File "/home/rushikeshkadam/code_space/videoView/server/venv/lib/python3.10/site-packages/rest_framework/serializers.py", line 1367, in build_unknown_field
    raise ImproperlyConfigured(
django.core.exceptions.ImproperlyConfigured: Field name `username` is not valid for model `Users` in `api.serializer.UserSerializer`.
ERROR 2025-01-01 14:32:46,404 log.py log log_response 248: Internal Server Error: /api/v1/get_all_videos
Traceback (most recent call last):
  File "/home/rushikeshkadam/code_space/videoView/server/venv/lib/python3.10/site-packages/django/core/handlers/exception.py", line 55, in inner
    response = get_response(request)
  File "/home/rushikeshkadam/code_space/videoView/server/venv/lib/python3.10/site-packages/django/core/handlers/base.py", line 220, in _get_response
    response = response.render()
  File "/home/rushikeshkadam/code_space/videoView/server/venv/lib/python3.10/site-packages/django/template/response.py", line 114, in render
    self.content = self.rendered_content
  File "/home/rushikeshkadam/code_space/videoView/server/venv/lib/python3.10/site-packages/rest_framework/response.py", line 74, in rendered_content
    ret = renderer.render(self.data, accepted_media_type, context)
  File "/home/rushikeshkadam/code_space/videoView/server/venv/lib/python3.10/site-packages/rest_framework/renderers.py", line 100, in render
    ret = json.dumps(
  File "/home/rushikeshkadam/code_space/videoView/server/venv/lib/python3.10/site-packages/rest_framework/utils/json.py", line 25, in dumps
    return json.dumps(*args, **kwargs)
  File "/usr/lib/python3.10/json/__init__.py", line 238, in dumps
    **kw).encode(obj)
  File "/usr/lib/python3.10/json/encoder.py", line 199, in encode
    chunks = self.iterencode(o, _one_shot=True)
  File "/usr/lib/python3.10/json/encoder.py", line 257, in iterencode
    return _iterencode(o, 0)
  File "/home/rushikeshkadam/code_space/videoView/server/venv/lib/python3.10/site-packages/rest_framework/utils/encoders.py", line 67, in default
    return super().default(obj)
  File "/usr/lib/python3.10/json/encoder.py", line 179, in default
    raise TypeError(f'Object of type {o.__class__.__name__} '
TypeError: Object of type ApiResponse is not JSON serializable
WARNING 2025-01-12 06:36:13,109 log.py log log_response 248: Not Found: /api/v1/get_all_video/:id
WARNING 2025-01-12 06:36:24,901 log.py log log_response 248: Not Found: /api/v1/get_all_video
WARNING 2025-01-12 06:36:27,987 log.py log log_response 248: Not Found: /api/v1/get_all_video
ERROR 2025-01-12 06:37:12,352 log.py log log_response 248: Internal Server Error: /api/v1/get_video_by_videoId/600ac1bb-4047-40a2-8aa3-bb4135870516
Traceback (most recent call last):
  File "/home/rushikeshkadam/code_space/videoView/server/venv/lib/python3.10/site-packages/django/core/handlers/exception.py", line 55, in inner
    response = get_response(request)
  File "/home/rushikeshkadam/code_space/videoView/server/venv/lib/python3.10/site-packages/django/core/handlers/base.py", line 197, in _get_response
    response = wrapped_callback(request, *callback_args, **callback_kwargs)
  File "/home/rushikeshkadam/code_space/videoView/server/venv/lib/python3.10/site-packages/django/views/decorators/csrf.py", line 65, in _view_wrapper
    return view_func(request, *args, **kwargs)
  File "/home/rushikeshkadam/code_space/videoView/server/venv/lib/python3.10/site-packages/django/views/generic/base.py", line 104, in view
    return self.dispatch(request, *args, **kwargs)
  File "/home/rushikeshkadam/code_space/videoView/server/venv/lib/python3.10/site-packages/rest_framework/views.py", line 509, in dispatch
    response = self.handle_exception(exc)
  File "/home/rushikeshkadam/code_space/videoView/server/venv/lib/python3.10/site-packages/rest_framework/views.py", line 469, in handle_exception
    self.raise_uncaught_exception(exc)
  File "/home/rushikeshkadam/code_space/videoView/server/venv/lib/python3.10/site-packages/rest_framework/views.py", line 480, in raise_uncaught_exception
    raise exc
  File "/home/rushikeshkadam/code_space/videoView/server/venv/lib/python3.10/site-packages/rest_framework/views.py", line 506, in dispatch
    response = handler(request, *args, **kwargs)
  File "/home/rushikeshkadam/code_space/videoView/server/venv/lib/python3.10/site-packages/rest_framework/decorators.py", line 50, in handler
    return func(*args, **kwargs)
TypeError: get_video_by_videoId() got an unexpected keyword argument 'id'
ERROR 2025-01-12 06:37:59,785 log.py log log_response 248: Internal Server Error: /api/v1/get_video_by_videoId/600ac1bb-4047-40a2-8aa3-bb4135870516
Traceback (most recent call last):
  File "/home/rushikeshkadam/code_space/videoView/server/venv/lib/python3.10/site-packages/django/core/handlers/exception.py", line 55, in inner
    response = get_response(request)
  File "/home/rushikeshkadam/code_space/videoView/server/venv/lib/python3.10/site-packages/django/core/handlers/base.py", line 197, in _get_response
    response = wrapped_callback(request, *callback_args, **callback_kwargs)
  File "/home/rushikeshkadam/code_space/videoView/server/venv/lib/python3.10/site-packages/django/views/decorators/csrf.py", line 65, in _view_wrapper
    return view_func(request, *args, **kwargs)
  File "/home/rushikeshkadam/code_space/videoView/server/venv/lib/python3.10/site-packages/django/views/generic/base.py", line 104, in view
    return self.dispatch(request, *args, **kwargs)
  File "/home/rushikeshkadam/code_space/videoView/server/venv/lib/python3.10/site-packages/rest_framework/views.py", line 509, in dispatch
    response = self.handle_exception(exc)
  File "/home/rushikeshkadam/code_space/videoView/server/venv/lib/python3.10/site-packages/rest_framework/views.py", line 469, in handle_exception
    self.raise_uncaught_exception(exc)
  File "/home/rushikeshkadam/code_space/videoView/server/venv/lib/python3.10/site-packages/rest_framework/views.py", line 480, in raise_uncaught_exception
    raise exc
  File "/home/rushikeshkadam/code_space/videoView/server/venv/lib/python3.10/site-packages/rest_framework/views.py", line 506, in dispatch
    response = handler(request, *args, **kwargs)
  File "/home/rushikeshkadam/code_space/videoView/server/venv/lib/python3.10/site-packages/rest_framework/decorators.py", line 50, in handler
    return func(*args, **kwargs)
TypeError: get_video_by_videoId() got an unexpected keyword argument 'id'
ERROR 2025-01-12 06:38:04,318 log.py log log_response 248: Internal Server Error: /api/v1/get_video_by_videoId/600ac1bb-4047-40a2-8aa3-bb4135870516
Traceback (most recent call last):
  File "/home/rushikeshkadam/code_space/videoView/server/venv/lib/python3.10/site-packages/django/core/handlers/exception.py", line 55, in inner
    response = get_response(request)
  File "/home/rushikeshkadam/code_space/videoView/server/venv/lib/python3.10/site-packages/django/core/handlers/base.py", line 197, in _get_response
    response = wrapped_callback(request, *callback_args, **callback_kwargs)
  File "/home/rushikeshkadam/code_space/videoView/server/venv/lib/python3.10/site-packages/django/views/decorators/csrf.py", line 65, in _view_wrapper
    return view_func(request, *args, **kwargs)
  File "/home/rushikeshkadam/code_space/videoView/server/venv/lib/python3.10/site-packages/django/views/generic/base.py", line 104, in view
    return self.dispatch(request, *args, **kwargs)
  File "/home/rushikeshkadam/code_space/videoView/server/venv/lib/python3.10/site-packages/rest_framework/views.py", line 509, in dispatch
    response = self.handle_exception(exc)
  File "/home/rushikeshkadam/code_space/videoView/server/venv/lib/python3.10/site-packages/rest_framework/views.py", line 469, in handle_exception
    self.raise_uncaught_exception(exc)
  File "/home/rushikeshkadam/code_space/videoView/server/venv/lib/python3.10/site-packages/rest_framework/views.py", line 480, in raise_uncaught_exception
    raise exc
  File "/home/rushikeshkadam/code_space/videoView/server/venv/lib/python3.10/site-packages/rest_framework/views.py", line 506, in dispatch
    response = handler(request, *args, **kwargs)
  File "/home/rushikeshkadam/code_space/videoView/server/venv/lib/python3.10/site-packages/rest_framework/decorators.py", line 50, in handler
    return func(*args, **kwargs)
TypeError: get_video_by_videoId() got an unexpected keyword argument 'id'
ERROR 2025-01-12 06:38:06,445 log.py log log_response 248: Internal Server Error: /api/v1/get_video_by_videoId/600ac1bb-4047-40a2-8aa3-bb4135870516
Traceback (most recent call last):
  File "/home/rushikeshkadam/code_space/videoView/server/venv/lib/python3.10/site-packages/django/core/handlers/exception.py", line 55, in inner
    response = get_response(request)
  File "/home/rushikeshkadam/code_space/videoView/server/venv/lib/python3.10/site-packages/django/core/handlers/base.py", line 197, in _get_response
    response = wrapped_callback(request, *callback_args, **callback_kwargs)
  File "/home/rushikeshkadam/code_space/videoView/server/venv/lib/python3.10/site-packages/django/views/decorators/csrf.py", line 65, in _view_wrapper
    return view_func(request, *args, **kwargs)
  File "/home/rushikeshkadam/code_space/videoView/server/venv/lib/python3.10/site-packages/django/views/generic/base.py", line 104, in view
    return self.dispatch(request, *args, **kwargs)
  File "/home/rushikeshkadam/code_space/videoView/server/venv/lib/python3.10/site-packages/rest_framework/views.py", line 509, in dispatch
    response = self.handle_exception(exc)
  File "/home/rushikeshkadam/code_space/videoView/server/venv/lib/python3.10/site-packages/rest_framework/views.py", line 469, in handle_exception
    self.raise_uncaught_exception(exc)
  File "/home/rushikeshkadam/code_space/videoView/server/venv/lib/python3.10/site-packages/rest_framework/views.py", line 480, in raise_uncaught_exception
    raise exc
  File "/home/rushikeshkadam/code_space/videoView/server/venv/lib/python3.10/site-packages/rest_framework/views.py", line 506, in dispatch
    response = handler(request, *args, **kwargs)
  File "/home/rushikeshkadam/code_space/videoView/server/venv/lib/python3.10/site-packages/rest_framework/decorators.py", line 50, in handler
    return func(*args, **kwargs)
TypeError: get_video_by_videoId() got an unexpected keyword argument 'id'
ERROR 2025-01-12 06:40:03,199 log.py log log_response 248: Internal Server Error: /api/v1/get_video_by_videoId/600ac1bb-4047-40a2-8aa3-bb4135870516/
Traceback (most recent call last):
  File "/home/rushikeshkadam/code_space/videoView/server/venv/lib/python3.10/site-packages/django/core/handlers/exception.py", line 55, in inner
    response = get_response(request)
  File "/home/rushikeshkadam/code_space/videoView/server/venv/lib/python3.10/site-packages/django/core/handlers/base.py", line 197, in _get_response
    response = wrapped_callback(request, *callback_args, **callback_kwargs)
  File "/home/rushikeshkadam/code_space/videoView/server/venv/lib/python3.10/site-packages/django/views/decorators/csrf.py", line 65, in _view_wrapper
    return view_func(request, *args, **kwargs)
  File "/home/rushikeshkadam/code_space/videoView/server/venv/lib/python3.10/site-packages/django/views/generic/base.py", line 104, in view
    return self.dispatch(request, *args, **kwargs)
  File "/home/rushikeshkadam/code_space/videoView/server/venv/lib/python3.10/site-packages/rest_framework/views.py", line 509, in dispatch
    response = self.handle_exception(exc)
  File "/home/rushikeshkadam/code_space/videoView/server/venv/lib/python3.10/site-packages/rest_framework/views.py", line 469, in handle_exception
    self.raise_uncaught_exception(exc)
  File "/home/rushikeshkadam/code_space/videoView/server/venv/lib/python3.10/site-packages/rest_framework/views.py", line 480, in raise_uncaught_exception
    raise exc
  File "/home/rushikeshkadam/code_space/videoView/server/venv/lib/python3.10/site-packages/rest_framework/views.py", line 506, in dispatch
    response = handler(request, *args, **kwargs)
  File "/home/rushikeshkadam/code_space/videoView/server/venv/lib/python3.10/site-packages/rest_framework/decorators.py", line 50, in handler
    return func(*args, **kwargs)
TypeError: get_video_by_videoId() got an unexpected keyword argument 'id'
ERROR 2025-01-12 06:41:34,911 log.py log log_response 248: Internal Server Error: /api/v1/get_video_by_videoId/600ac1bb-4047-40a2-8aa3-bb4135870516/
Traceback (most recent call last):
  File "/home/rushikeshkadam/code_space/videoView/server/venv/lib/python3.10/site-packages/django/core/handlers/exception.py", line 55, in inner
    response = get_response(request)
  File "/home/rushikeshkadam/code_space/videoView/server/venv/lib/python3.10/site-packages/django/core/handlers/base.py", line 220, in _get_response
    response = response.render()
  File "/home/rushikeshkadam/code_space/videoView/server/venv/lib/python3.10/site-packages/django/template/response.py", line 114, in render
    self.content = self.rendered_content
  File "/home/rushikeshkadam/code_space/videoView/server/venv/lib/python3.10/site-packages/rest_framework/response.py", line 74, in rendered_content
    ret = renderer.render(self.data, accepted_media_type, context)
  File "/home/rushikeshkadam/code_space/videoView/server/venv/lib/python3.10/site-packages/rest_framework/renderers.py", line 100, in render
    ret = json.dumps(
  File "/home/rushikeshkadam/code_space/videoView/server/venv/lib/python3.10/site-packages/rest_framework/utils/json.py", line 25, in dumps
    return json.dumps(*args, **kwargs)
  File "/usr/lib/python3.10/json/__init__.py", line 238, in dumps
    **kw).encode(obj)
  File "/usr/lib/python3.10/json/encoder.py", line 199, in encode
    chunks = self.iterencode(o, _one_shot=True)
  File "/usr/lib/python3.10/json/encoder.py", line 257, in iterencode
    return _iterencode(o, 0)
  File "/home/rushikeshkadam/code_space/videoView/server/venv/lib/python3.10/site-packages/rest_framework/utils/encoders.py", line 67, in default
    return super().default(obj)
  File "/usr/lib/python3.10/json/encoder.py", line 179, in default
    raise TypeError(f'Object of type {o.__class__.__name__} '
TypeError: Object of type Videos is not JSON serializable
ERROR 2025-01-12 06:42:27,259 log.py log log_response 248: Internal Server Error: /api/v1/get_video_by_videoId/600ac1bb-4047-40a2-8aa3-bb4135870516/
Traceback (most recent call last):
  File "/home/rushikeshkadam/code_space/videoView/server/venv/lib/python3.10/site-packages/django/core/handlers/exception.py", line 55, in inner
    response = get_response(request)
  File "/home/rushikeshkadam/code_space/videoView/server/venv/lib/python3.10/site-packages/django/core/handlers/base.py", line 220, in _get_response
    response = response.render()
  File "/home/rushikeshkadam/code_space/videoView/server/venv/lib/python3.10/site-packages/django/template/response.py", line 114, in render
    self.content = self.rendered_content
  File "/home/rushikeshkadam/code_space/videoView/server/venv/lib/python3.10/site-packages/rest_framework/response.py", line 74, in rendered_content
    ret = renderer.render(self.data, accepted_media_type, context)
  File "/home/rushikeshkadam/code_space/videoView/server/venv/lib/python3.10/site-packages/rest_framework/renderers.py", line 100, in render
    ret = json.dumps(
  File "/home/rushikeshkadam/code_space/videoView/server/venv/lib/python3.10/site-packages/rest_framework/utils/json.py", line 25, in dumps
    return json.dumps(*args, **kwargs)
  File "/usr/lib/python3.10/json/__init__.py", line 238, in dumps
    **kw).encode(obj)
  File "/usr/lib/python3.10/json/encoder.py", line 199, in encode
    chunks = self.iterencode(o, _one_shot=True)
  File "/usr/lib/python3.10/json/encoder.py", line 257, in iterencode
    return _iterencode(o, 0)
  File "/home/rushikeshkadam/code_space/videoView/server/venv/lib/python3.10/site-packages/rest_framework/utils/encoders.py", line 67, in default
    return super().default(obj)
  File "/usr/lib/python3.10/json/encoder.py", line 179, in default
    raise TypeError(f'Object of type {o.__class__.__name__} '
TypeError: Object of type ApiResponse is not JSON serializable
ERROR 2025-01-12 06:46:14,373 log.py log log_response 248: Internal Server Error: /api/v1/get_video_by_videoId/600ac1bb-4047-40a2-aa3-bb4135870516/
Traceback (most recent call last):
  File "/home/rushikeshkadam/code_space/videoView/server/venv/lib/python3.10/site-packages/django/db/models/fields/__init__.py", line 2761, in to_python
    return uuid.UUID(**{input_form: value})
  File "/usr/lib/python3.10/uuid.py", line 177, in __init__
    raise ValueError('badly formed hexadecimal UUID string')
ValueError: badly formed hexadecimal UUID string

During handling of the above exception, another exception occurred:

Traceback (most recent call last):
  File "/home/rushikeshkadam/code_space/videoView/server/venv/lib/python3.10/site-packages/django/core/handlers/exception.py", line 55, in inner
    response = get_response(request)
  File "/home/rushikeshkadam/code_space/videoView/server/venv/lib/python3.10/site-packages/django/core/handlers/base.py", line 197, in _get_response
    response = wrapped_callback(request, *callback_args, **callback_kwargs)
  File "/home/rushikeshkadam/code_space/videoView/server/venv/lib/python3.10/site-packages/django/views/decorators/csrf.py", line 65, in _view_wrapper
    return view_func(request, *args, **kwargs)
  File "/home/rushikeshkadam/code_space/videoView/server/venv/lib/python3.10/site-packages/django/views/generic/base.py", line 104, in view
    return self.dispatch(request, *args, **kwargs)
  File "/home/rushikeshkadam/code_space/videoView/server/venv/lib/python3.10/site-packages/rest_framework/views.py", line 509, in dispatch
    response = self.handle_exception(exc)
  File "/home/rushikeshkadam/code_space/videoView/server/venv/lib/python3.10/site-packages/rest_framework/views.py", line 469, in handle_exception
    self.raise_uncaught_exception(exc)
  File "/home/rushikeshkadam/code_space/videoView/server/venv/lib/python3.10/site-packages/rest_framework/views.py", line 480, in raise_uncaught_exception
    raise exc
  File "/home/rushikeshkadam/code_space/videoView/server/venv/lib/python3.10/site-packages/rest_framework/views.py", line 506, in dispatch
    response = handler(request, *args, **kwargs)
  File "/home/rushikeshkadam/code_space/videoView/server/venv/lib/python3.10/site-packages/rest_framework/decorators.py", line 50, in handler
    return func(*args, **kwargs)
  File "/home/rushikeshkadam/code_space/videoView/server/videoView/api/Views/VideoView.py", line 51, in get_video_by_videoId
    video_data=Videos.objects.get(id=id)
  File "/home/rushikeshkadam/code_space/videoView/server/venv/lib/python3.10/site-packages/django/db/models/manager.py", line 87, in manager_method
    return getattr(self.get_queryset(), name)(*args, **kwargs)
  File "/home/rushikeshkadam/code_space/videoView/server/venv/lib/python3.10/site-packages/django/db/models/query.py", line 635, in get
    clone = self._chain() if self.query.combinator else self.filter(*args, **kwargs)
  File "/home/rushikeshkadam/code_space/videoView/server/venv/lib/python3.10/site-packages/django/db/models/query.py", line 1476, in filter
    return self._filter_or_exclude(False, args, kwargs)
  File "/home/rushikeshkadam/code_space/videoView/server/venv/lib/python3.10/site-packages/django/db/models/query.py", line 1494, in _filter_or_exclude
    clone._filter_or_exclude_inplace(negate, args, kwargs)
  File "/home/rushikeshkadam/code_space/videoView/server/venv/lib/python3.10/site-packages/django/db/models/query.py", line 1501, in _filter_or_exclude_inplace
    self._query.add_q(Q(*args, **kwargs))
  File "/home/rushikeshkadam/code_space/videoView/server/venv/lib/python3.10/site-packages/django/db/models/sql/query.py", line 1609, in add_q
    clause, _ = self._add_q(q_object, self.used_aliases)
  File "/home/rushikeshkadam/code_space/videoView/server/venv/lib/python3.10/site-packages/django/db/models/sql/query.py", line 1641, in _add_q
    child_clause, needed_inner = self.build_filter(
  File "/home/rushikeshkadam/code_space/videoView/server/venv/lib/python3.10/site-packages/django/db/models/sql/query.py", line 1555, in build_filter
    condition = self.build_lookup(lookups, col, value)
  File "/home/rushikeshkadam/code_space/videoView/server/venv/lib/python3.10/site-packages/django/db/models/sql/query.py", line 1385, in build_lookup
    lookup = lookup_class(lhs, rhs)
  File "/home/rushikeshkadam/code_space/videoView/server/venv/lib/python3.10/site-packages/django/db/models/lookups.py", line 30, in __init__
    self.rhs = self.get_prep_lookup()
  File "/home/rushikeshkadam/code_space/videoView/server/venv/lib/python3.10/site-packages/django/db/models/lookups.py", line 369, in get_prep_lookup
    return super().get_prep_lookup()
  File "/home/rushikeshkadam/code_space/videoView/server/venv/lib/python3.10/site-packages/django/db/models/lookups.py", line 88, in get_prep_lookup
    return self.lhs.output_field.get_prep_value(self.rhs)
  File "/home/rushikeshkadam/code_space/videoView/server/venv/lib/python3.10/site-packages/django/db/models/fields/__init__.py", line 2745, in get_prep_value
    return self.to_python(value)
  File "/home/rushikeshkadam/code_space/videoView/server/venv/lib/python3.10/site-packages/django/db/models/fields/__init__.py", line 2763, in to_python
    raise exceptions.ValidationError(
django.core.exceptions.ValidationError: ['“600ac1bb-4047-40a2-aa3-bb4135870516” is not a valid UUID.']
DEBUG 2025-01-12 06:48:17,175 VideoView.py VideoView get_video_by_videoId 59: Error as occurred : ['“600ac1bb-4047-40a2-aa3-bb4135870516” is not a valid UUID.']
WARNING 2025-01-12 06:48:17,176 log.py log log_response 248: Unauthorized: /api/v1/get_video_by_videoId/600ac1bb-4047-40a2-aa3-bb4135870516/
