WARNING 2024-12-31 20:29:40,740 log.py log log_response 248: Method Not Allowed: /api/v1/login
DEBUG 2024-12-31 20:29:55,886 VideoView.py VideoView upload_video 34: 'Request' object has no attribute 'user_id'
ERROR 2024-12-31 20:29:55,887 log.py log log_response 248: Internal Server Error: /api/v1/upload_video
DEBUG 2024-12-31 20:30:33,364 VideoView.py VideoView upload_video 34: 'Request' object has no attribute 'user_id'
ERROR 2024-12-31 20:30:33,364 log.py log log_response 248: Internal Server Error: /api/v1/upload_video
WARNING 2024-12-31 20:33:37,856 log.py log log_response 248: Unauthorized: /api/v1/upload_video
WARNING 2024-12-31 20:40:58,799 log.py log log_response 248: Unauthorized: /api/v1/upload_video
DEBUG 2024-12-31 20:41:09,565 VideoView.py VideoView upload_video 35: 'str' object has no attribute '_meta'
ERROR 2024-12-31 20:41:09,565 log.py log log_response 248: Internal Server Error: /api/v1/upload_video
DEBUG 2024-12-31 20:43:07,580 VideoView.py VideoView upload_video 35: 'str' object has no attribute '_meta'
ERROR 2024-12-31 20:43:07,580 log.py log log_response 248: Internal Server Error: /api/v1/upload_video
DEBUG 2024-12-31 20:43:37,907 VideoView.py VideoView upload_video 35: 'str' object has no attribute '_meta'
ERROR 2024-12-31 20:43:37,907 log.py log log_response 248: Internal Server Error: /api/v1/upload_video
DEBUG 2024-12-31 20:46:07,000 VideoView.py VideoView upload_video 35: 'str' object has no attribute '_meta'
ERROR 2024-12-31 20:46:07,001 log.py log log_response 248: Internal Server Error: /api/v1/upload_video
DEBUG 2024-12-31 20:51:37,707 VideoView.py VideoView upload_video 35: 'NoneType' object has no attribute 'user_id'
ERROR 2024-12-31 20:51:37,708 log.py log log_response 248: Internal Server Error: /api/v1/upload_video
DEBUG 2024-12-31 20:52:04,966 VideoView.py VideoView upload_video 35: 'str' object has no attribute 'user_id'
ERROR 2024-12-31 20:52:04,966 log.py log log_response 248: Internal Server Error: /api/v1/upload_video
DEBUG 2024-12-31 20:52:17,392 VideoView.py VideoView upload_video 35: name 'instance' is not defined
ERROR 2024-12-31 20:52:17,393 log.py log log_response 248: Internal Server Error: /api/v1/upload_video
WARNING 2025-01-01 08:04:04,541 log.py log log_response 248: Unauthorized: /api/v1/upload_video
WARNING 2025-01-01 08:05:47,171 log.py log log_response 248: Method Not Allowed: /api/v1/login
WARNING 2025-01-01 08:06:20,567 log.py log log_response 248: Unauthorized: /api/v1/upload_video
WARNING 2025-01-01 08:11:23,970 log.py log log_response 248: Unauthorized: /api/v1/upload_video
DEBUG 2025-01-01 08:11:35,617 VideoView.py VideoView upload_video 35: name 'instance' is not defined
ERROR 2025-01-01 08:11:35,617 log.py log log_response 248: Internal Server Error: /api/v1/upload_video
DEBUG 2025-01-01 08:12:29,605 VideoView.py VideoView upload_video 35: 'TemporaryUploadedFile' object has no attribute 'get'
ERROR 2025-01-01 08:12:29,607 log.py log log_response 248: Internal Server Error: /api/v1/upload_video
DEBUG 2025-01-01 08:13:27,437 serializer.py serializer create 151: 4973185-hd_1920_1080_30fps.mp4
DEBUG 2025-01-01 08:13:28,986 VideoView.py VideoView upload_video 35: 'TemporaryUploadedFile' object has no attribute 'get'
ERROR 2025-01-01 08:13:28,988 log.py log log_response 248: Internal Server Error: /api/v1/upload_video
DEBUG 2025-01-01 08:14:53,357 serializer.py serializer create 151: 4973185-hd_1920_1080_30fps.mp4
DEBUG 2025-01-01 08:15:01,249 VideoView.py VideoView upload_video 35: NOT NULL constraint failed: api_videos.duration
ERROR 2025-01-01 08:15:01,250 log.py log log_response 248: Internal Server Error: /api/v1/upload_video
DEBUG 2025-01-01 08:15:35,585 serializer.py serializer create 151: 4973185-hd_1920_1080_30fps.mp4
DEBUG 2025-01-01 08:15:47,943 VideoView.py VideoView upload_video 35: NOT NULL constraint failed: api_videos.views
ERROR 2025-01-01 08:15:47,945 log.py log log_response 248: Internal Server Error: /api/v1/upload_video
DEBUG 2025-01-01 08:16:30,884 serializer.py serializer create 151: 4973185-hd_1920_1080_30fps.mp4
DEBUG 2025-01-01 08:16:42,421 VideoView.py VideoView upload_video 35: NOT NULL constraint failed: api_videos.isPublished
ERROR 2025-01-01 08:16:42,422 log.py log log_response 248: Internal Server Error: /api/v1/upload_video
DEBUG 2025-01-01 08:17:06,179 serializer.py serializer create 151: 4973185-hd_1920_1080_30fps.mp4
DEBUG 2025-01-01 08:17:15,704 VideoView.py VideoView upload_video 35: int() argument must be a string, a bytes-like object or a real number, not 'DeferredAttribute'
ERROR 2025-01-01 08:17:15,705 log.py log log_response 248: Internal Server Error: /api/v1/upload_video
DEBUG 2025-01-01 08:21:29,765 serializer.py serializer create 151: 4973185-hd_1920_1080_30fps.mp4
DEBUG 2025-01-01 08:21:41,614 VideoView.py VideoView upload_video 35: int() argument must be a string, a bytes-like object or a real number, not 'DeferredAttribute'
ERROR 2025-01-01 08:21:41,615 log.py log log_response 248: Internal Server Error: /api/v1/upload_video
DEBUG 2025-01-01 08:22:56,214 serializer.py serializer create 151: 4973185-hd_1920_1080_30fps.mp4
DEBUG 2025-01-01 08:23:09,288 VideoView.py VideoView upload_video 35: int() argument must be a string, a bytes-like object or a real number, not 'DeferredAttribute'
ERROR 2025-01-01 08:23:09,289 log.py log log_response 248: Internal Server Error: /api/v1/upload_video
DEBUG 2025-01-01 08:24:37,784 serializer.py serializer create 151: 4973185-hd_1920_1080_30fps.mp4
DEBUG 2025-01-01 08:24:49,948 VideoView.py VideoView upload_video 35: int() argument must be a string, a bytes-like object or a real number, not 'DeferredAttribute'
ERROR 2025-01-01 08:24:49,950 log.py log log_response 248: Internal Server Error: /api/v1/upload_video
DEBUG 2025-01-01 08:26:16,870 serializer.py serializer create 151: 4973185-hd_1920_1080_30fps.mp4
DEBUG 2025-01-01 08:26:16,872 serializer.py serializer create 153: 10
DEBUG 2025-01-01 08:26:31,909 serializer.py serializer create 151: 4973185-hd_1920_1080_30fps.mp4
DEBUG 2025-01-01 08:26:31,910 serializer.py serializer create 153: <class 'int'>
DEBUG 2025-01-01 08:26:49,126 serializer.py serializer create 151: 4973185-hd_1920_1080_30fps.mp4
DEBUG 2025-01-01 08:26:49,129 serializer.py serializer create 153: <class 'str'>
DEBUG 2025-01-01 08:27:02,195 serializer.py serializer create 151: 4973185-hd_1920_1080_30fps.mp4
DEBUG 2025-01-01 08:27:02,197 serializer.py serializer create 153: 10
DEBUG 2025-01-01 08:27:14,740 VideoView.py VideoView upload_video 35: int() argument must be a string, a bytes-like object or a real number, not 'DeferredAttribute'
ERROR 2025-01-01 08:27:14,742 log.py log log_response 248: Internal Server Error: /api/v1/upload_video
DEBUG 2025-01-01 08:32:42,255 serializer.py serializer create 151: 4973185-hd_1920_1080_30fps.mp4
DEBUG 2025-01-01 08:32:42,256 serializer.py serializer create 153: 10
DEBUG 2025-01-01 08:32:54,792 VideoView.py VideoView upload_video 35: int() argument must be a string, a bytes-like object or a real number, not 'DeferredAttribute'
ERROR 2025-01-01 08:32:54,793 log.py log log_response 248: Internal Server Error: /api/v1/upload_video
DEBUG 2025-01-01 08:33:42,915 serializer.py serializer create 151: 4973185-hd_1920_1080_30fps.mp4
DEBUG 2025-01-01 08:33:42,917 serializer.py serializer create 153: 10
DEBUG 2025-01-01 08:33:54,743 VideoView.py VideoView upload_video 35: int() argument must be a string, a bytes-like object or a real number, not 'DeferredAttribute'
ERROR 2025-01-01 08:33:54,745 log.py log log_response 248: Internal Server Error: /api/v1/upload_video
DEBUG 2025-01-01 08:36:35,906 serializer.py serializer create 151: 4973185-hd_1920_1080_30fps.mp4
DEBUG 2025-01-01 08:36:35,909 serializer.py serializer create 153: 10
ERROR 2025-01-01 09:07:57,960 log.py log log_response 248: Internal Server Error: /api/v1/signup
Traceback (most recent call last):
  File "/home/rushikeshkadam/code_space/videoView/server/venv/lib/python3.10/site-packages/django/core/handlers/exception.py", line 55, in inner
    response = get_response(request)
  File "/home/rushikeshkadam/code_space/videoView/server/venv/lib/python3.10/site-packages/django/core/handlers/base.py", line 197, in _get_response
    response = wrapped_callback(request, *callback_args, **callback_kwargs)
  File "/home/rushikeshkadam/code_space/videoView/server/venv/lib/python3.10/site-packages/django/views/decorators/csrf.py", line 65, in _view_wrapper
    return view_func(request, *args, **kwargs)
  File "/home/rushikeshkadam/code_space/videoView/server/venv/lib/python3.10/site-packages/django/views/generic/base.py", line 104, in view
    return self.dispatch(request, *args, **kwargs)
  File "/home/rushikeshkadam/code_space/videoView/server/venv/lib/python3.10/site-packages/rest_framework/views.py", line 509, in dispatch
    response = self.handle_exception(exc)
  File "/home/rushikeshkadam/code_space/videoView/server/venv/lib/python3.10/site-packages/rest_framework/views.py", line 469, in handle_exception
    self.raise_uncaught_exception(exc)
  File "/home/rushikeshkadam/code_space/videoView/server/venv/lib/python3.10/site-packages/rest_framework/views.py", line 480, in raise_uncaught_exception
    raise exc
  File "/home/rushikeshkadam/code_space/videoView/server/venv/lib/python3.10/site-packages/rest_framework/views.py", line 506, in dispatch
    response = handler(request, *args, **kwargs)
  File "/home/rushikeshkadam/code_space/videoView/server/venv/lib/python3.10/site-packages/rest_framework/decorators.py", line 50, in handler
    return func(*args, **kwargs)
  File "/home/rushikeshkadam/code_space/videoView/server/videoView/api/Views/UserViews.py", line 37, in signup
    user,token=serializer.save()
  File "/home/rushikeshkadam/code_space/videoView/server/venv/lib/python3.10/site-packages/rest_framework/serializers.py", line 208, in save
    self.instance = self.create(validated_data)
  File "/home/rushikeshkadam/code_space/videoView/server/videoView/api/serializer.py", line 43, in create
    coverImage_img=cloudinary.uploader.upload(image2)
  File "/home/rushikeshkadam/code_space/videoView/server/venv/lib/python3.10/site-packages/cloudinary/uploader.py", line 45, in upload
    return call_cacheable_api("upload", params, file=file, **options)
  File "/home/rushikeshkadam/code_space/videoView/server/venv/lib/python3.10/site-packages/cloudinary/uploader.py", line 462, in call_cacheable_api
    result = call_api(action, params, http_headers, return_error, unsigned, file, timeout, **options)
  File "/home/rushikeshkadam/code_space/videoView/server/venv/lib/python3.10/site-packages/cloudinary/uploader.py", line 527, in call_api
    raise Error(result["error"]["message"])
cloudinary.exceptions.Error: Missing required parameter - file
ERROR 2025-01-01 09:11:17,008 log.py log log_response 248: Internal Server Error: /api/v1/signup
Traceback (most recent call last):
  File "/home/rushikeshkadam/code_space/videoView/server/venv/lib/python3.10/site-packages/django/core/handlers/exception.py", line 55, in inner
    response = get_response(request)
  File "/home/rushikeshkadam/code_space/videoView/server/venv/lib/python3.10/site-packages/django/core/handlers/base.py", line 197, in _get_response
    response = wrapped_callback(request, *callback_args, **callback_kwargs)
  File "/home/rushikeshkadam/code_space/videoView/server/venv/lib/python3.10/site-packages/django/views/decorators/csrf.py", line 65, in _view_wrapper
    return view_func(request, *args, **kwargs)
  File "/home/rushikeshkadam/code_space/videoView/server/venv/lib/python3.10/site-packages/django/views/generic/base.py", line 104, in view
    return self.dispatch(request, *args, **kwargs)
  File "/home/rushikeshkadam/code_space/videoView/server/venv/lib/python3.10/site-packages/rest_framework/views.py", line 509, in dispatch
    response = self.handle_exception(exc)
  File "/home/rushikeshkadam/code_space/videoView/server/venv/lib/python3.10/site-packages/rest_framework/views.py", line 469, in handle_exception
    self.raise_uncaught_exception(exc)
  File "/home/rushikeshkadam/code_space/videoView/server/venv/lib/python3.10/site-packages/rest_framework/views.py", line 480, in raise_uncaught_exception
    raise exc
  File "/home/rushikeshkadam/code_space/videoView/server/venv/lib/python3.10/site-packages/rest_framework/views.py", line 506, in dispatch
    response = handler(request, *args, **kwargs)
  File "/home/rushikeshkadam/code_space/videoView/server/venv/lib/python3.10/site-packages/rest_framework/decorators.py", line 50, in handler
    return func(*args, **kwargs)
  File "/home/rushikeshkadam/code_space/videoView/server/videoView/api/Views/UserViews.py", line 37, in signup
    user,token=serializer.save()
  File "/home/rushikeshkadam/code_space/videoView/server/venv/lib/python3.10/site-packages/rest_framework/serializers.py", line 208, in save
    self.instance = self.create(validated_data)
  File "/home/rushikeshkadam/code_space/videoView/server/videoView/api/serializer.py", line 43, in create
    coverImage_img=cloudinary.uploader.upload(image2)
  File "/home/rushikeshkadam/code_space/videoView/server/venv/lib/python3.10/site-packages/cloudinary/uploader.py", line 45, in upload
    return call_cacheable_api("upload", params, file=file, **options)
  File "/home/rushikeshkadam/code_space/videoView/server/venv/lib/python3.10/site-packages/cloudinary/uploader.py", line 462, in call_cacheable_api
    result = call_api(action, params, http_headers, return_error, unsigned, file, timeout, **options)
  File "/home/rushikeshkadam/code_space/videoView/server/venv/lib/python3.10/site-packages/cloudinary/uploader.py", line 527, in call_api
    raise Error(result["error"]["message"])
cloudinary.exceptions.Error: Missing required parameter - file
ERROR 2025-01-01 09:14:14,624 log.py log log_response 248: Internal Server Error: /api/v1/signup
Traceback (most recent call last):
  File "/home/rushikeshkadam/code_space/videoView/server/venv/lib/python3.10/site-packages/django/core/handlers/exception.py", line 55, in inner
    response = get_response(request)
  File "/home/rushikeshkadam/code_space/videoView/server/venv/lib/python3.10/site-packages/django/core/handlers/base.py", line 197, in _get_response
    response = wrapped_callback(request, *callback_args, **callback_kwargs)
  File "/home/rushikeshkadam/code_space/videoView/server/venv/lib/python3.10/site-packages/django/views/decorators/csrf.py", line 65, in _view_wrapper
    return view_func(request, *args, **kwargs)
  File "/home/rushikeshkadam/code_space/videoView/server/venv/lib/python3.10/site-packages/django/views/generic/base.py", line 104, in view
    return self.dispatch(request, *args, **kwargs)
  File "/home/rushikeshkadam/code_space/videoView/server/venv/lib/python3.10/site-packages/rest_framework/views.py", line 509, in dispatch
    response = self.handle_exception(exc)
  File "/home/rushikeshkadam/code_space/videoView/server/venv/lib/python3.10/site-packages/rest_framework/views.py", line 469, in handle_exception
    self.raise_uncaught_exception(exc)
  File "/home/rushikeshkadam/code_space/videoView/server/venv/lib/python3.10/site-packages/rest_framework/views.py", line 480, in raise_uncaught_exception
    raise exc
  File "/home/rushikeshkadam/code_space/videoView/server/venv/lib/python3.10/site-packages/rest_framework/views.py", line 506, in dispatch
    response = handler(request, *args, **kwargs)
  File "/home/rushikeshkadam/code_space/videoView/server/venv/lib/python3.10/site-packages/rest_framework/decorators.py", line 50, in handler
    return func(*args, **kwargs)
  File "/home/rushikeshkadam/code_space/videoView/server/videoView/api/Views/UserViews.py", line 37, in signup
    user,token=serializer.save()
  File "/home/rushikeshkadam/code_space/videoView/server/venv/lib/python3.10/site-packages/rest_framework/serializers.py", line 208, in save
    self.instance = self.create(validated_data)
  File "/home/rushikeshkadam/code_space/videoView/server/videoView/api/serializer.py", line 44, in create
    coverImage_img=cloudinary.uploader.upload(image2)
  File "/home/rushikeshkadam/code_space/videoView/server/venv/lib/python3.10/site-packages/cloudinary/uploader.py", line 45, in upload
    return call_cacheable_api("upload", params, file=file, **options)
  File "/home/rushikeshkadam/code_space/videoView/server/venv/lib/python3.10/site-packages/cloudinary/uploader.py", line 462, in call_cacheable_api
    result = call_api(action, params, http_headers, return_error, unsigned, file, timeout, **options)
  File "/home/rushikeshkadam/code_space/videoView/server/venv/lib/python3.10/site-packages/cloudinary/uploader.py", line 527, in call_api
    raise Error(result["error"]["message"])
cloudinary.exceptions.Error: Missing required parameter - file
ERROR 2025-01-01 09:15:29,295 log.py log log_response 248: Internal Server Error: /api/v1/signup
Traceback (most recent call last):
  File "/home/rushikeshkadam/code_space/videoView/server/venv/lib/python3.10/site-packages/django/core/handlers/exception.py", line 55, in inner
    response = get_response(request)
  File "/home/rushikeshkadam/code_space/videoView/server/venv/lib/python3.10/site-packages/django/core/handlers/base.py", line 197, in _get_response
    response = wrapped_callback(request, *callback_args, **callback_kwargs)
  File "/home/rushikeshkadam/code_space/videoView/server/venv/lib/python3.10/site-packages/django/views/decorators/csrf.py", line 65, in _view_wrapper
    return view_func(request, *args, **kwargs)
  File "/home/rushikeshkadam/code_space/videoView/server/venv/lib/python3.10/site-packages/django/views/generic/base.py", line 104, in view
    return self.dispatch(request, *args, **kwargs)
  File "/home/rushikeshkadam/code_space/videoView/server/venv/lib/python3.10/site-packages/rest_framework/views.py", line 509, in dispatch
    response = self.handle_exception(exc)
  File "/home/rushikeshkadam/code_space/videoView/server/venv/lib/python3.10/site-packages/rest_framework/views.py", line 469, in handle_exception
    self.raise_uncaught_exception(exc)
  File "/home/rushikeshkadam/code_space/videoView/server/venv/lib/python3.10/site-packages/rest_framework/views.py", line 480, in raise_uncaught_exception
    raise exc
  File "/home/rushikeshkadam/code_space/videoView/server/venv/lib/python3.10/site-packages/rest_framework/views.py", line 506, in dispatch
    response = handler(request, *args, **kwargs)
  File "/home/rushikeshkadam/code_space/videoView/server/venv/lib/python3.10/site-packages/rest_framework/decorators.py", line 50, in handler
    return func(*args, **kwargs)
  File "/home/rushikeshkadam/code_space/videoView/server/videoView/api/Views/UserViews.py", line 37, in signup
    user,token=serializer.save()
  File "/home/rushikeshkadam/code_space/videoView/server/venv/lib/python3.10/site-packages/rest_framework/serializers.py", line 208, in save
    self.instance = self.create(validated_data)
  File "/home/rushikeshkadam/code_space/videoView/server/videoView/api/serializer.py", line 44, in create
    coverImage_img=cloudinary.uploader.upload(image2)
  File "/home/rushikeshkadam/code_space/videoView/server/venv/lib/python3.10/site-packages/cloudinary/uploader.py", line 45, in upload
    return call_cacheable_api("upload", params, file=file, **options)
  File "/home/rushikeshkadam/code_space/videoView/server/venv/lib/python3.10/site-packages/cloudinary/uploader.py", line 462, in call_cacheable_api
    result = call_api(action, params, http_headers, return_error, unsigned, file, timeout, **options)
  File "/home/rushikeshkadam/code_space/videoView/server/venv/lib/python3.10/site-packages/cloudinary/uploader.py", line 527, in call_api
    raise Error(result["error"]["message"])
cloudinary.exceptions.Error: Missing required parameter - file
ERROR 2025-01-01 09:17:04,575 log.py log log_response 248: Internal Server Error: /api/v1/signup
Traceback (most recent call last):
  File "/home/rushikeshkadam/code_space/videoView/server/venv/lib/python3.10/site-packages/django/core/handlers/exception.py", line 55, in inner
    response = get_response(request)
  File "/home/rushikeshkadam/code_space/videoView/server/venv/lib/python3.10/site-packages/django/core/handlers/base.py", line 197, in _get_response
    response = wrapped_callback(request, *callback_args, **callback_kwargs)
  File "/home/rushikeshkadam/code_space/videoView/server/venv/lib/python3.10/site-packages/django/views/decorators/csrf.py", line 65, in _view_wrapper
    return view_func(request, *args, **kwargs)
  File "/home/rushikeshkadam/code_space/videoView/server/venv/lib/python3.10/site-packages/django/views/generic/base.py", line 104, in view
    return self.dispatch(request, *args, **kwargs)
  File "/home/rushikeshkadam/code_space/videoView/server/venv/lib/python3.10/site-packages/rest_framework/views.py", line 509, in dispatch
    response = self.handle_exception(exc)
  File "/home/rushikeshkadam/code_space/videoView/server/venv/lib/python3.10/site-packages/rest_framework/views.py", line 469, in handle_exception
    self.raise_uncaught_exception(exc)
  File "/home/rushikeshkadam/code_space/videoView/server/venv/lib/python3.10/site-packages/rest_framework/views.py", line 480, in raise_uncaught_exception
    raise exc
  File "/home/rushikeshkadam/code_space/videoView/server/venv/lib/python3.10/site-packages/rest_framework/views.py", line 506, in dispatch
    response = handler(request, *args, **kwargs)
  File "/home/rushikeshkadam/code_space/videoView/server/venv/lib/python3.10/site-packages/rest_framework/decorators.py", line 50, in handler
    return func(*args, **kwargs)
  File "/home/rushikeshkadam/code_space/videoView/server/videoView/api/Views/UserViews.py", line 36, in signup
    user,token=serializer.save()
  File "/home/rushikeshkadam/code_space/videoView/server/venv/lib/python3.10/site-packages/rest_framework/serializers.py", line 208, in save
    self.instance = self.create(validated_data)
  File "/home/rushikeshkadam/code_space/videoView/server/videoView/api/serializer.py", line 54, in create
    if coverImage_img:
UnboundLocalError: local variable 'coverImage_img' referenced before assignment
WARNING 2025-01-01 09:17:25,317 log.py log log_response 248: Unauthorized: /api/v1/signup
WARNING 2025-01-01 13:52:39,733 log.py log log_response 248: Not Found: /api/v1/get_all_video
WARNING 2025-01-01 13:53:37,249 log.py log log_response 248: Method Not Allowed: /api/v1/login
WARNING 2025-01-01 13:53:49,683 log.py log log_response 248: Not Found: /api/v1/get_all_video
WARNING 2025-01-01 13:53:55,286 log.py log log_response 248: Not Found: /api/v1/get_all_video
ERROR 2025-01-01 13:54:11,699 log.py log log_response 248: Internal Server Error: /api/v1/get_all_videos
Traceback (most recent call last):
  File "/home/rushikeshkadam/code_space/videoView/server/venv/lib/python3.10/site-packages/django/core/handlers/exception.py", line 55, in inner
    response = get_response(request)
  File "/home/rushikeshkadam/code_space/videoView/server/venv/lib/python3.10/site-packages/django/core/handlers/base.py", line 220, in _get_response
    response = response.render()
  File "/home/rushikeshkadam/code_space/videoView/server/venv/lib/python3.10/site-packages/django/template/response.py", line 114, in render
    self.content = self.rendered_content
  File "/home/rushikeshkadam/code_space/videoView/server/venv/lib/python3.10/site-packages/rest_framework/response.py", line 74, in rendered_content
    ret = renderer.render(self.data, accepted_media_type, context)
  File "/home/rushikeshkadam/code_space/videoView/server/venv/lib/python3.10/site-packages/rest_framework/renderers.py", line 100, in render
    ret = json.dumps(
  File "/home/rushikeshkadam/code_space/videoView/server/venv/lib/python3.10/site-packages/rest_framework/utils/json.py", line 25, in dumps
    return json.dumps(*args, **kwargs)
  File "/usr/lib/python3.10/json/__init__.py", line 238, in dumps
    **kw).encode(obj)
  File "/usr/lib/python3.10/json/encoder.py", line 199, in encode
    chunks = self.iterencode(o, _one_shot=True)
  File "/usr/lib/python3.10/json/encoder.py", line 257, in iterencode
    return _iterencode(o, 0)
  File "/home/rushikeshkadam/code_space/videoView/server/venv/lib/python3.10/site-packages/rest_framework/utils/encoders.py", line 67, in default
    return super().default(obj)
  File "/usr/lib/python3.10/json/encoder.py", line 179, in default
    raise TypeError(f'Object of type {o.__class__.__name__} '
TypeError: Object of type ApiResponse is not JSON serializable
ERROR 2025-01-01 13:54:52,558 log.py log log_response 248: Internal Server Error: /api/v1/get_all_videos
Traceback (most recent call last):
  File "/home/rushikeshkadam/code_space/videoView/server/venv/lib/python3.10/site-packages/django/core/handlers/exception.py", line 55, in inner
    response = get_response(request)
  File "/home/rushikeshkadam/code_space/videoView/server/venv/lib/python3.10/site-packages/django/core/handlers/base.py", line 220, in _get_response
    response = response.render()
  File "/home/rushikeshkadam/code_space/videoView/server/venv/lib/python3.10/site-packages/django/template/response.py", line 114, in render
    self.content = self.rendered_content
  File "/home/rushikeshkadam/code_space/videoView/server/venv/lib/python3.10/site-packages/rest_framework/response.py", line 74, in rendered_content
    ret = renderer.render(self.data, accepted_media_type, context)
  File "/home/rushikeshkadam/code_space/videoView/server/venv/lib/python3.10/site-packages/rest_framework/renderers.py", line 100, in render
    ret = json.dumps(
  File "/home/rushikeshkadam/code_space/videoView/server/venv/lib/python3.10/site-packages/rest_framework/utils/json.py", line 25, in dumps
    return json.dumps(*args, **kwargs)
  File "/usr/lib/python3.10/json/__init__.py", line 238, in dumps
    **kw).encode(obj)
  File "/usr/lib/python3.10/json/encoder.py", line 199, in encode
    chunks = self.iterencode(o, _one_shot=True)
  File "/usr/lib/python3.10/json/encoder.py", line 257, in iterencode
    return _iterencode(o, 0)
  File "/home/rushikeshkadam/code_space/videoView/server/venv/lib/python3.10/site-packages/rest_framework/utils/encoders.py", line 67, in default
    return super().default(obj)
  File "/usr/lib/python3.10/json/encoder.py", line 179, in default
    raise TypeError(f'Object of type {o.__class__.__name__} '
TypeError: Object of type Videos is not JSON serializable
WARNING 2025-01-01 14:03:47,620 log.py log log_response 248: Not Found: /api/v1/get_all_video/:id
WARNING 2025-01-01 14:04:30,305 log.py log log_response 248: Not Found: /api/v1/get_all_video
ERROR 2025-01-01 14:04:32,033 log.py log log_response 248: Internal Server Error: /api/v1/get_all_videos
Traceback (most recent call last):
  File "/home/rushikeshkadam/code_space/videoView/server/venv/lib/python3.10/site-packages/django/core/handlers/exception.py", line 55, in inner
    response = get_response(request)
  File "/home/rushikeshkadam/code_space/videoView/server/venv/lib/python3.10/site-packages/django/core/handlers/base.py", line 197, in _get_response
    response = wrapped_callback(request, *callback_args, **callback_kwargs)
  File "/home/rushikeshkadam/code_space/videoView/server/venv/lib/python3.10/site-packages/django/views/decorators/csrf.py", line 65, in _view_wrapper
    return view_func(request, *args, **kwargs)
  File "/home/rushikeshkadam/code_space/videoView/server/venv/lib/python3.10/site-packages/django/views/generic/base.py", line 104, in view
    return self.dispatch(request, *args, **kwargs)
  File "/home/rushikeshkadam/code_space/videoView/server/venv/lib/python3.10/site-packages/rest_framework/views.py", line 509, in dispatch
    response = self.handle_exception(exc)
  File "/home/rushikeshkadam/code_space/videoView/server/venv/lib/python3.10/site-packages/rest_framework/views.py", line 469, in handle_exception
    self.raise_uncaught_exception(exc)
  File "/home/rushikeshkadam/code_space/videoView/server/venv/lib/python3.10/site-packages/rest_framework/views.py", line 480, in raise_uncaught_exception
    raise exc
  File "/home/rushikeshkadam/code_space/videoView/server/venv/lib/python3.10/site-packages/rest_framework/views.py", line 506, in dispatch
    response = handler(request, *args, **kwargs)
  File "/home/rushikeshkadam/code_space/videoView/server/venv/lib/python3.10/site-packages/rest_framework/decorators.py", line 50, in handler
    return func(*args, **kwargs)
  File "/home/rushikeshkadam/code_space/videoView/server/videoView/api/Views/VideoView.py", line 43, in get_all_videos
    return Response(ApiResponse.success(200,"fetched all videos",response=serializer.data).__dict__,status=200)
  File "/home/rushikeshkadam/code_space/videoView/server/venv/lib/python3.10/site-packages/rest_framework/serializers.py", line 795, in data
    ret = super().data
  File "/home/rushikeshkadam/code_space/videoView/server/venv/lib/python3.10/site-packages/rest_framework/serializers.py", line 245, in data
    raise AssertionError(msg)
AssertionError: When a serializer is passed a `data` keyword argument you must call `.is_valid()` before attempting to access the serialized `.data` representation.
You should either call `.is_valid()` first, or access `.initial_data` instead.
ERROR 2025-01-01 14:05:27,014 log.py log log_response 248: Internal Server Error: /api/v1/get_all_videos
Traceback (most recent call last):
  File "/home/rushikeshkadam/code_space/videoView/server/venv/lib/python3.10/site-packages/django/core/handlers/exception.py", line 55, in inner
    response = get_response(request)
  File "/home/rushikeshkadam/code_space/videoView/server/venv/lib/python3.10/site-packages/django/core/handlers/base.py", line 197, in _get_response
    response = wrapped_callback(request, *callback_args, **callback_kwargs)
  File "/home/rushikeshkadam/code_space/videoView/server/venv/lib/python3.10/site-packages/django/views/decorators/csrf.py", line 65, in _view_wrapper
    return view_func(request, *args, **kwargs)
  File "/home/rushikeshkadam/code_space/videoView/server/venv/lib/python3.10/site-packages/django/views/generic/base.py", line 104, in view
    return self.dispatch(request, *args, **kwargs)
  File "/home/rushikeshkadam/code_space/videoView/server/venv/lib/python3.10/site-packages/rest_framework/views.py", line 509, in dispatch
    response = self.handle_exception(exc)
  File "/home/rushikeshkadam/code_space/videoView/server/venv/lib/python3.10/site-packages/rest_framework/views.py", line 469, in handle_exception
    self.raise_uncaught_exception(exc)
  File "/home/rushikeshkadam/code_space/videoView/server/venv/lib/python3.10/site-packages/rest_framework/views.py", line 480, in raise_uncaught_exception
    raise exc
  File "/home/rushikeshkadam/code_space/videoView/server/venv/lib/python3.10/site-packages/rest_framework/views.py", line 506, in dispatch
    response = handler(request, *args, **kwargs)
  File "/home/rushikeshkadam/code_space/videoView/server/venv/lib/python3.10/site-packages/rest_framework/decorators.py", line 50, in handler
    return func(*args, **kwargs)
  File "/home/rushikeshkadam/code_space/videoView/server/videoView/api/Views/VideoView.py", line 45, in get_all_videos
    return Response(ApiResponse.success(200,"fetched all videos",response=serializer.data).__dict__,status=200)
  File "/home/rushikeshkadam/code_space/videoView/server/venv/lib/python3.10/site-packages/rest_framework/serializers.py", line 795, in data
    ret = super().data
  File "/home/rushikeshkadam/code_space/videoView/server/venv/lib/python3.10/site-packages/rest_framework/serializers.py", line 245, in data
    raise AssertionError(msg)
AssertionError: When a serializer is passed a `data` keyword argument you must call `.is_valid()` before attempting to access the serialized `.data` representation.
You should either call `.is_valid()` first, or access `.initial_data` instead.
ERROR 2025-01-01 14:06:05,383 log.py log log_response 248: Internal Server Error: /api/v1/get_all_videos
Traceback (most recent call last):
  File "/home/rushikeshkadam/code_space/videoView/server/venv/lib/python3.10/site-packages/django/core/handlers/exception.py", line 55, in inner
    response = get_response(request)
  File "/home/rushikeshkadam/code_space/videoView/server/venv/lib/python3.10/site-packages/django/core/handlers/base.py", line 220, in _get_response
    response = response.render()
  File "/home/rushikeshkadam/code_space/videoView/server/venv/lib/python3.10/site-packages/django/template/response.py", line 114, in render
    self.content = self.rendered_content
  File "/home/rushikeshkadam/code_space/videoView/server/venv/lib/python3.10/site-packages/rest_framework/response.py", line 74, in rendered_content
    ret = renderer.render(self.data, accepted_media_type, context)
  File "/home/rushikeshkadam/code_space/videoView/server/venv/lib/python3.10/site-packages/rest_framework/renderers.py", line 100, in render
    ret = json.dumps(
  File "/home/rushikeshkadam/code_space/videoView/server/venv/lib/python3.10/site-packages/rest_framework/utils/json.py", line 25, in dumps
    return json.dumps(*args, **kwargs)
  File "/usr/lib/python3.10/json/__init__.py", line 238, in dumps
    **kw).encode(obj)
  File "/usr/lib/python3.10/json/encoder.py", line 199, in encode
    chunks = self.iterencode(o, _one_shot=True)
  File "/usr/lib/python3.10/json/encoder.py", line 257, in iterencode
    return _iterencode(o, 0)
  File "/home/rushikeshkadam/code_space/videoView/server/venv/lib/python3.10/site-packages/rest_framework/utils/encoders.py", line 67, in default
    return super().default(obj)
  File "/usr/lib/python3.10/json/encoder.py", line 179, in default
    raise TypeError(f'Object of type {o.__class__.__name__} '
TypeError: Object of type Videos is not JSON serializable
ERROR 2025-01-01 14:06:58,123 log.py log log_response 248: Internal Server Error: /api/v1/get_all_videos
Traceback (most recent call last):
  File "/home/rushikeshkadam/code_space/videoView/server/venv/lib/python3.10/site-packages/django/core/handlers/exception.py", line 55, in inner
    response = get_response(request)
  File "/home/rushikeshkadam/code_space/videoView/server/venv/lib/python3.10/site-packages/django/core/handlers/base.py", line 197, in _get_response
    response = wrapped_callback(request, *callback_args, **callback_kwargs)
  File "/home/rushikeshkadam/code_space/videoView/server/venv/lib/python3.10/site-packages/django/views/decorators/csrf.py", line 65, in _view_wrapper
    return view_func(request, *args, **kwargs)
  File "/home/rushikeshkadam/code_space/videoView/server/venv/lib/python3.10/site-packages/django/views/generic/base.py", line 104, in view
    return self.dispatch(request, *args, **kwargs)
  File "/home/rushikeshkadam/code_space/videoView/server/venv/lib/python3.10/site-packages/rest_framework/views.py", line 509, in dispatch
    response = self.handle_exception(exc)
  File "/home/rushikeshkadam/code_space/videoView/server/venv/lib/python3.10/site-packages/rest_framework/views.py", line 469, in handle_exception
    self.raise_uncaught_exception(exc)
  File "/home/rushikeshkadam/code_space/videoView/server/venv/lib/python3.10/site-packages/rest_framework/views.py", line 480, in raise_uncaught_exception
    raise exc
  File "/home/rushikeshkadam/code_space/videoView/server/venv/lib/python3.10/site-packages/rest_framework/views.py", line 506, in dispatch
    response = handler(request, *args, **kwargs)
  File "/home/rushikeshkadam/code_space/videoView/server/venv/lib/python3.10/site-packages/rest_framework/decorators.py", line 50, in handler
    return func(*args, **kwargs)
  File "/home/rushikeshkadam/code_space/videoView/server/videoView/api/Views/VideoView.py", line 45, in get_all_videos
    return Response(ApiResponse.success(200,"fetched all videos",response=serializer.data).__dict__,status=200)
  File "/home/rushikeshkadam/code_space/videoView/server/venv/lib/python3.10/site-packages/rest_framework/serializers.py", line 795, in data
    ret = super().data
  File "/home/rushikeshkadam/code_space/videoView/server/venv/lib/python3.10/site-packages/rest_framework/serializers.py", line 245, in data
    raise AssertionError(msg)
AssertionError: When a serializer is passed a `data` keyword argument you must call `.is_valid()` before attempting to access the serialized `.data` representation.
You should either call `.is_valid()` first, or access `.initial_data` instead.
ERROR 2025-01-01 14:10:22,089 log.py log log_response 248: Internal Server Error: /api/v1/get_all_videos
Traceback (most recent call last):
  File "/home/rushikeshkadam/code_space/videoView/server/venv/lib/python3.10/site-packages/django/core/handlers/exception.py", line 55, in inner
    response = get_response(request)
  File "/home/rushikeshkadam/code_space/videoView/server/venv/lib/python3.10/site-packages/django/core/handlers/base.py", line 197, in _get_response
    response = wrapped_callback(request, *callback_args, **callback_kwargs)
  File "/home/rushikeshkadam/code_space/videoView/server/venv/lib/python3.10/site-packages/django/views/decorators/csrf.py", line 65, in _view_wrapper
    return view_func(request, *args, **kwargs)
  File "/home/rushikeshkadam/code_space/videoView/server/venv/lib/python3.10/site-packages/django/views/generic/base.py", line 104, in view
    return self.dispatch(request, *args, **kwargs)
  File "/home/rushikeshkadam/code_space/videoView/server/venv/lib/python3.10/site-packages/rest_framework/views.py", line 509, in dispatch
    response = self.handle_exception(exc)
  File "/home/rushikeshkadam/code_space/videoView/server/venv/lib/python3.10/site-packages/rest_framework/views.py", line 469, in handle_exception
    self.raise_uncaught_exception(exc)
  File "/home/rushikeshkadam/code_space/videoView/server/venv/lib/python3.10/site-packages/rest_framework/views.py", line 480, in raise_uncaught_exception
    raise exc
  File "/home/rushikeshkadam/code_space/videoView/server/venv/lib/python3.10/site-packages/rest_framework/views.py", line 506, in dispatch
    response = handler(request, *args, **kwargs)
  File "/home/rushikeshkadam/code_space/videoView/server/venv/lib/python3.10/site-packages/rest_framework/decorators.py", line 50, in handler
    return func(*args, **kwargs)
  File "/home/rushikeshkadam/code_space/videoView/server/videoView/api/Views/VideoView.py", line 45, in get_all_videos
    return Response(ApiResponse.success(200,"fetched all videos",response=serializer.data).__dict__,status=200)
  File "/home/rushikeshkadam/code_space/videoView/server/venv/lib/python3.10/site-packages/rest_framework/serializers.py", line 571, in data
    ret = super().data
  File "/home/rushikeshkadam/code_space/videoView/server/venv/lib/python3.10/site-packages/rest_framework/serializers.py", line 253, in data
    self._data = self.get_initial()
  File "/home/rushikeshkadam/code_space/videoView/server/venv/lib/python3.10/site-packages/rest_framework/serializers.py", line 421, in get_initial
    for field in self.fields.values()
  File "/home/rushikeshkadam/code_space/videoView/server/venv/lib/python3.10/site-packages/django/utils/functional.py", line 47, in __get__
    res = instance.__dict__[self.name] = self.func(instance)
  File "/home/rushikeshkadam/code_space/videoView/server/venv/lib/python3.10/site-packages/rest_framework/serializers.py", line 372, in fields
    for key, value in self.get_fields().items():
  File "/home/rushikeshkadam/code_space/videoView/server/venv/lib/python3.10/site-packages/rest_framework/serializers.py", line 1103, in get_fields
    field_class, field_kwargs = self.build_field(
  File "/home/rushikeshkadam/code_space/videoView/server/venv/lib/python3.10/site-packages/rest_framework/serializers.py", line 1249, in build_field
    return self.build_unknown_field(field_name, model_class)
  File "/home/rushikeshkadam/code_space/videoView/server/venv/lib/python3.10/site-packages/rest_framework/serializers.py", line 1367, in build_unknown_field
    raise ImproperlyConfigured(
django.core.exceptions.ImproperlyConfigured: Field name `isPublish` is not valid for model `Videos` in `api.serializer.AllVideoSerializer`.
ERROR 2025-01-01 14:11:03,222 log.py log log_response 248: Internal Server Error: /api/v1/get_all_videos
Traceback (most recent call last):
  File "/home/rushikeshkadam/code_space/videoView/server/venv/lib/python3.10/site-packages/django/core/handlers/exception.py", line 55, in inner
    response = get_response(request)
  File "/home/rushikeshkadam/code_space/videoView/server/venv/lib/python3.10/site-packages/django/core/handlers/base.py", line 197, in _get_response
    response = wrapped_callback(request, *callback_args, **callback_kwargs)
  File "/home/rushikeshkadam/code_space/videoView/server/venv/lib/python3.10/site-packages/django/views/decorators/csrf.py", line 65, in _view_wrapper
    return view_func(request, *args, **kwargs)
  File "/home/rushikeshkadam/code_space/videoView/server/venv/lib/python3.10/site-packages/django/views/generic/base.py", line 104, in view
    return self.dispatch(request, *args, **kwargs)
  File "/home/rushikeshkadam/code_space/videoView/server/venv/lib/python3.10/site-packages/rest_framework/views.py", line 509, in dispatch
    response = self.handle_exception(exc)
  File "/home/rushikeshkadam/code_space/videoView/server/venv/lib/python3.10/site-packages/rest_framework/views.py", line 469, in handle_exception
    self.raise_uncaught_exception(exc)
  File "/home/rushikeshkadam/code_space/videoView/server/venv/lib/python3.10/site-packages/rest_framework/views.py", line 480, in raise_uncaught_exception
    raise exc
  File "/home/rushikeshkadam/code_space/videoView/server/venv/lib/python3.10/site-packages/rest_framework/views.py", line 506, in dispatch
    response = handler(request, *args, **kwargs)
  File "/home/rushikeshkadam/code_space/videoView/server/venv/lib/python3.10/site-packages/rest_framework/decorators.py", line 50, in handler
    return func(*args, **kwargs)
  File "/home/rushikeshkadam/code_space/videoView/server/videoView/api/Views/VideoView.py", line 45, in get_all_videos
    return Response(ApiResponse.success(200,"fetched all videos",response=serializer.data).__dict__,status=200)
  File "/home/rushikeshkadam/code_space/videoView/server/venv/lib/python3.10/site-packages/rest_framework/serializers.py", line 795, in data
    ret = super().data
  File "/home/rushikeshkadam/code_space/videoView/server/venv/lib/python3.10/site-packages/rest_framework/serializers.py", line 249, in data
    self._data = self.to_representation(self.instance)
  File "/home/rushikeshkadam/code_space/videoView/server/venv/lib/python3.10/site-packages/rest_framework/serializers.py", line 713, in to_representation
    return [
  File "/home/rushikeshkadam/code_space/videoView/server/venv/lib/python3.10/site-packages/rest_framework/serializers.py", line 714, in <listcomp>
    self.child.to_representation(item) for item in iterable
  File "/home/rushikeshkadam/code_space/videoView/server/venv/lib/python3.10/site-packages/rest_framework/serializers.py", line 523, in to_representation
    for field in fields:
  File "/home/rushikeshkadam/code_space/videoView/server/venv/lib/python3.10/site-packages/rest_framework/serializers.py", line 384, in _readable_fields
    for field in self.fields.values():
  File "/home/rushikeshkadam/code_space/videoView/server/venv/lib/python3.10/site-packages/django/utils/functional.py", line 47, in __get__
    res = instance.__dict__[self.name] = self.func(instance)
  File "/home/rushikeshkadam/code_space/videoView/server/venv/lib/python3.10/site-packages/rest_framework/serializers.py", line 372, in fields
    for key, value in self.get_fields().items():
  File "/home/rushikeshkadam/code_space/videoView/server/venv/lib/python3.10/site-packages/rest_framework/serializers.py", line 1103, in get_fields
    field_class, field_kwargs = self.build_field(
  File "/home/rushikeshkadam/code_space/videoView/server/venv/lib/python3.10/site-packages/rest_framework/serializers.py", line 1249, in build_field
    return self.build_unknown_field(field_name, model_class)
  File "/home/rushikeshkadam/code_space/videoView/server/venv/lib/python3.10/site-packages/rest_framework/serializers.py", line 1367, in build_unknown_field
    raise ImproperlyConfigured(
django.core.exceptions.ImproperlyConfigured: Field name `isPublish` is not valid for model `Videos` in `api.serializer.AllVideoSerializer`.
ERROR 2025-01-01 14:20:30,271 log.py log log_response 248: Internal Server Error: /api/v1/get_all_videos
Traceback (most recent call last):
  File "/home/rushikeshkadam/code_space/videoView/server/venv/lib/python3.10/site-packages/django/core/handlers/exception.py", line 55, in inner
    response = get_response(request)
  File "/home/rushikeshkadam/code_space/videoView/server/venv/lib/python3.10/site-packages/django/core/handlers/base.py", line 197, in _get_response
    response = wrapped_callback(request, *callback_args, **callback_kwargs)
  File "/home/rushikeshkadam/code_space/videoView/server/venv/lib/python3.10/site-packages/django/views/decorators/csrf.py", line 65, in _view_wrapper
    return view_func(request, *args, **kwargs)
  File "/home/rushikeshkadam/code_space/videoView/server/venv/lib/python3.10/site-packages/django/views/generic/base.py", line 104, in view
    return self.dispatch(request, *args, **kwargs)
  File "/home/rushikeshkadam/code_space/videoView/server/venv/lib/python3.10/site-packages/rest_framework/views.py", line 509, in dispatch
    response = self.handle_exception(exc)
  File "/home/rushikeshkadam/code_space/videoView/server/venv/lib/python3.10/site-packages/rest_framework/views.py", line 469, in handle_exception
    self.raise_uncaught_exception(exc)
  File "/home/rushikeshkadam/code_space/videoView/server/venv/lib/python3.10/site-packages/rest_framework/views.py", line 480, in raise_uncaught_exception
    raise exc
  File "/home/rushikeshkadam/code_space/videoView/server/venv/lib/python3.10/site-packages/rest_framework/views.py", line 506, in dispatch
    response = handler(request, *args, **kwargs)
  File "/home/rushikeshkadam/code_space/videoView/server/venv/lib/python3.10/site-packages/rest_framework/decorators.py", line 50, in handler
    return func(*args, **kwargs)
  File "/home/rushikeshkadam/code_space/videoView/server/videoView/api/Views/VideoView.py", line 45, in get_all_videos
    return Response(ApiResponse.success(200,"fetched all videos",response=serializer.data).__dict__,status=200)
  File "/home/rushikeshkadam/code_space/videoView/server/venv/lib/python3.10/site-packages/rest_framework/serializers.py", line 795, in data
    ret = super().data
  File "/home/rushikeshkadam/code_space/videoView/server/venv/lib/python3.10/site-packages/rest_framework/serializers.py", line 249, in data
    self._data = self.to_representation(self.instance)
  File "/home/rushikeshkadam/code_space/videoView/server/venv/lib/python3.10/site-packages/rest_framework/serializers.py", line 713, in to_representation
    return [
  File "/home/rushikeshkadam/code_space/videoView/server/venv/lib/python3.10/site-packages/rest_framework/serializers.py", line 714, in <listcomp>
    self.child.to_representation(item) for item in iterable
  File "/home/rushikeshkadam/code_space/videoView/server/venv/lib/python3.10/site-packages/rest_framework/serializers.py", line 538, in to_representation
    ret[field.field_name] = field.to_representation(attribute)
  File "/home/rushikeshkadam/code_space/videoView/server/venv/lib/python3.10/site-packages/rest_framework/serializers.py", line 523, in to_representation
    for field in fields:
  File "/home/rushikeshkadam/code_space/videoView/server/venv/lib/python3.10/site-packages/rest_framework/serializers.py", line 384, in _readable_fields
    for field in self.fields.values():
  File "/home/rushikeshkadam/code_space/videoView/server/venv/lib/python3.10/site-packages/django/utils/functional.py", line 47, in __get__
    res = instance.__dict__[self.name] = self.func(instance)
  File "/home/rushikeshkadam/code_space/videoView/server/venv/lib/python3.10/site-packages/rest_framework/serializers.py", line 372, in fields
    for key, value in self.get_fields().items():
  File "/home/rushikeshkadam/code_space/videoView/server/venv/lib/python3.10/site-packages/rest_framework/serializers.py", line 1103, in get_fields
    field_class, field_kwargs = self.build_field(
  File "/home/rushikeshkadam/code_space/videoView/server/venv/lib/python3.10/site-packages/rest_framework/serializers.py", line 1249, in build_field
    return self.build_unknown_field(field_name, model_class)
  File "/home/rushikeshkadam/code_space/videoView/server/venv/lib/python3.10/site-packages/rest_framework/serializers.py", line 1367, in build_unknown_field
    raise ImproperlyConfigured(
django.core.exceptions.ImproperlyConfigured: Field name `username` is not valid for model `Users` in `api.serializer.UserSerializer`.
ERROR 2025-01-01 14:32:46,404 log.py log log_response 248: Internal Server Error: /api/v1/get_all_videos
Traceback (most recent call last):
  File "/home/rushikeshkadam/code_space/videoView/server/venv/lib/python3.10/site-packages/django/core/handlers/exception.py", line 55, in inner
    response = get_response(request)
  File "/home/rushikeshkadam/code_space/videoView/server/venv/lib/python3.10/site-packages/django/core/handlers/base.py", line 220, in _get_response
    response = response.render()
  File "/home/rushikeshkadam/code_space/videoView/server/venv/lib/python3.10/site-packages/django/template/response.py", line 114, in render
    self.content = self.rendered_content
  File "/home/rushikeshkadam/code_space/videoView/server/venv/lib/python3.10/site-packages/rest_framework/response.py", line 74, in rendered_content
    ret = renderer.render(self.data, accepted_media_type, context)
  File "/home/rushikeshkadam/code_space/videoView/server/venv/lib/python3.10/site-packages/rest_framework/renderers.py", line 100, in render
    ret = json.dumps(
  File "/home/rushikeshkadam/code_space/videoView/server/venv/lib/python3.10/site-packages/rest_framework/utils/json.py", line 25, in dumps
    return json.dumps(*args, **kwargs)
  File "/usr/lib/python3.10/json/__init__.py", line 238, in dumps
    **kw).encode(obj)
  File "/usr/lib/python3.10/json/encoder.py", line 199, in encode
    chunks = self.iterencode(o, _one_shot=True)
  File "/usr/lib/python3.10/json/encoder.py", line 257, in iterencode
    return _iterencode(o, 0)
  File "/home/rushikeshkadam/code_space/videoView/server/venv/lib/python3.10/site-packages/rest_framework/utils/encoders.py", line 67, in default
    return super().default(obj)
  File "/usr/lib/python3.10/json/encoder.py", line 179, in default
    raise TypeError(f'Object of type {o.__class__.__name__} '
TypeError: Object of type ApiResponse is not JSON serializable
WARNING 2025-01-12 06:36:13,109 log.py log log_response 248: Not Found: /api/v1/get_all_video/:id
WARNING 2025-01-12 06:36:24,901 log.py log log_response 248: Not Found: /api/v1/get_all_video
WARNING 2025-01-12 06:36:27,987 log.py log log_response 248: Not Found: /api/v1/get_all_video
ERROR 2025-01-12 06:37:12,352 log.py log log_response 248: Internal Server Error: /api/v1/get_video_by_videoId/600ac1bb-4047-40a2-8aa3-bb4135870516
Traceback (most recent call last):
  File "/home/rushikeshkadam/code_space/videoView/server/venv/lib/python3.10/site-packages/django/core/handlers/exception.py", line 55, in inner
    response = get_response(request)
  File "/home/rushikeshkadam/code_space/videoView/server/venv/lib/python3.10/site-packages/django/core/handlers/base.py", line 197, in _get_response
    response = wrapped_callback(request, *callback_args, **callback_kwargs)
  File "/home/rushikeshkadam/code_space/videoView/server/venv/lib/python3.10/site-packages/django/views/decorators/csrf.py", line 65, in _view_wrapper
    return view_func(request, *args, **kwargs)
  File "/home/rushikeshkadam/code_space/videoView/server/venv/lib/python3.10/site-packages/django/views/generic/base.py", line 104, in view
    return self.dispatch(request, *args, **kwargs)
  File "/home/rushikeshkadam/code_space/videoView/server/venv/lib/python3.10/site-packages/rest_framework/views.py", line 509, in dispatch
    response = self.handle_exception(exc)
  File "/home/rushikeshkadam/code_space/videoView/server/venv/lib/python3.10/site-packages/rest_framework/views.py", line 469, in handle_exception
    self.raise_uncaught_exception(exc)
  File "/home/rushikeshkadam/code_space/videoView/server/venv/lib/python3.10/site-packages/rest_framework/views.py", line 480, in raise_uncaught_exception
    raise exc
  File "/home/rushikeshkadam/code_space/videoView/server/venv/lib/python3.10/site-packages/rest_framework/views.py", line 506, in dispatch
    response = handler(request, *args, **kwargs)
  File "/home/rushikeshkadam/code_space/videoView/server/venv/lib/python3.10/site-packages/rest_framework/decorators.py", line 50, in handler
    return func(*args, **kwargs)
TypeError: get_video_by_videoId() got an unexpected keyword argument 'id'
ERROR 2025-01-12 06:37:59,785 log.py log log_response 248: Internal Server Error: /api/v1/get_video_by_videoId/600ac1bb-4047-40a2-8aa3-bb4135870516
Traceback (most recent call last):
  File "/home/rushikeshkadam/code_space/videoView/server/venv/lib/python3.10/site-packages/django/core/handlers/exception.py", line 55, in inner
    response = get_response(request)
  File "/home/rushikeshkadam/code_space/videoView/server/venv/lib/python3.10/site-packages/django/core/handlers/base.py", line 197, in _get_response
    response = wrapped_callback(request, *callback_args, **callback_kwargs)
  File "/home/rushikeshkadam/code_space/videoView/server/venv/lib/python3.10/site-packages/django/views/decorators/csrf.py", line 65, in _view_wrapper
    return view_func(request, *args, **kwargs)
  File "/home/rushikeshkadam/code_space/videoView/server/venv/lib/python3.10/site-packages/django/views/generic/base.py", line 104, in view
    return self.dispatch(request, *args, **kwargs)
  File "/home/rushikeshkadam/code_space/videoView/server/venv/lib/python3.10/site-packages/rest_framework/views.py", line 509, in dispatch
    response = self.handle_exception(exc)
  File "/home/rushikeshkadam/code_space/videoView/server/venv/lib/python3.10/site-packages/rest_framework/views.py", line 469, in handle_exception
    self.raise_uncaught_exception(exc)
  File "/home/rushikeshkadam/code_space/videoView/server/venv/lib/python3.10/site-packages/rest_framework/views.py", line 480, in raise_uncaught_exception
    raise exc
  File "/home/rushikeshkadam/code_space/videoView/server/venv/lib/python3.10/site-packages/rest_framework/views.py", line 506, in dispatch
    response = handler(request, *args, **kwargs)
  File "/home/rushikeshkadam/code_space/videoView/server/venv/lib/python3.10/site-packages/rest_framework/decorators.py", line 50, in handler
    return func(*args, **kwargs)
TypeError: get_video_by_videoId() got an unexpected keyword argument 'id'
ERROR 2025-01-12 06:38:04,318 log.py log log_response 248: Internal Server Error: /api/v1/get_video_by_videoId/600ac1bb-4047-40a2-8aa3-bb4135870516
Traceback (most recent call last):
  File "/home/rushikeshkadam/code_space/videoView/server/venv/lib/python3.10/site-packages/django/core/handlers/exception.py", line 55, in inner
    response = get_response(request)
  File "/home/rushikeshkadam/code_space/videoView/server/venv/lib/python3.10/site-packages/django/core/handlers/base.py", line 197, in _get_response
    response = wrapped_callback(request, *callback_args, **callback_kwargs)
  File "/home/rushikeshkadam/code_space/videoView/server/venv/lib/python3.10/site-packages/django/views/decorators/csrf.py", line 65, in _view_wrapper
    return view_func(request, *args, **kwargs)
  File "/home/rushikeshkadam/code_space/videoView/server/venv/lib/python3.10/site-packages/django/views/generic/base.py", line 104, in view
    return self.dispatch(request, *args, **kwargs)
  File "/home/rushikeshkadam/code_space/videoView/server/venv/lib/python3.10/site-packages/rest_framework/views.py", line 509, in dispatch
    response = self.handle_exception(exc)
  File "/home/rushikeshkadam/code_space/videoView/server/venv/lib/python3.10/site-packages/rest_framework/views.py", line 469, in handle_exception
    self.raise_uncaught_exception(exc)
  File "/home/rushikeshkadam/code_space/videoView/server/venv/lib/python3.10/site-packages/rest_framework/views.py", line 480, in raise_uncaught_exception
    raise exc
  File "/home/rushikeshkadam/code_space/videoView/server/venv/lib/python3.10/site-packages/rest_framework/views.py", line 506, in dispatch
    response = handler(request, *args, **kwargs)
  File "/home/rushikeshkadam/code_space/videoView/server/venv/lib/python3.10/site-packages/rest_framework/decorators.py", line 50, in handler
    return func(*args, **kwargs)
TypeError: get_video_by_videoId() got an unexpected keyword argument 'id'
ERROR 2025-01-12 06:38:06,445 log.py log log_response 248: Internal Server Error: /api/v1/get_video_by_videoId/600ac1bb-4047-40a2-8aa3-bb4135870516
Traceback (most recent call last):
  File "/home/rushikeshkadam/code_space/videoView/server/venv/lib/python3.10/site-packages/django/core/handlers/exception.py", line 55, in inner
    response = get_response(request)
  File "/home/rushikeshkadam/code_space/videoView/server/venv/lib/python3.10/site-packages/django/core/handlers/base.py", line 197, in _get_response
    response = wrapped_callback(request, *callback_args, **callback_kwargs)
  File "/home/rushikeshkadam/code_space/videoView/server/venv/lib/python3.10/site-packages/django/views/decorators/csrf.py", line 65, in _view_wrapper
    return view_func(request, *args, **kwargs)
  File "/home/rushikeshkadam/code_space/videoView/server/venv/lib/python3.10/site-packages/django/views/generic/base.py", line 104, in view
    return self.dispatch(request, *args, **kwargs)
  File "/home/rushikeshkadam/code_space/videoView/server/venv/lib/python3.10/site-packages/rest_framework/views.py", line 509, in dispatch
    response = self.handle_exception(exc)
  File "/home/rushikeshkadam/code_space/videoView/server/venv/lib/python3.10/site-packages/rest_framework/views.py", line 469, in handle_exception
    self.raise_uncaught_exception(exc)
  File "/home/rushikeshkadam/code_space/videoView/server/venv/lib/python3.10/site-packages/rest_framework/views.py", line 480, in raise_uncaught_exception
    raise exc
  File "/home/rushikeshkadam/code_space/videoView/server/venv/lib/python3.10/site-packages/rest_framework/views.py", line 506, in dispatch
    response = handler(request, *args, **kwargs)
  File "/home/rushikeshkadam/code_space/videoView/server/venv/lib/python3.10/site-packages/rest_framework/decorators.py", line 50, in handler
    return func(*args, **kwargs)
TypeError: get_video_by_videoId() got an unexpected keyword argument 'id'
ERROR 2025-01-12 06:40:03,199 log.py log log_response 248: Internal Server Error: /api/v1/get_video_by_videoId/600ac1bb-4047-40a2-8aa3-bb4135870516/
Traceback (most recent call last):
  File "/home/rushikeshkadam/code_space/videoView/server/venv/lib/python3.10/site-packages/django/core/handlers/exception.py", line 55, in inner
    response = get_response(request)
  File "/home/rushikeshkadam/code_space/videoView/server/venv/lib/python3.10/site-packages/django/core/handlers/base.py", line 197, in _get_response
    response = wrapped_callback(request, *callback_args, **callback_kwargs)
  File "/home/rushikeshkadam/code_space/videoView/server/venv/lib/python3.10/site-packages/django/views/decorators/csrf.py", line 65, in _view_wrapper
    return view_func(request, *args, **kwargs)
  File "/home/rushikeshkadam/code_space/videoView/server/venv/lib/python3.10/site-packages/django/views/generic/base.py", line 104, in view
    return self.dispatch(request, *args, **kwargs)
  File "/home/rushikeshkadam/code_space/videoView/server/venv/lib/python3.10/site-packages/rest_framework/views.py", line 509, in dispatch
    response = self.handle_exception(exc)
  File "/home/rushikeshkadam/code_space/videoView/server/venv/lib/python3.10/site-packages/rest_framework/views.py", line 469, in handle_exception
    self.raise_uncaught_exception(exc)
  File "/home/rushikeshkadam/code_space/videoView/server/venv/lib/python3.10/site-packages/rest_framework/views.py", line 480, in raise_uncaught_exception
    raise exc
  File "/home/rushikeshkadam/code_space/videoView/server/venv/lib/python3.10/site-packages/rest_framework/views.py", line 506, in dispatch
    response = handler(request, *args, **kwargs)
  File "/home/rushikeshkadam/code_space/videoView/server/venv/lib/python3.10/site-packages/rest_framework/decorators.py", line 50, in handler
    return func(*args, **kwargs)
TypeError: get_video_by_videoId() got an unexpected keyword argument 'id'
ERROR 2025-01-12 06:41:34,911 log.py log log_response 248: Internal Server Error: /api/v1/get_video_by_videoId/600ac1bb-4047-40a2-8aa3-bb4135870516/
Traceback (most recent call last):
  File "/home/rushikeshkadam/code_space/videoView/server/venv/lib/python3.10/site-packages/django/core/handlers/exception.py", line 55, in inner
    response = get_response(request)
  File "/home/rushikeshkadam/code_space/videoView/server/venv/lib/python3.10/site-packages/django/core/handlers/base.py", line 220, in _get_response
    response = response.render()
  File "/home/rushikeshkadam/code_space/videoView/server/venv/lib/python3.10/site-packages/django/template/response.py", line 114, in render
    self.content = self.rendered_content
  File "/home/rushikeshkadam/code_space/videoView/server/venv/lib/python3.10/site-packages/rest_framework/response.py", line 74, in rendered_content
    ret = renderer.render(self.data, accepted_media_type, context)
  File "/home/rushikeshkadam/code_space/videoView/server/venv/lib/python3.10/site-packages/rest_framework/renderers.py", line 100, in render
    ret = json.dumps(
  File "/home/rushikeshkadam/code_space/videoView/server/venv/lib/python3.10/site-packages/rest_framework/utils/json.py", line 25, in dumps
    return json.dumps(*args, **kwargs)
  File "/usr/lib/python3.10/json/__init__.py", line 238, in dumps
    **kw).encode(obj)
  File "/usr/lib/python3.10/json/encoder.py", line 199, in encode
    chunks = self.iterencode(o, _one_shot=True)
  File "/usr/lib/python3.10/json/encoder.py", line 257, in iterencode
    return _iterencode(o, 0)
  File "/home/rushikeshkadam/code_space/videoView/server/venv/lib/python3.10/site-packages/rest_framework/utils/encoders.py", line 67, in default
    return super().default(obj)
  File "/usr/lib/python3.10/json/encoder.py", line 179, in default
    raise TypeError(f'Object of type {o.__class__.__name__} '
TypeError: Object of type Videos is not JSON serializable
ERROR 2025-01-12 06:42:27,259 log.py log log_response 248: Internal Server Error: /api/v1/get_video_by_videoId/600ac1bb-4047-40a2-8aa3-bb4135870516/
Traceback (most recent call last):
  File "/home/rushikeshkadam/code_space/videoView/server/venv/lib/python3.10/site-packages/django/core/handlers/exception.py", line 55, in inner
    response = get_response(request)
  File "/home/rushikeshkadam/code_space/videoView/server/venv/lib/python3.10/site-packages/django/core/handlers/base.py", line 220, in _get_response
    response = response.render()
  File "/home/rushikeshkadam/code_space/videoView/server/venv/lib/python3.10/site-packages/django/template/response.py", line 114, in render
    self.content = self.rendered_content
  File "/home/rushikeshkadam/code_space/videoView/server/venv/lib/python3.10/site-packages/rest_framework/response.py", line 74, in rendered_content
    ret = renderer.render(self.data, accepted_media_type, context)
  File "/home/rushikeshkadam/code_space/videoView/server/venv/lib/python3.10/site-packages/rest_framework/renderers.py", line 100, in render
    ret = json.dumps(
  File "/home/rushikeshkadam/code_space/videoView/server/venv/lib/python3.10/site-packages/rest_framework/utils/json.py", line 25, in dumps
    return json.dumps(*args, **kwargs)
  File "/usr/lib/python3.10/json/__init__.py", line 238, in dumps
    **kw).encode(obj)
  File "/usr/lib/python3.10/json/encoder.py", line 199, in encode
    chunks = self.iterencode(o, _one_shot=True)
  File "/usr/lib/python3.10/json/encoder.py", line 257, in iterencode
    return _iterencode(o, 0)
  File "/home/rushikeshkadam/code_space/videoView/server/venv/lib/python3.10/site-packages/rest_framework/utils/encoders.py", line 67, in default
    return super().default(obj)
  File "/usr/lib/python3.10/json/encoder.py", line 179, in default
    raise TypeError(f'Object of type {o.__class__.__name__} '
TypeError: Object of type ApiResponse is not JSON serializable
ERROR 2025-01-12 06:46:14,373 log.py log log_response 248: Internal Server Error: /api/v1/get_video_by_videoId/600ac1bb-4047-40a2-aa3-bb4135870516/
Traceback (most recent call last):
  File "/home/rushikeshkadam/code_space/videoView/server/venv/lib/python3.10/site-packages/django/db/models/fields/__init__.py", line 2761, in to_python
    return uuid.UUID(**{input_form: value})
  File "/usr/lib/python3.10/uuid.py", line 177, in __init__
    raise ValueError('badly formed hexadecimal UUID string')
ValueError: badly formed hexadecimal UUID string

During handling of the above exception, another exception occurred:

Traceback (most recent call last):
  File "/home/rushikeshkadam/code_space/videoView/server/venv/lib/python3.10/site-packages/django/core/handlers/exception.py", line 55, in inner
    response = get_response(request)
  File "/home/rushikeshkadam/code_space/videoView/server/venv/lib/python3.10/site-packages/django/core/handlers/base.py", line 197, in _get_response
    response = wrapped_callback(request, *callback_args, **callback_kwargs)
  File "/home/rushikeshkadam/code_space/videoView/server/venv/lib/python3.10/site-packages/django/views/decorators/csrf.py", line 65, in _view_wrapper
    return view_func(request, *args, **kwargs)
  File "/home/rushikeshkadam/code_space/videoView/server/venv/lib/python3.10/site-packages/django/views/generic/base.py", line 104, in view
    return self.dispatch(request, *args, **kwargs)
  File "/home/rushikeshkadam/code_space/videoView/server/venv/lib/python3.10/site-packages/rest_framework/views.py", line 509, in dispatch
    response = self.handle_exception(exc)
  File "/home/rushikeshkadam/code_space/videoView/server/venv/lib/python3.10/site-packages/rest_framework/views.py", line 469, in handle_exception
    self.raise_uncaught_exception(exc)
  File "/home/rushikeshkadam/code_space/videoView/server/venv/lib/python3.10/site-packages/rest_framework/views.py", line 480, in raise_uncaught_exception
    raise exc
  File "/home/rushikeshkadam/code_space/videoView/server/venv/lib/python3.10/site-packages/rest_framework/views.py", line 506, in dispatch
    response = handler(request, *args, **kwargs)
  File "/home/rushikeshkadam/code_space/videoView/server/venv/lib/python3.10/site-packages/rest_framework/decorators.py", line 50, in handler
    return func(*args, **kwargs)
  File "/home/rushikeshkadam/code_space/videoView/server/videoView/api/Views/VideoView.py", line 51, in get_video_by_videoId
    video_data=Videos.objects.get(id=id)
  File "/home/rushikeshkadam/code_space/videoView/server/venv/lib/python3.10/site-packages/django/db/models/manager.py", line 87, in manager_method
    return getattr(self.get_queryset(), name)(*args, **kwargs)
  File "/home/rushikeshkadam/code_space/videoView/server/venv/lib/python3.10/site-packages/django/db/models/query.py", line 635, in get
    clone = self._chain() if self.query.combinator else self.filter(*args, **kwargs)
  File "/home/rushikeshkadam/code_space/videoView/server/venv/lib/python3.10/site-packages/django/db/models/query.py", line 1476, in filter
    return self._filter_or_exclude(False, args, kwargs)
  File "/home/rushikeshkadam/code_space/videoView/server/venv/lib/python3.10/site-packages/django/db/models/query.py", line 1494, in _filter_or_exclude
    clone._filter_or_exclude_inplace(negate, args, kwargs)
  File "/home/rushikeshkadam/code_space/videoView/server/venv/lib/python3.10/site-packages/django/db/models/query.py", line 1501, in _filter_or_exclude_inplace
    self._query.add_q(Q(*args, **kwargs))
  File "/home/rushikeshkadam/code_space/videoView/server/venv/lib/python3.10/site-packages/django/db/models/sql/query.py", line 1609, in add_q
    clause, _ = self._add_q(q_object, self.used_aliases)
  File "/home/rushikeshkadam/code_space/videoView/server/venv/lib/python3.10/site-packages/django/db/models/sql/query.py", line 1641, in _add_q
    child_clause, needed_inner = self.build_filter(
  File "/home/rushikeshkadam/code_space/videoView/server/venv/lib/python3.10/site-packages/django/db/models/sql/query.py", line 1555, in build_filter
    condition = self.build_lookup(lookups, col, value)
  File "/home/rushikeshkadam/code_space/videoView/server/venv/lib/python3.10/site-packages/django/db/models/sql/query.py", line 1385, in build_lookup
    lookup = lookup_class(lhs, rhs)
  File "/home/rushikeshkadam/code_space/videoView/server/venv/lib/python3.10/site-packages/django/db/models/lookups.py", line 30, in __init__
    self.rhs = self.get_prep_lookup()
  File "/home/rushikeshkadam/code_space/videoView/server/venv/lib/python3.10/site-packages/django/db/models/lookups.py", line 369, in get_prep_lookup
    return super().get_prep_lookup()
  File "/home/rushikeshkadam/code_space/videoView/server/venv/lib/python3.10/site-packages/django/db/models/lookups.py", line 88, in get_prep_lookup
    return self.lhs.output_field.get_prep_value(self.rhs)
  File "/home/rushikeshkadam/code_space/videoView/server/venv/lib/python3.10/site-packages/django/db/models/fields/__init__.py", line 2745, in get_prep_value
    return self.to_python(value)
  File "/home/rushikeshkadam/code_space/videoView/server/venv/lib/python3.10/site-packages/django/db/models/fields/__init__.py", line 2763, in to_python
    raise exceptions.ValidationError(
django.core.exceptions.ValidationError: ['“600ac1bb-4047-40a2-aa3-bb4135870516” is not a valid UUID.']
DEBUG 2025-01-12 06:48:17,175 VideoView.py VideoView get_video_by_videoId 59: Error as occurred : ['“600ac1bb-4047-40a2-aa3-bb4135870516” is not a valid UUID.']
WARNING 2025-01-12 06:48:17,176 log.py log log_response 248: Unauthorized: /api/v1/get_video_by_videoId/600ac1bb-4047-40a2-aa3-bb4135870516/
WARNING 2025-01-15 17:12:39,772 log.py log log_response 248: Unauthorized: /api/v1/upload_video
WARNING 2025-01-15 17:13:45,601 log.py log log_response 248: Not Found: /api/v1/update_video
WARNING 2025-01-15 17:16:12,051 log.py log log_response 248: Not Found: /api/v1/update_video
WARNING 2025-01-15 17:17:30,661 log.py log log_response 248: Not Found: /api/v1/update_video
WARNING 2025-01-15 17:17:35,770 log.py log log_response 248: Not Found: /api/v1/update_video
WARNING 2025-01-15 17:18:02,644 log.py log log_response 248: Not Found: /api/v1/get_all_video/:id
ERROR 2025-01-15 17:19:57,505 log.py log log_response 248: Internal Server Error: /api/v1/update_video/600ac1bb-4047-40a2-8aa3-bb4135870516
Traceback (most recent call last):
  File "/home/rushikeshkadam/code_space/videoView/server/venv/lib/python3.10/site-packages/django/core/handlers/exception.py", line 55, in inner
    response = get_response(request)
  File "/home/rushikeshkadam/code_space/videoView/server/venv/lib/python3.10/site-packages/django/utils/deprecation.py", line 131, in __call__
    response = self.process_response(request, response)
  File "/home/rushikeshkadam/code_space/videoView/server/venv/lib/python3.10/site-packages/django/middleware/common.py", line 108, in process_response
    return self.response_redirect_class(self.get_full_path_with_slash(request))
  File "/home/rushikeshkadam/code_space/videoView/server/venv/lib/python3.10/site-packages/django/middleware/common.py", line 87, in get_full_path_with_slash
    raise RuntimeError(
RuntimeError: You called this URL via PATCH, but the URL doesn't end in a slash and you have APPEND_SLASH set. Django can't redirect to the slash URL while maintaining PATCH data. Change your form to point to 127.0.0.1:8000/api/v1/update_video/600ac1bb-4047-40a2-8aa3-bb4135870516/ (note the trailing slash), or set APPEND_SLASH=False in your Django settings.
WARNING 2025-01-15 17:23:23,406 log.py log log_response 248: Unauthorized: /api/v1/update_video/600ac1bb-4047-40a2-8aa3-bb4135870516/
WARNING 2025-01-15 17:23:59,766 log.py log log_response 248: Unauthorized: /api/v1/update_video/600ac1bb-4047-40a2-8aa3-bb4135870516/
ERROR 2025-01-15 17:24:21,891 log.py log log_response 248: Internal Server Error: /api/v1/update_video/600ac1bb-4047-40a2-8aa3-bb4135870516/
Traceback (most recent call last):
  File "/home/rushikeshkadam/code_space/videoView/server/venv/lib/python3.10/site-packages/django/core/handlers/exception.py", line 55, in inner
    response = get_response(request)
  File "/home/rushikeshkadam/code_space/videoView/server/venv/lib/python3.10/site-packages/django/core/handlers/base.py", line 220, in _get_response
    response = response.render()
  File "/home/rushikeshkadam/code_space/videoView/server/venv/lib/python3.10/site-packages/django/template/response.py", line 114, in render
    self.content = self.rendered_content
  File "/home/rushikeshkadam/code_space/videoView/server/venv/lib/python3.10/site-packages/rest_framework/response.py", line 74, in rendered_content
    ret = renderer.render(self.data, accepted_media_type, context)
  File "/home/rushikeshkadam/code_space/videoView/server/venv/lib/python3.10/site-packages/rest_framework/renderers.py", line 100, in render
    ret = json.dumps(
  File "/home/rushikeshkadam/code_space/videoView/server/venv/lib/python3.10/site-packages/rest_framework/utils/json.py", line 25, in dumps
    return json.dumps(*args, **kwargs)
  File "/usr/lib/python3.10/json/__init__.py", line 238, in dumps
    **kw).encode(obj)
  File "/usr/lib/python3.10/json/encoder.py", line 199, in encode
    chunks = self.iterencode(o, _one_shot=True)
  File "/usr/lib/python3.10/json/encoder.py", line 257, in iterencode
    return _iterencode(o, 0)
  File "/home/rushikeshkadam/code_space/videoView/server/venv/lib/python3.10/site-packages/rest_framework/utils/encoders.py", line 52, in default
    return obj.decode()
UnicodeDecodeError: 'utf-8' codec can't decode byte 0x90 in position 20: invalid start byte
ERROR 2025-01-15 17:24:47,332 log.py log log_response 248: Internal Server Error: /api/v1/update_video/600ac1bb-4047-40a2-8aa3-bb4135870516/
Traceback (most recent call last):
  File "/home/rushikeshkadam/code_space/videoView/server/venv/lib/python3.10/site-packages/django/core/handlers/exception.py", line 55, in inner
    response = get_response(request)
  File "/home/rushikeshkadam/code_space/videoView/server/venv/lib/python3.10/site-packages/django/core/handlers/base.py", line 220, in _get_response
    response = response.render()
  File "/home/rushikeshkadam/code_space/videoView/server/venv/lib/python3.10/site-packages/django/template/response.py", line 114, in render
    self.content = self.rendered_content
  File "/home/rushikeshkadam/code_space/videoView/server/venv/lib/python3.10/site-packages/rest_framework/response.py", line 74, in rendered_content
    ret = renderer.render(self.data, accepted_media_type, context)
  File "/home/rushikeshkadam/code_space/videoView/server/venv/lib/python3.10/site-packages/rest_framework/renderers.py", line 100, in render
    ret = json.dumps(
  File "/home/rushikeshkadam/code_space/videoView/server/venv/lib/python3.10/site-packages/rest_framework/utils/json.py", line 25, in dumps
    return json.dumps(*args, **kwargs)
  File "/usr/lib/python3.10/json/__init__.py", line 238, in dumps
    **kw).encode(obj)
  File "/usr/lib/python3.10/json/encoder.py", line 199, in encode
    chunks = self.iterencode(o, _one_shot=True)
  File "/usr/lib/python3.10/json/encoder.py", line 257, in iterencode
    return _iterencode(o, 0)
  File "/home/rushikeshkadam/code_space/videoView/server/venv/lib/python3.10/site-packages/rest_framework/utils/encoders.py", line 52, in default
    return obj.decode()
UnicodeDecodeError: 'utf-8' codec can't decode byte 0x90 in position 20: invalid start byte
ERROR 2025-01-15 17:27:33,625 log.py log log_response 248: Internal Server Error: /api/v1/update_video/600ac1bb-4047-40a2-8aa3-bb4135870516/
Traceback (most recent call last):
  File "/home/rushikeshkadam/code_space/videoView/server/venv/lib/python3.10/site-packages/django/core/handlers/exception.py", line 55, in inner
    response = get_response(request)
  File "/home/rushikeshkadam/code_space/videoView/server/venv/lib/python3.10/site-packages/django/core/handlers/base.py", line 220, in _get_response
    response = response.render()
  File "/home/rushikeshkadam/code_space/videoView/server/venv/lib/python3.10/site-packages/django/template/response.py", line 114, in render
    self.content = self.rendered_content
  File "/home/rushikeshkadam/code_space/videoView/server/venv/lib/python3.10/site-packages/rest_framework/response.py", line 74, in rendered_content
    ret = renderer.render(self.data, accepted_media_type, context)
  File "/home/rushikeshkadam/code_space/videoView/server/venv/lib/python3.10/site-packages/rest_framework/renderers.py", line 100, in render
    ret = json.dumps(
  File "/home/rushikeshkadam/code_space/videoView/server/venv/lib/python3.10/site-packages/rest_framework/utils/json.py", line 25, in dumps
    return json.dumps(*args, **kwargs)
  File "/usr/lib/python3.10/json/__init__.py", line 238, in dumps
    **kw).encode(obj)
  File "/usr/lib/python3.10/json/encoder.py", line 199, in encode
    chunks = self.iterencode(o, _one_shot=True)
  File "/usr/lib/python3.10/json/encoder.py", line 257, in iterencode
    return _iterencode(o, 0)
  File "/home/rushikeshkadam/code_space/videoView/server/venv/lib/python3.10/site-packages/rest_framework/utils/encoders.py", line 52, in default
    return obj.decode()
UnicodeDecodeError: 'utf-8' codec can't decode byte 0xff in position 0: invalid start byte
ERROR 2025-01-15 17:27:58,712 log.py log log_response 248: Internal Server Error: /api/v1/update_video/600ac1bb-4047-40a2-8aa3-bb4135870516/
Traceback (most recent call last):
  File "/home/rushikeshkadam/code_space/videoView/server/venv/lib/python3.10/site-packages/django/core/handlers/exception.py", line 55, in inner
    response = get_response(request)
  File "/home/rushikeshkadam/code_space/videoView/server/venv/lib/python3.10/site-packages/django/core/handlers/base.py", line 220, in _get_response
    response = response.render()
  File "/home/rushikeshkadam/code_space/videoView/server/venv/lib/python3.10/site-packages/django/template/response.py", line 114, in render
    self.content = self.rendered_content
  File "/home/rushikeshkadam/code_space/videoView/server/venv/lib/python3.10/site-packages/rest_framework/response.py", line 74, in rendered_content
    ret = renderer.render(self.data, accepted_media_type, context)
  File "/home/rushikeshkadam/code_space/videoView/server/venv/lib/python3.10/site-packages/rest_framework/renderers.py", line 100, in render
    ret = json.dumps(
  File "/home/rushikeshkadam/code_space/videoView/server/venv/lib/python3.10/site-packages/rest_framework/utils/json.py", line 25, in dumps
    return json.dumps(*args, **kwargs)
  File "/usr/lib/python3.10/json/__init__.py", line 238, in dumps
    **kw).encode(obj)
  File "/usr/lib/python3.10/json/encoder.py", line 199, in encode
    chunks = self.iterencode(o, _one_shot=True)
  File "/usr/lib/python3.10/json/encoder.py", line 257, in iterencode
    return _iterencode(o, 0)
  File "/home/rushikeshkadam/code_space/videoView/server/venv/lib/python3.10/site-packages/rest_framework/utils/encoders.py", line 52, in default
    return obj.decode()
UnicodeDecodeError: 'utf-8' codec can't decode byte 0xff in position 0: invalid start byte
ERROR 2025-01-15 17:29:28,919 log.py log log_response 248: Internal Server Error: /api/v1/update_video/600ac1bb-4047-40a2-8aa3-bb4135870516/
Traceback (most recent call last):
  File "/home/rushikeshkadam/code_space/videoView/server/venv/lib/python3.10/site-packages/django/core/handlers/exception.py", line 55, in inner
    response = get_response(request)
  File "/home/rushikeshkadam/code_space/videoView/server/venv/lib/python3.10/site-packages/django/core/handlers/base.py", line 220, in _get_response
    response = response.render()
  File "/home/rushikeshkadam/code_space/videoView/server/venv/lib/python3.10/site-packages/django/template/response.py", line 114, in render
    self.content = self.rendered_content
  File "/home/rushikeshkadam/code_space/videoView/server/venv/lib/python3.10/site-packages/rest_framework/response.py", line 74, in rendered_content
    ret = renderer.render(self.data, accepted_media_type, context)
  File "/home/rushikeshkadam/code_space/videoView/server/venv/lib/python3.10/site-packages/rest_framework/renderers.py", line 100, in render
    ret = json.dumps(
  File "/home/rushikeshkadam/code_space/videoView/server/venv/lib/python3.10/site-packages/rest_framework/utils/json.py", line 25, in dumps
    return json.dumps(*args, **kwargs)
  File "/usr/lib/python3.10/json/__init__.py", line 238, in dumps
    **kw).encode(obj)
  File "/usr/lib/python3.10/json/encoder.py", line 199, in encode
    chunks = self.iterencode(o, _one_shot=True)
  File "/usr/lib/python3.10/json/encoder.py", line 257, in iterencode
    return _iterencode(o, 0)
  File "/home/rushikeshkadam/code_space/videoView/server/venv/lib/python3.10/site-packages/rest_framework/utils/encoders.py", line 52, in default
    return obj.decode()
UnicodeDecodeError: 'utf-8' codec can't decode byte 0xff in position 0: invalid start byte
ERROR 2025-01-15 17:33:04,759 log.py log log_response 248: Internal Server Error: /api/v1/update_video/600ac1bb-4047-40a2-8aa3-bb4135870516/
Traceback (most recent call last):
  File "/home/rushikeshkadam/code_space/videoView/server/venv/lib/python3.10/site-packages/django/core/handlers/exception.py", line 55, in inner
    response = get_response(request)
  File "/home/rushikeshkadam/code_space/videoView/server/venv/lib/python3.10/site-packages/django/core/handlers/base.py", line 220, in _get_response
    response = response.render()
  File "/home/rushikeshkadam/code_space/videoView/server/venv/lib/python3.10/site-packages/django/template/response.py", line 114, in render
    self.content = self.rendered_content
  File "/home/rushikeshkadam/code_space/videoView/server/venv/lib/python3.10/site-packages/rest_framework/response.py", line 74, in rendered_content
    ret = renderer.render(self.data, accepted_media_type, context)
  File "/home/rushikeshkadam/code_space/videoView/server/venv/lib/python3.10/site-packages/rest_framework/renderers.py", line 100, in render
    ret = json.dumps(
  File "/home/rushikeshkadam/code_space/videoView/server/venv/lib/python3.10/site-packages/rest_framework/utils/json.py", line 25, in dumps
    return json.dumps(*args, **kwargs)
  File "/usr/lib/python3.10/json/__init__.py", line 238, in dumps
    **kw).encode(obj)
  File "/usr/lib/python3.10/json/encoder.py", line 199, in encode
    chunks = self.iterencode(o, _one_shot=True)
  File "/usr/lib/python3.10/json/encoder.py", line 257, in iterencode
    return _iterencode(o, 0)
  File "/home/rushikeshkadam/code_space/videoView/server/venv/lib/python3.10/site-packages/rest_framework/utils/encoders.py", line 52, in default
    return obj.decode()
UnicodeDecodeError: 'utf-8' codec can't decode byte 0xff in position 0: invalid start byte
ERROR 2025-01-15 17:33:23,738 log.py log log_response 248: Internal Server Error: /api/v1/update_video/600ac1bb-4047-40a2-8aa3-bb4135870516/
Traceback (most recent call last):
  File "/home/rushikeshkadam/code_space/videoView/server/venv/lib/python3.10/site-packages/django/core/handlers/exception.py", line 55, in inner
    response = get_response(request)
  File "/home/rushikeshkadam/code_space/videoView/server/venv/lib/python3.10/site-packages/django/core/handlers/base.py", line 220, in _get_response
    response = response.render()
  File "/home/rushikeshkadam/code_space/videoView/server/venv/lib/python3.10/site-packages/django/template/response.py", line 114, in render
    self.content = self.rendered_content
  File "/home/rushikeshkadam/code_space/videoView/server/venv/lib/python3.10/site-packages/rest_framework/response.py", line 74, in rendered_content
    ret = renderer.render(self.data, accepted_media_type, context)
  File "/home/rushikeshkadam/code_space/videoView/server/venv/lib/python3.10/site-packages/rest_framework/renderers.py", line 100, in render
    ret = json.dumps(
  File "/home/rushikeshkadam/code_space/videoView/server/venv/lib/python3.10/site-packages/rest_framework/utils/json.py", line 25, in dumps
    return json.dumps(*args, **kwargs)
  File "/usr/lib/python3.10/json/__init__.py", line 238, in dumps
    **kw).encode(obj)
  File "/usr/lib/python3.10/json/encoder.py", line 199, in encode
    chunks = self.iterencode(o, _one_shot=True)
  File "/usr/lib/python3.10/json/encoder.py", line 257, in iterencode
    return _iterencode(o, 0)
  File "/home/rushikeshkadam/code_space/videoView/server/venv/lib/python3.10/site-packages/rest_framework/utils/encoders.py", line 52, in default
    return obj.decode()
UnicodeDecodeError: 'utf-8' codec can't decode byte 0xff in position 0: invalid start byte
ERROR 2025-01-15 17:34:02,772 log.py log log_response 248: Internal Server Error: /api/v1/update_video/600ac1bb-4047-40a2-8aa3-bb4135870516/
Traceback (most recent call last):
  File "/home/rushikeshkadam/code_space/videoView/server/venv/lib/python3.10/site-packages/django/core/handlers/exception.py", line 55, in inner
    response = get_response(request)
  File "/home/rushikeshkadam/code_space/videoView/server/venv/lib/python3.10/site-packages/django/core/handlers/base.py", line 220, in _get_response
    response = response.render()
  File "/home/rushikeshkadam/code_space/videoView/server/venv/lib/python3.10/site-packages/django/template/response.py", line 114, in render
    self.content = self.rendered_content
  File "/home/rushikeshkadam/code_space/videoView/server/venv/lib/python3.10/site-packages/rest_framework/response.py", line 74, in rendered_content
    ret = renderer.render(self.data, accepted_media_type, context)
  File "/home/rushikeshkadam/code_space/videoView/server/venv/lib/python3.10/site-packages/rest_framework/renderers.py", line 100, in render
    ret = json.dumps(
  File "/home/rushikeshkadam/code_space/videoView/server/venv/lib/python3.10/site-packages/rest_framework/utils/json.py", line 25, in dumps
    return json.dumps(*args, **kwargs)
  File "/usr/lib/python3.10/json/__init__.py", line 238, in dumps
    **kw).encode(obj)
  File "/usr/lib/python3.10/json/encoder.py", line 199, in encode
    chunks = self.iterencode(o, _one_shot=True)
  File "/usr/lib/python3.10/json/encoder.py", line 257, in iterencode
    return _iterencode(o, 0)
  File "/home/rushikeshkadam/code_space/videoView/server/venv/lib/python3.10/site-packages/rest_framework/utils/encoders.py", line 52, in default
    return obj.decode()
UnicodeDecodeError: 'utf-8' codec can't decode byte 0xff in position 0: invalid start byte
ERROR 2025-01-15 17:34:24,767 log.py log log_response 248: Internal Server Error: /api/v1/update_video/600ac1bb-4047-40a2-8aa3-bb4135870516/
Traceback (most recent call last):
  File "/home/rushikeshkadam/code_space/videoView/server/venv/lib/python3.10/site-packages/django/core/handlers/exception.py", line 55, in inner
    response = get_response(request)
  File "/home/rushikeshkadam/code_space/videoView/server/venv/lib/python3.10/site-packages/django/core/handlers/base.py", line 220, in _get_response
    response = response.render()
  File "/home/rushikeshkadam/code_space/videoView/server/venv/lib/python3.10/site-packages/django/template/response.py", line 114, in render
    self.content = self.rendered_content
  File "/home/rushikeshkadam/code_space/videoView/server/venv/lib/python3.10/site-packages/rest_framework/response.py", line 74, in rendered_content
    ret = renderer.render(self.data, accepted_media_type, context)
  File "/home/rushikeshkadam/code_space/videoView/server/venv/lib/python3.10/site-packages/rest_framework/renderers.py", line 100, in render
    ret = json.dumps(
  File "/home/rushikeshkadam/code_space/videoView/server/venv/lib/python3.10/site-packages/rest_framework/utils/json.py", line 25, in dumps
    return json.dumps(*args, **kwargs)
  File "/usr/lib/python3.10/json/__init__.py", line 238, in dumps
    **kw).encode(obj)
  File "/usr/lib/python3.10/json/encoder.py", line 199, in encode
    chunks = self.iterencode(o, _one_shot=True)
  File "/usr/lib/python3.10/json/encoder.py", line 257, in iterencode
    return _iterencode(o, 0)
  File "/home/rushikeshkadam/code_space/videoView/server/venv/lib/python3.10/site-packages/rest_framework/utils/encoders.py", line 52, in default
    return obj.decode()
UnicodeDecodeError: 'utf-8' codec can't decode byte 0xff in position 0: invalid start byte
ERROR 2025-01-15 17:34:53,683 log.py log log_response 248: Internal Server Error: /api/v1/update_video/600ac1bb-4047-40a2-8aa3-bb4135870516/
Traceback (most recent call last):
  File "/home/rushikeshkadam/code_space/videoView/server/venv/lib/python3.10/site-packages/django/core/handlers/exception.py", line 55, in inner
    response = get_response(request)
  File "/home/rushikeshkadam/code_space/videoView/server/venv/lib/python3.10/site-packages/django/core/handlers/base.py", line 220, in _get_response
    response = response.render()
  File "/home/rushikeshkadam/code_space/videoView/server/venv/lib/python3.10/site-packages/django/template/response.py", line 114, in render
    self.content = self.rendered_content
  File "/home/rushikeshkadam/code_space/videoView/server/venv/lib/python3.10/site-packages/rest_framework/response.py", line 74, in rendered_content
    ret = renderer.render(self.data, accepted_media_type, context)
  File "/home/rushikeshkadam/code_space/videoView/server/venv/lib/python3.10/site-packages/rest_framework/renderers.py", line 100, in render
    ret = json.dumps(
  File "/home/rushikeshkadam/code_space/videoView/server/venv/lib/python3.10/site-packages/rest_framework/utils/json.py", line 25, in dumps
    return json.dumps(*args, **kwargs)
  File "/usr/lib/python3.10/json/__init__.py", line 238, in dumps
    **kw).encode(obj)
  File "/usr/lib/python3.10/json/encoder.py", line 199, in encode
    chunks = self.iterencode(o, _one_shot=True)
  File "/usr/lib/python3.10/json/encoder.py", line 257, in iterencode
    return _iterencode(o, 0)
  File "/home/rushikeshkadam/code_space/videoView/server/venv/lib/python3.10/site-packages/rest_framework/utils/encoders.py", line 52, in default
    return obj.decode()
UnicodeDecodeError: 'utf-8' codec can't decode byte 0xff in position 0: invalid start byte
ERROR 2025-01-15 17:35:17,507 log.py log log_response 248: Internal Server Error: /api/v1/update_video/600ac1bb-4047-40a2-8aa3-bb4135870516/
Traceback (most recent call last):
  File "/home/rushikeshkadam/code_space/videoView/server/venv/lib/python3.10/site-packages/django/core/handlers/exception.py", line 55, in inner
    response = get_response(request)
  File "/home/rushikeshkadam/code_space/videoView/server/venv/lib/python3.10/site-packages/django/core/handlers/base.py", line 220, in _get_response
    response = response.render()
  File "/home/rushikeshkadam/code_space/videoView/server/venv/lib/python3.10/site-packages/django/template/response.py", line 114, in render
    self.content = self.rendered_content
  File "/home/rushikeshkadam/code_space/videoView/server/venv/lib/python3.10/site-packages/rest_framework/response.py", line 74, in rendered_content
    ret = renderer.render(self.data, accepted_media_type, context)
  File "/home/rushikeshkadam/code_space/videoView/server/venv/lib/python3.10/site-packages/rest_framework/renderers.py", line 100, in render
    ret = json.dumps(
  File "/home/rushikeshkadam/code_space/videoView/server/venv/lib/python3.10/site-packages/rest_framework/utils/json.py", line 25, in dumps
    return json.dumps(*args, **kwargs)
  File "/usr/lib/python3.10/json/__init__.py", line 238, in dumps
    **kw).encode(obj)
  File "/usr/lib/python3.10/json/encoder.py", line 199, in encode
    chunks = self.iterencode(o, _one_shot=True)
  File "/usr/lib/python3.10/json/encoder.py", line 257, in iterencode
    return _iterencode(o, 0)
  File "/home/rushikeshkadam/code_space/videoView/server/venv/lib/python3.10/site-packages/rest_framework/utils/encoders.py", line 52, in default
    return obj.decode()
UnicodeDecodeError: 'utf-8' codec can't decode byte 0xff in position 0: invalid start byte
WARNING 2025-01-16 04:22:45,246 log.py log log_response 248: Not Found: /api/v1/update_video/
WARNING 2025-01-16 04:23:23,277 log.py log log_response 248: Not Found: /api/v1/update_video/
WARNING 2025-01-16 04:23:43,287 log.py log log_response 248: Not Found: /api/v1/update_video/
WARNING 2025-01-16 04:24:10,940 log.py log log_response 248: Not Found: /api/v1/update_video/
ERROR 2025-01-16 04:25:22,148 log.py log log_response 248: Internal Server Error: /api/v1/update_video/600ac1bb-4047-40a2-8aa3-bb4135870516/
Traceback (most recent call last):
  File "/home/rushikeshkadam/code_space/videoView/server/venv/lib/python3.10/site-packages/django/core/handlers/exception.py", line 55, in inner
    response = get_response(request)
  File "/home/rushikeshkadam/code_space/videoView/server/venv/lib/python3.10/site-packages/django/core/handlers/base.py", line 220, in _get_response
    response = response.render()
  File "/home/rushikeshkadam/code_space/videoView/server/venv/lib/python3.10/site-packages/django/template/response.py", line 114, in render
    self.content = self.rendered_content
  File "/home/rushikeshkadam/code_space/videoView/server/venv/lib/python3.10/site-packages/rest_framework/response.py", line 74, in rendered_content
    ret = renderer.render(self.data, accepted_media_type, context)
  File "/home/rushikeshkadam/code_space/videoView/server/venv/lib/python3.10/site-packages/rest_framework/renderers.py", line 100, in render
    ret = json.dumps(
  File "/home/rushikeshkadam/code_space/videoView/server/venv/lib/python3.10/site-packages/rest_framework/utils/json.py", line 25, in dumps
    return json.dumps(*args, **kwargs)
  File "/usr/lib/python3.10/json/__init__.py", line 238, in dumps
    **kw).encode(obj)
  File "/usr/lib/python3.10/json/encoder.py", line 199, in encode
    chunks = self.iterencode(o, _one_shot=True)
  File "/usr/lib/python3.10/json/encoder.py", line 257, in iterencode
    return _iterencode(o, 0)
  File "/home/rushikeshkadam/code_space/videoView/server/venv/lib/python3.10/site-packages/rest_framework/utils/encoders.py", line 52, in default
    return obj.decode()
UnicodeDecodeError: 'utf-8' codec can't decode byte 0xff in position 0: invalid start byte
DEBUG 2025-01-16 04:26:01,336 VideoView.py VideoView update_video 69: https://res.cloudinary.com/das30jn7u/image/upload/v1735723183/dymvpuh72cp4bgv1sh7a.png
ERROR 2025-01-16 04:26:01,402 log.py log log_response 248: Internal Server Error: /api/v1/update_video/600ac1bb-4047-40a2-8aa3-bb4135870516/
Traceback (most recent call last):
  File "/home/rushikeshkadam/code_space/videoView/server/venv/lib/python3.10/site-packages/django/core/handlers/exception.py", line 55, in inner
    response = get_response(request)
  File "/home/rushikeshkadam/code_space/videoView/server/venv/lib/python3.10/site-packages/django/core/handlers/base.py", line 220, in _get_response
    response = response.render()
  File "/home/rushikeshkadam/code_space/videoView/server/venv/lib/python3.10/site-packages/django/template/response.py", line 114, in render
    self.content = self.rendered_content
  File "/home/rushikeshkadam/code_space/videoView/server/venv/lib/python3.10/site-packages/rest_framework/response.py", line 74, in rendered_content
    ret = renderer.render(self.data, accepted_media_type, context)
  File "/home/rushikeshkadam/code_space/videoView/server/venv/lib/python3.10/site-packages/rest_framework/renderers.py", line 100, in render
    ret = json.dumps(
  File "/home/rushikeshkadam/code_space/videoView/server/venv/lib/python3.10/site-packages/rest_framework/utils/json.py", line 25, in dumps
    return json.dumps(*args, **kwargs)
  File "/usr/lib/python3.10/json/__init__.py", line 238, in dumps
    **kw).encode(obj)
  File "/usr/lib/python3.10/json/encoder.py", line 199, in encode
    chunks = self.iterencode(o, _one_shot=True)
  File "/usr/lib/python3.10/json/encoder.py", line 257, in iterencode
    return _iterencode(o, 0)
  File "/home/rushikeshkadam/code_space/videoView/server/venv/lib/python3.10/site-packages/rest_framework/utils/encoders.py", line 52, in default
    return obj.decode()
UnicodeDecodeError: 'utf-8' codec can't decode byte 0xff in position 0: invalid start byte
ERROR 2025-01-16 04:26:37,420 log.py log log_response 248: Internal Server Error: /api/v1/update_video/600ac1bb-4047-40a2-8aa3-bb4135870516/
Traceback (most recent call last):
  File "/home/rushikeshkadam/code_space/videoView/server/venv/lib/python3.10/site-packages/django/core/handlers/exception.py", line 55, in inner
    response = get_response(request)
  File "/home/rushikeshkadam/code_space/videoView/server/venv/lib/python3.10/site-packages/django/core/handlers/base.py", line 220, in _get_response
    response = response.render()
  File "/home/rushikeshkadam/code_space/videoView/server/venv/lib/python3.10/site-packages/django/template/response.py", line 114, in render
    self.content = self.rendered_content
  File "/home/rushikeshkadam/code_space/videoView/server/venv/lib/python3.10/site-packages/rest_framework/response.py", line 74, in rendered_content
    ret = renderer.render(self.data, accepted_media_type, context)
  File "/home/rushikeshkadam/code_space/videoView/server/venv/lib/python3.10/site-packages/rest_framework/renderers.py", line 100, in render
    ret = json.dumps(
  File "/home/rushikeshkadam/code_space/videoView/server/venv/lib/python3.10/site-packages/rest_framework/utils/json.py", line 25, in dumps
    return json.dumps(*args, **kwargs)
  File "/usr/lib/python3.10/json/__init__.py", line 238, in dumps
    **kw).encode(obj)
  File "/usr/lib/python3.10/json/encoder.py", line 199, in encode
    chunks = self.iterencode(o, _one_shot=True)
  File "/usr/lib/python3.10/json/encoder.py", line 257, in iterencode
    return _iterencode(o, 0)
  File "/home/rushikeshkadam/code_space/videoView/server/venv/lib/python3.10/site-packages/rest_framework/utils/encoders.py", line 52, in default
    return obj.decode()
UnicodeDecodeError: 'utf-8' codec can't decode byte 0xff in position 0: invalid start byte
DEBUG 2025-01-16 05:12:40,296 VideoView.py VideoView get_video_by_videoId 60: Error as occurred : type object 'super' has no attribute 'to_representation'
WARNING 2025-01-16 05:12:40,296 log.py log log_response 248: Unauthorized: /api/v1/get_video_by_videoId/600ac1bb-4047-40a2-8aa3-bb4135870516/
DEBUG 2025-01-16 05:15:05,520 VideoView.py VideoView get_video_by_videoId 60: Error as occurred : type object 'super' has no attribute 'to_representation'
WARNING 2025-01-16 05:15:05,520 log.py log log_response 248: Unauthorized: /api/v1/get_video_by_videoId/600ac1bb-4047-40a2-8aa3-bb4135870516/
DEBUG 2025-01-16 05:15:29,080 VideoView.py VideoView get_video_by_videoId 60: Error as occurred : type object 'super' has no attribute 'to_representation'
WARNING 2025-01-16 05:15:29,081 log.py log log_response 248: Unauthorized: /api/v1/get_video_by_videoId/600ac1bb-4047-40a2-8aa3-bb4135870516/
DEBUG 2025-01-16 05:16:16,620 VideoView.py VideoView get_video_by_videoId 52: 600ac1bb-4047-40a2-8aa3-bb4135870516
DEBUG 2025-01-16 05:16:16,625 VideoView.py VideoView get_video_by_videoId 61: Error as occurred : type object 'super' has no attribute 'to_representation'
WARNING 2025-01-16 05:16:16,626 log.py log log_response 248: Unauthorized: /api/v1/get_video_by_videoId/600ac1bb-4047-40a2-8aa3-bb4135870516/
DEBUG 2025-01-16 05:17:56,452 VideoView.py VideoView get_video_by_videoId 64: Error as occurred : type object 'super' has no attribute 'to_representation'
WARNING 2025-01-16 05:17:56,453 log.py log log_response 248: Unauthorized: /api/v1/get_video_by_videoId/600ac1bb-4047-40a2-8aa3-bb4135870516/
DEBUG 2025-01-16 05:20:19,245 VideoView.py VideoView get_video_by_videoId 64: Error as occurred : super(type, obj): obj must be an instance or subtype of type
WARNING 2025-01-16 05:20:19,245 log.py log log_response 248: Unauthorized: /api/v1/get_video_by_videoId/600ac1bb-4047-40a2-8aa3-bb4135870516/
DEBUG 2025-01-16 05:28:14,897 VideoView.py VideoView get_video_by_videoId 64: Error as occurred : 'NoneType' object has no attribute 'watchHistory'
WARNING 2025-01-16 05:28:14,898 log.py log log_response 248: Unauthorized: /api/v1/get_video_by_videoId/600ac1bb-4047-40a2-8aa3-bb4135870516/
DEBUG 2025-01-16 05:29:44,643 VideoView.py VideoView get_video_by_videoId 64: Error as occurred : Users matching query does not exist.
WARNING 2025-01-16 05:29:44,643 log.py log log_response 248: Unauthorized: /api/v1/get_video_by_videoId/600ac1bb-4047-40a2-8aa3-bb4135870516/
DEBUG 2025-01-16 05:30:13,126 VideoView.py VideoView get_video_by_videoId 64: Error as occurred : Users matching query does not exist.
WARNING 2025-01-16 05:30:13,126 log.py log log_response 248: Unauthorized: /api/v1/get_video_by_videoId/600ac1bb-4047-40a2-8aa3-bb4135870516/
DEBUG 2025-01-16 05:30:30,346 VideoView.py VideoView get_video_by_videoId 64: Error as occurred : Users matching query does not exist.
WARNING 2025-01-16 05:30:30,348 log.py log log_response 248: Unauthorized: /api/v1/get_video_by_videoId/600ac1bb-4047-40a2-8aa3-bb4135870516/
DEBUG 2025-01-16 05:30:50,962 VideoView.py VideoView get_video_by_videoId 64: Error as occurred : Users matching query does not exist.
WARNING 2025-01-16 05:30:50,963 log.py log log_response 248: Unauthorized: /api/v1/get_video_by_videoId/600ac1bb-4047-40a2-8aa3-bb4135870516/
DEBUG 2025-01-16 05:31:05,403 VideoView.py VideoView get_video_by_videoId 64: Error as occurred : Users matching query does not exist.
WARNING 2025-01-16 05:31:05,403 log.py log log_response 248: Unauthorized: /api/v1/get_video_by_videoId/600ac1bb-4047-40a2-8aa3-bb4135870516/
DEBUG 2025-01-16 05:32:36,311 VideoView.py VideoView get_video_by_videoId 66: Error as occurred : Users matching query does not exist.
WARNING 2025-01-16 05:32:36,312 log.py log log_response 248: Unauthorized: /api/v1/get_video_by_videoId/600ac1bb-4047-40a2-8aa3-bb4135870516/
DEBUG 2025-01-16 05:32:51,015 VideoView.py VideoView get_video_by_videoId 66: Error as occurred : Users matching query does not exist.
WARNING 2025-01-16 05:32:51,016 log.py log log_response 248: Unauthorized: /api/v1/get_video_by_videoId/600ac1bb-4047-40a2-8aa3-bb4135870516/
DEBUG 2025-01-16 05:35:41,167 VideoView.py VideoView get_video_by_videoId 66: Error as occurred : name 'user' is not defined
WARNING 2025-01-16 05:35:41,167 log.py log log_response 248: Unauthorized: /api/v1/get_video_by_videoId/600ac1bb-4047-40a2-8aa3-bb4135870516/
DEBUG 2025-01-16 05:38:33,942 serializer.py serializer to_representation 200: 600ac1bb-4047-40a2-8aa3-bb4135870516
DEBUG 2025-01-16 05:39:11,776 VideoView.py VideoView get_video_by_videoId 66: Error as occurred : 'Videos' object has no attribute 'Videos'
WARNING 2025-01-16 05:39:11,777 log.py log log_response 248: Unauthorized: /api/v1/get_video_by_videoId/600ac1bb-4047-40a2-8aa3-bb4135870516/
DEBUG 2025-01-16 05:39:36,360 serializer.py serializer to_representation 200: api.Users.None
DEBUG 2025-01-16 05:40:03,148 VideoView.py VideoView get_video_by_videoId 66: Error as occurred : 'ManyRelatedManager' object has no attribute 'fullName'
WARNING 2025-01-16 05:40:03,149 log.py log log_response 248: Unauthorized: /api/v1/get_video_by_videoId/600ac1bb-4047-40a2-8aa3-bb4135870516/
DEBUG 2025-01-16 05:40:16,917 serializer.py serializer to_representation 200: api.Users.None
DEBUG 2025-01-16 05:45:30,931 serializer.py serializer to_representation 201: checking........None
DEBUG 2025-01-16 05:46:54,696 serializer.py serializer to_representation 201: checking........api.Users.None
DEBUG 2025-01-17 16:14:32,355 VideoView.py VideoView get_video_by_videoId 67: Error as occurred : When a serializer is passed a `data` keyword argument you must call `.is_valid()` before attempting to access the serialized `.data` representation.
You should either call `.is_valid()` first, or access `.initial_data` instead.
WARNING 2025-01-17 16:14:32,355 log.py log log_response 248: Unauthorized: /api/v1/get_video_by_videoId/600ac1bb-4047-40a2-8aa3-bb4135870516/
DEBUG 2025-01-17 16:24:20,491 VideoView.py VideoView get_video_by_videoId 63: checking..........{}
DEBUG 2025-01-17 16:24:24,799 VideoView.py VideoView get_video_by_videoId 63: checking..........{}
DEBUG 2025-01-17 16:24:40,908 VideoView.py VideoView get_video_by_videoId 63: checking..........{}
DEBUG 2025-01-17 16:24:41,720 VideoView.py VideoView get_video_by_videoId 63: checking..........{}
DEBUG 2025-01-17 16:24:42,441 VideoView.py VideoView get_video_by_videoId 63: checking..........{}
DEBUG 2025-01-17 16:24:43,240 VideoView.py VideoView get_video_by_videoId 63: checking..........{}
DEBUG 2025-01-17 16:25:35,096 VideoView.py VideoView get_video_by_videoId 67: Error as occurred : Cannot call `.is_valid()` as no `data=` keyword argument was passed when instantiating the serializer instance.
WARNING 2025-01-17 16:25:35,096 log.py log log_response 248: Unauthorized: /api/v1/get_video_by_videoId/600ac1bb-4047-40a2-8aa3-bb4135870516/
DEBUG 2025-01-17 16:25:51,705 VideoView.py VideoView get_video_by_videoId 63: checking..........{'id': '600ac1bb-4047-40a2-8aa3-bb4135870516', 'videoFile': 'https://res.cloudinary.com/das30jn7u/video/upload/v1735723199/k9lnoob0onluxttai59v.mp4', 'thumbnail': '4482736.png', 'owner': {'id': '4ee934b7-161c-4392-ae2f-2d74587d6d44', 'fullName': 'rushi', 'email': 'rushi@124gmail.com', 'avatar': 'https://res.cloudinary.com/das30jn7u/image/upload/v1735723073/nxxcfzveixpcpoznse4x.png', 'coverImage': None}, 'title': 'test101', 'description': 'description', 'duration': 10, 'views': 14, 'isPublished': True, 'created_at': '2025-01-01T09:20:00.581499Z', 'updated_at': '2025-01-17T16:25:51.695796Z'}
DEBUG 2025-01-17 16:25:55,956 VideoView.py VideoView get_video_by_videoId 63: checking..........{'id': '600ac1bb-4047-40a2-8aa3-bb4135870516', 'videoFile': 'https://res.cloudinary.com/das30jn7u/video/upload/v1735723199/k9lnoob0onluxttai59v.mp4', 'thumbnail': '4482736.png', 'owner': {'id': '4ee934b7-161c-4392-ae2f-2d74587d6d44', 'fullName': 'rushi', 'email': 'rushi@124gmail.com', 'avatar': 'https://res.cloudinary.com/das30jn7u/image/upload/v1735723073/nxxcfzveixpcpoznse4x.png', 'coverImage': None}, 'title': 'test101', 'description': 'description', 'duration': 10, 'views': 15, 'isPublished': True, 'created_at': '2025-01-01T09:20:00.581499Z', 'updated_at': '2025-01-17T16:25:55.950413Z'}
ERROR 2025-01-17 16:49:19,956 log.py log log_response 248: Internal Server Error: /api/v1/delete_video/600ac1bb-4047-40a2-8aa3-bb4135870516/
ERROR 2025-01-17 16:50:15,367 log.py log log_response 248: Internal Server Error: /api/v1/delete_video/600ac1bb-4047-40a2-8aa3-bb4135870516/
DEBUG 2025-01-17 16:55:52,555 VideoView.py VideoView get_video_by_videoId 67: Error as occurred : local variable 'video_data' referenced before assignment
WARNING 2025-01-17 16:55:52,555 log.py log log_response 248: Unauthorized: /api/v1/get_video_by_videoId/600ac1bb-4047-40a2-8aa3-bb4135870516/
WARNING 2025-01-17 17:02:23,990 log.py log log_response 248: Method Not Allowed: /api/v1/is_published/600ac1bb-4047-40a2-8aa3-bb4135870516/
ERROR 2025-01-17 17:02:57,398 log.py log log_response 248: Internal Server Error: /api/v1/is_published/600ac1bb-4047-40a2-8aa3-bb4135870516/
ERROR 2025-01-17 17:05:17,309 log.py log log_response 248: Internal Server Error: /api/v1/is_published/600ac1bb-4047-40a2-8aa3-bb4135870516/
ERROR 2025-01-17 17:06:32,429 log.py log log_response 248: Internal Server Error: /api/v1/is_published/4ea48abe-cec6-4b37-ab9c-37e253412416/
Traceback (most recent call last):
  File "/home/rushikeshkadam/code_space/videoView/server/venv/lib/python3.10/site-packages/django/core/handlers/exception.py", line 55, in inner
    response = get_response(request)
  File "/home/rushikeshkadam/code_space/videoView/server/venv/lib/python3.10/site-packages/django/core/handlers/base.py", line 220, in _get_response
    response = response.render()
  File "/home/rushikeshkadam/code_space/videoView/server/venv/lib/python3.10/site-packages/django/template/response.py", line 114, in render
    self.content = self.rendered_content
  File "/home/rushikeshkadam/code_space/videoView/server/venv/lib/python3.10/site-packages/rest_framework/response.py", line 74, in rendered_content
    ret = renderer.render(self.data, accepted_media_type, context)
  File "/home/rushikeshkadam/code_space/videoView/server/venv/lib/python3.10/site-packages/rest_framework/renderers.py", line 100, in render
    ret = json.dumps(
  File "/home/rushikeshkadam/code_space/videoView/server/venv/lib/python3.10/site-packages/rest_framework/utils/json.py", line 25, in dumps
    return json.dumps(*args, **kwargs)
  File "/usr/lib/python3.10/json/__init__.py", line 238, in dumps
    **kw).encode(obj)
  File "/usr/lib/python3.10/json/encoder.py", line 199, in encode
    chunks = self.iterencode(o, _one_shot=True)
  File "/usr/lib/python3.10/json/encoder.py", line 257, in iterencode
    return _iterencode(o, 0)
  File "/home/rushikeshkadam/code_space/videoView/server/venv/lib/python3.10/site-packages/rest_framework/utils/encoders.py", line 67, in default
    return super().default(obj)
  File "/usr/lib/python3.10/json/encoder.py", line 179, in default
    raise TypeError(f'Object of type {o.__class__.__name__} '
TypeError: Object of type Videos is not JSON serializable
ERROR 2025-01-17 17:06:54,138 log.py log log_response 248: Internal Server Error: /api/v1/is_published/4ea48abe-cec6-4b37-ab9c-37e253412416/
Traceback (most recent call last):
  File "/home/rushikeshkadam/code_space/videoView/server/venv/lib/python3.10/site-packages/django/core/handlers/exception.py", line 55, in inner
    response = get_response(request)
  File "/home/rushikeshkadam/code_space/videoView/server/venv/lib/python3.10/site-packages/django/core/handlers/base.py", line 220, in _get_response
    response = response.render()
  File "/home/rushikeshkadam/code_space/videoView/server/venv/lib/python3.10/site-packages/django/template/response.py", line 114, in render
    self.content = self.rendered_content
  File "/home/rushikeshkadam/code_space/videoView/server/venv/lib/python3.10/site-packages/rest_framework/response.py", line 74, in rendered_content
    ret = renderer.render(self.data, accepted_media_type, context)
  File "/home/rushikeshkadam/code_space/videoView/server/venv/lib/python3.10/site-packages/rest_framework/renderers.py", line 100, in render
    ret = json.dumps(
  File "/home/rushikeshkadam/code_space/videoView/server/venv/lib/python3.10/site-packages/rest_framework/utils/json.py", line 25, in dumps
    return json.dumps(*args, **kwargs)
  File "/usr/lib/python3.10/json/__init__.py", line 238, in dumps
    **kw).encode(obj)
  File "/usr/lib/python3.10/json/encoder.py", line 199, in encode
    chunks = self.iterencode(o, _one_shot=True)
  File "/usr/lib/python3.10/json/encoder.py", line 257, in iterencode
    return _iterencode(o, 0)
  File "/home/rushikeshkadam/code_space/videoView/server/venv/lib/python3.10/site-packages/rest_framework/utils/encoders.py", line 67, in default
    return super().default(obj)
  File "/usr/lib/python3.10/json/encoder.py", line 179, in default
    raise TypeError(f'Object of type {o.__class__.__name__} '
TypeError: Object of type ModelState is not JSON serializable
ERROR 2025-01-17 17:08:29,845 log.py log log_response 248: Internal Server Error: /api/v1/is_published/4ea48abe-cec6-4b37-ab9c-37e253412416/
ERROR 2025-01-17 17:08:43,463 log.py log log_response 248: Internal Server Error: /api/v1/is_published/4ea48abe-cec6-4b37-ab9c-37e253412416/
DEBUG 2025-01-17 17:11:51,130 VideoView.py VideoView get_video_by_videoId 63: checking..........{'id': '4ea48abe-cec6-4b37-ab9c-37e253412416', 'videoFile': 'https://res.cloudinary.com/das30jn7u/video/upload/v1736961185/yd7svebhffp8e1nhbz2r.mp4', 'thumbnail': 'https://res.cloudinary.com/das30jn7u/image/upload/v1736961175/n196naoywz58y3iuvgu5.png', 'owner': {'id': '4ee934b7-161c-4392-ae2f-2d74587d6d44', 'fullName': 'rushi', 'email': 'rushi@124gmail.com', 'avatar': 'https://res.cloudinary.com/das30jn7u/image/upload/v1735723073/nxxcfzveixpcpoznse4x.png', 'coverImage': None}, 'title': 'test', 'description': 'test', 'duration': 10, 'views': 1, 'isPublished': False, 'created_at': '2025-01-15T17:13:05.828791Z', 'updated_at': '2025-01-17T17:11:51.122809Z'}
WARNING 2025-01-18 18:35:24,963 log.py log log_response 248: Unauthorized: /api/v1/get_all_videos
DEBUG 2025-01-18 18:35:59,296 SubscriberView.py SubscriberView toggle_subscription 34: Error found : Users matching query does not exist.
ERROR 2025-01-18 18:35:59,296 log.py log log_response 248: Internal Server Error: /api/v1/toggle_subscription/4ea48abe-cec6-4b37-ab9c-37e253412416/
DEBUG 2025-01-18 18:37:32,679 SubscriberView.py SubscriberView toggle_subscription 34: Error found : Users matching query does not exist.
ERROR 2025-01-18 18:37:32,680 log.py log log_response 248: Internal Server Error: /api/v1/toggle_subscription/4ea48abe-cec6-4b37-ab9c-37e253412416/
DEBUG 2025-01-18 18:38:17,574 SubscriberView.py SubscriberView toggle_subscription 25: 4ee934b7-161c-4392-ae2f-2d74587d6d44
DEBUG 2025-01-18 18:38:17,576 SubscriberView.py SubscriberView toggle_subscription 34: Error found : Users matching query does not exist.
ERROR 2025-01-18 18:38:17,577 log.py log log_response 248: Internal Server Error: /api/v1/toggle_subscription/4ea48abe-cec6-4b37-ab9c-37e253412416/
DEBUG 2025-01-18 18:41:25,047 SubscriberView.py SubscriberView toggle_subscription 37: Error found : Users matching query does not exist.
ERROR 2025-01-18 18:41:25,048 log.py log log_response 248: Internal Server Error: /api/v1/toggle_subscription/4ea48abe-cec6-4b37-ab9c-37e253412416/
DEBUG 2025-01-18 18:41:39,910 SubscriberView.py SubscriberView toggle_subscription 37: Error found : Users matching query does not exist.
ERROR 2025-01-18 18:41:39,910 log.py log log_response 248: Internal Server Error: /api/v1/toggle_subscription/4ea48abe-cec6-4b37-ab9c-37e253412416/
DEBUG 2025-01-18 18:42:25,617 SubscriberView.py SubscriberView toggle_subscription 37: Error found : Users matching query does not exist.
ERROR 2025-01-18 18:42:25,617 log.py log log_response 248: Internal Server Error: /api/v1/toggle_subscription/4ea48abe-cec6-4b37-ab9c-37e253412416/
DEBUG 2025-01-18 18:42:39,399 SubscriberView.py SubscriberView toggle_subscription 37: Error found : Users matching query does not exist.
ERROR 2025-01-18 18:42:39,399 log.py log log_response 248: Internal Server Error: /api/v1/toggle_subscription/4ea48abe-cec6-4b37-ab9c-37e253412416/
DEBUG 2025-01-18 18:43:32,060 SubscriberView.py SubscriberView toggle_subscription 37: Error found : Users matching query does not exist.
ERROR 2025-01-18 18:43:32,061 log.py log log_response 248: Internal Server Error: /api/v1/toggle_subscription/4ea48abe-cec6-4b37-ab9c-37e253412416/
DEBUG 2025-01-18 18:44:06,946 SubscriberView.py SubscriberView toggle_subscription 27: rushi
DEBUG 2025-01-18 18:44:06,947 SubscriberView.py SubscriberView toggle_subscription 37: Error found : Users matching query does not exist.
ERROR 2025-01-18 18:44:06,948 log.py log log_response 248: Internal Server Error: /api/v1/toggle_subscription/4ea48abe-cec6-4b37-ab9c-37e253412416/
DEBUG 2025-01-18 18:45:58,703 SubscriberView.py SubscriberView toggle_subscription 36: Error found : Users matching query does not exist.
ERROR 2025-01-18 18:45:58,703 log.py log log_response 248: Internal Server Error: /api/v1/toggle_subscription/4ea48abe-cec6-4b37-ab9c-37e253412416/
DEBUG 2025-01-18 18:48:28,386 SubscriberView.py SubscriberView toggle_subscription 36: Error found : NOT NULL constraint failed: api_subscriptions.channel_id
ERROR 2025-01-18 18:48:28,386 log.py log log_response 248: Internal Server Error: /api/v1/toggle_subscription/4ea48abe-cec6-4b37-ab9c-37e253412416/
DEBUG 2025-01-18 18:55:57,704 SubscriberView.py SubscriberView toggle_subscription 36: Error found : name 'subscription' is not defined
ERROR 2025-01-18 18:55:57,705 log.py log log_response 248: Internal Server Error: /api/v1/toggle_subscription/4ea48abe-cec6-4b37-ab9c-37e253412416/
DEBUG 2025-01-18 18:56:17,519 SubscriberView.py SubscriberView toggle_subscription 36: Error found : Cannot assign "'4ee934b7-161c-4392-ae2f-2d74587d6d44'": "Subscriptions.subscriber" must be a "Users" instance.
ERROR 2025-01-18 18:56:17,520 log.py log log_response 248: Internal Server Error: /api/v1/toggle_subscription/4ea48abe-cec6-4b37-ab9c-37e253412416/
DEBUG 2025-01-18 18:57:26,064 SubscriberView.py SubscriberView toggle_subscription 36: Error found : Users matching query does not exist.
ERROR 2025-01-18 18:57:26,064 log.py log log_response 248: Internal Server Error: /api/v1/toggle_subscription/4ea48abe-cec6-4b37-ab9c-37e253412416/
DEBUG 2025-01-22 04:02:04,325 SubscriberView.py SubscriberView toggle_subscription 36: Error found : Users matching query does not exist.
ERROR 2025-01-22 04:02:04,327 log.py log log_response 248: Internal Server Error: /api/v1/toggle_subscription/4ea48abe-cec6-4b37-ab9c-37e253412416/
DEBUG 2025-01-22 04:06:14,190 SubscriberView.py SubscriberView toggle_subscription 38: Error found : 'Users' object has no attribute 'username'
ERROR 2025-01-22 04:06:14,190 log.py log log_response 248: Internal Server Error: /api/v1/toggle_subscription/4ea48abe-cec6-4b37-ab9c-37e253412416/
DEBUG 2025-01-22 04:06:30,542 SubscriberView.py SubscriberView toggle_subscription 38: Error found : 'Users' object has no attribute 'username'
ERROR 2025-01-22 04:06:30,543 log.py log log_response 248: Internal Server Error: /api/v1/toggle_subscription/4ea48abe-cec6-4b37-ab9c-37e253412416/
DEBUG 2025-01-22 04:12:25,647 SubscriberView.py SubscriberView toggle_subscription 25: logged in user:rushi
DEBUG 2025-01-22 04:12:25,647 SubscriberView.py SubscriberView toggle_subscription 39: Error found : Users matching query does not exist.
ERROR 2025-01-22 04:12:25,647 log.py log log_response 248: Internal Server Error: /api/v1/toggle_subscription/4ea48abe-cec6-4b37-ab9c-37e253412416/
DEBUG 2025-01-22 04:18:58,877 SubscriberView.py SubscriberView toggle_subscription 25: logged in user:rushi
DEBUG 2025-01-22 04:18:58,878 SubscriberView.py SubscriberView toggle_subscription 26: channel user:rushi
DEBUG 2025-01-22 04:51:08,376 SubscriberView.py SubscriberView toggle_subscription 25: logged in user:rushi
DEBUG 2025-01-22 04:51:08,378 SubscriberView.py SubscriberView toggle_subscription 26: channel user:rushi
DEBUG 2025-01-22 04:52:26,108 SubscriberView.py SubscriberView toggle_subscription 25: logged in user:rushi
DEBUG 2025-01-22 04:52:26,109 SubscriberView.py SubscriberView toggle_subscription 26: channel user:rushi
DEBUG 2025-01-22 04:52:26,110 SubscriberView.py SubscriberView toggle_subscription 43: Error found : get() returned more than one Subscriptions -- it returned 2!
ERROR 2025-01-22 04:52:26,110 log.py log log_response 248: Internal Server Error: /api/v1/toggle_subscription/44d0472f-7c4d-4a93-99b7-ad6728c86e86/
DEBUG 2025-01-22 04:52:36,527 SubscriberView.py SubscriberView toggle_subscription 25: logged in user:rushi
DEBUG 2025-01-22 04:52:36,527 SubscriberView.py SubscriberView toggle_subscription 26: channel user:rushi
DEBUG 2025-01-22 04:52:36,528 SubscriberView.py SubscriberView toggle_subscription 43: Error found : get() returned more than one Subscriptions -- it returned 2!
ERROR 2025-01-22 04:52:36,529 log.py log log_response 248: Internal Server Error: /api/v1/toggle_subscription/44d0472f-7c4d-4a93-99b7-ad6728c86e86/
DEBUG 2025-01-22 04:52:54,541 SubscriberView.py SubscriberView toggle_subscription 25: logged in user:rushi
DEBUG 2025-01-22 04:52:54,542 SubscriberView.py SubscriberView toggle_subscription 26: channel user:rushi
DEBUG 2025-01-22 04:52:54,542 SubscriberView.py SubscriberView toggle_subscription 44: Error found : get() returned more than one Subscriptions -- it returned 2!
ERROR 2025-01-22 04:52:54,543 log.py log log_response 248: Internal Server Error: /api/v1/toggle_subscription/44d0472f-7c4d-4a93-99b7-ad6728c86e86/
DEBUG 2025-01-22 04:54:11,876 SubscriberView.py SubscriberView toggle_subscription 25: logged in user:rushi
DEBUG 2025-01-22 04:54:11,877 SubscriberView.py SubscriberView toggle_subscription 26: channel user:rushi
DEBUG 2025-01-22 04:54:11,879 SubscriberView.py SubscriberView toggle_subscription 44: Error found : get() returned more than one Subscriptions -- it returned 2!
ERROR 2025-01-22 04:54:11,880 log.py log log_response 248: Internal Server Error: /api/v1/toggle_subscription/44d0472f-7c4d-4a93-99b7-ad6728c86e86/
DEBUG 2025-01-22 04:54:28,154 SubscriberView.py SubscriberView toggle_subscription 25: logged in user:rushi
DEBUG 2025-01-22 04:54:28,154 SubscriberView.py SubscriberView toggle_subscription 26: channel user:rushi
DEBUG 2025-01-22 04:54:28,155 SubscriberView.py SubscriberView toggle_subscription 44: Error found : get() returned more than one Subscriptions -- it returned 2!
ERROR 2025-01-22 04:54:28,156 log.py log log_response 248: Internal Server Error: /api/v1/toggle_subscription/44d0472f-7c4d-4a93-99b7-ad6728c86e86/
WARNING 2025-01-22 16:53:13,202 log.py log log_response 248: Unauthorized: /api/v1/toggle_subscription/44d0472f-7c4d-4a93-99b7-ad6728c86e86/
DEBUG 2025-01-22 16:53:24,263 SubscriberView.py SubscriberView toggle_subscription 25: logged in user:rushi
DEBUG 2025-01-22 16:53:24,264 SubscriberView.py SubscriberView toggle_subscription 26: channel user:rushi
DEBUG 2025-01-22 16:53:24,265 SubscriberView.py SubscriberView toggle_subscription 48: Error found : get() returned more than one Subscriptions -- it returned 2!
ERROR 2025-01-22 16:53:24,266 log.py log log_response 248: Internal Server Error: /api/v1/toggle_subscription/44d0472f-7c4d-4a93-99b7-ad6728c86e86/
DEBUG 2025-01-22 16:53:28,470 SubscriberView.py SubscriberView toggle_subscription 25: logged in user:rushi
DEBUG 2025-01-22 16:53:28,471 SubscriberView.py SubscriberView toggle_subscription 26: channel user:rushi
DEBUG 2025-01-22 16:53:28,472 SubscriberView.py SubscriberView toggle_subscription 48: Error found : get() returned more than one Subscriptions -- it returned 2!
ERROR 2025-01-22 16:53:28,473 log.py log log_response 248: Internal Server Error: /api/v1/toggle_subscription/44d0472f-7c4d-4a93-99b7-ad6728c86e86/
DEBUG 2025-01-22 16:54:19,437 SubscriberView.py SubscriberView toggle_subscription 25: logged in user:rushi
DEBUG 2025-01-22 16:54:19,438 SubscriberView.py SubscriberView toggle_subscription 26: channel user:rushi
DEBUG 2025-01-22 16:54:19,438 SubscriberView.py SubscriberView toggle_subscription 48: Error found : get() returned more than one Subscriptions -- it returned 2!
ERROR 2025-01-22 16:54:19,438 log.py log log_response 248: Internal Server Error: /api/v1/toggle_subscription/44d0472f-7c4d-4a93-99b7-ad6728c86e86/
DEBUG 2025-01-22 16:54:43,476 SubscriberView.py SubscriberView toggle_subscription 25: logged in user:rushi
DEBUG 2025-01-22 16:54:43,477 SubscriberView.py SubscriberView toggle_subscription 26: channel user:rushi
DEBUG 2025-01-22 16:54:43,478 SubscriberView.py SubscriberView toggle_subscription 48: Error found : get() returned more than one Subscriptions -- it returned 2!
ERROR 2025-01-22 16:54:43,479 log.py log log_response 248: Internal Server Error: /api/v1/toggle_subscription/44d0472f-7c4d-4a93-99b7-ad6728c86e86/
DEBUG 2025-01-22 16:54:45,020 SubscriberView.py SubscriberView toggle_subscription 25: logged in user:rushi
DEBUG 2025-01-22 16:54:45,021 SubscriberView.py SubscriberView toggle_subscription 26: channel user:rushi
DEBUG 2025-01-22 16:54:45,021 SubscriberView.py SubscriberView toggle_subscription 48: Error found : get() returned more than one Subscriptions -- it returned 2!
ERROR 2025-01-22 16:54:45,021 log.py log log_response 248: Internal Server Error: /api/v1/toggle_subscription/44d0472f-7c4d-4a93-99b7-ad6728c86e86/
DEBUG 2025-01-22 16:54:54,310 SubscriberView.py SubscriberView toggle_subscription 25: logged in user:rushi
DEBUG 2025-01-22 16:54:54,311 SubscriberView.py SubscriberView toggle_subscription 26: channel user:rushi
DEBUG 2025-01-22 16:54:54,312 SubscriberView.py SubscriberView toggle_subscription 48: Error found : get() returned more than one Subscriptions -- it returned 2!
ERROR 2025-01-22 16:54:54,312 log.py log log_response 248: Internal Server Error: /api/v1/toggle_subscription/44d0472f-7c4d-4a93-99b7-ad6728c86e86/
DEBUG 2025-01-22 16:55:18,049 SubscriberView.py SubscriberView toggle_subscription 25: logged in user:rushi
DEBUG 2025-01-22 16:55:18,050 SubscriberView.py SubscriberView toggle_subscription 26: channel user:rushi
DEBUG 2025-01-22 16:55:18,052 SubscriberView.py SubscriberView toggle_subscription 48: Error found : get() returned more than one Subscriptions -- it returned 2!
ERROR 2025-01-22 16:55:18,052 log.py log log_response 248: Internal Server Error: /api/v1/toggle_subscription/44d0472f-7c4d-4a93-99b7-ad6728c86e86/
DEBUG 2025-01-22 16:56:12,115 SubscriberView.py SubscriberView toggle_subscription 25: logged in user:rushi
DEBUG 2025-01-22 16:56:12,115 SubscriberView.py SubscriberView toggle_subscription 26: channel user:rushi
DEBUG 2025-01-22 16:56:12,117 SubscriberView.py SubscriberView toggle_subscription 31: rushi
DEBUG 2025-01-22 16:56:41,685 SubscriberView.py SubscriberView toggle_subscription 25: logged in user:rushi
DEBUG 2025-01-22 16:56:41,686 SubscriberView.py SubscriberView toggle_subscription 26: channel user:rushi
DEBUG 2025-01-22 16:56:50,831 SubscriberView.py SubscriberView toggle_subscription 25: logged in user:rushi
DEBUG 2025-01-22 16:56:50,831 SubscriberView.py SubscriberView toggle_subscription 26: channel user:rushi
DEBUG 2025-01-22 16:57:02,279 SubscriberView.py SubscriberView toggle_subscription 25: logged in user:rushi
DEBUG 2025-01-22 16:57:02,279 SubscriberView.py SubscriberView toggle_subscription 26: channel user:rushi
DEBUG 2025-01-22 16:57:02,280 SubscriberView.py SubscriberView toggle_subscription 48: Error found : 'QuerySet' object has no attribute 'subscriber'
ERROR 2025-01-22 16:57:02,280 log.py log log_response 248: Internal Server Error: /api/v1/toggle_subscription/44d0472f-7c4d-4a93-99b7-ad6728c86e86/
DEBUG 2025-01-22 16:57:12,046 SubscriberView.py SubscriberView toggle_subscription 25: logged in user:rushi
DEBUG 2025-01-22 16:57:12,046 SubscriberView.py SubscriberView toggle_subscription 26: channel user:rushi
DEBUG 2025-01-22 17:02:38,138 SubscriberView.py SubscriberView toggle_subscription 25: logged in user:rushi
DEBUG 2025-01-22 17:02:38,139 SubscriberView.py SubscriberView toggle_subscription 26: channel user:rushi
DEBUG 2025-01-22 17:02:38,140 SubscriberView.py SubscriberView toggle_subscription 49: Error found : 'QuerySet' object has no attribute 'subscriber'
ERROR 2025-01-22 17:02:38,140 log.py log log_response 248: Internal Server Error: /api/v1/toggle_subscription/44d0472f-7c4d-4a93-99b7-ad6728c86e86/
DEBUG 2025-01-22 17:03:43,652 SubscriberView.py SubscriberView toggle_subscription 25: logged in user:rushi
DEBUG 2025-01-22 17:03:43,653 SubscriberView.py SubscriberView toggle_subscription 26: channel user:rushi
DEBUG 2025-01-22 17:03:43,654 SubscriberView.py SubscriberView toggle_subscription 49: Error found : 'QuerySet' object has no attribute 'subscriber'
ERROR 2025-01-22 17:03:43,654 log.py log log_response 248: Internal Server Error: /api/v1/toggle_subscription/44d0472f-7c4d-4a93-99b7-ad6728c86e86/
DEBUG 2025-01-22 17:04:26,071 SubscriberView.py SubscriberView toggle_subscription 25: logged in user:rushi
DEBUG 2025-01-22 17:04:26,072 SubscriberView.py SubscriberView toggle_subscription 26: channel user:rushi
DEBUG 2025-01-22 17:04:26,073 SubscriberView.py SubscriberView toggle_subscription 49: Error found : Subscriptions matching query does not exist.
ERROR 2025-01-22 17:04:26,073 log.py log log_response 248: Internal Server Error: /api/v1/toggle_subscription/44d0472f-7c4d-4a93-99b7-ad6728c86e86/
DEBUG 2025-01-22 17:05:12,796 SubscriberView.py SubscriberView toggle_subscription 25: logged in user:rushi
DEBUG 2025-01-22 17:05:12,796 SubscriberView.py SubscriberView toggle_subscription 26: channel user:rushi
DEBUG 2025-01-22 17:05:12,798 SubscriberView.py SubscriberView toggle_subscription 49: Error found : Subscriptions matching query does not exist.
ERROR 2025-01-22 17:05:12,798 log.py log log_response 248: Internal Server Error: /api/v1/toggle_subscription/44d0472f-7c4d-4a93-99b7-ad6728c86e86/
DEBUG 2025-01-22 17:06:36,533 SubscriberView.py SubscriberView toggle_subscription 25: logged in user:rushi
DEBUG 2025-01-22 17:06:36,534 SubscriberView.py SubscriberView toggle_subscription 26: channel user:rushi
DEBUG 2025-01-22 17:07:40,693 SubscriberView.py SubscriberView toggle_subscription 25: logged in user:rushi
DEBUG 2025-01-22 17:07:40,694 SubscriberView.py SubscriberView toggle_subscription 26: channel user:rushi
DEBUG 2025-01-22 17:07:40,695 SubscriberView.py SubscriberView toggle_subscription 34: subscriber doesn't exits
DEBUG 2025-01-22 17:07:40,695 SubscriberView.py SubscriberView toggle_subscription 51: Error found : local variable 'already_exits' referenced before assignment
ERROR 2025-01-22 17:07:40,695 log.py log log_response 248: Internal Server Error: /api/v1/toggle_subscription/44d0472f-7c4d-4a93-99b7-ad6728c86e86/
DEBUG 2025-01-22 17:08:09,512 SubscriberView.py SubscriberView toggle_subscription 25: logged in user:rushi
DEBUG 2025-01-22 17:08:09,514 SubscriberView.py SubscriberView toggle_subscription 26: channel user:rushi
DEBUG 2025-01-22 17:08:09,515 SubscriberView.py SubscriberView toggle_subscription 34: subscriber doesn't exits
DEBUG 2025-01-22 17:08:19,665 SubscriberView.py SubscriberView toggle_subscription 25: logged in user:rushi
DEBUG 2025-01-22 17:08:19,666 SubscriberView.py SubscriberView toggle_subscription 26: channel user:rushi
DEBUG 2025-01-22 17:11:02,918 SubscriberView.py SubscriberView toggle_subscription 25: logged in user:rushi
DEBUG 2025-01-22 17:11:02,918 SubscriberView.py SubscriberView toggle_subscription 26: channel user:rushi
DEBUG 2025-01-22 17:12:19,539 SubscriberView.py SubscriberView toggle_subscription 25: logged in user:rushi
DEBUG 2025-01-22 17:12:19,540 SubscriberView.py SubscriberView toggle_subscription 26: channel user:rushi
DEBUG 2025-01-22 17:12:36,163 SubscriberView.py SubscriberView toggle_subscription 25: logged in user:rushi
DEBUG 2025-01-22 17:12:36,163 SubscriberView.py SubscriberView toggle_subscription 26: channel user:rushi
DEBUG 2025-01-22 17:12:36,165 SubscriberView.py SubscriberView toggle_subscription 53: Error found : 'Manager' object has no attribute 'create_or_update'
ERROR 2025-01-22 17:12:36,166 log.py log log_response 248: Internal Server Error: /api/v1/toggle_subscription/44d0472f-7c4d-4a93-99b7-ad6728c86e86/
DEBUG 2025-01-22 17:13:22,422 SubscriberView.py SubscriberView toggle_subscription 25: logged in user:rushi
DEBUG 2025-01-22 17:13:22,423 SubscriberView.py SubscriberView toggle_subscription 26: channel user:rushi
DEBUG 2025-01-22 17:13:35,149 SubscriberView.py SubscriberView toggle_subscription 25: logged in user:rushi
DEBUG 2025-01-22 17:13:35,150 SubscriberView.py SubscriberView toggle_subscription 26: channel user:rushi
DEBUG 2025-01-22 17:16:35,030 SubscriberView.py SubscriberView toggle_subscription 25: logged in user:rushi
DEBUG 2025-01-22 17:16:35,031 SubscriberView.py SubscriberView toggle_subscription 26: channel user:rushi
DEBUG 2025-01-22 17:16:35,035 SubscriberView.py SubscriberView toggle_subscription 54: Error found : 'function' object has no attribute 'all'
ERROR 2025-01-22 17:16:35,036 log.py log log_response 248: Internal Server Error: /api/v1/toggle_subscription/44d0472f-7c4d-4a93-99b7-ad6728c86e86/
DEBUG 2025-01-22 17:17:10,193 SubscriberView.py SubscriberView toggle_subscription 25: logged in user:rushi
DEBUG 2025-01-22 17:17:10,194 SubscriberView.py SubscriberView toggle_subscription 26: channel user:rushi
DEBUG 2025-01-22 17:17:10,197 SubscriberView.py SubscriberView toggle_subscription 54: Error found : Manager isn't accessible via Subscriptions instances
ERROR 2025-01-22 17:17:10,197 log.py log log_response 248: Internal Server Error: /api/v1/toggle_subscription/44d0472f-7c4d-4a93-99b7-ad6728c86e86/
DEBUG 2025-01-22 17:17:36,625 SubscriberView.py SubscriberView toggle_subscription 25: logged in user:rushi
DEBUG 2025-01-22 17:17:36,626 SubscriberView.py SubscriberView toggle_subscription 26: channel user:rushi
DEBUG 2025-01-22 17:17:36,630 SubscriberView.py SubscriberView toggle_subscription 54: Error found : Manager isn't accessible via Subscriptions instances
ERROR 2025-01-22 17:17:36,630 log.py log log_response 248: Internal Server Error: /api/v1/toggle_subscription/44d0472f-7c4d-4a93-99b7-ad6728c86e86/
DEBUG 2025-01-22 17:17:57,334 SubscriberView.py SubscriberView toggle_subscription 25: logged in user:rushi
DEBUG 2025-01-22 17:17:57,335 SubscriberView.py SubscriberView toggle_subscription 26: channel user:rushi
DEBUG 2025-01-22 17:18:03,770 SubscriberView.py SubscriberView toggle_subscription 25: logged in user:rushi
DEBUG 2025-01-22 17:18:03,771 SubscriberView.py SubscriberView toggle_subscription 26: channel user:rushi
DEBUG 2025-01-22 17:18:05,264 SubscriberView.py SubscriberView toggle_subscription 25: logged in user:rushi
DEBUG 2025-01-22 17:18:05,264 SubscriberView.py SubscriberView toggle_subscription 26: channel user:rushi
DEBUG 2025-01-22 17:18:27,128 SubscriberView.py SubscriberView toggle_subscription 25: logged in user:rushi
DEBUG 2025-01-22 17:18:27,129 SubscriberView.py SubscriberView toggle_subscription 26: channel user:rushi
DEBUG 2025-01-22 17:18:30,147 SubscriberView.py SubscriberView toggle_subscription 25: logged in user:rushi
DEBUG 2025-01-22 17:18:30,148 SubscriberView.py SubscriberView toggle_subscription 26: channel user:rushi
DEBUG 2025-01-22 17:20:24,798 SubscriberView.py SubscriberView toggle_subscription 25: logged in user:rushi
DEBUG 2025-01-22 17:20:24,798 SubscriberView.py SubscriberView toggle_subscription 26: channel user:rushi
DEBUG 2025-01-22 17:21:26,065 SubscriberView.py SubscriberView toggle_subscription 25: logged in user:rushi
DEBUG 2025-01-22 17:21:26,066 SubscriberView.py SubscriberView toggle_subscription 26: channel user:rushi
DEBUG 2025-01-22 17:21:29,426 SubscriberView.py SubscriberView toggle_subscription 25: logged in user:rushi
DEBUG 2025-01-22 17:21:29,427 SubscriberView.py SubscriberView toggle_subscription 26: channel user:rushi
DEBUG 2025-01-22 17:22:36,692 SubscriberView.py SubscriberView toggle_subscription 25: logged in user:rushi
DEBUG 2025-01-22 17:22:36,693 SubscriberView.py SubscriberView toggle_subscription 26: channel user:rushi
DEBUG 2025-01-22 17:22:51,097 SubscriberView.py SubscriberView toggle_subscription 25: logged in user:rushi
DEBUG 2025-01-22 17:22:51,098 SubscriberView.py SubscriberView toggle_subscription 26: channel user:rushi
DEBUG 2025-01-22 17:23:38,180 SubscriberView.py SubscriberView toggle_subscription 25: logged in user:rushi
DEBUG 2025-01-22 17:23:38,181 SubscriberView.py SubscriberView toggle_subscription 26: channel user:rushi
DEBUG 2025-01-22 17:25:20,966 SubscriberView.py SubscriberView toggle_subscription 25: logged in user:rushi
DEBUG 2025-01-22 17:25:20,967 SubscriberView.py SubscriberView toggle_subscription 26: channel user:rushi
DEBUG 2025-01-22 17:25:20,968 SubscriberView.py SubscriberView toggle_subscription 38: Subscriptions matching query does not exist.
DEBUG 2025-01-22 17:25:20,972 SubscriberView.py SubscriberView toggle_subscription 52: Error found : cannot unpack non-iterable Subscriptions object
ERROR 2025-01-22 17:25:20,973 log.py log log_response 248: Internal Server Error: /api/v1/toggle_subscription/44d0472f-7c4d-4a93-99b7-ad6728c86e86/
DEBUG 2025-01-22 17:25:50,974 SubscriberView.py SubscriberView toggle_subscription 25: logged in user:rushi
DEBUG 2025-01-22 17:25:50,974 SubscriberView.py SubscriberView toggle_subscription 26: channel user:rushi
DEBUG 2025-01-22 17:27:47,100 SubscriberView.py SubscriberView toggle_subscription 25: logged in user:rushi
DEBUG 2025-01-22 17:27:47,101 SubscriberView.py SubscriberView toggle_subscription 26: channel user:rushi
DEBUG 2025-01-22 17:27:47,103 SubscriberView.py SubscriberView toggle_subscription 38: Subscriptions matching query does not exist.
DEBUG 2025-01-22 17:27:47,107 SubscriberView.py SubscriberView toggle_subscription 52: Error found : cannot unpack non-iterable Subscriptions object
ERROR 2025-01-22 17:27:47,108 log.py log log_response 248: Internal Server Error: /api/v1/toggle_subscription/44d0472f-7c4d-4a93-99b7-ad6728c86e86/
DEBUG 2025-01-22 17:28:22,785 SubscriberView.py SubscriberView toggle_subscription 25: logged in user:rushi
DEBUG 2025-01-22 17:28:22,786 SubscriberView.py SubscriberView toggle_subscription 26: channel user:rushi
DEBUG 2025-01-22 17:30:00,755 SubscriberView.py SubscriberView toggle_subscription 25: logged in user:rushi
DEBUG 2025-01-22 17:30:00,755 SubscriberView.py SubscriberView toggle_subscription 26: channel user:rushi
DEBUG 2025-01-22 17:30:04,074 SubscriberView.py SubscriberView toggle_subscription 25: logged in user:rushi
DEBUG 2025-01-22 17:30:04,075 SubscriberView.py SubscriberView toggle_subscription 26: channel user:rushi
DEBUG 2025-01-22 17:30:04,076 SubscriberView.py SubscriberView toggle_subscription 38: Subscriptions matching query does not exist.
ERROR 2025-01-22 17:30:04,099 log.py log log_response 248: Internal Server Error: /api/v1/toggle_subscription/44d0472f-7c4d-4a93-99b7-ad6728c86e86/
Traceback (most recent call last):
  File "/home/rushikeshkadam/code_space/videoView/server/venv/lib/python3.10/site-packages/django/core/handlers/exception.py", line 55, in inner
    response = get_response(request)
  File "/home/rushikeshkadam/code_space/videoView/server/venv/lib/python3.10/site-packages/django/core/handlers/base.py", line 220, in _get_response
    response = response.render()
  File "/home/rushikeshkadam/code_space/videoView/server/venv/lib/python3.10/site-packages/django/template/response.py", line 114, in render
    self.content = self.rendered_content
  File "/home/rushikeshkadam/code_space/videoView/server/venv/lib/python3.10/site-packages/rest_framework/response.py", line 74, in rendered_content
    ret = renderer.render(self.data, accepted_media_type, context)
  File "/home/rushikeshkadam/code_space/videoView/server/venv/lib/python3.10/site-packages/rest_framework/renderers.py", line 100, in render
    ret = json.dumps(
  File "/home/rushikeshkadam/code_space/videoView/server/venv/lib/python3.10/site-packages/rest_framework/utils/json.py", line 25, in dumps
    return json.dumps(*args, **kwargs)
  File "/usr/lib/python3.10/json/__init__.py", line 238, in dumps
    **kw).encode(obj)
  File "/usr/lib/python3.10/json/encoder.py", line 199, in encode
    chunks = self.iterencode(o, _one_shot=True)
  File "/usr/lib/python3.10/json/encoder.py", line 257, in iterencode
    return _iterencode(o, 0)
  File "/home/rushikeshkadam/code_space/videoView/server/venv/lib/python3.10/site-packages/rest_framework/utils/encoders.py", line 67, in default
    return super().default(obj)
  File "/usr/lib/python3.10/json/encoder.py", line 179, in default
    raise TypeError(f'Object of type {o.__class__.__name__} '
TypeError: Object of type Users is not JSON serializable
DEBUG 2025-01-22 17:30:30,115 SubscriberView.py SubscriberView toggle_subscription 25: logged in user:rushi
DEBUG 2025-01-22 17:30:30,116 SubscriberView.py SubscriberView toggle_subscription 26: channel user:rushi
DEBUG 2025-01-22 17:30:33,091 SubscriberView.py SubscriberView toggle_subscription 25: logged in user:rushi
DEBUG 2025-01-22 17:30:33,092 SubscriberView.py SubscriberView toggle_subscription 26: channel user:rushi
DEBUG 2025-01-22 17:30:33,094 SubscriberView.py SubscriberView toggle_subscription 38: Subscriptions matching query does not exist.
DEBUG 2025-01-22 17:30:35,907 SubscriberView.py SubscriberView toggle_subscription 25: logged in user:rushi
DEBUG 2025-01-22 17:30:35,907 SubscriberView.py SubscriberView toggle_subscription 26: channel user:rushi
DEBUG 2025-01-22 17:30:37,112 SubscriberView.py SubscriberView toggle_subscription 25: logged in user:rushi
DEBUG 2025-01-22 17:30:37,112 SubscriberView.py SubscriberView toggle_subscription 26: channel user:rushi
DEBUG 2025-01-22 17:30:37,113 SubscriberView.py SubscriberView toggle_subscription 38: Subscriptions matching query does not exist.
DEBUG 2025-01-22 17:31:01,501 SubscriberView.py SubscriberView toggle_subscription 25: logged in user:rushi
DEBUG 2025-01-22 17:31:01,501 SubscriberView.py SubscriberView toggle_subscription 26: channel user:rushi
DEBUG 2025-01-22 17:31:06,109 SubscriberView.py SubscriberView toggle_subscription 25: logged in user:rushi
DEBUG 2025-01-22 17:31:06,110 SubscriberView.py SubscriberView toggle_subscription 26: channel user:rushi
DEBUG 2025-01-22 17:31:06,111 SubscriberView.py SubscriberView toggle_subscription 38: Subscriptions matching query does not exist.
DEBUG 2025-01-23 04:31:50,772 SubscriberView.py SubscriberView get_videos_by_channel_Id 67: Error found :QuerySet.first() got an unexpected keyword argument 'owner'
ERROR 2025-01-23 04:31:50,799 log.py log log_response 248: Internal Server Error: /api/v1/get_videos_by_channel_Id/44d0472f-7c4d-4a93-99b7-ad6728c86e86/
Traceback (most recent call last):
  File "/home/rushikeshkadam/code_space/videoView/server/venv/lib/python3.10/site-packages/django/core/handlers/exception.py", line 55, in inner
    response = get_response(request)
  File "/home/rushikeshkadam/code_space/videoView/server/venv/lib/python3.10/site-packages/django/core/handlers/base.py", line 197, in _get_response
    response = wrapped_callback(request, *callback_args, **callback_kwargs)
  File "/home/rushikeshkadam/code_space/videoView/server/venv/lib/python3.10/site-packages/django/views/decorators/csrf.py", line 65, in _view_wrapper
    return view_func(request, *args, **kwargs)
  File "/home/rushikeshkadam/code_space/videoView/server/venv/lib/python3.10/site-packages/django/views/generic/base.py", line 104, in view
    return self.dispatch(request, *args, **kwargs)
  File "/home/rushikeshkadam/code_space/videoView/server/venv/lib/python3.10/site-packages/rest_framework/views.py", line 511, in dispatch
    self.response = self.finalize_response(request, response, *args, **kwargs)
  File "/home/rushikeshkadam/code_space/videoView/server/venv/lib/python3.10/site-packages/rest_framework/views.py", line 423, in finalize_response
    assert isinstance(response, HttpResponseBase), (
AssertionError: Expected a `Response`, `HttpResponse` or `StreamingHttpResponse` to be returned from the view, but received a `<class 'NoneType'>`
DEBUG 2025-01-23 04:32:55,626 SubscriberView.py SubscriberView get_videos_by_channel_Id 68: Error found :QuerySet.first() got an unexpected keyword argument 'owner'
ERROR 2025-01-23 04:32:55,629 log.py log log_response 248: Internal Server Error: /api/v1/get_videos_by_channel_Id/44d0472f-7c4d-4a93-99b7-ad6728c86e86/
DEBUG 2025-01-23 04:34:38,595 SubscriberView.py SubscriberView get_videos_by_channel_Id 68: Error found :Users matching query does not exist.
ERROR 2025-01-23 04:34:38,595 log.py log log_response 248: Internal Server Error: /api/v1/get_videos_by_channel_Id/44d0472f-7c4d-4a93-99b7-ad6728c86e86/
WARNING 2025-01-23 16:58:32,883 log.py log log_response 248: Unauthorized: /api/v1/toggle_subscription/44d0472f-7c4d-4a93-99b7-ad6728c86e86/
DEBUG 2025-01-23 16:58:43,149 SubscriberView.py SubscriberView toggle_subscription 25: logged in user:rushi
DEBUG 2025-01-23 16:58:43,149 SubscriberView.py SubscriberView toggle_subscription 26: channel user:rushi
DEBUG 2025-01-23 16:58:46,249 SubscriberView.py SubscriberView toggle_subscription 25: logged in user:rushi
DEBUG 2025-01-23 16:58:46,250 SubscriberView.py SubscriberView toggle_subscription 26: channel user:rushi
DEBUG 2025-01-23 16:58:46,251 SubscriberView.py SubscriberView toggle_subscription 37: Subscriptions matching query does not exist.
DEBUG 2025-01-23 16:59:22,856 SubscriberView.py SubscriberView get_videos_by_channel_Id 72: Error found :Users matching query does not exist.
ERROR 2025-01-23 16:59:22,856 log.py log log_response 248: Internal Server Error: /api/v1/get_videos_by_channel_Id/44d0472f-7c4d-4a93-99b7-ad6728c86e86/
DEBUG 2025-01-23 17:04:10,537 SubscriberView.py SubscriberView toggle_subscription 25: logged in user:rushi
DEBUG 2025-01-23 17:04:10,538 SubscriberView.py SubscriberView toggle_subscription 26: channel user:rushi
DEBUG 2025-01-23 17:04:10,539 SubscriberView.py SubscriberView toggle_subscription 37: Subscriptions matching query does not exist.
DEBUG 2025-01-23 17:04:14,643 SubscriberView.py SubscriberView toggle_subscription 25: logged in user:rushi
DEBUG 2025-01-23 17:04:14,644 SubscriberView.py SubscriberView toggle_subscription 26: channel user:rushi
DEBUG 2025-01-23 17:04:22,073 SubscriberView.py SubscriberView get_videos_by_channel_Id 72: Error found :Users matching query does not exist.
ERROR 2025-01-23 17:04:22,073 log.py log log_response 248: Internal Server Error: /api/v1/get_videos_by_channel_Id/4ee934b7-161c-4392-ae2f-2d74587d6d44/
DEBUG 2025-01-23 17:06:48,591 SubscriberView.py SubscriberView get_videos_by_channel_Id 73: Error found :Cannot use QuerySet for "Subscriptions": Use a QuerySet for "Users".
ERROR 2025-01-23 17:06:48,592 log.py log log_response 248: Internal Server Error: /api/v1/get_videos_by_channel_Id/4ee934b7-161c-4392-ae2f-2d74587d6d44/
DEBUG 2025-01-23 17:07:35,996 SubscriberView.py SubscriberView get_videos_by_channel_Id 73: Error found :Cannot use QuerySet for "Subscriptions": Use a QuerySet for "Users".
ERROR 2025-01-23 17:07:35,997 log.py log log_response 248: Internal Server Error: /api/v1/get_videos_by_channel_Id/4ee934b7-161c-4392-ae2f-2d74587d6d44/
DEBUG 2025-01-23 17:09:14,834 SubscriberView.py SubscriberView get_videos_by_channel_Id 73: Error found :Cannot use QuerySet for "Subscriptions": Use a QuerySet for "Users".
ERROR 2025-01-23 17:09:14,835 log.py log log_response 248: Internal Server Error: /api/v1/get_videos_by_channel_Id/4ee934b7-161c-4392-ae2f-2d74587d6d44/
DEBUG 2025-01-23 17:11:40,516 SubscriberView.py SubscriberView get_videos_by_channel_Id 74: Error found :Subscriptions matching query does not exist.
ERROR 2025-01-23 17:11:40,517 log.py log log_response 248: Internal Server Error: /api/v1/get_videos_by_channel_Id/4ee934b7-161c-4392-ae2f-2d74587d6d44/
DEBUG 2025-01-23 17:11:57,326 SubscriberView.py SubscriberView get_videos_by_channel_Id 74: Error found :Subscriptions matching query does not exist.
ERROR 2025-01-23 17:11:57,327 log.py log log_response 248: Internal Server Error: /api/v1/get_videos_by_channel_Id/4ee934b7-161c-4392-ae2f-2d74587d6d44/
DEBUG 2025-01-23 17:12:18,887 SubscriberView.py SubscriberView get_videos_by_channel_Id 74: Error found :Subscriptions matching query does not exist.
ERROR 2025-01-23 17:12:18,888 log.py log log_response 248: Internal Server Error: /api/v1/get_videos_by_channel_Id/4ee934b7-161c-4392-ae2f-2d74587d6d44/
DEBUG 2025-01-23 17:12:36,402 SubscriberView.py SubscriberView get_videos_by_channel_Id 74: Error found :Subscriptions matching query does not exist.
ERROR 2025-01-23 17:12:36,402 log.py log log_response 248: Internal Server Error: /api/v1/get_videos_by_channel_Id/4ee934b7-161c-4392-ae2f-2d74587d6d44/
DEBUG 2025-01-23 17:13:08,789 SubscriberView.py SubscriberView get_videos_by_channel_Id 74: Error found :Subscriptions matching query does not exist.
ERROR 2025-01-23 17:13:08,790 log.py log log_response 248: Internal Server Error: /api/v1/get_videos_by_channel_Id/4ee934b7-161c-4392-ae2f-2d74587d6d44/
DEBUG 2025-01-23 17:13:53,226 SubscriberView.py SubscriberView get_videos_by_channel_Id 66: channel_obj..............: <QuerySet []>
DEBUG 2025-01-23 17:14:10,856 SubscriberView.py SubscriberView get_videos_by_channel_Id 66: channel_obj..............: None
DEBUG 2025-01-23 17:14:44,772 SubscriberView.py SubscriberView get_videos_by_channel_Id 66: channel_obj..............: Subscriptions object (ffd27642-1a82-4d13-9ffe-9b83abaea6b6)
DEBUG 2025-01-23 17:15:40,844 SubscriberView.py SubscriberView get_videos_by_channel_Id 66: channel_obj..............: Subscriptions object (ffd27642-1a82-4d13-9ffe-9b83abaea6b6)
DEBUG 2025-01-23 17:15:40,844 SubscriberView.py SubscriberView get_videos_by_channel_Id 74: Error found :Cannot query "Subscriptions object (ffd27642-1a82-4d13-9ffe-9b83abaea6b6)": Must be "Users" instance.
ERROR 2025-01-23 17:15:40,845 log.py log log_response 248: Internal Server Error: /api/v1/get_videos_by_channel_Id/44d0472f-7c4d-4a93-99b7-ad6728c86e86/
DEBUG 2025-01-23 17:16:52,765 SubscriberView.py SubscriberView get_videos_by_channel_Id 66: channel_obj..............: rushi
DEBUG 2025-01-23 17:16:52,765 SubscriberView.py SubscriberView get_videos_by_channel_Id 74: Error found :name 'all_videos_list' is not defined
ERROR 2025-01-23 17:16:52,766 log.py log log_response 248: Internal Server Error: /api/v1/get_videos_by_channel_Id/44d0472f-7c4d-4a93-99b7-ad6728c86e86/
DEBUG 2025-01-23 17:17:09,038 SubscriberView.py SubscriberView get_videos_by_channel_Id 66: channel_obj..............: rushi
DEBUG 2025-01-23 17:17:09,040 SubscriberView.py SubscriberView get_videos_by_channel_Id 71: rushi@100gmail.com
DEBUG 2025-01-23 17:21:13,096 SubscriberView.py SubscriberView get_videos_by_channel_Id 66: channel_obj..............: rushi
DEBUG 2025-01-23 17:21:13,099 SubscriberView.py SubscriberView get_videos_by_channel_Id 73: rushi@100gmail.com
DEBUG 2025-01-23 17:21:52,618 SubscriberView.py SubscriberView get_videos_by_channel_Id 66: channel_obj..............: rushi
DEBUG 2025-01-23 17:21:52,620 SubscriberView.py SubscriberView get_videos_by_channel_Id 73: rushi@124gmail.com
ERROR 2025-01-23 17:33:57,678 log.py log log_response 248: Internal Server Error: /api/v1/get_subscriber_count/4ee934b7-161c-4392-ae2f-2d74587d6d44/
Traceback (most recent call last):
  File "/home/rushikeshkadam/code_space/videoView/server/venv/lib/python3.10/site-packages/django/core/handlers/exception.py", line 55, in inner
    response = get_response(request)
  File "/home/rushikeshkadam/code_space/videoView/server/venv/lib/python3.10/site-packages/django/core/handlers/base.py", line 197, in _get_response
    response = wrapped_callback(request, *callback_args, **callback_kwargs)
  File "/home/rushikeshkadam/code_space/videoView/server/venv/lib/python3.10/site-packages/django/views/decorators/csrf.py", line 65, in _view_wrapper
    return view_func(request, *args, **kwargs)
  File "/home/rushikeshkadam/code_space/videoView/server/venv/lib/python3.10/site-packages/django/views/generic/base.py", line 104, in view
    return self.dispatch(request, *args, **kwargs)
  File "/home/rushikeshkadam/code_space/videoView/server/venv/lib/python3.10/site-packages/rest_framework/views.py", line 509, in dispatch
    response = self.handle_exception(exc)
  File "/home/rushikeshkadam/code_space/videoView/server/venv/lib/python3.10/site-packages/rest_framework/views.py", line 469, in handle_exception
    self.raise_uncaught_exception(exc)
  File "/home/rushikeshkadam/code_space/videoView/server/venv/lib/python3.10/site-packages/rest_framework/views.py", line 480, in raise_uncaught_exception
    raise exc
  File "/home/rushikeshkadam/code_space/videoView/server/venv/lib/python3.10/site-packages/rest_framework/views.py", line 506, in dispatch
    response = handler(request, *args, **kwargs)
  File "/home/rushikeshkadam/code_space/videoView/server/venv/lib/python3.10/site-packages/rest_framework/decorators.py", line 50, in handler
    return func(*args, **kwargs)
TypeError: get_subscriber_count() got an unexpected keyword argument 'channel_id'
ERROR 2025-01-23 17:34:18,938 log.py log log_response 248: Internal Server Error: /api/v1/get_subscriber_count/4ee934b7-161c-4392-ae2f-2d74587d6d44/
Traceback (most recent call last):
  File "/home/rushikeshkadam/code_space/videoView/server/venv/lib/python3.10/site-packages/django/core/handlers/exception.py", line 55, in inner
    response = get_response(request)
  File "/home/rushikeshkadam/code_space/videoView/server/venv/lib/python3.10/site-packages/django/core/handlers/base.py", line 197, in _get_response
    response = wrapped_callback(request, *callback_args, **callback_kwargs)
  File "/home/rushikeshkadam/code_space/videoView/server/venv/lib/python3.10/site-packages/django/views/decorators/csrf.py", line 65, in _view_wrapper
    return view_func(request, *args, **kwargs)
  File "/home/rushikeshkadam/code_space/videoView/server/venv/lib/python3.10/site-packages/django/views/generic/base.py", line 104, in view
    return self.dispatch(request, *args, **kwargs)
  File "/home/rushikeshkadam/code_space/videoView/server/venv/lib/python3.10/site-packages/rest_framework/views.py", line 509, in dispatch
    response = self.handle_exception(exc)
  File "/home/rushikeshkadam/code_space/videoView/server/venv/lib/python3.10/site-packages/rest_framework/views.py", line 469, in handle_exception
    self.raise_uncaught_exception(exc)
  File "/home/rushikeshkadam/code_space/videoView/server/venv/lib/python3.10/site-packages/rest_framework/views.py", line 480, in raise_uncaught_exception
    raise exc
  File "/home/rushikeshkadam/code_space/videoView/server/venv/lib/python3.10/site-packages/rest_framework/views.py", line 506, in dispatch
    response = handler(request, *args, **kwargs)
  File "/home/rushikeshkadam/code_space/videoView/server/venv/lib/python3.10/site-packages/rest_framework/decorators.py", line 50, in handler
    return func(*args, **kwargs)
TypeError: get_subscriber_count() got an unexpected keyword argument 'channel_id'
ERROR 2025-01-23 17:37:07,691 log.py log log_response 248: Internal Server Error: /api/v1/get_subscriber_count/4ee934b7-161c-4392-ae2f-2d74587d6d44/
Traceback (most recent call last):
  File "/home/rushikeshkadam/code_space/videoView/server/venv/lib/python3.10/site-packages/django/core/handlers/exception.py", line 55, in inner
    response = get_response(request)
  File "/home/rushikeshkadam/code_space/videoView/server/venv/lib/python3.10/site-packages/django/core/handlers/base.py", line 197, in _get_response
    response = wrapped_callback(request, *callback_args, **callback_kwargs)
  File "/home/rushikeshkadam/code_space/videoView/server/venv/lib/python3.10/site-packages/django/views/decorators/csrf.py", line 65, in _view_wrapper
    return view_func(request, *args, **kwargs)
  File "/home/rushikeshkadam/code_space/videoView/server/venv/lib/python3.10/site-packages/django/views/generic/base.py", line 104, in view
    return self.dispatch(request, *args, **kwargs)
  File "/home/rushikeshkadam/code_space/videoView/server/venv/lib/python3.10/site-packages/rest_framework/views.py", line 509, in dispatch
    response = self.handle_exception(exc)
  File "/home/rushikeshkadam/code_space/videoView/server/venv/lib/python3.10/site-packages/rest_framework/views.py", line 469, in handle_exception
    self.raise_uncaught_exception(exc)
  File "/home/rushikeshkadam/code_space/videoView/server/venv/lib/python3.10/site-packages/rest_framework/views.py", line 480, in raise_uncaught_exception
    raise exc
  File "/home/rushikeshkadam/code_space/videoView/server/venv/lib/python3.10/site-packages/rest_framework/views.py", line 506, in dispatch
    response = handler(request, *args, **kwargs)
  File "/home/rushikeshkadam/code_space/videoView/server/venv/lib/python3.10/site-packages/rest_framework/decorators.py", line 50, in handler
    return func(*args, **kwargs)
TypeError: get_subscriber_count() got an unexpected keyword argument 'channel_id'
ERROR 2025-01-23 17:37:42,038 log.py log log_response 248: Internal Server Error: /api/v1/get_subscriber_count/4ee934b7-161c-4392-ae2f-2d74587d6d44/
Traceback (most recent call last):
  File "/home/rushikeshkadam/code_space/videoView/server/venv/lib/python3.10/site-packages/django/core/handlers/exception.py", line 55, in inner
    response = get_response(request)
  File "/home/rushikeshkadam/code_space/videoView/server/venv/lib/python3.10/site-packages/django/core/handlers/base.py", line 197, in _get_response
    response = wrapped_callback(request, *callback_args, **callback_kwargs)
  File "/home/rushikeshkadam/code_space/videoView/server/venv/lib/python3.10/site-packages/django/views/decorators/csrf.py", line 65, in _view_wrapper
    return view_func(request, *args, **kwargs)
  File "/home/rushikeshkadam/code_space/videoView/server/venv/lib/python3.10/site-packages/django/views/generic/base.py", line 104, in view
    return self.dispatch(request, *args, **kwargs)
  File "/home/rushikeshkadam/code_space/videoView/server/venv/lib/python3.10/site-packages/rest_framework/views.py", line 509, in dispatch
    response = self.handle_exception(exc)
  File "/home/rushikeshkadam/code_space/videoView/server/venv/lib/python3.10/site-packages/rest_framework/views.py", line 469, in handle_exception
    self.raise_uncaught_exception(exc)
  File "/home/rushikeshkadam/code_space/videoView/server/venv/lib/python3.10/site-packages/rest_framework/views.py", line 480, in raise_uncaught_exception
    raise exc
  File "/home/rushikeshkadam/code_space/videoView/server/venv/lib/python3.10/site-packages/rest_framework/views.py", line 506, in dispatch
    response = handler(request, *args, **kwargs)
  File "/home/rushikeshkadam/code_space/videoView/server/venv/lib/python3.10/site-packages/rest_framework/decorators.py", line 50, in handler
    return func(*args, **kwargs)
TypeError: get_subscriber_count() got an unexpected keyword argument 'channel_id'
ERROR 2025-01-23 17:38:18,589 log.py log log_response 248: Internal Server Error: /api/v1/get_subscriber_count/4ee934b7-161c-4392-ae2f-2d74587d6d44/
Traceback (most recent call last):
  File "/home/rushikeshkadam/code_space/videoView/server/venv/lib/python3.10/site-packages/django/core/handlers/exception.py", line 55, in inner
    response = get_response(request)
  File "/home/rushikeshkadam/code_space/videoView/server/venv/lib/python3.10/site-packages/django/core/handlers/base.py", line 197, in _get_response
    response = wrapped_callback(request, *callback_args, **callback_kwargs)
  File "/home/rushikeshkadam/code_space/videoView/server/venv/lib/python3.10/site-packages/django/views/decorators/csrf.py", line 65, in _view_wrapper
    return view_func(request, *args, **kwargs)
  File "/home/rushikeshkadam/code_space/videoView/server/venv/lib/python3.10/site-packages/django/views/generic/base.py", line 104, in view
    return self.dispatch(request, *args, **kwargs)
  File "/home/rushikeshkadam/code_space/videoView/server/venv/lib/python3.10/site-packages/rest_framework/views.py", line 509, in dispatch
    response = self.handle_exception(exc)
  File "/home/rushikeshkadam/code_space/videoView/server/venv/lib/python3.10/site-packages/rest_framework/views.py", line 469, in handle_exception
    self.raise_uncaught_exception(exc)
  File "/home/rushikeshkadam/code_space/videoView/server/venv/lib/python3.10/site-packages/rest_framework/views.py", line 480, in raise_uncaught_exception
    raise exc
  File "/home/rushikeshkadam/code_space/videoView/server/venv/lib/python3.10/site-packages/rest_framework/views.py", line 506, in dispatch
    response = handler(request, *args, **kwargs)
  File "/home/rushikeshkadam/code_space/videoView/server/venv/lib/python3.10/site-packages/rest_framework/decorators.py", line 50, in handler
    return func(*args, **kwargs)
TypeError: get_subscriber_count() got an unexpected keyword argument 'channel_id'
ERROR 2025-01-23 17:40:03,237 log.py log log_response 248: Internal Server Error: /api/v1/get_subscriber_count/4ee934b7-161c-4392-ae2f-2d74587d6d44/
Traceback (most recent call last):
  File "/home/rushikeshkadam/code_space/videoView/server/venv/lib/python3.10/site-packages/django/core/handlers/exception.py", line 55, in inner
    response = get_response(request)
  File "/home/rushikeshkadam/code_space/videoView/server/venv/lib/python3.10/site-packages/django/core/handlers/base.py", line 197, in _get_response
    response = wrapped_callback(request, *callback_args, **callback_kwargs)
  File "/home/rushikeshkadam/code_space/videoView/server/venv/lib/python3.10/site-packages/django/views/decorators/csrf.py", line 65, in _view_wrapper
    return view_func(request, *args, **kwargs)
  File "/home/rushikeshkadam/code_space/videoView/server/venv/lib/python3.10/site-packages/django/views/generic/base.py", line 104, in view
    return self.dispatch(request, *args, **kwargs)
  File "/home/rushikeshkadam/code_space/videoView/server/venv/lib/python3.10/site-packages/rest_framework/views.py", line 509, in dispatch
    response = self.handle_exception(exc)
  File "/home/rushikeshkadam/code_space/videoView/server/venv/lib/python3.10/site-packages/rest_framework/views.py", line 469, in handle_exception
    self.raise_uncaught_exception(exc)
  File "/home/rushikeshkadam/code_space/videoView/server/venv/lib/python3.10/site-packages/rest_framework/views.py", line 480, in raise_uncaught_exception
    raise exc
  File "/home/rushikeshkadam/code_space/videoView/server/venv/lib/python3.10/site-packages/rest_framework/views.py", line 506, in dispatch
    response = handler(request, *args, **kwargs)
  File "/home/rushikeshkadam/code_space/videoView/server/venv/lib/python3.10/site-packages/rest_framework/decorators.py", line 50, in handler
    return func(*args, **kwargs)
TypeError: get_subscriber_count() got an unexpected keyword argument 'channel_id'
ERROR 2025-01-23 17:41:13,812 log.py log log_response 248: Internal Server Error: /api/v1/get_subscriber_count/4ee934b7-161c-4392-ae2f-2d74587d6d44/
Traceback (most recent call last):
  File "/home/rushikeshkadam/code_space/videoView/server/venv/lib/python3.10/site-packages/django/core/handlers/exception.py", line 55, in inner
    response = get_response(request)
  File "/home/rushikeshkadam/code_space/videoView/server/venv/lib/python3.10/site-packages/django/core/handlers/base.py", line 220, in _get_response
    response = response.render()
  File "/home/rushikeshkadam/code_space/videoView/server/venv/lib/python3.10/site-packages/django/template/response.py", line 114, in render
    self.content = self.rendered_content
  File "/home/rushikeshkadam/code_space/videoView/server/venv/lib/python3.10/site-packages/rest_framework/response.py", line 74, in rendered_content
    ret = renderer.render(self.data, accepted_media_type, context)
  File "/home/rushikeshkadam/code_space/videoView/server/venv/lib/python3.10/site-packages/rest_framework/renderers.py", line 100, in render
    ret = json.dumps(
  File "/home/rushikeshkadam/code_space/videoView/server/venv/lib/python3.10/site-packages/rest_framework/utils/json.py", line 25, in dumps
    return json.dumps(*args, **kwargs)
  File "/usr/lib/python3.10/json/__init__.py", line 238, in dumps
    **kw).encode(obj)
  File "/usr/lib/python3.10/json/encoder.py", line 199, in encode
    chunks = self.iterencode(o, _one_shot=True)
  File "/usr/lib/python3.10/json/encoder.py", line 257, in iterencode
    return _iterencode(o, 0)
  File "/home/rushikeshkadam/code_space/videoView/server/venv/lib/python3.10/site-packages/rest_framework/utils/encoders.py", line 67, in default
    return super().default(obj)
  File "/usr/lib/python3.10/json/encoder.py", line 179, in default
    raise TypeError(f'Object of type {o.__class__.__name__} '
TypeError: Object of type method is not JSON serializable
DEBUG 2025-01-23 17:42:06,981 SubscriberView.py SubscriberView toggle_subscription 25: logged in user:rushi
DEBUG 2025-01-23 17:42:06,982 SubscriberView.py SubscriberView toggle_subscription 26: channel user:rushi
DEBUG 2025-01-23 17:42:06,983 SubscriberView.py SubscriberView toggle_subscription 37: Subscriptions matching query does not exist.
WARNING 2025-01-25 12:27:40,108 log.py log log_response 248: Unauthorized: /api/v1/get_channel_info/4ee934b7-161c-4392-ae2f-2d74587d6d44/
DEBUG 2025-01-25 12:27:51,453 SubscriberView.py SubscriberView get_channel_info 96: Error found:name 'channel_Id' is not defined
ERROR 2025-01-25 12:27:51,453 log.py log log_response 248: Internal Server Error: /api/v1/get_channel_info/4ee934b7-161c-4392-ae2f-2d74587d6d44/
DEBUG 2025-01-25 12:28:50,108 SubscriberView.py SubscriberView get_channel_info 99: Error found:local variable 'serializer' referenced before assignment
ERROR 2025-01-25 12:28:50,109 log.py log log_response 248: Internal Server Error: /api/v1/get_channel_info/4ee934b7-161c-4392-ae2f-2d74587d6d44/
DEBUG 2025-01-25 12:29:40,584 SubscriberView.py SubscriberView get_channel_info 102: Error found:local variable 'serializer' referenced before assignment
ERROR 2025-01-25 12:29:40,587 log.py log log_response 248: Internal Server Error: /api/v1/get_channel_info/4ee934b7-161c-4392-ae2f-2d74587d6d44/
DEBUG 2025-01-25 12:30:12,271 SubscriberView.py SubscriberView get_channel_info 102: Error found:local variable 'serializer' referenced before assignment
ERROR 2025-01-25 12:30:12,272 log.py log log_response 248: Internal Server Error: /api/v1/get_channel_info/4ee934b7-161c-4392-ae2f-2d74587d6d44/
DEBUG 2025-01-25 12:30:30,822 SubscriberView.py SubscriberView get_channel_info 102: Error found:name 'serializer' is not defined
ERROR 2025-01-25 12:30:30,822 log.py log log_response 248: Internal Server Error: /api/v1/get_channel_info/4ee934b7-161c-4392-ae2f-2d74587d6d44/
DEBUG 2025-01-25 12:31:53,177 SubscriberView.py SubscriberView get_channel_info 102: Error found:Cannot call `.is_valid()` as no `data=` keyword argument was passed when instantiating the serializer instance.
ERROR 2025-01-25 12:31:53,177 log.py log log_response 248: Internal Server Error: /api/v1/get_channel_info/4ee934b7-161c-4392-ae2f-2d74587d6d44/
DEBUG 2025-01-25 12:32:05,341 SubscriberView.py SubscriberView get_channel_info 102: Error found:Cannot call `.is_valid()` as no `data=` keyword argument was passed when instantiating the serializer instance.
ERROR 2025-01-25 12:32:05,342 log.py log log_response 248: Internal Server Error: /api/v1/get_channel_info/4ee934b7-161c-4392-ae2f-2d74587d6d44/
DEBUG 2025-01-25 12:32:38,647 SubscriberView.py SubscriberView get_channel_info 102: Error found:Cannot call `.is_valid()` as no `data=` keyword argument was passed when instantiating the serializer instance.
ERROR 2025-01-25 12:32:38,647 log.py log log_response 248: Internal Server Error: /api/v1/get_channel_info/4ee934b7-161c-4392-ae2f-2d74587d6d44/
DEBUG 2025-01-25 12:32:48,045 SubscriberView.py SubscriberView get_channel_info 102: Error found:local variable 'result' referenced before assignment
ERROR 2025-01-25 12:32:48,046 log.py log log_response 248: Internal Server Error: /api/v1/get_channel_info/4ee934b7-161c-4392-ae2f-2d74587d6d44/
ERROR 2025-01-25 12:33:34,808 log.py log log_response 248: Internal Server Error: /api/v1/get_channel_info/4ee934b7-161c-4392-ae2f-2d74587d6d44/
Traceback (most recent call last):
  File "/home/rushikeshkadam/code_space/videoView/server/venv/lib/python3.10/site-packages/django/core/handlers/exception.py", line 55, in inner
    response = get_response(request)
  File "/home/rushikeshkadam/code_space/videoView/server/venv/lib/python3.10/site-packages/django/core/handlers/base.py", line 197, in _get_response
    response = wrapped_callback(request, *callback_args, **callback_kwargs)
  File "/home/rushikeshkadam/code_space/videoView/server/venv/lib/python3.10/site-packages/django/views/decorators/csrf.py", line 65, in _view_wrapper
    return view_func(request, *args, **kwargs)
  File "/home/rushikeshkadam/code_space/videoView/server/venv/lib/python3.10/site-packages/django/views/generic/base.py", line 104, in view
    return self.dispatch(request, *args, **kwargs)
  File "/home/rushikeshkadam/code_space/videoView/server/venv/lib/python3.10/site-packages/rest_framework/views.py", line 511, in dispatch
    self.response = self.finalize_response(request, response, *args, **kwargs)
  File "/home/rushikeshkadam/code_space/videoView/server/venv/lib/python3.10/site-packages/rest_framework/views.py", line 423, in finalize_response
    assert isinstance(response, HttpResponseBase), (
AssertionError: Expected a `Response`, `HttpResponse` or `StreamingHttpResponse` to be returned from the view, but received a `<class 'NoneType'>`
WARNING 2025-01-25 12:34:13,150 log.py log log_response 248: Bad Request: /api/v1/get_channel_info/4ee934b7-161c-4392-ae2f-2d74587d6d44/
DEBUG 2025-01-25 12:36:04,966 SubscriberView.py SubscriberView get_channel_info 104: Error found:When a serializer is passed a `data` keyword argument you must call `.is_valid()` before attempting to access the serialized `.data` representation.
You should either call `.is_valid()` first, or access `.initial_data` instead.
ERROR 2025-01-25 12:36:04,967 log.py log log_response 248: Internal Server Error: /api/v1/get_channel_info/4ee934b7-161c-4392-ae2f-2d74587d6d44/
DEBUG 2025-01-25 12:36:23,716 SubscriberView.py SubscriberView get_channel_info 96: rushi@124gmail.com
WARNING 2025-01-25 12:36:23,717 log.py log log_response 248: Bad Request: /api/v1/get_channel_info/4ee934b7-161c-4392-ae2f-2d74587d6d44/
DEBUG 2025-01-25 12:37:16,315 SubscriberView.py SubscriberView get_channel_info 101: Error found:When a serializer is passed a `data` keyword argument you must call `.is_valid()` before attempting to access the serialized `.data` representation.
You should either call `.is_valid()` first, or access `.initial_data` instead.
ERROR 2025-01-25 12:37:16,316 log.py log log_response 248: Internal Server Error: /api/v1/get_channel_info/4ee934b7-161c-4392-ae2f-2d74587d6d44/
DEBUG 2025-01-25 12:38:19,027 SubscriberView.py SubscriberView get_channel_info 100: Error found:['“4ee934b7-161c-4392-ae2f-2d74587d6d4” is not a valid UUID.']
ERROR 2025-01-25 12:38:19,028 log.py log log_response 248: Internal Server Error: /api/v1/get_channel_info/4ee934b7-161c-4392-ae2f-2d74587d6d4/
DEBUG 2025-01-25 12:38:55,416 SubscriberView.py SubscriberView get_channel_info 100: Error found:['“4ee934b7-161c-4392-ae2f-2d74587d6d4” is not a valid UUID.']
ERROR 2025-01-25 12:38:55,417 log.py log log_response 248: Internal Server Error: /api/v1/get_channel_info/4ee934b7-161c-4392-ae2f-2d74587d6d4/
DEBUG 2025-01-25 12:39:07,005 SubscriberView.py SubscriberView get_channel_info 101: Error found:['“4ee934b7-161c-4392-ae2f-2d74587d6d4” is not a valid UUID.']
ERROR 2025-01-25 12:39:07,006 log.py log log_response 248: Internal Server Error: /api/v1/get_channel_info/4ee934b7-161c-4392-ae2f-2d74587d6d4/
DEBUG 2025-01-25 13:55:28,088 utility.py utility wraps_func 86: Invalid token type. Token must be a <class 'bytes'>
WARNING 2025-01-25 13:55:28,088 log.py log log_response 248: Forbidden: /api/v1/get_channel_info/4ee934b7-161c-4392-ae2f-2d74587d6d44/
DEBUG 2025-01-25 13:56:18,832 utility.py utility wraps_func 86: Invalid token type. Token must be a <class 'bytes'>
WARNING 2025-01-25 13:56:18,832 log.py log log_response 248: Forbidden: /api/v1/like_video_by_user/4ee934b7-161c-4392-ae2f-2d74587d6d44/
DEBUG 2025-01-25 13:56:48,028 utility.py utility wraps_func 86: Invalid token type. Token must be a <class 'bytes'>
WARNING 2025-01-25 13:56:48,028 log.py log log_response 248: Forbidden: /api/v1/get_videos_by_channel_Id/44d0472f-7c4d-4a93-99b7-ad6728c86e86/
DEBUG 2025-01-25 13:56:55,143 LikesView.py LikesView like_video_by_user 44: Error found : Videos matching query does not exist.
ERROR 2025-01-25 13:56:55,143 log.py log log_response 248: Internal Server Error: /api/v1/like_video_by_user/4ee934b7-161c-4392-ae2f-2d74587d6d44/
DEBUG 2025-01-25 13:57:30,740 LikesView.py LikesView like_video_by_user 44: Error found : Cannot assign "'97315440-5ec6-4e71-b852-5a5229ae0bda'": "Likes.video" must be a "Videos" instance.
ERROR 2025-01-25 13:57:30,740 log.py log log_response 248: Internal Server Error: /api/v1/like_video_by_user/97315440-5ec6-4e71-b852-5a5229ae0bda/
WARNING 2025-01-25 13:58:47,914 log.py log log_response 248: Bad Request: /api/v1/like_video_by_user/97315440-5ec6-4e71-b852-5a5229ae0bda/
WARNING 2025-02-01 04:48:42,458 log.py log log_response 248: Not Found: /api/devices/
DEBUG 2025-02-01 04:54:09,678 CommentsView.py CommentsView add_comment_to_video 48: Error found : 'Request' object has no attribute 'userId'
ERROR 2025-02-01 04:54:09,679 log.py log log_response 248: Internal Server Error: /api/v1/add_comment_to_video/4ea48abe-cec6-4b37-ab9c-37e253412416/
DEBUG 2025-02-01 04:55:02,693 CommentsView.py CommentsView add_comment_to_video 48: Error found : NOT NULL constraint failed: api_comments.content
ERROR 2025-02-01 04:55:02,694 log.py log log_response 248: Internal Server Error: /api/v1/add_comment_to_video/4ea48abe-cec6-4b37-ab9c-37e253412416/
ERROR 2025-02-01 04:55:28,793 log.py log log_response 248: Internal Server Error: /api/v1/add_comment_to_video/4ea48abe-cec6-4b37-ab9c-37e253412416/
