DEBUG 2024-12-31 03:15:52,103 UserViews.py UserViews wraps_func 40: name 'request' is not defined
DEBUG 2024-12-31 03:16:38,936 UserViews.py UserViews wraps_func 40: name 'request' is not defined
DEBUG 2024-12-31 03:17:34,314 UserViews.py UserViews wraps_func 27: eyJhbGciOiJIUzI1NiIsInR5cCI6IkpXVCJ9.eyJpZCI6ImMwN2I5NTczLWVlNjktNDEzNy1iMDM3LWY1NDllY2IzNTRiOSIsImVtYWlsIjoicnVzaGkxMjIyQGV4YW1wbGUuY29tIiwiZXhwIjoxNzM1NzAxMTQ0fQ.mJU4agW2u-Ga6DoOSjPRiGj8YnlWWb8bgZNxCbAcw2E
DEBUG 2024-12-31 03:18:02,330 UserViews.py UserViews wraps_func 39: c07b9573-ee69-4137-b037-f549ecb354b9
ERROR 2024-12-31 03:20:31,969 log.py log log_response 248: Internal Server Error: /api/v1/getuser
Traceback (most recent call last):
  File "/home/rushikeshkadam/code_space/videoView/server/venv/lib/python3.10/site-packages/django/core/handlers/exception.py", line 55, in inner
    response = get_response(request)
  File "/home/rushikeshkadam/code_space/videoView/server/venv/lib/python3.10/site-packages/django/core/handlers/base.py", line 197, in _get_response
    response = wrapped_callback(request, *callback_args, **callback_kwargs)
  File "/home/rushikeshkadam/code_space/videoView/server/venv/lib/python3.10/site-packages/django/views/decorators/csrf.py", line 65, in _view_wrapper
    return view_func(request, *args, **kwargs)
  File "/home/rushikeshkadam/code_space/videoView/server/venv/lib/python3.10/site-packages/django/views/generic/base.py", line 104, in view
    return self.dispatch(request, *args, **kwargs)
  File "/home/rushikeshkadam/code_space/videoView/server/venv/lib/python3.10/site-packages/rest_framework/views.py", line 509, in dispatch
    response = self.handle_exception(exc)
  File "/home/rushikeshkadam/code_space/videoView/server/venv/lib/python3.10/site-packages/rest_framework/views.py", line 469, in handle_exception
    self.raise_uncaught_exception(exc)
  File "/home/rushikeshkadam/code_space/videoView/server/venv/lib/python3.10/site-packages/rest_framework/views.py", line 480, in raise_uncaught_exception
    raise exc
  File "/home/rushikeshkadam/code_space/videoView/server/venv/lib/python3.10/site-packages/rest_framework/views.py", line 506, in dispatch
    response = handler(request, *args, **kwargs)
  File "/home/rushikeshkadam/code_space/videoView/server/venv/lib/python3.10/site-packages/rest_framework/decorators.py", line 50, in handler
    return func(*args, **kwargs)
  File "/home/rushikeshkadam/code_space/videoView/server/videoView/api/Views/UserViews.py", line 42, in wraps_func
    return func(request,*args,**kwargs)
  File "/home/rushikeshkadam/code_space/videoView/server/videoView/api/Views/UserViews.py", line 113, in get_user
    user=Users.objects.first(pk=request.user_id)
  File "/home/rushikeshkadam/code_space/videoView/server/venv/lib/python3.10/site-packages/django/db/models/manager.py", line 87, in manager_method
    return getattr(self.get_queryset(), name)(*args, **kwargs)
TypeError: QuerySet.first() got an unexpected keyword argument 'pk'
ERROR 2024-12-31 03:21:55,865 log.py log log_response 248: Internal Server Error: /api/v1/getuser
Traceback (most recent call last):
  File "/home/rushikeshkadam/code_space/videoView/server/venv/lib/python3.10/site-packages/django/core/handlers/exception.py", line 55, in inner
    response = get_response(request)
  File "/home/rushikeshkadam/code_space/videoView/server/venv/lib/python3.10/site-packages/django/core/handlers/base.py", line 220, in _get_response
    response = response.render()
  File "/home/rushikeshkadam/code_space/videoView/server/venv/lib/python3.10/site-packages/django/template/response.py", line 114, in render
    self.content = self.rendered_content
  File "/home/rushikeshkadam/code_space/videoView/server/venv/lib/python3.10/site-packages/rest_framework/response.py", line 74, in rendered_content
    ret = renderer.render(self.data, accepted_media_type, context)
  File "/home/rushikeshkadam/code_space/videoView/server/venv/lib/python3.10/site-packages/rest_framework/renderers.py", line 100, in render
    ret = json.dumps(
  File "/home/rushikeshkadam/code_space/videoView/server/venv/lib/python3.10/site-packages/rest_framework/utils/json.py", line 25, in dumps
    return json.dumps(*args, **kwargs)
  File "/usr/lib/python3.10/json/__init__.py", line 238, in dumps
    **kw).encode(obj)
  File "/usr/lib/python3.10/json/encoder.py", line 199, in encode
    chunks = self.iterencode(o, _one_shot=True)
  File "/usr/lib/python3.10/json/encoder.py", line 257, in iterencode
    return _iterencode(o, 0)
  File "/home/rushikeshkadam/code_space/videoView/server/venv/lib/python3.10/site-packages/rest_framework/utils/encoders.py", line 67, in default
    return super().default(obj)
  File "/usr/lib/python3.10/json/encoder.py", line 179, in default
    raise TypeError(f'Object of type {o.__class__.__name__} '
TypeError: Object of type ModelState is not JSON serializable
ERROR 2024-12-31 03:22:06,299 log.py log log_response 248: Internal Server Error: /api/v1/getuser
Traceback (most recent call last):
  File "/home/rushikeshkadam/code_space/videoView/server/venv/lib/python3.10/site-packages/django/core/handlers/exception.py", line 55, in inner
    response = get_response(request)
  File "/home/rushikeshkadam/code_space/videoView/server/venv/lib/python3.10/site-packages/django/core/handlers/base.py", line 220, in _get_response
    response = response.render()
  File "/home/rushikeshkadam/code_space/videoView/server/venv/lib/python3.10/site-packages/django/template/response.py", line 114, in render
    self.content = self.rendered_content
  File "/home/rushikeshkadam/code_space/videoView/server/venv/lib/python3.10/site-packages/rest_framework/response.py", line 74, in rendered_content
    ret = renderer.render(self.data, accepted_media_type, context)
  File "/home/rushikeshkadam/code_space/videoView/server/venv/lib/python3.10/site-packages/rest_framework/renderers.py", line 100, in render
    ret = json.dumps(
  File "/home/rushikeshkadam/code_space/videoView/server/venv/lib/python3.10/site-packages/rest_framework/utils/json.py", line 25, in dumps
    return json.dumps(*args, **kwargs)
  File "/usr/lib/python3.10/json/__init__.py", line 238, in dumps
    **kw).encode(obj)
  File "/usr/lib/python3.10/json/encoder.py", line 199, in encode
    chunks = self.iterencode(o, _one_shot=True)
  File "/usr/lib/python3.10/json/encoder.py", line 257, in iterencode
    return _iterencode(o, 0)
  File "/home/rushikeshkadam/code_space/videoView/server/venv/lib/python3.10/site-packages/rest_framework/utils/encoders.py", line 67, in default
    return super().default(obj)
  File "/usr/lib/python3.10/json/encoder.py", line 179, in default
    raise TypeError(f'Object of type {o.__class__.__name__} '
TypeError: Object of type Users is not JSON serializable
ERROR 2024-12-31 03:22:22,825 log.py log log_response 248: Internal Server Error: /api/v1/getuser
Traceback (most recent call last):
  File "/home/rushikeshkadam/code_space/videoView/server/venv/lib/python3.10/site-packages/django/core/handlers/exception.py", line 55, in inner
    response = get_response(request)
  File "/home/rushikeshkadam/code_space/videoView/server/venv/lib/python3.10/site-packages/django/core/handlers/base.py", line 220, in _get_response
    response = response.render()
  File "/home/rushikeshkadam/code_space/videoView/server/venv/lib/python3.10/site-packages/django/template/response.py", line 114, in render
    self.content = self.rendered_content
  File "/home/rushikeshkadam/code_space/videoView/server/venv/lib/python3.10/site-packages/rest_framework/response.py", line 74, in rendered_content
    ret = renderer.render(self.data, accepted_media_type, context)
  File "/home/rushikeshkadam/code_space/videoView/server/venv/lib/python3.10/site-packages/rest_framework/renderers.py", line 100, in render
    ret = json.dumps(
  File "/home/rushikeshkadam/code_space/videoView/server/venv/lib/python3.10/site-packages/rest_framework/utils/json.py", line 25, in dumps
    return json.dumps(*args, **kwargs)
  File "/usr/lib/python3.10/json/__init__.py", line 238, in dumps
    **kw).encode(obj)
  File "/usr/lib/python3.10/json/encoder.py", line 199, in encode
    chunks = self.iterencode(o, _one_shot=True)
  File "/usr/lib/python3.10/json/encoder.py", line 257, in iterencode
    return _iterencode(o, 0)
  File "/home/rushikeshkadam/code_space/videoView/server/venv/lib/python3.10/site-packages/rest_framework/utils/encoders.py", line 67, in default
    return super().default(obj)
  File "/usr/lib/python3.10/json/encoder.py", line 179, in default
    raise TypeError(f'Object of type {o.__class__.__name__} '
TypeError: Object of type Users is not JSON serializable
ERROR 2024-12-31 03:28:00,427 log.py log log_response 248: Internal Server Error: /api/v1/getuser
Traceback (most recent call last):
  File "/home/rushikeshkadam/code_space/videoView/server/venv/lib/python3.10/site-packages/django/core/handlers/exception.py", line 55, in inner
    response = get_response(request)
  File "/home/rushikeshkadam/code_space/videoView/server/venv/lib/python3.10/site-packages/django/core/handlers/base.py", line 197, in _get_response
    response = wrapped_callback(request, *callback_args, **callback_kwargs)
  File "/home/rushikeshkadam/code_space/videoView/server/venv/lib/python3.10/site-packages/django/views/decorators/csrf.py", line 65, in _view_wrapper
    return view_func(request, *args, **kwargs)
  File "/home/rushikeshkadam/code_space/videoView/server/venv/lib/python3.10/site-packages/django/views/generic/base.py", line 104, in view
    return self.dispatch(request, *args, **kwargs)
  File "/home/rushikeshkadam/code_space/videoView/server/venv/lib/python3.10/site-packages/rest_framework/views.py", line 509, in dispatch
    response = self.handle_exception(exc)
  File "/home/rushikeshkadam/code_space/videoView/server/venv/lib/python3.10/site-packages/rest_framework/views.py", line 469, in handle_exception
    self.raise_uncaught_exception(exc)
  File "/home/rushikeshkadam/code_space/videoView/server/venv/lib/python3.10/site-packages/rest_framework/views.py", line 480, in raise_uncaught_exception
    raise exc
  File "/home/rushikeshkadam/code_space/videoView/server/venv/lib/python3.10/site-packages/rest_framework/views.py", line 506, in dispatch
    response = handler(request, *args, **kwargs)
  File "/home/rushikeshkadam/code_space/videoView/server/venv/lib/python3.10/site-packages/rest_framework/decorators.py", line 50, in handler
    return func(*args, **kwargs)
  File "/home/rushikeshkadam/code_space/videoView/server/videoView/api/Views/UserViews.py", line 42, in wraps_func
    return func(request,*args,**kwargs)
  File "/home/rushikeshkadam/code_space/videoView/server/videoView/api/Views/UserViews.py", line 124, in get_user
    return Response(user.id,status=200)
AttributeError: 'dict' object has no attribute 'id'
ERROR 2024-12-31 03:29:06,798 log.py log log_response 248: Internal Server Error: /api/v1/getuser
Traceback (most recent call last):
  File "/home/rushikeshkadam/code_space/videoView/server/venv/lib/python3.10/site-packages/django/core/handlers/exception.py", line 55, in inner
    response = get_response(request)
  File "/home/rushikeshkadam/code_space/videoView/server/venv/lib/python3.10/site-packages/django/core/handlers/base.py", line 220, in _get_response
    response = response.render()
  File "/home/rushikeshkadam/code_space/videoView/server/venv/lib/python3.10/site-packages/django/template/response.py", line 114, in render
    self.content = self.rendered_content
  File "/home/rushikeshkadam/code_space/videoView/server/venv/lib/python3.10/site-packages/rest_framework/response.py", line 74, in rendered_content
    ret = renderer.render(self.data, accepted_media_type, context)
  File "/home/rushikeshkadam/code_space/videoView/server/venv/lib/python3.10/site-packages/rest_framework/renderers.py", line 100, in render
    ret = json.dumps(
  File "/home/rushikeshkadam/code_space/videoView/server/venv/lib/python3.10/site-packages/rest_framework/utils/json.py", line 25, in dumps
    return json.dumps(*args, **kwargs)
  File "/usr/lib/python3.10/json/__init__.py", line 238, in dumps
    **kw).encode(obj)
  File "/usr/lib/python3.10/json/encoder.py", line 199, in encode
    chunks = self.iterencode(o, _one_shot=True)
  File "/usr/lib/python3.10/json/encoder.py", line 257, in iterencode
    return _iterencode(o, 0)
  File "/home/rushikeshkadam/code_space/videoView/server/venv/lib/python3.10/site-packages/rest_framework/utils/encoders.py", line 67, in default
    return super().default(obj)
  File "/usr/lib/python3.10/json/encoder.py", line 179, in default
    raise TypeError(f'Object of type {o.__class__.__name__} '
TypeError: Object of type ApiResponse is not JSON serializable
ERROR 2024-12-31 03:29:25,969 log.py log log_response 248: Internal Server Error: /api/v1/getuser
Traceback (most recent call last):
  File "/home/rushikeshkadam/code_space/videoView/server/venv/lib/python3.10/site-packages/django/core/handlers/exception.py", line 55, in inner
    response = get_response(request)
  File "/home/rushikeshkadam/code_space/videoView/server/venv/lib/python3.10/site-packages/django/core/handlers/base.py", line 220, in _get_response
    response = response.render()
  File "/home/rushikeshkadam/code_space/videoView/server/venv/lib/python3.10/site-packages/django/template/response.py", line 114, in render
    self.content = self.rendered_content
  File "/home/rushikeshkadam/code_space/videoView/server/venv/lib/python3.10/site-packages/rest_framework/response.py", line 74, in rendered_content
    ret = renderer.render(self.data, accepted_media_type, context)
  File "/home/rushikeshkadam/code_space/videoView/server/venv/lib/python3.10/site-packages/rest_framework/renderers.py", line 100, in render
    ret = json.dumps(
  File "/home/rushikeshkadam/code_space/videoView/server/venv/lib/python3.10/site-packages/rest_framework/utils/json.py", line 25, in dumps
    return json.dumps(*args, **kwargs)
  File "/usr/lib/python3.10/json/__init__.py", line 238, in dumps
    **kw).encode(obj)
  File "/usr/lib/python3.10/json/encoder.py", line 199, in encode
    chunks = self.iterencode(o, _one_shot=True)
  File "/usr/lib/python3.10/json/encoder.py", line 257, in iterencode
    return _iterencode(o, 0)
  File "/home/rushikeshkadam/code_space/videoView/server/venv/lib/python3.10/site-packages/rest_framework/utils/encoders.py", line 67, in default
    return super().default(obj)
  File "/usr/lib/python3.10/json/encoder.py", line 179, in default
    raise TypeError(f'Object of type {o.__class__.__name__} '
TypeError: Object of type ApiResponse is not JSON serializable
WARNING 2024-12-31 03:42:34,568 log.py log log_response 248: Method Not Allowed: /api/v1/signup
WARNING 2024-12-31 03:42:38,399 log.py log log_response 248: Unauthorized: /api/v1/signup
ERROR 2024-12-31 03:42:51,192 log.py log log_response 248: Internal Server Error: /api/v1/signup
Traceback (most recent call last):
  File "/home/rushikeshkadam/code_space/videoView/server/venv/lib/python3.10/site-packages/django/db/backends/utils.py", line 105, in _execute
    return self.cursor.execute(sql, params)
  File "/home/rushikeshkadam/code_space/videoView/server/venv/lib/python3.10/site-packages/django/db/backends/sqlite3/base.py", line 354, in execute
    return super().execute(query, params)
sqlite3.IntegrityError: NOT NULL constraint failed: api_users.coverImage

The above exception was the direct cause of the following exception:

Traceback (most recent call last):
  File "/home/rushikeshkadam/code_space/videoView/server/venv/lib/python3.10/site-packages/django/core/handlers/exception.py", line 55, in inner
    response = get_response(request)
  File "/home/rushikeshkadam/code_space/videoView/server/venv/lib/python3.10/site-packages/django/core/handlers/base.py", line 197, in _get_response
    response = wrapped_callback(request, *callback_args, **callback_kwargs)
  File "/home/rushikeshkadam/code_space/videoView/server/venv/lib/python3.10/site-packages/django/views/decorators/csrf.py", line 65, in _view_wrapper
    return view_func(request, *args, **kwargs)
  File "/home/rushikeshkadam/code_space/videoView/server/venv/lib/python3.10/site-packages/django/views/generic/base.py", line 104, in view
    return self.dispatch(request, *args, **kwargs)
  File "/home/rushikeshkadam/code_space/videoView/server/venv/lib/python3.10/site-packages/rest_framework/views.py", line 509, in dispatch
    response = self.handle_exception(exc)
  File "/home/rushikeshkadam/code_space/videoView/server/venv/lib/python3.10/site-packages/rest_framework/views.py", line 469, in handle_exception
    self.raise_uncaught_exception(exc)
  File "/home/rushikeshkadam/code_space/videoView/server/venv/lib/python3.10/site-packages/rest_framework/views.py", line 480, in raise_uncaught_exception
    raise exc
  File "/home/rushikeshkadam/code_space/videoView/server/venv/lib/python3.10/site-packages/rest_framework/views.py", line 506, in dispatch
    response = handler(request, *args, **kwargs)
  File "/home/rushikeshkadam/code_space/videoView/server/venv/lib/python3.10/site-packages/rest_framework/decorators.py", line 50, in handler
    return func(*args, **kwargs)
  File "/home/rushikeshkadam/code_space/videoView/server/videoView/api/Views/UserViews.py", line 61, in signup
    user,token=serializer.save()
  File "/home/rushikeshkadam/code_space/videoView/server/venv/lib/python3.10/site-packages/rest_framework/serializers.py", line 208, in save
    self.instance = self.create(validated_data)
  File "/home/rushikeshkadam/code_space/videoView/server/videoView/api/serializer.py", line 46, in create
    user=Users.objects.create(**validate_data)
  File "/home/rushikeshkadam/code_space/videoView/server/venv/lib/python3.10/site-packages/django/db/models/manager.py", line 87, in manager_method
    return getattr(self.get_queryset(), name)(*args, **kwargs)
  File "/home/rushikeshkadam/code_space/videoView/server/venv/lib/python3.10/site-packages/django/db/models/query.py", line 679, in create
    obj.save(force_insert=True, using=self.db)
  File "/home/rushikeshkadam/code_space/videoView/server/venv/lib/python3.10/site-packages/django/db/models/base.py", line 892, in save
    self.save_base(
  File "/home/rushikeshkadam/code_space/videoView/server/venv/lib/python3.10/site-packages/django/db/models/base.py", line 998, in save_base
    updated = self._save_table(
  File "/home/rushikeshkadam/code_space/videoView/server/venv/lib/python3.10/site-packages/django/db/models/base.py", line 1161, in _save_table
    results = self._do_insert(
  File "/home/rushikeshkadam/code_space/videoView/server/venv/lib/python3.10/site-packages/django/db/models/base.py", line 1202, in _do_insert
    return manager._insert(
  File "/home/rushikeshkadam/code_space/videoView/server/venv/lib/python3.10/site-packages/django/db/models/manager.py", line 87, in manager_method
    return getattr(self.get_queryset(), name)(*args, **kwargs)
  File "/home/rushikeshkadam/code_space/videoView/server/venv/lib/python3.10/site-packages/django/db/models/query.py", line 1847, in _insert
    return query.get_compiler(using=using).execute_sql(returning_fields)
  File "/home/rushikeshkadam/code_space/videoView/server/venv/lib/python3.10/site-packages/django/db/models/sql/compiler.py", line 1836, in execute_sql
    cursor.execute(sql, params)
  File "/home/rushikeshkadam/code_space/videoView/server/venv/lib/python3.10/site-packages/django/db/backends/utils.py", line 122, in execute
    return super().execute(sql, params)
  File "/home/rushikeshkadam/code_space/videoView/server/venv/lib/python3.10/site-packages/django/db/backends/utils.py", line 79, in execute
    return self._execute_with_wrappers(
  File "/home/rushikeshkadam/code_space/videoView/server/venv/lib/python3.10/site-packages/django/db/backends/utils.py", line 92, in _execute_with_wrappers
    return executor(sql, params, many, context)
  File "/home/rushikeshkadam/code_space/videoView/server/venv/lib/python3.10/site-packages/django/db/backends/utils.py", line 100, in _execute
    with self.db.wrap_database_errors:
  File "/home/rushikeshkadam/code_space/videoView/server/venv/lib/python3.10/site-packages/django/db/utils.py", line 91, in __exit__
    raise dj_exc_value.with_traceback(traceback) from exc_value
  File "/home/rushikeshkadam/code_space/videoView/server/venv/lib/python3.10/site-packages/django/db/backends/utils.py", line 105, in _execute
    return self.cursor.execute(sql, params)
  File "/home/rushikeshkadam/code_space/videoView/server/venv/lib/python3.10/site-packages/django/db/backends/sqlite3/base.py", line 354, in execute
    return super().execute(query, params)
django.db.utils.IntegrityError: NOT NULL constraint failed: api_users.coverImage
ERROR 2024-12-31 03:45:27,079 log.py log log_response 248: Internal Server Error: /api/v1/signup
Traceback (most recent call last):
  File "/home/rushikeshkadam/code_space/videoView/server/venv/lib/python3.10/site-packages/django/core/handlers/exception.py", line 55, in inner
    response = get_response(request)
  File "/home/rushikeshkadam/code_space/videoView/server/venv/lib/python3.10/site-packages/django/core/handlers/base.py", line 197, in _get_response
    response = wrapped_callback(request, *callback_args, **callback_kwargs)
  File "/home/rushikeshkadam/code_space/videoView/server/venv/lib/python3.10/site-packages/django/views/decorators/csrf.py", line 65, in _view_wrapper
    return view_func(request, *args, **kwargs)
  File "/home/rushikeshkadam/code_space/videoView/server/venv/lib/python3.10/site-packages/django/views/generic/base.py", line 104, in view
    return self.dispatch(request, *args, **kwargs)
  File "/home/rushikeshkadam/code_space/videoView/server/venv/lib/python3.10/site-packages/rest_framework/views.py", line 509, in dispatch
    response = self.handle_exception(exc)
  File "/home/rushikeshkadam/code_space/videoView/server/venv/lib/python3.10/site-packages/rest_framework/views.py", line 469, in handle_exception
    self.raise_uncaught_exception(exc)
  File "/home/rushikeshkadam/code_space/videoView/server/venv/lib/python3.10/site-packages/rest_framework/views.py", line 480, in raise_uncaught_exception
    raise exc
  File "/home/rushikeshkadam/code_space/videoView/server/venv/lib/python3.10/site-packages/rest_framework/views.py", line 506, in dispatch
    response = handler(request, *args, **kwargs)
  File "/home/rushikeshkadam/code_space/videoView/server/venv/lib/python3.10/site-packages/rest_framework/decorators.py", line 50, in handler
    return func(*args, **kwargs)
  File "/home/rushikeshkadam/code_space/videoView/server/videoView/api/Views/UserViews.py", line 61, in signup
    user,token=serializer.save()
  File "/home/rushikeshkadam/code_space/videoView/server/venv/lib/python3.10/site-packages/rest_framework/serializers.py", line 208, in save
    self.instance = self.create(validated_data)
  File "/home/rushikeshkadam/code_space/videoView/server/videoView/api/serializer.py", line 50, in create
    user.avatar=avatar_img['secure_url'] or None
UnboundLocalError: local variable 'avatar_img' referenced before assignment
WARNING 2024-12-31 03:46:27,531 log.py log log_response 248: Unauthorized: /api/v1/signup
ERROR 2024-12-31 03:46:35,844 log.py log log_response 248: Internal Server Error: /api/v1/signup
Traceback (most recent call last):
  File "/home/rushikeshkadam/code_space/videoView/server/venv/lib/python3.10/site-packages/django/core/handlers/exception.py", line 55, in inner
    response = get_response(request)
  File "/home/rushikeshkadam/code_space/videoView/server/venv/lib/python3.10/site-packages/django/core/handlers/base.py", line 197, in _get_response
    response = wrapped_callback(request, *callback_args, **callback_kwargs)
  File "/home/rushikeshkadam/code_space/videoView/server/venv/lib/python3.10/site-packages/django/views/decorators/csrf.py", line 65, in _view_wrapper
    return view_func(request, *args, **kwargs)
  File "/home/rushikeshkadam/code_space/videoView/server/venv/lib/python3.10/site-packages/django/views/generic/base.py", line 104, in view
    return self.dispatch(request, *args, **kwargs)
  File "/home/rushikeshkadam/code_space/videoView/server/venv/lib/python3.10/site-packages/rest_framework/views.py", line 509, in dispatch
    response = self.handle_exception(exc)
  File "/home/rushikeshkadam/code_space/videoView/server/venv/lib/python3.10/site-packages/rest_framework/views.py", line 469, in handle_exception
    self.raise_uncaught_exception(exc)
  File "/home/rushikeshkadam/code_space/videoView/server/venv/lib/python3.10/site-packages/rest_framework/views.py", line 480, in raise_uncaught_exception
    raise exc
  File "/home/rushikeshkadam/code_space/videoView/server/venv/lib/python3.10/site-packages/rest_framework/views.py", line 506, in dispatch
    response = handler(request, *args, **kwargs)
  File "/home/rushikeshkadam/code_space/videoView/server/venv/lib/python3.10/site-packages/rest_framework/decorators.py", line 50, in handler
    return func(*args, **kwargs)
  File "/home/rushikeshkadam/code_space/videoView/server/videoView/api/Views/UserViews.py", line 61, in signup
    user,token=serializer.save()
  File "/home/rushikeshkadam/code_space/videoView/server/venv/lib/python3.10/site-packages/rest_framework/serializers.py", line 208, in save
    self.instance = self.create(validated_data)
  File "/home/rushikeshkadam/code_space/videoView/server/videoView/api/serializer.py", line 57, in create
    user.avatar=avatar_img['secure_url']
UnboundLocalError: local variable 'avatar_img' referenced before assignment
WARNING 2024-12-31 03:47:09,351 log.py log log_response 248: Unauthorized: /api/v1/signup
WARNING 2024-12-31 04:27:37,130 log.py log log_response 248: Not Found: /api/v1/logout
DEBUG 2024-12-31 04:28:12,130 UserViews.py UserViews logout_user 135: name 'message' is not defined
ERROR 2024-12-31 04:28:12,146 log.py log log_response 248: Internal Server Error: /api/v1/logout
Traceback (most recent call last):
  File "/home/rushikeshkadam/code_space/videoView/server/venv/lib/python3.10/site-packages/django/core/handlers/exception.py", line 55, in inner
    response = get_response(request)
  File "/home/rushikeshkadam/code_space/videoView/server/venv/lib/python3.10/site-packages/django/core/handlers/base.py", line 197, in _get_response
    response = wrapped_callback(request, *callback_args, **callback_kwargs)
  File "/home/rushikeshkadam/code_space/videoView/server/venv/lib/python3.10/site-packages/django/views/decorators/csrf.py", line 65, in _view_wrapper
    return view_func(request, *args, **kwargs)
  File "/home/rushikeshkadam/code_space/videoView/server/venv/lib/python3.10/site-packages/django/views/generic/base.py", line 104, in view
    return self.dispatch(request, *args, **kwargs)
  File "/home/rushikeshkadam/code_space/videoView/server/venv/lib/python3.10/site-packages/rest_framework/views.py", line 511, in dispatch
    self.response = self.finalize_response(request, response, *args, **kwargs)
  File "/home/rushikeshkadam/code_space/videoView/server/venv/lib/python3.10/site-packages/rest_framework/views.py", line 423, in finalize_response
    assert isinstance(response, HttpResponseBase), (
AssertionError: Expected a `Response`, `HttpResponse` or `StreamingHttpResponse` to be returned from the view, but received a `<class 'NoneType'>`
DEBUG 2024-12-31 04:28:46,949 UserViews.py UserViews logout_user 135: name 'message' is not defined
ERROR 2024-12-31 04:28:46,964 log.py log log_response 248: Internal Server Error: /api/v1/logout
Traceback (most recent call last):
  File "/home/rushikeshkadam/code_space/videoView/server/venv/lib/python3.10/site-packages/django/core/handlers/exception.py", line 55, in inner
    response = get_response(request)
  File "/home/rushikeshkadam/code_space/videoView/server/venv/lib/python3.10/site-packages/django/core/handlers/base.py", line 197, in _get_response
    response = wrapped_callback(request, *callback_args, **callback_kwargs)
  File "/home/rushikeshkadam/code_space/videoView/server/venv/lib/python3.10/site-packages/django/views/decorators/csrf.py", line 65, in _view_wrapper
    return view_func(request, *args, **kwargs)
  File "/home/rushikeshkadam/code_space/videoView/server/venv/lib/python3.10/site-packages/django/views/generic/base.py", line 104, in view
    return self.dispatch(request, *args, **kwargs)
  File "/home/rushikeshkadam/code_space/videoView/server/venv/lib/python3.10/site-packages/rest_framework/views.py", line 511, in dispatch
    self.response = self.finalize_response(request, response, *args, **kwargs)
  File "/home/rushikeshkadam/code_space/videoView/server/venv/lib/python3.10/site-packages/rest_framework/views.py", line 423, in finalize_response
    assert isinstance(response, HttpResponseBase), (
AssertionError: Expected a `Response`, `HttpResponse` or `StreamingHttpResponse` to be returned from the view, but received a `<class 'NoneType'>`
DEBUG 2024-12-31 04:29:08,721 UserViews.py UserViews logout_user 135: name 'message' is not defined
ERROR 2024-12-31 04:29:08,738 log.py log log_response 248: Internal Server Error: /api/v1/logout
Traceback (most recent call last):
  File "/home/rushikeshkadam/code_space/videoView/server/venv/lib/python3.10/site-packages/django/core/handlers/exception.py", line 55, in inner
    response = get_response(request)
  File "/home/rushikeshkadam/code_space/videoView/server/venv/lib/python3.10/site-packages/django/core/handlers/base.py", line 197, in _get_response
    response = wrapped_callback(request, *callback_args, **callback_kwargs)
  File "/home/rushikeshkadam/code_space/videoView/server/venv/lib/python3.10/site-packages/django/views/decorators/csrf.py", line 65, in _view_wrapper
    return view_func(request, *args, **kwargs)
  File "/home/rushikeshkadam/code_space/videoView/server/venv/lib/python3.10/site-packages/django/views/generic/base.py", line 104, in view
    return self.dispatch(request, *args, **kwargs)
  File "/home/rushikeshkadam/code_space/videoView/server/venv/lib/python3.10/site-packages/rest_framework/views.py", line 511, in dispatch
    self.response = self.finalize_response(request, response, *args, **kwargs)
  File "/home/rushikeshkadam/code_space/videoView/server/venv/lib/python3.10/site-packages/rest_framework/views.py", line 423, in finalize_response
    assert isinstance(response, HttpResponseBase), (
AssertionError: Expected a `Response`, `HttpResponse` or `StreamingHttpResponse` to be returned from the view, but received a `<class 'NoneType'>`
DEBUG 2024-12-31 04:29:20,467 UserViews.py UserViews logout_user 136: name 'message' is not defined
ERROR 2024-12-31 04:29:20,481 log.py log log_response 248: Internal Server Error: /api/v1/logout
Traceback (most recent call last):
  File "/home/rushikeshkadam/code_space/videoView/server/venv/lib/python3.10/site-packages/django/core/handlers/exception.py", line 55, in inner
    response = get_response(request)
  File "/home/rushikeshkadam/code_space/videoView/server/venv/lib/python3.10/site-packages/django/core/handlers/base.py", line 197, in _get_response
    response = wrapped_callback(request, *callback_args, **callback_kwargs)
  File "/home/rushikeshkadam/code_space/videoView/server/venv/lib/python3.10/site-packages/django/views/decorators/csrf.py", line 65, in _view_wrapper
    return view_func(request, *args, **kwargs)
  File "/home/rushikeshkadam/code_space/videoView/server/venv/lib/python3.10/site-packages/django/views/generic/base.py", line 104, in view
    return self.dispatch(request, *args, **kwargs)
  File "/home/rushikeshkadam/code_space/videoView/server/venv/lib/python3.10/site-packages/rest_framework/views.py", line 511, in dispatch
    self.response = self.finalize_response(request, response, *args, **kwargs)
  File "/home/rushikeshkadam/code_space/videoView/server/venv/lib/python3.10/site-packages/rest_framework/views.py", line 423, in finalize_response
    assert isinstance(response, HttpResponseBase), (
AssertionError: Expected a `Response`, `HttpResponse` or `StreamingHttpResponse` to be returned from the view, but received a `<class 'NoneType'>`
DEBUG 2024-12-31 04:29:33,864 UserViews.py UserViews logout_user 136: name 'message' is not defined
ERROR 2024-12-31 04:29:33,881 log.py log log_response 248: Internal Server Error: /api/v1/logout
Traceback (most recent call last):
  File "/home/rushikeshkadam/code_space/videoView/server/venv/lib/python3.10/site-packages/django/core/handlers/exception.py", line 55, in inner
    response = get_response(request)
  File "/home/rushikeshkadam/code_space/videoView/server/venv/lib/python3.10/site-packages/django/core/handlers/base.py", line 197, in _get_response
    response = wrapped_callback(request, *callback_args, **callback_kwargs)
  File "/home/rushikeshkadam/code_space/videoView/server/venv/lib/python3.10/site-packages/django/views/decorators/csrf.py", line 65, in _view_wrapper
    return view_func(request, *args, **kwargs)
  File "/home/rushikeshkadam/code_space/videoView/server/venv/lib/python3.10/site-packages/django/views/generic/base.py", line 104, in view
    return self.dispatch(request, *args, **kwargs)
  File "/home/rushikeshkadam/code_space/videoView/server/venv/lib/python3.10/site-packages/rest_framework/views.py", line 511, in dispatch
    self.response = self.finalize_response(request, response, *args, **kwargs)
  File "/home/rushikeshkadam/code_space/videoView/server/venv/lib/python3.10/site-packages/rest_framework/views.py", line 423, in finalize_response
    assert isinstance(response, HttpResponseBase), (
AssertionError: Expected a `Response`, `HttpResponse` or `StreamingHttpResponse` to be returned from the view, but received a `<class 'NoneType'>`
DEBUG 2024-12-31 04:29:39,333 UserViews.py UserViews logout_user 136: 'dict' object has no attribute 'delete_cookie'
ERROR 2024-12-31 04:29:39,350 log.py log log_response 248: Internal Server Error: /api/v1/logout
Traceback (most recent call last):
  File "/home/rushikeshkadam/code_space/videoView/server/venv/lib/python3.10/site-packages/django/core/handlers/exception.py", line 55, in inner
    response = get_response(request)
  File "/home/rushikeshkadam/code_space/videoView/server/venv/lib/python3.10/site-packages/django/core/handlers/base.py", line 197, in _get_response
    response = wrapped_callback(request, *callback_args, **callback_kwargs)
  File "/home/rushikeshkadam/code_space/videoView/server/venv/lib/python3.10/site-packages/django/views/decorators/csrf.py", line 65, in _view_wrapper
    return view_func(request, *args, **kwargs)
  File "/home/rushikeshkadam/code_space/videoView/server/venv/lib/python3.10/site-packages/django/views/generic/base.py", line 104, in view
    return self.dispatch(request, *args, **kwargs)
  File "/home/rushikeshkadam/code_space/videoView/server/venv/lib/python3.10/site-packages/rest_framework/views.py", line 511, in dispatch
    self.response = self.finalize_response(request, response, *args, **kwargs)
  File "/home/rushikeshkadam/code_space/videoView/server/venv/lib/python3.10/site-packages/rest_framework/views.py", line 423, in finalize_response
    assert isinstance(response, HttpResponseBase), (
AssertionError: Expected a `Response`, `HttpResponse` or `StreamingHttpResponse` to be returned from the view, but received a `<class 'NoneType'>`
ERROR 2024-12-31 04:29:58,323 log.py log log_response 248: Internal Server Error: /api/v1/logout
Traceback (most recent call last):
  File "/home/rushikeshkadam/code_space/videoView/server/venv/lib/python3.10/site-packages/django/core/handlers/exception.py", line 55, in inner
    response = get_response(request)
  File "/home/rushikeshkadam/code_space/videoView/server/venv/lib/python3.10/site-packages/django/core/handlers/base.py", line 220, in _get_response
    response = response.render()
  File "/home/rushikeshkadam/code_space/videoView/server/venv/lib/python3.10/site-packages/django/template/response.py", line 114, in render
    self.content = self.rendered_content
  File "/home/rushikeshkadam/code_space/videoView/server/venv/lib/python3.10/site-packages/rest_framework/response.py", line 74, in rendered_content
    ret = renderer.render(self.data, accepted_media_type, context)
  File "/home/rushikeshkadam/code_space/videoView/server/venv/lib/python3.10/site-packages/rest_framework/renderers.py", line 100, in render
    ret = json.dumps(
  File "/home/rushikeshkadam/code_space/videoView/server/venv/lib/python3.10/site-packages/rest_framework/utils/json.py", line 25, in dumps
    return json.dumps(*args, **kwargs)
  File "/usr/lib/python3.10/json/__init__.py", line 238, in dumps
    **kw).encode(obj)
  File "/usr/lib/python3.10/json/encoder.py", line 199, in encode
    chunks = self.iterencode(o, _one_shot=True)
  File "/usr/lib/python3.10/json/encoder.py", line 257, in iterencode
    return _iterencode(o, 0)
  File "/home/rushikeshkadam/code_space/videoView/server/venv/lib/python3.10/site-packages/rest_framework/utils/encoders.py", line 67, in default
    return super().default(obj)
  File "/usr/lib/python3.10/json/encoder.py", line 179, in default
    raise TypeError(f'Object of type {o.__class__.__name__} '
TypeError: Object of type JsonResponse is not JSON serializable
ERROR 2024-12-31 04:30:34,977 log.py log log_response 248: Internal Server Error: /api/v1/logout
Traceback (most recent call last):
  File "/home/rushikeshkadam/code_space/videoView/server/venv/lib/python3.10/site-packages/django/core/handlers/exception.py", line 55, in inner
    response = get_response(request)
  File "/home/rushikeshkadam/code_space/videoView/server/venv/lib/python3.10/site-packages/django/core/handlers/base.py", line 220, in _get_response
    response = response.render()
  File "/home/rushikeshkadam/code_space/videoView/server/venv/lib/python3.10/site-packages/django/template/response.py", line 114, in render
    self.content = self.rendered_content
  File "/home/rushikeshkadam/code_space/videoView/server/venv/lib/python3.10/site-packages/rest_framework/response.py", line 74, in rendered_content
    ret = renderer.render(self.data, accepted_media_type, context)
  File "/home/rushikeshkadam/code_space/videoView/server/venv/lib/python3.10/site-packages/rest_framework/renderers.py", line 100, in render
    ret = json.dumps(
  File "/home/rushikeshkadam/code_space/videoView/server/venv/lib/python3.10/site-packages/rest_framework/utils/json.py", line 25, in dumps
    return json.dumps(*args, **kwargs)
  File "/usr/lib/python3.10/json/__init__.py", line 238, in dumps
    **kw).encode(obj)
  File "/usr/lib/python3.10/json/encoder.py", line 199, in encode
    chunks = self.iterencode(o, _one_shot=True)
  File "/usr/lib/python3.10/json/encoder.py", line 257, in iterencode
    return _iterencode(o, 0)
  File "/home/rushikeshkadam/code_space/videoView/server/venv/lib/python3.10/site-packages/rest_framework/utils/encoders.py", line 67, in default
    return super().default(obj)
  File "/usr/lib/python3.10/json/encoder.py", line 179, in default
    raise TypeError(f'Object of type {o.__class__.__name__} '
TypeError: Object of type JsonResponse is not JSON serializable
ERROR 2024-12-31 04:31:58,527 log.py log log_response 248: Internal Server Error: /api/v1/logout
Traceback (most recent call last):
  File "/home/rushikeshkadam/code_space/videoView/server/venv/lib/python3.10/site-packages/django/core/handlers/exception.py", line 55, in inner
    response = get_response(request)
  File "/home/rushikeshkadam/code_space/videoView/server/venv/lib/python3.10/site-packages/django/core/handlers/base.py", line 220, in _get_response
    response = response.render()
  File "/home/rushikeshkadam/code_space/videoView/server/venv/lib/python3.10/site-packages/django/template/response.py", line 114, in render
    self.content = self.rendered_content
  File "/home/rushikeshkadam/code_space/videoView/server/venv/lib/python3.10/site-packages/rest_framework/response.py", line 74, in rendered_content
    ret = renderer.render(self.data, accepted_media_type, context)
  File "/home/rushikeshkadam/code_space/videoView/server/venv/lib/python3.10/site-packages/rest_framework/renderers.py", line 100, in render
    ret = json.dumps(
  File "/home/rushikeshkadam/code_space/videoView/server/venv/lib/python3.10/site-packages/rest_framework/utils/json.py", line 25, in dumps
    return json.dumps(*args, **kwargs)
  File "/usr/lib/python3.10/json/__init__.py", line 238, in dumps
    **kw).encode(obj)
  File "/usr/lib/python3.10/json/encoder.py", line 199, in encode
    chunks = self.iterencode(o, _one_shot=True)
  File "/usr/lib/python3.10/json/encoder.py", line 257, in iterencode
    return _iterencode(o, 0)
  File "/home/rushikeshkadam/code_space/videoView/server/venv/lib/python3.10/site-packages/rest_framework/utils/encoders.py", line 67, in default
    return super().default(obj)
  File "/usr/lib/python3.10/json/encoder.py", line 179, in default
    raise TypeError(f'Object of type {o.__class__.__name__} '
TypeError: Object of type JsonResponse is not JSON serializable
ERROR 2024-12-31 04:35:02,215 log.py log log_response 248: Internal Server Error: /api/v1/logout
Traceback (most recent call last):
  File "/home/rushikeshkadam/code_space/videoView/server/venv/lib/python3.10/site-packages/django/core/handlers/exception.py", line 55, in inner
    response = get_response(request)
  File "/home/rushikeshkadam/code_space/videoView/server/venv/lib/python3.10/site-packages/django/core/handlers/base.py", line 220, in _get_response
    response = response.render()
  File "/home/rushikeshkadam/code_space/videoView/server/venv/lib/python3.10/site-packages/django/template/response.py", line 114, in render
    self.content = self.rendered_content
  File "/home/rushikeshkadam/code_space/videoView/server/venv/lib/python3.10/site-packages/rest_framework/response.py", line 74, in rendered_content
    ret = renderer.render(self.data, accepted_media_type, context)
  File "/home/rushikeshkadam/code_space/videoView/server/venv/lib/python3.10/site-packages/rest_framework/renderers.py", line 100, in render
    ret = json.dumps(
  File "/home/rushikeshkadam/code_space/videoView/server/venv/lib/python3.10/site-packages/rest_framework/utils/json.py", line 25, in dumps
    return json.dumps(*args, **kwargs)
  File "/usr/lib/python3.10/json/__init__.py", line 238, in dumps
    **kw).encode(obj)
  File "/usr/lib/python3.10/json/encoder.py", line 199, in encode
    chunks = self.iterencode(o, _one_shot=True)
  File "/usr/lib/python3.10/json/encoder.py", line 257, in iterencode
    return _iterencode(o, 0)
  File "/home/rushikeshkadam/code_space/videoView/server/venv/lib/python3.10/site-packages/rest_framework/utils/encoders.py", line 67, in default
    return super().default(obj)
  File "/usr/lib/python3.10/json/encoder.py", line 179, in default
    raise TypeError(f'Object of type {o.__class__.__name__} '
TypeError: Object of type JsonResponse is not JSON serializable
ERROR 2024-12-31 04:41:03,315 log.py log log_response 248: Internal Server Error: /api/v1/logout
Traceback (most recent call last):
  File "/home/rushikeshkadam/code_space/videoView/server/venv/lib/python3.10/site-packages/django/core/handlers/exception.py", line 55, in inner
    response = get_response(request)
  File "/home/rushikeshkadam/code_space/videoView/server/venv/lib/python3.10/site-packages/django/core/handlers/base.py", line 220, in _get_response
    response = response.render()
  File "/home/rushikeshkadam/code_space/videoView/server/venv/lib/python3.10/site-packages/django/template/response.py", line 114, in render
    self.content = self.rendered_content
  File "/home/rushikeshkadam/code_space/videoView/server/venv/lib/python3.10/site-packages/rest_framework/response.py", line 74, in rendered_content
    ret = renderer.render(self.data, accepted_media_type, context)
  File "/home/rushikeshkadam/code_space/videoView/server/venv/lib/python3.10/site-packages/rest_framework/renderers.py", line 100, in render
    ret = json.dumps(
  File "/home/rushikeshkadam/code_space/videoView/server/venv/lib/python3.10/site-packages/rest_framework/utils/json.py", line 25, in dumps
    return json.dumps(*args, **kwargs)
  File "/usr/lib/python3.10/json/__init__.py", line 238, in dumps
    **kw).encode(obj)
  File "/usr/lib/python3.10/json/encoder.py", line 199, in encode
    chunks = self.iterencode(o, _one_shot=True)
  File "/usr/lib/python3.10/json/encoder.py", line 257, in iterencode
    return _iterencode(o, 0)
  File "/home/rushikeshkadam/code_space/videoView/server/venv/lib/python3.10/site-packages/rest_framework/utils/encoders.py", line 67, in default
    return super().default(obj)
  File "/usr/lib/python3.10/json/encoder.py", line 179, in default
    raise TypeError(f'Object of type {o.__class__.__name__} '
TypeError: Object of type JsonResponse is not JSON serializable
DEBUG 2024-12-31 04:41:35,366 UserViews.py UserViews logout_user 137: 'dict' object has no attribute 'delete_cookie'
ERROR 2024-12-31 04:41:35,367 log.py log log_response 248: Internal Server Error: /api/v1/logout
DEBUG 2024-12-31 04:43:13,303 UserViews.py UserViews logout_user 137: 'dict' object has no attribute 'delete_cookie'
ERROR 2024-12-31 04:43:13,304 log.py log log_response 248: Internal Server Error: /api/v1/logout
DEBUG 2024-12-31 04:43:51,138 UserViews.py UserViews wraps_func 40: 'access_token'
ERROR 2024-12-31 04:43:51,161 log.py log log_response 248: Internal Server Error: /api/v1/getuser
Traceback (most recent call last):
  File "/home/rushikeshkadam/code_space/videoView/server/venv/lib/python3.10/site-packages/rest_framework/request.py", line 421, in __getattr__
    return getattr(_request, attr)
AttributeError: 'WSGIRequest' object has no attribute 'user_id'

During handling of the above exception, another exception occurred:

Traceback (most recent call last):
  File "/home/rushikeshkadam/code_space/videoView/server/venv/lib/python3.10/site-packages/django/core/handlers/exception.py", line 55, in inner
    response = get_response(request)
  File "/home/rushikeshkadam/code_space/videoView/server/venv/lib/python3.10/site-packages/django/core/handlers/base.py", line 197, in _get_response
    response = wrapped_callback(request, *callback_args, **callback_kwargs)
  File "/home/rushikeshkadam/code_space/videoView/server/venv/lib/python3.10/site-packages/django/views/decorators/csrf.py", line 65, in _view_wrapper
    return view_func(request, *args, **kwargs)
  File "/home/rushikeshkadam/code_space/videoView/server/venv/lib/python3.10/site-packages/django/views/generic/base.py", line 104, in view
    return self.dispatch(request, *args, **kwargs)
  File "/home/rushikeshkadam/code_space/videoView/server/venv/lib/python3.10/site-packages/rest_framework/views.py", line 509, in dispatch
    response = self.handle_exception(exc)
  File "/home/rushikeshkadam/code_space/videoView/server/venv/lib/python3.10/site-packages/rest_framework/views.py", line 469, in handle_exception
    self.raise_uncaught_exception(exc)
  File "/home/rushikeshkadam/code_space/videoView/server/venv/lib/python3.10/site-packages/rest_framework/views.py", line 480, in raise_uncaught_exception
    raise exc
  File "/home/rushikeshkadam/code_space/videoView/server/venv/lib/python3.10/site-packages/rest_framework/views.py", line 506, in dispatch
    response = handler(request, *args, **kwargs)
  File "/home/rushikeshkadam/code_space/videoView/server/venv/lib/python3.10/site-packages/rest_framework/decorators.py", line 50, in handler
    return func(*args, **kwargs)
  File "/home/rushikeshkadam/code_space/videoView/server/videoView/api/Views/UserViews.py", line 42, in wraps_func
    return func(request,*args,**kwargs)
  File "/home/rushikeshkadam/code_space/videoView/server/videoView/api/Views/UserViews.py", line 113, in get_user
    user=Users.objects.filter(pk=request.user_id).first()
  File "/home/rushikeshkadam/code_space/videoView/server/venv/lib/python3.10/site-packages/rest_framework/request.py", line 423, in __getattr__
    return self.__getattribute__(attr)
AttributeError: 'Request' object has no attribute 'user_id'
DEBUG 2024-12-31 04:44:14,277 UserViews.py UserViews wraps_func 39: 'access_token'
ERROR 2024-12-31 04:44:14,308 log.py log log_response 248: Internal Server Error: /api/v1/getuser
Traceback (most recent call last):
  File "/home/rushikeshkadam/code_space/videoView/server/venv/lib/python3.10/site-packages/rest_framework/request.py", line 421, in __getattr__
    return getattr(_request, attr)
AttributeError: 'WSGIRequest' object has no attribute 'user_id'

During handling of the above exception, another exception occurred:

Traceback (most recent call last):
  File "/home/rushikeshkadam/code_space/videoView/server/venv/lib/python3.10/site-packages/django/core/handlers/exception.py", line 55, in inner
    response = get_response(request)
  File "/home/rushikeshkadam/code_space/videoView/server/venv/lib/python3.10/site-packages/django/core/handlers/base.py", line 197, in _get_response
    response = wrapped_callback(request, *callback_args, **callback_kwargs)
  File "/home/rushikeshkadam/code_space/videoView/server/venv/lib/python3.10/site-packages/django/views/decorators/csrf.py", line 65, in _view_wrapper
    return view_func(request, *args, **kwargs)
  File "/home/rushikeshkadam/code_space/videoView/server/venv/lib/python3.10/site-packages/django/views/generic/base.py", line 104, in view
    return self.dispatch(request, *args, **kwargs)
  File "/home/rushikeshkadam/code_space/videoView/server/venv/lib/python3.10/site-packages/rest_framework/views.py", line 509, in dispatch
    response = self.handle_exception(exc)
  File "/home/rushikeshkadam/code_space/videoView/server/venv/lib/python3.10/site-packages/rest_framework/views.py", line 469, in handle_exception
    self.raise_uncaught_exception(exc)
  File "/home/rushikeshkadam/code_space/videoView/server/venv/lib/python3.10/site-packages/rest_framework/views.py", line 480, in raise_uncaught_exception
    raise exc
  File "/home/rushikeshkadam/code_space/videoView/server/venv/lib/python3.10/site-packages/rest_framework/views.py", line 506, in dispatch
    response = handler(request, *args, **kwargs)
  File "/home/rushikeshkadam/code_space/videoView/server/venv/lib/python3.10/site-packages/rest_framework/decorators.py", line 50, in handler
    return func(*args, **kwargs)
  File "/home/rushikeshkadam/code_space/videoView/server/videoView/api/Views/UserViews.py", line 41, in wraps_func
    return func(request,*args,**kwargs)
  File "/home/rushikeshkadam/code_space/videoView/server/videoView/api/Views/UserViews.py", line 112, in get_user
    user=Users.objects.filter(pk=request.user_id).first()
  File "/home/rushikeshkadam/code_space/videoView/server/venv/lib/python3.10/site-packages/rest_framework/request.py", line 423, in __getattr__
    return self.__getattribute__(attr)
AttributeError: 'Request' object has no attribute 'user_id'
DEBUG 2024-12-31 04:47:59,778 UserViews.py UserViews wraps_func 39: 'access_token'
ERROR 2024-12-31 04:47:59,795 log.py log log_response 248: Internal Server Error: /api/v1/getuser
Traceback (most recent call last):
  File "/home/rushikeshkadam/code_space/videoView/server/venv/lib/python3.10/site-packages/rest_framework/request.py", line 421, in __getattr__
    return getattr(_request, attr)
AttributeError: 'WSGIRequest' object has no attribute 'user_id'

During handling of the above exception, another exception occurred:

Traceback (most recent call last):
  File "/home/rushikeshkadam/code_space/videoView/server/venv/lib/python3.10/site-packages/django/core/handlers/exception.py", line 55, in inner
    response = get_response(request)
  File "/home/rushikeshkadam/code_space/videoView/server/venv/lib/python3.10/site-packages/django/core/handlers/base.py", line 197, in _get_response
    response = wrapped_callback(request, *callback_args, **callback_kwargs)
  File "/home/rushikeshkadam/code_space/videoView/server/venv/lib/python3.10/site-packages/django/views/decorators/csrf.py", line 65, in _view_wrapper
    return view_func(request, *args, **kwargs)
  File "/home/rushikeshkadam/code_space/videoView/server/venv/lib/python3.10/site-packages/django/views/generic/base.py", line 104, in view
    return self.dispatch(request, *args, **kwargs)
  File "/home/rushikeshkadam/code_space/videoView/server/venv/lib/python3.10/site-packages/rest_framework/views.py", line 509, in dispatch
    response = self.handle_exception(exc)
  File "/home/rushikeshkadam/code_space/videoView/server/venv/lib/python3.10/site-packages/rest_framework/views.py", line 469, in handle_exception
    self.raise_uncaught_exception(exc)
  File "/home/rushikeshkadam/code_space/videoView/server/venv/lib/python3.10/site-packages/rest_framework/views.py", line 480, in raise_uncaught_exception
    raise exc
  File "/home/rushikeshkadam/code_space/videoView/server/venv/lib/python3.10/site-packages/rest_framework/views.py", line 506, in dispatch
    response = handler(request, *args, **kwargs)
  File "/home/rushikeshkadam/code_space/videoView/server/venv/lib/python3.10/site-packages/rest_framework/decorators.py", line 50, in handler
    return func(*args, **kwargs)
  File "/home/rushikeshkadam/code_space/videoView/server/videoView/api/Views/UserViews.py", line 41, in wraps_func
    return func(request,*args,**kwargs)
  File "/home/rushikeshkadam/code_space/videoView/server/videoView/api/Views/UserViews.py", line 112, in get_user
    user=Users.objects.filter(pk=request.user_id).first()
  File "/home/rushikeshkadam/code_space/videoView/server/venv/lib/python3.10/site-packages/rest_framework/request.py", line 423, in __getattr__
    return self.__getattribute__(attr)
AttributeError: 'Request' object has no attribute 'user_id'
DEBUG 2024-12-31 04:50:43,156 UserViews.py UserViews wraps_func 39: 'access_token'
ERROR 2024-12-31 04:50:43,172 log.py log log_response 248: Internal Server Error: /api/v1/getuser
Traceback (most recent call last):
  File "/home/rushikeshkadam/code_space/videoView/server/venv/lib/python3.10/site-packages/rest_framework/request.py", line 421, in __getattr__
    return getattr(_request, attr)
AttributeError: 'WSGIRequest' object has no attribute 'get'

During handling of the above exception, another exception occurred:

Traceback (most recent call last):
  File "/home/rushikeshkadam/code_space/videoView/server/venv/lib/python3.10/site-packages/django/core/handlers/exception.py", line 55, in inner
    response = get_response(request)
  File "/home/rushikeshkadam/code_space/videoView/server/venv/lib/python3.10/site-packages/django/core/handlers/base.py", line 197, in _get_response
    response = wrapped_callback(request, *callback_args, **callback_kwargs)
  File "/home/rushikeshkadam/code_space/videoView/server/venv/lib/python3.10/site-packages/django/views/decorators/csrf.py", line 65, in _view_wrapper
    return view_func(request, *args, **kwargs)
  File "/home/rushikeshkadam/code_space/videoView/server/venv/lib/python3.10/site-packages/django/views/generic/base.py", line 104, in view
    return self.dispatch(request, *args, **kwargs)
  File "/home/rushikeshkadam/code_space/videoView/server/venv/lib/python3.10/site-packages/rest_framework/views.py", line 509, in dispatch
    response = self.handle_exception(exc)
  File "/home/rushikeshkadam/code_space/videoView/server/venv/lib/python3.10/site-packages/rest_framework/views.py", line 469, in handle_exception
    self.raise_uncaught_exception(exc)
  File "/home/rushikeshkadam/code_space/videoView/server/venv/lib/python3.10/site-packages/rest_framework/views.py", line 480, in raise_uncaught_exception
    raise exc
  File "/home/rushikeshkadam/code_space/videoView/server/venv/lib/python3.10/site-packages/rest_framework/views.py", line 506, in dispatch
    response = handler(request, *args, **kwargs)
  File "/home/rushikeshkadam/code_space/videoView/server/venv/lib/python3.10/site-packages/rest_framework/decorators.py", line 50, in handler
    return func(*args, **kwargs)
  File "/home/rushikeshkadam/code_space/videoView/server/videoView/api/Views/UserViews.py", line 41, in wraps_func
    return func(request,*args,**kwargs)
  File "/home/rushikeshkadam/code_space/videoView/server/videoView/api/Views/UserViews.py", line 112, in get_user
    user=Users.objects.filter(pk=request.get('user_id')).first()
  File "/home/rushikeshkadam/code_space/videoView/server/venv/lib/python3.10/site-packages/rest_framework/request.py", line 423, in __getattr__
    return self.__getattribute__(attr)
AttributeError: 'Request' object has no attribute 'get'
DEBUG 2024-12-31 04:51:38,962 UserViews.py UserViews wraps_func 39: 'access_token'
ERROR 2024-12-31 04:51:38,978 log.py log log_response 248: Internal Server Error: /api/v1/getuser
Traceback (most recent call last):
  File "/home/rushikeshkadam/code_space/videoView/server/venv/lib/python3.10/site-packages/rest_framework/request.py", line 421, in __getattr__
    return getattr(_request, attr)
AttributeError: 'WSGIRequest' object has no attribute 'get'

During handling of the above exception, another exception occurred:

Traceback (most recent call last):
  File "/home/rushikeshkadam/code_space/videoView/server/venv/lib/python3.10/site-packages/django/core/handlers/exception.py", line 55, in inner
    response = get_response(request)
  File "/home/rushikeshkadam/code_space/videoView/server/venv/lib/python3.10/site-packages/django/core/handlers/base.py", line 197, in _get_response
    response = wrapped_callback(request, *callback_args, **callback_kwargs)
  File "/home/rushikeshkadam/code_space/videoView/server/venv/lib/python3.10/site-packages/django/views/decorators/csrf.py", line 65, in _view_wrapper
    return view_func(request, *args, **kwargs)
  File "/home/rushikeshkadam/code_space/videoView/server/venv/lib/python3.10/site-packages/django/views/generic/base.py", line 104, in view
    return self.dispatch(request, *args, **kwargs)
  File "/home/rushikeshkadam/code_space/videoView/server/venv/lib/python3.10/site-packages/rest_framework/views.py", line 509, in dispatch
    response = self.handle_exception(exc)
  File "/home/rushikeshkadam/code_space/videoView/server/venv/lib/python3.10/site-packages/rest_framework/views.py", line 469, in handle_exception
    self.raise_uncaught_exception(exc)
  File "/home/rushikeshkadam/code_space/videoView/server/venv/lib/python3.10/site-packages/rest_framework/views.py", line 480, in raise_uncaught_exception
    raise exc
  File "/home/rushikeshkadam/code_space/videoView/server/venv/lib/python3.10/site-packages/rest_framework/views.py", line 506, in dispatch
    response = handler(request, *args, **kwargs)
  File "/home/rushikeshkadam/code_space/videoView/server/venv/lib/python3.10/site-packages/rest_framework/decorators.py", line 50, in handler
    return func(*args, **kwargs)
  File "/home/rushikeshkadam/code_space/videoView/server/videoView/api/Views/UserViews.py", line 41, in wraps_func
    return func(request,*args,**kwargs)
  File "/home/rushikeshkadam/code_space/videoView/server/videoView/api/Views/UserViews.py", line 112, in get_user
    user=Users.objects.filter(pk=request.get('user_id')).first()
  File "/home/rushikeshkadam/code_space/videoView/server/venv/lib/python3.10/site-packages/rest_framework/request.py", line 423, in __getattr__
    return self.__getattribute__(attr)
AttributeError: 'Request' object has no attribute 'get'
DEBUG 2024-12-31 04:52:01,159 UserViews.py UserViews wraps_func 39: 'access_token'
ERROR 2024-12-31 04:52:01,174 log.py log log_response 248: Internal Server Error: /api/v1/getuser
Traceback (most recent call last):
  File "/home/rushikeshkadam/code_space/videoView/server/venv/lib/python3.10/site-packages/rest_framework/request.py", line 421, in __getattr__
    return getattr(_request, attr)
AttributeError: 'WSGIRequest' object has no attribute 'get'

During handling of the above exception, another exception occurred:

Traceback (most recent call last):
  File "/home/rushikeshkadam/code_space/videoView/server/venv/lib/python3.10/site-packages/django/core/handlers/exception.py", line 55, in inner
    response = get_response(request)
  File "/home/rushikeshkadam/code_space/videoView/server/venv/lib/python3.10/site-packages/django/core/handlers/base.py", line 197, in _get_response
    response = wrapped_callback(request, *callback_args, **callback_kwargs)
  File "/home/rushikeshkadam/code_space/videoView/server/venv/lib/python3.10/site-packages/django/views/decorators/csrf.py", line 65, in _view_wrapper
    return view_func(request, *args, **kwargs)
  File "/home/rushikeshkadam/code_space/videoView/server/venv/lib/python3.10/site-packages/django/views/generic/base.py", line 104, in view
    return self.dispatch(request, *args, **kwargs)
  File "/home/rushikeshkadam/code_space/videoView/server/venv/lib/python3.10/site-packages/rest_framework/views.py", line 509, in dispatch
    response = self.handle_exception(exc)
  File "/home/rushikeshkadam/code_space/videoView/server/venv/lib/python3.10/site-packages/rest_framework/views.py", line 469, in handle_exception
    self.raise_uncaught_exception(exc)
  File "/home/rushikeshkadam/code_space/videoView/server/venv/lib/python3.10/site-packages/rest_framework/views.py", line 480, in raise_uncaught_exception
    raise exc
  File "/home/rushikeshkadam/code_space/videoView/server/venv/lib/python3.10/site-packages/rest_framework/views.py", line 506, in dispatch
    response = handler(request, *args, **kwargs)
  File "/home/rushikeshkadam/code_space/videoView/server/venv/lib/python3.10/site-packages/rest_framework/decorators.py", line 50, in handler
    return func(*args, **kwargs)
  File "/home/rushikeshkadam/code_space/videoView/server/videoView/api/Views/UserViews.py", line 41, in wraps_func
    return func(request,*args,**kwargs)
  File "/home/rushikeshkadam/code_space/videoView/server/videoView/api/Views/UserViews.py", line 112, in get_user
    user=Users.objects.filter(pk=request.get('user_id')).first()
  File "/home/rushikeshkadam/code_space/videoView/server/venv/lib/python3.10/site-packages/rest_framework/request.py", line 423, in __getattr__
    return self.__getattribute__(attr)
AttributeError: 'Request' object has no attribute 'get'
DEBUG 2024-12-31 04:52:20,802 UserViews.py UserViews wraps_func 39: 'access_token'
ERROR 2024-12-31 04:52:20,818 log.py log log_response 248: Internal Server Error: /api/v1/getuser
Traceback (most recent call last):
  File "/home/rushikeshkadam/code_space/videoView/server/venv/lib/python3.10/site-packages/rest_framework/request.py", line 421, in __getattr__
    return getattr(_request, attr)
AttributeError: 'WSGIRequest' object has no attribute 'get'

During handling of the above exception, another exception occurred:

Traceback (most recent call last):
  File "/home/rushikeshkadam/code_space/videoView/server/venv/lib/python3.10/site-packages/django/core/handlers/exception.py", line 55, in inner
    response = get_response(request)
  File "/home/rushikeshkadam/code_space/videoView/server/venv/lib/python3.10/site-packages/django/core/handlers/base.py", line 197, in _get_response
    response = wrapped_callback(request, *callback_args, **callback_kwargs)
  File "/home/rushikeshkadam/code_space/videoView/server/venv/lib/python3.10/site-packages/django/views/decorators/csrf.py", line 65, in _view_wrapper
    return view_func(request, *args, **kwargs)
  File "/home/rushikeshkadam/code_space/videoView/server/venv/lib/python3.10/site-packages/django/views/generic/base.py", line 104, in view
    return self.dispatch(request, *args, **kwargs)
  File "/home/rushikeshkadam/code_space/videoView/server/venv/lib/python3.10/site-packages/rest_framework/views.py", line 509, in dispatch
    response = self.handle_exception(exc)
  File "/home/rushikeshkadam/code_space/videoView/server/venv/lib/python3.10/site-packages/rest_framework/views.py", line 469, in handle_exception
    self.raise_uncaught_exception(exc)
  File "/home/rushikeshkadam/code_space/videoView/server/venv/lib/python3.10/site-packages/rest_framework/views.py", line 480, in raise_uncaught_exception
    raise exc
  File "/home/rushikeshkadam/code_space/videoView/server/venv/lib/python3.10/site-packages/rest_framework/views.py", line 506, in dispatch
    response = handler(request, *args, **kwargs)
  File "/home/rushikeshkadam/code_space/videoView/server/venv/lib/python3.10/site-packages/rest_framework/decorators.py", line 50, in handler
    return func(*args, **kwargs)
  File "/home/rushikeshkadam/code_space/videoView/server/videoView/api/Views/UserViews.py", line 41, in wraps_func
    return func(request,*args,**kwargs)
  File "/home/rushikeshkadam/code_space/videoView/server/videoView/api/Views/UserViews.py", line 112, in get_user
    user=Users.objects.filter(pk=request.get('user_id')).first()
  File "/home/rushikeshkadam/code_space/videoView/server/venv/lib/python3.10/site-packages/rest_framework/request.py", line 423, in __getattr__
    return self.__getattribute__(attr)
AttributeError: 'Request' object has no attribute 'get'
DEBUG 2024-12-31 04:52:40,368 UserViews.py UserViews wraps_func 39: 'access_token'
ERROR 2024-12-31 04:52:40,390 log.py log log_response 248: Internal Server Error: /api/v1/getuser
Traceback (most recent call last):
  File "/home/rushikeshkadam/code_space/videoView/server/venv/lib/python3.10/site-packages/rest_framework/request.py", line 421, in __getattr__
    return getattr(_request, attr)
AttributeError: 'WSGIRequest' object has no attribute 'user_id'

During handling of the above exception, another exception occurred:

Traceback (most recent call last):
  File "/home/rushikeshkadam/code_space/videoView/server/venv/lib/python3.10/site-packages/django/core/handlers/exception.py", line 55, in inner
    response = get_response(request)
  File "/home/rushikeshkadam/code_space/videoView/server/venv/lib/python3.10/site-packages/django/core/handlers/base.py", line 197, in _get_response
    response = wrapped_callback(request, *callback_args, **callback_kwargs)
  File "/home/rushikeshkadam/code_space/videoView/server/venv/lib/python3.10/site-packages/django/views/decorators/csrf.py", line 65, in _view_wrapper
    return view_func(request, *args, **kwargs)
  File "/home/rushikeshkadam/code_space/videoView/server/venv/lib/python3.10/site-packages/django/views/generic/base.py", line 104, in view
    return self.dispatch(request, *args, **kwargs)
  File "/home/rushikeshkadam/code_space/videoView/server/venv/lib/python3.10/site-packages/rest_framework/views.py", line 509, in dispatch
    response = self.handle_exception(exc)
  File "/home/rushikeshkadam/code_space/videoView/server/venv/lib/python3.10/site-packages/rest_framework/views.py", line 469, in handle_exception
    self.raise_uncaught_exception(exc)
  File "/home/rushikeshkadam/code_space/videoView/server/venv/lib/python3.10/site-packages/rest_framework/views.py", line 480, in raise_uncaught_exception
    raise exc
  File "/home/rushikeshkadam/code_space/videoView/server/venv/lib/python3.10/site-packages/rest_framework/views.py", line 506, in dispatch
    response = handler(request, *args, **kwargs)
  File "/home/rushikeshkadam/code_space/videoView/server/venv/lib/python3.10/site-packages/rest_framework/decorators.py", line 50, in handler
    return func(*args, **kwargs)
  File "/home/rushikeshkadam/code_space/videoView/server/videoView/api/Views/UserViews.py", line 41, in wraps_func
    return func(request,*args,**kwargs)
  File "/home/rushikeshkadam/code_space/videoView/server/videoView/api/Views/UserViews.py", line 112, in get_user
    user=Users.objects.filter(pk=request.user_id).first()
  File "/home/rushikeshkadam/code_space/videoView/server/venv/lib/python3.10/site-packages/rest_framework/request.py", line 423, in __getattr__
    return self.__getattribute__(attr)
AttributeError: 'Request' object has no attribute 'user_id'
DEBUG 2024-12-31 04:53:23,224 UserViews.py UserViews wraps_func 39: 'access_token'
ERROR 2024-12-31 04:53:23,241 log.py log log_response 248: Internal Server Error: /api/v1/getuser
Traceback (most recent call last):
  File "/home/rushikeshkadam/code_space/videoView/server/venv/lib/python3.10/site-packages/rest_framework/request.py", line 421, in __getattr__
    return getattr(_request, attr)
AttributeError: 'WSGIRequest' object has no attribute 'user_id'

During handling of the above exception, another exception occurred:

Traceback (most recent call last):
  File "/home/rushikeshkadam/code_space/videoView/server/venv/lib/python3.10/site-packages/django/core/handlers/exception.py", line 55, in inner
    response = get_response(request)
  File "/home/rushikeshkadam/code_space/videoView/server/venv/lib/python3.10/site-packages/django/core/handlers/base.py", line 197, in _get_response
    response = wrapped_callback(request, *callback_args, **callback_kwargs)
  File "/home/rushikeshkadam/code_space/videoView/server/venv/lib/python3.10/site-packages/django/views/decorators/csrf.py", line 65, in _view_wrapper
    return view_func(request, *args, **kwargs)
  File "/home/rushikeshkadam/code_space/videoView/server/venv/lib/python3.10/site-packages/django/views/generic/base.py", line 104, in view
    return self.dispatch(request, *args, **kwargs)
  File "/home/rushikeshkadam/code_space/videoView/server/venv/lib/python3.10/site-packages/rest_framework/views.py", line 509, in dispatch
    response = self.handle_exception(exc)
  File "/home/rushikeshkadam/code_space/videoView/server/venv/lib/python3.10/site-packages/rest_framework/views.py", line 469, in handle_exception
    self.raise_uncaught_exception(exc)
  File "/home/rushikeshkadam/code_space/videoView/server/venv/lib/python3.10/site-packages/rest_framework/views.py", line 480, in raise_uncaught_exception
    raise exc
  File "/home/rushikeshkadam/code_space/videoView/server/venv/lib/python3.10/site-packages/rest_framework/views.py", line 506, in dispatch
    response = handler(request, *args, **kwargs)
  File "/home/rushikeshkadam/code_space/videoView/server/venv/lib/python3.10/site-packages/rest_framework/decorators.py", line 50, in handler
    return func(*args, **kwargs)
  File "/home/rushikeshkadam/code_space/videoView/server/videoView/api/Views/UserViews.py", line 41, in wraps_func
    return func(request,*args,**kwargs)
  File "/home/rushikeshkadam/code_space/videoView/server/videoView/api/Views/UserViews.py", line 112, in get_user
    user=Users.objects.filter(pk=request.user_id).first()
  File "/home/rushikeshkadam/code_space/videoView/server/venv/lib/python3.10/site-packages/rest_framework/request.py", line 423, in __getattr__
    return self.__getattribute__(attr)
AttributeError: 'Request' object has no attribute 'user_id'
DEBUG 2024-12-31 04:53:31,458 UserViews.py UserViews wraps_func 39: 'access_token'
ERROR 2024-12-31 04:53:31,481 log.py log log_response 248: Internal Server Error: /api/v1/getuser
Traceback (most recent call last):
  File "/home/rushikeshkadam/code_space/videoView/server/venv/lib/python3.10/site-packages/rest_framework/request.py", line 421, in __getattr__
    return getattr(_request, attr)
AttributeError: 'WSGIRequest' object has no attribute 'user_id'

During handling of the above exception, another exception occurred:

Traceback (most recent call last):
  File "/home/rushikeshkadam/code_space/videoView/server/venv/lib/python3.10/site-packages/django/core/handlers/exception.py", line 55, in inner
    response = get_response(request)
  File "/home/rushikeshkadam/code_space/videoView/server/venv/lib/python3.10/site-packages/django/core/handlers/base.py", line 197, in _get_response
    response = wrapped_callback(request, *callback_args, **callback_kwargs)
  File "/home/rushikeshkadam/code_space/videoView/server/venv/lib/python3.10/site-packages/django/views/decorators/csrf.py", line 65, in _view_wrapper
    return view_func(request, *args, **kwargs)
  File "/home/rushikeshkadam/code_space/videoView/server/venv/lib/python3.10/site-packages/django/views/generic/base.py", line 104, in view
    return self.dispatch(request, *args, **kwargs)
  File "/home/rushikeshkadam/code_space/videoView/server/venv/lib/python3.10/site-packages/rest_framework/views.py", line 509, in dispatch
    response = self.handle_exception(exc)
  File "/home/rushikeshkadam/code_space/videoView/server/venv/lib/python3.10/site-packages/rest_framework/views.py", line 469, in handle_exception
    self.raise_uncaught_exception(exc)
  File "/home/rushikeshkadam/code_space/videoView/server/venv/lib/python3.10/site-packages/rest_framework/views.py", line 480, in raise_uncaught_exception
    raise exc
  File "/home/rushikeshkadam/code_space/videoView/server/venv/lib/python3.10/site-packages/rest_framework/views.py", line 506, in dispatch
    response = handler(request, *args, **kwargs)
  File "/home/rushikeshkadam/code_space/videoView/server/venv/lib/python3.10/site-packages/rest_framework/decorators.py", line 50, in handler
    return func(*args, **kwargs)
  File "/home/rushikeshkadam/code_space/videoView/server/videoView/api/Views/UserViews.py", line 41, in wraps_func
    return func(request,*args,**kwargs)
  File "/home/rushikeshkadam/code_space/videoView/server/videoView/api/Views/UserViews.py", line 112, in get_user
    user=Users.objects.filter(pk=request.user_id).first()
  File "/home/rushikeshkadam/code_space/videoView/server/venv/lib/python3.10/site-packages/rest_framework/request.py", line 423, in __getattr__
    return self.__getattribute__(attr)
AttributeError: 'Request' object has no attribute 'user_id'
DEBUG 2024-12-31 04:55:54,071 UserViews.py UserViews wraps_func 39: 'access_token'
ERROR 2024-12-31 04:55:54,088 log.py log log_response 248: Internal Server Error: /api/v1/getuser
Traceback (most recent call last):
  File "/home/rushikeshkadam/code_space/videoView/server/venv/lib/python3.10/site-packages/rest_framework/request.py", line 421, in __getattr__
    return getattr(_request, attr)
AttributeError: 'WSGIRequest' object has no attribute 'user_id'

During handling of the above exception, another exception occurred:

Traceback (most recent call last):
  File "/home/rushikeshkadam/code_space/videoView/server/venv/lib/python3.10/site-packages/django/core/handlers/exception.py", line 55, in inner
    response = get_response(request)
  File "/home/rushikeshkadam/code_space/videoView/server/venv/lib/python3.10/site-packages/django/core/handlers/base.py", line 197, in _get_response
    response = wrapped_callback(request, *callback_args, **callback_kwargs)
  File "/home/rushikeshkadam/code_space/videoView/server/venv/lib/python3.10/site-packages/django/views/decorators/csrf.py", line 65, in _view_wrapper
    return view_func(request, *args, **kwargs)
  File "/home/rushikeshkadam/code_space/videoView/server/venv/lib/python3.10/site-packages/django/views/generic/base.py", line 104, in view
    return self.dispatch(request, *args, **kwargs)
  File "/home/rushikeshkadam/code_space/videoView/server/venv/lib/python3.10/site-packages/rest_framework/views.py", line 509, in dispatch
    response = self.handle_exception(exc)
  File "/home/rushikeshkadam/code_space/videoView/server/venv/lib/python3.10/site-packages/rest_framework/views.py", line 469, in handle_exception
    self.raise_uncaught_exception(exc)
  File "/home/rushikeshkadam/code_space/videoView/server/venv/lib/python3.10/site-packages/rest_framework/views.py", line 480, in raise_uncaught_exception
    raise exc
  File "/home/rushikeshkadam/code_space/videoView/server/venv/lib/python3.10/site-packages/rest_framework/views.py", line 506, in dispatch
    response = handler(request, *args, **kwargs)
  File "/home/rushikeshkadam/code_space/videoView/server/venv/lib/python3.10/site-packages/rest_framework/decorators.py", line 50, in handler
    return func(*args, **kwargs)
  File "/home/rushikeshkadam/code_space/videoView/server/videoView/api/Views/UserViews.py", line 41, in wraps_func
    return func(request,*args,**kwargs)
  File "/home/rushikeshkadam/code_space/videoView/server/videoView/api/Views/UserViews.py", line 112, in get_user
    user=Users.objects.filter(pk=request.user_id).first()
  File "/home/rushikeshkadam/code_space/videoView/server/venv/lib/python3.10/site-packages/rest_framework/request.py", line 423, in __getattr__
    return self.__getattribute__(attr)
AttributeError: 'Request' object has no attribute 'user_id'
DEBUG 2024-12-31 04:56:36,762 UserViews.py UserViews wraps_func 39: ApiResponse.error() missing 1 required positional argument: 'message'
ERROR 2024-12-31 04:56:36,783 log.py log log_response 248: Internal Server Error: /api/v1/getuser
Traceback (most recent call last):
  File "/home/rushikeshkadam/code_space/videoView/server/venv/lib/python3.10/site-packages/rest_framework/request.py", line 421, in __getattr__
    return getattr(_request, attr)
AttributeError: 'WSGIRequest' object has no attribute 'user_id'

During handling of the above exception, another exception occurred:

Traceback (most recent call last):
  File "/home/rushikeshkadam/code_space/videoView/server/venv/lib/python3.10/site-packages/django/core/handlers/exception.py", line 55, in inner
    response = get_response(request)
  File "/home/rushikeshkadam/code_space/videoView/server/venv/lib/python3.10/site-packages/django/core/handlers/base.py", line 197, in _get_response
    response = wrapped_callback(request, *callback_args, **callback_kwargs)
  File "/home/rushikeshkadam/code_space/videoView/server/venv/lib/python3.10/site-packages/django/views/decorators/csrf.py", line 65, in _view_wrapper
    return view_func(request, *args, **kwargs)
  File "/home/rushikeshkadam/code_space/videoView/server/venv/lib/python3.10/site-packages/django/views/generic/base.py", line 104, in view
    return self.dispatch(request, *args, **kwargs)
  File "/home/rushikeshkadam/code_space/videoView/server/venv/lib/python3.10/site-packages/rest_framework/views.py", line 509, in dispatch
    response = self.handle_exception(exc)
  File "/home/rushikeshkadam/code_space/videoView/server/venv/lib/python3.10/site-packages/rest_framework/views.py", line 469, in handle_exception
    self.raise_uncaught_exception(exc)
  File "/home/rushikeshkadam/code_space/videoView/server/venv/lib/python3.10/site-packages/rest_framework/views.py", line 480, in raise_uncaught_exception
    raise exc
  File "/home/rushikeshkadam/code_space/videoView/server/venv/lib/python3.10/site-packages/rest_framework/views.py", line 506, in dispatch
    response = handler(request, *args, **kwargs)
  File "/home/rushikeshkadam/code_space/videoView/server/venv/lib/python3.10/site-packages/rest_framework/decorators.py", line 50, in handler
    return func(*args, **kwargs)
  File "/home/rushikeshkadam/code_space/videoView/server/videoView/api/Views/UserViews.py", line 41, in wraps_func
    return func(request,*args,**kwargs)
  File "/home/rushikeshkadam/code_space/videoView/server/videoView/api/Views/UserViews.py", line 112, in get_user
    user=Users.objects.filter(pk=request.user_id).first()
  File "/home/rushikeshkadam/code_space/videoView/server/venv/lib/python3.10/site-packages/rest_framework/request.py", line 423, in __getattr__
    return self.__getattribute__(attr)
AttributeError: 'Request' object has no attribute 'user_id'
DEBUG 2024-12-31 05:00:55,245 UserViews.py UserViews wraps_func 39: ApiResponse.error() missing 1 required positional argument: 'message'
ERROR 2024-12-31 05:00:55,265 log.py log log_response 248: Internal Server Error: /api/v1/getuser
Traceback (most recent call last):
  File "/home/rushikeshkadam/code_space/videoView/server/venv/lib/python3.10/site-packages/rest_framework/request.py", line 421, in __getattr__
    return getattr(_request, attr)
AttributeError: 'WSGIRequest' object has no attribute 'user_id'

During handling of the above exception, another exception occurred:

Traceback (most recent call last):
  File "/home/rushikeshkadam/code_space/videoView/server/venv/lib/python3.10/site-packages/django/core/handlers/exception.py", line 55, in inner
    response = get_response(request)
  File "/home/rushikeshkadam/code_space/videoView/server/venv/lib/python3.10/site-packages/django/core/handlers/base.py", line 197, in _get_response
    response = wrapped_callback(request, *callback_args, **callback_kwargs)
  File "/home/rushikeshkadam/code_space/videoView/server/venv/lib/python3.10/site-packages/django/views/decorators/csrf.py", line 65, in _view_wrapper
    return view_func(request, *args, **kwargs)
  File "/home/rushikeshkadam/code_space/videoView/server/venv/lib/python3.10/site-packages/django/views/generic/base.py", line 104, in view
    return self.dispatch(request, *args, **kwargs)
  File "/home/rushikeshkadam/code_space/videoView/server/venv/lib/python3.10/site-packages/rest_framework/views.py", line 509, in dispatch
    response = self.handle_exception(exc)
  File "/home/rushikeshkadam/code_space/videoView/server/venv/lib/python3.10/site-packages/rest_framework/views.py", line 469, in handle_exception
    self.raise_uncaught_exception(exc)
  File "/home/rushikeshkadam/code_space/videoView/server/venv/lib/python3.10/site-packages/rest_framework/views.py", line 480, in raise_uncaught_exception
    raise exc
  File "/home/rushikeshkadam/code_space/videoView/server/venv/lib/python3.10/site-packages/rest_framework/views.py", line 506, in dispatch
    response = handler(request, *args, **kwargs)
  File "/home/rushikeshkadam/code_space/videoView/server/venv/lib/python3.10/site-packages/rest_framework/decorators.py", line 50, in handler
    return func(*args, **kwargs)
  File "/home/rushikeshkadam/code_space/videoView/server/videoView/api/Views/UserViews.py", line 41, in wraps_func
    return func(request,*args,**kwargs)
  File "/home/rushikeshkadam/code_space/videoView/server/videoView/api/Views/UserViews.py", line 112, in get_user
    user=Users.objects.filter(pk=request.user_id).first()
  File "/home/rushikeshkadam/code_space/videoView/server/venv/lib/python3.10/site-packages/rest_framework/request.py", line 423, in __getattr__
    return self.__getattribute__(attr)
AttributeError: 'Request' object has no attribute 'user_id'
DEBUG 2024-12-31 05:05:18,255 UserViews.py UserViews wraps_func 37: ApiResponse.error() missing 1 required positional argument: 'message'
ERROR 2024-12-31 05:05:18,270 log.py log log_response 248: Internal Server Error: /api/v1/getuser
Traceback (most recent call last):
  File "/home/rushikeshkadam/code_space/videoView/server/videoView/api/Views/UserViews.py", line 29, in wraps_func
    return Response(ApiResponse.error(401,error="Unauthorized user").__dict__,status=401)
TypeError: ApiResponse.error() missing 1 required positional argument: 'message'

During handling of the above exception, another exception occurred:

Traceback (most recent call last):
  File "/home/rushikeshkadam/code_space/videoView/server/venv/lib/python3.10/site-packages/django/core/handlers/exception.py", line 55, in inner
    response = get_response(request)
  File "/home/rushikeshkadam/code_space/videoView/server/venv/lib/python3.10/site-packages/django/core/handlers/base.py", line 197, in _get_response
    response = wrapped_callback(request, *callback_args, **callback_kwargs)
  File "/home/rushikeshkadam/code_space/videoView/server/venv/lib/python3.10/site-packages/django/views/decorators/csrf.py", line 65, in _view_wrapper
    return view_func(request, *args, **kwargs)
  File "/home/rushikeshkadam/code_space/videoView/server/venv/lib/python3.10/site-packages/django/views/generic/base.py", line 104, in view
    return self.dispatch(request, *args, **kwargs)
  File "/home/rushikeshkadam/code_space/videoView/server/venv/lib/python3.10/site-packages/rest_framework/views.py", line 509, in dispatch
    response = self.handle_exception(exc)
  File "/home/rushikeshkadam/code_space/videoView/server/venv/lib/python3.10/site-packages/rest_framework/views.py", line 469, in handle_exception
    self.raise_uncaught_exception(exc)
  File "/home/rushikeshkadam/code_space/videoView/server/venv/lib/python3.10/site-packages/rest_framework/views.py", line 480, in raise_uncaught_exception
    raise exc
  File "/home/rushikeshkadam/code_space/videoView/server/venv/lib/python3.10/site-packages/rest_framework/views.py", line 506, in dispatch
    response = handler(request, *args, **kwargs)
  File "/home/rushikeshkadam/code_space/videoView/server/venv/lib/python3.10/site-packages/rest_framework/decorators.py", line 50, in handler
    return func(*args, **kwargs)
  File "/home/rushikeshkadam/code_space/videoView/server/videoView/api/Views/UserViews.py", line 38, in wraps_func
    return Response(ApiResponse.error(401,error="Invalid token").__dict__,status=401)
TypeError: ApiResponse.error() missing 1 required positional argument: 'message'
DEBUG 2024-12-31 05:05:27,298 UserViews.py UserViews wraps_func 37: ApiResponse.error() missing 1 required positional argument: 'message'
ERROR 2024-12-31 05:05:27,319 log.py log log_response 248: Internal Server Error: /api/v1/getuser
Traceback (most recent call last):
  File "/home/rushikeshkadam/code_space/videoView/server/videoView/api/Views/UserViews.py", line 29, in wraps_func
    return Response(ApiResponse.error(401,error="Unauthorized user").__dict__,status=401)
TypeError: ApiResponse.error() missing 1 required positional argument: 'message'

During handling of the above exception, another exception occurred:

Traceback (most recent call last):
  File "/home/rushikeshkadam/code_space/videoView/server/venv/lib/python3.10/site-packages/django/core/handlers/exception.py", line 55, in inner
    response = get_response(request)
  File "/home/rushikeshkadam/code_space/videoView/server/venv/lib/python3.10/site-packages/django/core/handlers/base.py", line 197, in _get_response
    response = wrapped_callback(request, *callback_args, **callback_kwargs)
  File "/home/rushikeshkadam/code_space/videoView/server/venv/lib/python3.10/site-packages/django/views/decorators/csrf.py", line 65, in _view_wrapper
    return view_func(request, *args, **kwargs)
  File "/home/rushikeshkadam/code_space/videoView/server/venv/lib/python3.10/site-packages/django/views/generic/base.py", line 104, in view
    return self.dispatch(request, *args, **kwargs)
  File "/home/rushikeshkadam/code_space/videoView/server/venv/lib/python3.10/site-packages/rest_framework/views.py", line 509, in dispatch
    response = self.handle_exception(exc)
  File "/home/rushikeshkadam/code_space/videoView/server/venv/lib/python3.10/site-packages/rest_framework/views.py", line 469, in handle_exception
    self.raise_uncaught_exception(exc)
  File "/home/rushikeshkadam/code_space/videoView/server/venv/lib/python3.10/site-packages/rest_framework/views.py", line 480, in raise_uncaught_exception
    raise exc
  File "/home/rushikeshkadam/code_space/videoView/server/venv/lib/python3.10/site-packages/rest_framework/views.py", line 506, in dispatch
    response = handler(request, *args, **kwargs)
  File "/home/rushikeshkadam/code_space/videoView/server/venv/lib/python3.10/site-packages/rest_framework/decorators.py", line 50, in handler
    return func(*args, **kwargs)
  File "/home/rushikeshkadam/code_space/videoView/server/videoView/api/Views/UserViews.py", line 38, in wraps_func
    return Response(ApiResponse.error(401,error="Invalid token").__dict__,status=401)
TypeError: ApiResponse.error() missing 1 required positional argument: 'message'
DEBUG 2024-12-31 05:05:45,628 UserViews.py UserViews wraps_func 37: ApiResponse.error() missing 1 required positional argument: 'message'
WARNING 2024-12-31 05:05:45,629 log.py log log_response 248: Unauthorized: /api/v1/getuser
DEBUG 2024-12-31 05:06:07,313 UserViews.py UserViews wraps_func 37: ApiResponse.error() missing 1 required positional argument: 'message'
WARNING 2024-12-31 05:06:07,313 log.py log log_response 248: Unauthorized: /api/v1/getuser
DEBUG 2024-12-31 05:06:25,827 UserViews.py UserViews wraps_func 37: ApiResponse.error() missing 1 required positional argument: 'message'
WARNING 2024-12-31 05:06:25,828 log.py log log_response 248: Unauthorized: /api/v1/getuser
WARNING 2024-12-31 05:06:50,286 log.py log log_response 248: Unauthorized: /api/v1/getuser
WARNING 2024-12-31 05:08:56,618 log.py log log_response 248: Unauthorized: /api/v1/getuser
WARNING 2024-12-31 05:17:29,947 log.py log log_response 248: Unauthorized: /api/v1/logout
WARNING 2024-12-31 05:17:35,281 log.py log log_response 248: Method Not Allowed: /api/v1/login
