WARNING 2024-12-31 20:29:40,740 log.py log log_response 248: Method Not Allowed: /api/v1/login
DEBUG 2024-12-31 20:29:55,886 VideoView.py VideoView upload_video 34: 'Request' object has no attribute 'user_id'
ERROR 2024-12-31 20:29:55,887 log.py log log_response 248: Internal Server Error: /api/v1/upload_video
DEBUG 2024-12-31 20:30:33,364 VideoView.py VideoView upload_video 34: 'Request' object has no attribute 'user_id'
ERROR 2024-12-31 20:30:33,364 log.py log log_response 248: Internal Server Error: /api/v1/upload_video
WARNING 2024-12-31 20:33:37,856 log.py log log_response 248: Unauthorized: /api/v1/upload_video
WARNING 2024-12-31 20:40:58,799 log.py log log_response 248: Unauthorized: /api/v1/upload_video
DEBUG 2024-12-31 20:41:09,565 VideoView.py VideoView upload_video 35: 'str' object has no attribute '_meta'
ERROR 2024-12-31 20:41:09,565 log.py log log_response 248: Internal Server Error: /api/v1/upload_video
DEBUG 2024-12-31 20:43:07,580 VideoView.py VideoView upload_video 35: 'str' object has no attribute '_meta'
ERROR 2024-12-31 20:43:07,580 log.py log log_response 248: Internal Server Error: /api/v1/upload_video
DEBUG 2024-12-31 20:43:37,907 VideoView.py VideoView upload_video 35: 'str' object has no attribute '_meta'
ERROR 2024-12-31 20:43:37,907 log.py log log_response 248: Internal Server Error: /api/v1/upload_video
DEBUG 2024-12-31 20:46:07,000 VideoView.py VideoView upload_video 35: 'str' object has no attribute '_meta'
ERROR 2024-12-31 20:46:07,001 log.py log log_response 248: Internal Server Error: /api/v1/upload_video
DEBUG 2024-12-31 20:51:37,707 VideoView.py VideoView upload_video 35: 'NoneType' object has no attribute 'user_id'
ERROR 2024-12-31 20:51:37,708 log.py log log_response 248: Internal Server Error: /api/v1/upload_video
DEBUG 2024-12-31 20:52:04,966 VideoView.py VideoView upload_video 35: 'str' object has no attribute 'user_id'
ERROR 2024-12-31 20:52:04,966 log.py log log_response 248: Internal Server Error: /api/v1/upload_video
DEBUG 2024-12-31 20:52:17,392 VideoView.py VideoView upload_video 35: name 'instance' is not defined
ERROR 2024-12-31 20:52:17,393 log.py log log_response 248: Internal Server Error: /api/v1/upload_video
WARNING 2025-01-01 08:04:04,541 log.py log log_response 248: Unauthorized: /api/v1/upload_video
WARNING 2025-01-01 08:05:47,171 log.py log log_response 248: Method Not Allowed: /api/v1/login
WARNING 2025-01-01 08:06:20,567 log.py log log_response 248: Unauthorized: /api/v1/upload_video
WARNING 2025-01-01 08:11:23,970 log.py log log_response 248: Unauthorized: /api/v1/upload_video
DEBUG 2025-01-01 08:11:35,617 VideoView.py VideoView upload_video 35: name 'instance' is not defined
ERROR 2025-01-01 08:11:35,617 log.py log log_response 248: Internal Server Error: /api/v1/upload_video
DEBUG 2025-01-01 08:12:29,605 VideoView.py VideoView upload_video 35: 'TemporaryUploadedFile' object has no attribute 'get'
ERROR 2025-01-01 08:12:29,607 log.py log log_response 248: Internal Server Error: /api/v1/upload_video
DEBUG 2025-01-01 08:13:27,437 serializer.py serializer create 151: 4973185-hd_1920_1080_30fps.mp4
DEBUG 2025-01-01 08:13:28,986 VideoView.py VideoView upload_video 35: 'TemporaryUploadedFile' object has no attribute 'get'
ERROR 2025-01-01 08:13:28,988 log.py log log_response 248: Internal Server Error: /api/v1/upload_video
DEBUG 2025-01-01 08:14:53,357 serializer.py serializer create 151: 4973185-hd_1920_1080_30fps.mp4
DEBUG 2025-01-01 08:15:01,249 VideoView.py VideoView upload_video 35: NOT NULL constraint failed: api_videos.duration
ERROR 2025-01-01 08:15:01,250 log.py log log_response 248: Internal Server Error: /api/v1/upload_video
DEBUG 2025-01-01 08:15:35,585 serializer.py serializer create 151: 4973185-hd_1920_1080_30fps.mp4
DEBUG 2025-01-01 08:15:47,943 VideoView.py VideoView upload_video 35: NOT NULL constraint failed: api_videos.views
ERROR 2025-01-01 08:15:47,945 log.py log log_response 248: Internal Server Error: /api/v1/upload_video
DEBUG 2025-01-01 08:16:30,884 serializer.py serializer create 151: 4973185-hd_1920_1080_30fps.mp4
DEBUG 2025-01-01 08:16:42,421 VideoView.py VideoView upload_video 35: NOT NULL constraint failed: api_videos.isPublished
ERROR 2025-01-01 08:16:42,422 log.py log log_response 248: Internal Server Error: /api/v1/upload_video
DEBUG 2025-01-01 08:17:06,179 serializer.py serializer create 151: 4973185-hd_1920_1080_30fps.mp4
DEBUG 2025-01-01 08:17:15,704 VideoView.py VideoView upload_video 35: int() argument must be a string, a bytes-like object or a real number, not 'DeferredAttribute'
ERROR 2025-01-01 08:17:15,705 log.py log log_response 248: Internal Server Error: /api/v1/upload_video
DEBUG 2025-01-01 08:21:29,765 serializer.py serializer create 151: 4973185-hd_1920_1080_30fps.mp4
DEBUG 2025-01-01 08:21:41,614 VideoView.py VideoView upload_video 35: int() argument must be a string, a bytes-like object or a real number, not 'DeferredAttribute'
ERROR 2025-01-01 08:21:41,615 log.py log log_response 248: Internal Server Error: /api/v1/upload_video
DEBUG 2025-01-01 08:22:56,214 serializer.py serializer create 151: 4973185-hd_1920_1080_30fps.mp4
DEBUG 2025-01-01 08:23:09,288 VideoView.py VideoView upload_video 35: int() argument must be a string, a bytes-like object or a real number, not 'DeferredAttribute'
ERROR 2025-01-01 08:23:09,289 log.py log log_response 248: Internal Server Error: /api/v1/upload_video
DEBUG 2025-01-01 08:24:37,784 serializer.py serializer create 151: 4973185-hd_1920_1080_30fps.mp4
DEBUG 2025-01-01 08:24:49,948 VideoView.py VideoView upload_video 35: int() argument must be a string, a bytes-like object or a real number, not 'DeferredAttribute'
ERROR 2025-01-01 08:24:49,950 log.py log log_response 248: Internal Server Error: /api/v1/upload_video
DEBUG 2025-01-01 08:26:16,870 serializer.py serializer create 151: 4973185-hd_1920_1080_30fps.mp4
DEBUG 2025-01-01 08:26:16,872 serializer.py serializer create 153: 10
DEBUG 2025-01-01 08:26:31,909 serializer.py serializer create 151: 4973185-hd_1920_1080_30fps.mp4
DEBUG 2025-01-01 08:26:31,910 serializer.py serializer create 153: <class 'int'>
DEBUG 2025-01-01 08:26:49,126 serializer.py serializer create 151: 4973185-hd_1920_1080_30fps.mp4
DEBUG 2025-01-01 08:26:49,129 serializer.py serializer create 153: <class 'str'>
DEBUG 2025-01-01 08:27:02,195 serializer.py serializer create 151: 4973185-hd_1920_1080_30fps.mp4
DEBUG 2025-01-01 08:27:02,197 serializer.py serializer create 153: 10
DEBUG 2025-01-01 08:27:14,740 VideoView.py VideoView upload_video 35: int() argument must be a string, a bytes-like object or a real number, not 'DeferredAttribute'
ERROR 2025-01-01 08:27:14,742 log.py log log_response 248: Internal Server Error: /api/v1/upload_video
DEBUG 2025-01-01 08:32:42,255 serializer.py serializer create 151: 4973185-hd_1920_1080_30fps.mp4
DEBUG 2025-01-01 08:32:42,256 serializer.py serializer create 153: 10
DEBUG 2025-01-01 08:32:54,792 VideoView.py VideoView upload_video 35: int() argument must be a string, a bytes-like object or a real number, not 'DeferredAttribute'
ERROR 2025-01-01 08:32:54,793 log.py log log_response 248: Internal Server Error: /api/v1/upload_video
DEBUG 2025-01-01 08:33:42,915 serializer.py serializer create 151: 4973185-hd_1920_1080_30fps.mp4
DEBUG 2025-01-01 08:33:42,917 serializer.py serializer create 153: 10
DEBUG 2025-01-01 08:33:54,743 VideoView.py VideoView upload_video 35: int() argument must be a string, a bytes-like object or a real number, not 'DeferredAttribute'
ERROR 2025-01-01 08:33:54,745 log.py log log_response 248: Internal Server Error: /api/v1/upload_video
DEBUG 2025-01-01 08:36:35,906 serializer.py serializer create 151: 4973185-hd_1920_1080_30fps.mp4
DEBUG 2025-01-01 08:36:35,909 serializer.py serializer create 153: 10
ERROR 2025-01-01 09:07:57,960 log.py log log_response 248: Internal Server Error: /api/v1/signup
Traceback (most recent call last):
  File "/home/rushikeshkadam/code_space/videoView/server/venv/lib/python3.10/site-packages/django/core/handlers/exception.py", line 55, in inner
    response = get_response(request)
  File "/home/rushikeshkadam/code_space/videoView/server/venv/lib/python3.10/site-packages/django/core/handlers/base.py", line 197, in _get_response
    response = wrapped_callback(request, *callback_args, **callback_kwargs)
  File "/home/rushikeshkadam/code_space/videoView/server/venv/lib/python3.10/site-packages/django/views/decorators/csrf.py", line 65, in _view_wrapper
    return view_func(request, *args, **kwargs)
  File "/home/rushikeshkadam/code_space/videoView/server/venv/lib/python3.10/site-packages/django/views/generic/base.py", line 104, in view
    return self.dispatch(request, *args, **kwargs)
  File "/home/rushikeshkadam/code_space/videoView/server/venv/lib/python3.10/site-packages/rest_framework/views.py", line 509, in dispatch
    response = self.handle_exception(exc)
  File "/home/rushikeshkadam/code_space/videoView/server/venv/lib/python3.10/site-packages/rest_framework/views.py", line 469, in handle_exception
    self.raise_uncaught_exception(exc)
  File "/home/rushikeshkadam/code_space/videoView/server/venv/lib/python3.10/site-packages/rest_framework/views.py", line 480, in raise_uncaught_exception
    raise exc
  File "/home/rushikeshkadam/code_space/videoView/server/venv/lib/python3.10/site-packages/rest_framework/views.py", line 506, in dispatch
    response = handler(request, *args, **kwargs)
  File "/home/rushikeshkadam/code_space/videoView/server/venv/lib/python3.10/site-packages/rest_framework/decorators.py", line 50, in handler
    return func(*args, **kwargs)
  File "/home/rushikeshkadam/code_space/videoView/server/videoView/api/Views/UserViews.py", line 37, in signup
    user,token=serializer.save()
  File "/home/rushikeshkadam/code_space/videoView/server/venv/lib/python3.10/site-packages/rest_framework/serializers.py", line 208, in save
    self.instance = self.create(validated_data)
  File "/home/rushikeshkadam/code_space/videoView/server/videoView/api/serializer.py", line 43, in create
    coverImage_img=cloudinary.uploader.upload(image2)
  File "/home/rushikeshkadam/code_space/videoView/server/venv/lib/python3.10/site-packages/cloudinary/uploader.py", line 45, in upload
    return call_cacheable_api("upload", params, file=file, **options)
  File "/home/rushikeshkadam/code_space/videoView/server/venv/lib/python3.10/site-packages/cloudinary/uploader.py", line 462, in call_cacheable_api
    result = call_api(action, params, http_headers, return_error, unsigned, file, timeout, **options)
  File "/home/rushikeshkadam/code_space/videoView/server/venv/lib/python3.10/site-packages/cloudinary/uploader.py", line 527, in call_api
    raise Error(result["error"]["message"])
cloudinary.exceptions.Error: Missing required parameter - file
ERROR 2025-01-01 09:11:17,008 log.py log log_response 248: Internal Server Error: /api/v1/signup
Traceback (most recent call last):
  File "/home/rushikeshkadam/code_space/videoView/server/venv/lib/python3.10/site-packages/django/core/handlers/exception.py", line 55, in inner
    response = get_response(request)
  File "/home/rushikeshkadam/code_space/videoView/server/venv/lib/python3.10/site-packages/django/core/handlers/base.py", line 197, in _get_response
    response = wrapped_callback(request, *callback_args, **callback_kwargs)
  File "/home/rushikeshkadam/code_space/videoView/server/venv/lib/python3.10/site-packages/django/views/decorators/csrf.py", line 65, in _view_wrapper
    return view_func(request, *args, **kwargs)
  File "/home/rushikeshkadam/code_space/videoView/server/venv/lib/python3.10/site-packages/django/views/generic/base.py", line 104, in view
    return self.dispatch(request, *args, **kwargs)
  File "/home/rushikeshkadam/code_space/videoView/server/venv/lib/python3.10/site-packages/rest_framework/views.py", line 509, in dispatch
    response = self.handle_exception(exc)
  File "/home/rushikeshkadam/code_space/videoView/server/venv/lib/python3.10/site-packages/rest_framework/views.py", line 469, in handle_exception
    self.raise_uncaught_exception(exc)
  File "/home/rushikeshkadam/code_space/videoView/server/venv/lib/python3.10/site-packages/rest_framework/views.py", line 480, in raise_uncaught_exception
    raise exc
  File "/home/rushikeshkadam/code_space/videoView/server/venv/lib/python3.10/site-packages/rest_framework/views.py", line 506, in dispatch
    response = handler(request, *args, **kwargs)
  File "/home/rushikeshkadam/code_space/videoView/server/venv/lib/python3.10/site-packages/rest_framework/decorators.py", line 50, in handler
    return func(*args, **kwargs)
  File "/home/rushikeshkadam/code_space/videoView/server/videoView/api/Views/UserViews.py", line 37, in signup
    user,token=serializer.save()
  File "/home/rushikeshkadam/code_space/videoView/server/venv/lib/python3.10/site-packages/rest_framework/serializers.py", line 208, in save
    self.instance = self.create(validated_data)
  File "/home/rushikeshkadam/code_space/videoView/server/videoView/api/serializer.py", line 43, in create
    coverImage_img=cloudinary.uploader.upload(image2)
  File "/home/rushikeshkadam/code_space/videoView/server/venv/lib/python3.10/site-packages/cloudinary/uploader.py", line 45, in upload
    return call_cacheable_api("upload", params, file=file, **options)
  File "/home/rushikeshkadam/code_space/videoView/server/venv/lib/python3.10/site-packages/cloudinary/uploader.py", line 462, in call_cacheable_api
    result = call_api(action, params, http_headers, return_error, unsigned, file, timeout, **options)
  File "/home/rushikeshkadam/code_space/videoView/server/venv/lib/python3.10/site-packages/cloudinary/uploader.py", line 527, in call_api
    raise Error(result["error"]["message"])
cloudinary.exceptions.Error: Missing required parameter - file
ERROR 2025-01-01 09:14:14,624 log.py log log_response 248: Internal Server Error: /api/v1/signup
Traceback (most recent call last):
  File "/home/rushikeshkadam/code_space/videoView/server/venv/lib/python3.10/site-packages/django/core/handlers/exception.py", line 55, in inner
    response = get_response(request)
  File "/home/rushikeshkadam/code_space/videoView/server/venv/lib/python3.10/site-packages/django/core/handlers/base.py", line 197, in _get_response
    response = wrapped_callback(request, *callback_args, **callback_kwargs)
  File "/home/rushikeshkadam/code_space/videoView/server/venv/lib/python3.10/site-packages/django/views/decorators/csrf.py", line 65, in _view_wrapper
    return view_func(request, *args, **kwargs)
  File "/home/rushikeshkadam/code_space/videoView/server/venv/lib/python3.10/site-packages/django/views/generic/base.py", line 104, in view
    return self.dispatch(request, *args, **kwargs)
  File "/home/rushikeshkadam/code_space/videoView/server/venv/lib/python3.10/site-packages/rest_framework/views.py", line 509, in dispatch
    response = self.handle_exception(exc)
  File "/home/rushikeshkadam/code_space/videoView/server/venv/lib/python3.10/site-packages/rest_framework/views.py", line 469, in handle_exception
    self.raise_uncaught_exception(exc)
  File "/home/rushikeshkadam/code_space/videoView/server/venv/lib/python3.10/site-packages/rest_framework/views.py", line 480, in raise_uncaught_exception
    raise exc
  File "/home/rushikeshkadam/code_space/videoView/server/venv/lib/python3.10/site-packages/rest_framework/views.py", line 506, in dispatch
    response = handler(request, *args, **kwargs)
  File "/home/rushikeshkadam/code_space/videoView/server/venv/lib/python3.10/site-packages/rest_framework/decorators.py", line 50, in handler
    return func(*args, **kwargs)
  File "/home/rushikeshkadam/code_space/videoView/server/videoView/api/Views/UserViews.py", line 37, in signup
    user,token=serializer.save()
  File "/home/rushikeshkadam/code_space/videoView/server/venv/lib/python3.10/site-packages/rest_framework/serializers.py", line 208, in save
    self.instance = self.create(validated_data)
  File "/home/rushikeshkadam/code_space/videoView/server/videoView/api/serializer.py", line 44, in create
    coverImage_img=cloudinary.uploader.upload(image2)
  File "/home/rushikeshkadam/code_space/videoView/server/venv/lib/python3.10/site-packages/cloudinary/uploader.py", line 45, in upload
    return call_cacheable_api("upload", params, file=file, **options)
  File "/home/rushikeshkadam/code_space/videoView/server/venv/lib/python3.10/site-packages/cloudinary/uploader.py", line 462, in call_cacheable_api
    result = call_api(action, params, http_headers, return_error, unsigned, file, timeout, **options)
  File "/home/rushikeshkadam/code_space/videoView/server/venv/lib/python3.10/site-packages/cloudinary/uploader.py", line 527, in call_api
    raise Error(result["error"]["message"])
cloudinary.exceptions.Error: Missing required parameter - file
ERROR 2025-01-01 09:15:29,295 log.py log log_response 248: Internal Server Error: /api/v1/signup
Traceback (most recent call last):
  File "/home/rushikeshkadam/code_space/videoView/server/venv/lib/python3.10/site-packages/django/core/handlers/exception.py", line 55, in inner
    response = get_response(request)
  File "/home/rushikeshkadam/code_space/videoView/server/venv/lib/python3.10/site-packages/django/core/handlers/base.py", line 197, in _get_response
    response = wrapped_callback(request, *callback_args, **callback_kwargs)
  File "/home/rushikeshkadam/code_space/videoView/server/venv/lib/python3.10/site-packages/django/views/decorators/csrf.py", line 65, in _view_wrapper
    return view_func(request, *args, **kwargs)
  File "/home/rushikeshkadam/code_space/videoView/server/venv/lib/python3.10/site-packages/django/views/generic/base.py", line 104, in view
    return self.dispatch(request, *args, **kwargs)
  File "/home/rushikeshkadam/code_space/videoView/server/venv/lib/python3.10/site-packages/rest_framework/views.py", line 509, in dispatch
    response = self.handle_exception(exc)
  File "/home/rushikeshkadam/code_space/videoView/server/venv/lib/python3.10/site-packages/rest_framework/views.py", line 469, in handle_exception
    self.raise_uncaught_exception(exc)
  File "/home/rushikeshkadam/code_space/videoView/server/venv/lib/python3.10/site-packages/rest_framework/views.py", line 480, in raise_uncaught_exception
    raise exc
  File "/home/rushikeshkadam/code_space/videoView/server/venv/lib/python3.10/site-packages/rest_framework/views.py", line 506, in dispatch
    response = handler(request, *args, **kwargs)
  File "/home/rushikeshkadam/code_space/videoView/server/venv/lib/python3.10/site-packages/rest_framework/decorators.py", line 50, in handler
    return func(*args, **kwargs)
  File "/home/rushikeshkadam/code_space/videoView/server/videoView/api/Views/UserViews.py", line 37, in signup
    user,token=serializer.save()
  File "/home/rushikeshkadam/code_space/videoView/server/venv/lib/python3.10/site-packages/rest_framework/serializers.py", line 208, in save
    self.instance = self.create(validated_data)
  File "/home/rushikeshkadam/code_space/videoView/server/videoView/api/serializer.py", line 44, in create
    coverImage_img=cloudinary.uploader.upload(image2)
  File "/home/rushikeshkadam/code_space/videoView/server/venv/lib/python3.10/site-packages/cloudinary/uploader.py", line 45, in upload
    return call_cacheable_api("upload", params, file=file, **options)
  File "/home/rushikeshkadam/code_space/videoView/server/venv/lib/python3.10/site-packages/cloudinary/uploader.py", line 462, in call_cacheable_api
    result = call_api(action, params, http_headers, return_error, unsigned, file, timeout, **options)
  File "/home/rushikeshkadam/code_space/videoView/server/venv/lib/python3.10/site-packages/cloudinary/uploader.py", line 527, in call_api
    raise Error(result["error"]["message"])
cloudinary.exceptions.Error: Missing required parameter - file
ERROR 2025-01-01 09:17:04,575 log.py log log_response 248: Internal Server Error: /api/v1/signup
Traceback (most recent call last):
  File "/home/rushikeshkadam/code_space/videoView/server/venv/lib/python3.10/site-packages/django/core/handlers/exception.py", line 55, in inner
    response = get_response(request)
  File "/home/rushikeshkadam/code_space/videoView/server/venv/lib/python3.10/site-packages/django/core/handlers/base.py", line 197, in _get_response
    response = wrapped_callback(request, *callback_args, **callback_kwargs)
  File "/home/rushikeshkadam/code_space/videoView/server/venv/lib/python3.10/site-packages/django/views/decorators/csrf.py", line 65, in _view_wrapper
    return view_func(request, *args, **kwargs)
  File "/home/rushikeshkadam/code_space/videoView/server/venv/lib/python3.10/site-packages/django/views/generic/base.py", line 104, in view
    return self.dispatch(request, *args, **kwargs)
  File "/home/rushikeshkadam/code_space/videoView/server/venv/lib/python3.10/site-packages/rest_framework/views.py", line 509, in dispatch
    response = self.handle_exception(exc)
  File "/home/rushikeshkadam/code_space/videoView/server/venv/lib/python3.10/site-packages/rest_framework/views.py", line 469, in handle_exception
    self.raise_uncaught_exception(exc)
  File "/home/rushikeshkadam/code_space/videoView/server/venv/lib/python3.10/site-packages/rest_framework/views.py", line 480, in raise_uncaught_exception
    raise exc
  File "/home/rushikeshkadam/code_space/videoView/server/venv/lib/python3.10/site-packages/rest_framework/views.py", line 506, in dispatch
    response = handler(request, *args, **kwargs)
  File "/home/rushikeshkadam/code_space/videoView/server/venv/lib/python3.10/site-packages/rest_framework/decorators.py", line 50, in handler
    return func(*args, **kwargs)
  File "/home/rushikeshkadam/code_space/videoView/server/videoView/api/Views/UserViews.py", line 36, in signup
    user,token=serializer.save()
  File "/home/rushikeshkadam/code_space/videoView/server/venv/lib/python3.10/site-packages/rest_framework/serializers.py", line 208, in save
    self.instance = self.create(validated_data)
  File "/home/rushikeshkadam/code_space/videoView/server/videoView/api/serializer.py", line 54, in create
    if coverImage_img:
UnboundLocalError: local variable 'coverImage_img' referenced before assignment
WARNING 2025-01-01 09:17:25,317 log.py log log_response 248: Unauthorized: /api/v1/signup
WARNING 2025-01-01 13:52:39,733 log.py log log_response 248: Not Found: /api/v1/get_all_video
WARNING 2025-01-01 13:53:37,249 log.py log log_response 248: Method Not Allowed: /api/v1/login
WARNING 2025-01-01 13:53:49,683 log.py log log_response 248: Not Found: /api/v1/get_all_video
WARNING 2025-01-01 13:53:55,286 log.py log log_response 248: Not Found: /api/v1/get_all_video
ERROR 2025-01-01 13:54:11,699 log.py log log_response 248: Internal Server Error: /api/v1/get_all_videos
Traceback (most recent call last):
  File "/home/rushikeshkadam/code_space/videoView/server/venv/lib/python3.10/site-packages/django/core/handlers/exception.py", line 55, in inner
    response = get_response(request)
  File "/home/rushikeshkadam/code_space/videoView/server/venv/lib/python3.10/site-packages/django/core/handlers/base.py", line 220, in _get_response
    response = response.render()
  File "/home/rushikeshkadam/code_space/videoView/server/venv/lib/python3.10/site-packages/django/template/response.py", line 114, in render
    self.content = self.rendered_content
  File "/home/rushikeshkadam/code_space/videoView/server/venv/lib/python3.10/site-packages/rest_framework/response.py", line 74, in rendered_content
    ret = renderer.render(self.data, accepted_media_type, context)
  File "/home/rushikeshkadam/code_space/videoView/server/venv/lib/python3.10/site-packages/rest_framework/renderers.py", line 100, in render
    ret = json.dumps(
  File "/home/rushikeshkadam/code_space/videoView/server/venv/lib/python3.10/site-packages/rest_framework/utils/json.py", line 25, in dumps
    return json.dumps(*args, **kwargs)
  File "/usr/lib/python3.10/json/__init__.py", line 238, in dumps
    **kw).encode(obj)
  File "/usr/lib/python3.10/json/encoder.py", line 199, in encode
    chunks = self.iterencode(o, _one_shot=True)
  File "/usr/lib/python3.10/json/encoder.py", line 257, in iterencode
    return _iterencode(o, 0)
  File "/home/rushikeshkadam/code_space/videoView/server/venv/lib/python3.10/site-packages/rest_framework/utils/encoders.py", line 67, in default
    return super().default(obj)
  File "/usr/lib/python3.10/json/encoder.py", line 179, in default
    raise TypeError(f'Object of type {o.__class__.__name__} '
TypeError: Object of type ApiResponse is not JSON serializable
ERROR 2025-01-01 13:54:52,558 log.py log log_response 248: Internal Server Error: /api/v1/get_all_videos
Traceback (most recent call last):
  File "/home/rushikeshkadam/code_space/videoView/server/venv/lib/python3.10/site-packages/django/core/handlers/exception.py", line 55, in inner
    response = get_response(request)
  File "/home/rushikeshkadam/code_space/videoView/server/venv/lib/python3.10/site-packages/django/core/handlers/base.py", line 220, in _get_response
    response = response.render()
  File "/home/rushikeshkadam/code_space/videoView/server/venv/lib/python3.10/site-packages/django/template/response.py", line 114, in render
    self.content = self.rendered_content
  File "/home/rushikeshkadam/code_space/videoView/server/venv/lib/python3.10/site-packages/rest_framework/response.py", line 74, in rendered_content
    ret = renderer.render(self.data, accepted_media_type, context)
  File "/home/rushikeshkadam/code_space/videoView/server/venv/lib/python3.10/site-packages/rest_framework/renderers.py", line 100, in render
    ret = json.dumps(
  File "/home/rushikeshkadam/code_space/videoView/server/venv/lib/python3.10/site-packages/rest_framework/utils/json.py", line 25, in dumps
    return json.dumps(*args, **kwargs)
  File "/usr/lib/python3.10/json/__init__.py", line 238, in dumps
    **kw).encode(obj)
  File "/usr/lib/python3.10/json/encoder.py", line 199, in encode
    chunks = self.iterencode(o, _one_shot=True)
  File "/usr/lib/python3.10/json/encoder.py", line 257, in iterencode
    return _iterencode(o, 0)
  File "/home/rushikeshkadam/code_space/videoView/server/venv/lib/python3.10/site-packages/rest_framework/utils/encoders.py", line 67, in default
    return super().default(obj)
  File "/usr/lib/python3.10/json/encoder.py", line 179, in default
    raise TypeError(f'Object of type {o.__class__.__name__} '
TypeError: Object of type Videos is not JSON serializable
WARNING 2025-01-01 14:03:47,620 log.py log log_response 248: Not Found: /api/v1/get_all_video/:id
WARNING 2025-01-01 14:04:30,305 log.py log log_response 248: Not Found: /api/v1/get_all_video
ERROR 2025-01-01 14:04:32,033 log.py log log_response 248: Internal Server Error: /api/v1/get_all_videos
Traceback (most recent call last):
  File "/home/rushikeshkadam/code_space/videoView/server/venv/lib/python3.10/site-packages/django/core/handlers/exception.py", line 55, in inner
    response = get_response(request)
  File "/home/rushikeshkadam/code_space/videoView/server/venv/lib/python3.10/site-packages/django/core/handlers/base.py", line 197, in _get_response
    response = wrapped_callback(request, *callback_args, **callback_kwargs)
  File "/home/rushikeshkadam/code_space/videoView/server/venv/lib/python3.10/site-packages/django/views/decorators/csrf.py", line 65, in _view_wrapper
    return view_func(request, *args, **kwargs)
  File "/home/rushikeshkadam/code_space/videoView/server/venv/lib/python3.10/site-packages/django/views/generic/base.py", line 104, in view
    return self.dispatch(request, *args, **kwargs)
  File "/home/rushikeshkadam/code_space/videoView/server/venv/lib/python3.10/site-packages/rest_framework/views.py", line 509, in dispatch
    response = self.handle_exception(exc)
  File "/home/rushikeshkadam/code_space/videoView/server/venv/lib/python3.10/site-packages/rest_framework/views.py", line 469, in handle_exception
    self.raise_uncaught_exception(exc)
  File "/home/rushikeshkadam/code_space/videoView/server/venv/lib/python3.10/site-packages/rest_framework/views.py", line 480, in raise_uncaught_exception
    raise exc
  File "/home/rushikeshkadam/code_space/videoView/server/venv/lib/python3.10/site-packages/rest_framework/views.py", line 506, in dispatch
    response = handler(request, *args, **kwargs)
  File "/home/rushikeshkadam/code_space/videoView/server/venv/lib/python3.10/site-packages/rest_framework/decorators.py", line 50, in handler
    return func(*args, **kwargs)
  File "/home/rushikeshkadam/code_space/videoView/server/videoView/api/Views/VideoView.py", line 43, in get_all_videos
    return Response(ApiResponse.success(200,"fetched all videos",response=serializer.data).__dict__,status=200)
  File "/home/rushikeshkadam/code_space/videoView/server/venv/lib/python3.10/site-packages/rest_framework/serializers.py", line 795, in data
    ret = super().data
  File "/home/rushikeshkadam/code_space/videoView/server/venv/lib/python3.10/site-packages/rest_framework/serializers.py", line 245, in data
    raise AssertionError(msg)
AssertionError: When a serializer is passed a `data` keyword argument you must call `.is_valid()` before attempting to access the serialized `.data` representation.
You should either call `.is_valid()` first, or access `.initial_data` instead.
ERROR 2025-01-01 14:05:27,014 log.py log log_response 248: Internal Server Error: /api/v1/get_all_videos
Traceback (most recent call last):
  File "/home/rushikeshkadam/code_space/videoView/server/venv/lib/python3.10/site-packages/django/core/handlers/exception.py", line 55, in inner
    response = get_response(request)
  File "/home/rushikeshkadam/code_space/videoView/server/venv/lib/python3.10/site-packages/django/core/handlers/base.py", line 197, in _get_response
    response = wrapped_callback(request, *callback_args, **callback_kwargs)
  File "/home/rushikeshkadam/code_space/videoView/server/venv/lib/python3.10/site-packages/django/views/decorators/csrf.py", line 65, in _view_wrapper
    return view_func(request, *args, **kwargs)
  File "/home/rushikeshkadam/code_space/videoView/server/venv/lib/python3.10/site-packages/django/views/generic/base.py", line 104, in view
    return self.dispatch(request, *args, **kwargs)
  File "/home/rushikeshkadam/code_space/videoView/server/venv/lib/python3.10/site-packages/rest_framework/views.py", line 509, in dispatch
    response = self.handle_exception(exc)
  File "/home/rushikeshkadam/code_space/videoView/server/venv/lib/python3.10/site-packages/rest_framework/views.py", line 469, in handle_exception
    self.raise_uncaught_exception(exc)
  File "/home/rushikeshkadam/code_space/videoView/server/venv/lib/python3.10/site-packages/rest_framework/views.py", line 480, in raise_uncaught_exception
    raise exc
  File "/home/rushikeshkadam/code_space/videoView/server/venv/lib/python3.10/site-packages/rest_framework/views.py", line 506, in dispatch
    response = handler(request, *args, **kwargs)
  File "/home/rushikeshkadam/code_space/videoView/server/venv/lib/python3.10/site-packages/rest_framework/decorators.py", line 50, in handler
    return func(*args, **kwargs)
  File "/home/rushikeshkadam/code_space/videoView/server/videoView/api/Views/VideoView.py", line 45, in get_all_videos
    return Response(ApiResponse.success(200,"fetched all videos",response=serializer.data).__dict__,status=200)
  File "/home/rushikeshkadam/code_space/videoView/server/venv/lib/python3.10/site-packages/rest_framework/serializers.py", line 795, in data
    ret = super().data
  File "/home/rushikeshkadam/code_space/videoView/server/venv/lib/python3.10/site-packages/rest_framework/serializers.py", line 245, in data
    raise AssertionError(msg)
AssertionError: When a serializer is passed a `data` keyword argument you must call `.is_valid()` before attempting to access the serialized `.data` representation.
You should either call `.is_valid()` first, or access `.initial_data` instead.
ERROR 2025-01-01 14:06:05,383 log.py log log_response 248: Internal Server Error: /api/v1/get_all_videos
Traceback (most recent call last):
  File "/home/rushikeshkadam/code_space/videoView/server/venv/lib/python3.10/site-packages/django/core/handlers/exception.py", line 55, in inner
    response = get_response(request)
  File "/home/rushikeshkadam/code_space/videoView/server/venv/lib/python3.10/site-packages/django/core/handlers/base.py", line 220, in _get_response
    response = response.render()
  File "/home/rushikeshkadam/code_space/videoView/server/venv/lib/python3.10/site-packages/django/template/response.py", line 114, in render
    self.content = self.rendered_content
  File "/home/rushikeshkadam/code_space/videoView/server/venv/lib/python3.10/site-packages/rest_framework/response.py", line 74, in rendered_content
    ret = renderer.render(self.data, accepted_media_type, context)
  File "/home/rushikeshkadam/code_space/videoView/server/venv/lib/python3.10/site-packages/rest_framework/renderers.py", line 100, in render
    ret = json.dumps(
  File "/home/rushikeshkadam/code_space/videoView/server/venv/lib/python3.10/site-packages/rest_framework/utils/json.py", line 25, in dumps
    return json.dumps(*args, **kwargs)
  File "/usr/lib/python3.10/json/__init__.py", line 238, in dumps
    **kw).encode(obj)
  File "/usr/lib/python3.10/json/encoder.py", line 199, in encode
    chunks = self.iterencode(o, _one_shot=True)
  File "/usr/lib/python3.10/json/encoder.py", line 257, in iterencode
    return _iterencode(o, 0)
  File "/home/rushikeshkadam/code_space/videoView/server/venv/lib/python3.10/site-packages/rest_framework/utils/encoders.py", line 67, in default
    return super().default(obj)
  File "/usr/lib/python3.10/json/encoder.py", line 179, in default
    raise TypeError(f'Object of type {o.__class__.__name__} '
TypeError: Object of type Videos is not JSON serializable
ERROR 2025-01-01 14:06:58,123 log.py log log_response 248: Internal Server Error: /api/v1/get_all_videos
Traceback (most recent call last):
  File "/home/rushikeshkadam/code_space/videoView/server/venv/lib/python3.10/site-packages/django/core/handlers/exception.py", line 55, in inner
    response = get_response(request)
  File "/home/rushikeshkadam/code_space/videoView/server/venv/lib/python3.10/site-packages/django/core/handlers/base.py", line 197, in _get_response
    response = wrapped_callback(request, *callback_args, **callback_kwargs)
  File "/home/rushikeshkadam/code_space/videoView/server/venv/lib/python3.10/site-packages/django/views/decorators/csrf.py", line 65, in _view_wrapper
    return view_func(request, *args, **kwargs)
  File "/home/rushikeshkadam/code_space/videoView/server/venv/lib/python3.10/site-packages/django/views/generic/base.py", line 104, in view
    return self.dispatch(request, *args, **kwargs)
  File "/home/rushikeshkadam/code_space/videoView/server/venv/lib/python3.10/site-packages/rest_framework/views.py", line 509, in dispatch
    response = self.handle_exception(exc)
  File "/home/rushikeshkadam/code_space/videoView/server/venv/lib/python3.10/site-packages/rest_framework/views.py", line 469, in handle_exception
    self.raise_uncaught_exception(exc)
  File "/home/rushikeshkadam/code_space/videoView/server/venv/lib/python3.10/site-packages/rest_framework/views.py", line 480, in raise_uncaught_exception
    raise exc
  File "/home/rushikeshkadam/code_space/videoView/server/venv/lib/python3.10/site-packages/rest_framework/views.py", line 506, in dispatch
    response = handler(request, *args, **kwargs)
  File "/home/rushikeshkadam/code_space/videoView/server/venv/lib/python3.10/site-packages/rest_framework/decorators.py", line 50, in handler
    return func(*args, **kwargs)
  File "/home/rushikeshkadam/code_space/videoView/server/videoView/api/Views/VideoView.py", line 45, in get_all_videos
    return Response(ApiResponse.success(200,"fetched all videos",response=serializer.data).__dict__,status=200)
  File "/home/rushikeshkadam/code_space/videoView/server/venv/lib/python3.10/site-packages/rest_framework/serializers.py", line 795, in data
    ret = super().data
  File "/home/rushikeshkadam/code_space/videoView/server/venv/lib/python3.10/site-packages/rest_framework/serializers.py", line 245, in data
    raise AssertionError(msg)
AssertionError: When a serializer is passed a `data` keyword argument you must call `.is_valid()` before attempting to access the serialized `.data` representation.
You should either call `.is_valid()` first, or access `.initial_data` instead.
ERROR 2025-01-01 14:10:22,089 log.py log log_response 248: Internal Server Error: /api/v1/get_all_videos
Traceback (most recent call last):
  File "/home/rushikeshkadam/code_space/videoView/server/venv/lib/python3.10/site-packages/django/core/handlers/exception.py", line 55, in inner
    response = get_response(request)
  File "/home/rushikeshkadam/code_space/videoView/server/venv/lib/python3.10/site-packages/django/core/handlers/base.py", line 197, in _get_response
    response = wrapped_callback(request, *callback_args, **callback_kwargs)
  File "/home/rushikeshkadam/code_space/videoView/server/venv/lib/python3.10/site-packages/django/views/decorators/csrf.py", line 65, in _view_wrapper
    return view_func(request, *args, **kwargs)
  File "/home/rushikeshkadam/code_space/videoView/server/venv/lib/python3.10/site-packages/django/views/generic/base.py", line 104, in view
    return self.dispatch(request, *args, **kwargs)
  File "/home/rushikeshkadam/code_space/videoView/server/venv/lib/python3.10/site-packages/rest_framework/views.py", line 509, in dispatch
    response = self.handle_exception(exc)
  File "/home/rushikeshkadam/code_space/videoView/server/venv/lib/python3.10/site-packages/rest_framework/views.py", line 469, in handle_exception
    self.raise_uncaught_exception(exc)
  File "/home/rushikeshkadam/code_space/videoView/server/venv/lib/python3.10/site-packages/rest_framework/views.py", line 480, in raise_uncaught_exception
    raise exc
  File "/home/rushikeshkadam/code_space/videoView/server/venv/lib/python3.10/site-packages/rest_framework/views.py", line 506, in dispatch
    response = handler(request, *args, **kwargs)
  File "/home/rushikeshkadam/code_space/videoView/server/venv/lib/python3.10/site-packages/rest_framework/decorators.py", line 50, in handler
    return func(*args, **kwargs)
  File "/home/rushikeshkadam/code_space/videoView/server/videoView/api/Views/VideoView.py", line 45, in get_all_videos
    return Response(ApiResponse.success(200,"fetched all videos",response=serializer.data).__dict__,status=200)
  File "/home/rushikeshkadam/code_space/videoView/server/venv/lib/python3.10/site-packages/rest_framework/serializers.py", line 571, in data
    ret = super().data
  File "/home/rushikeshkadam/code_space/videoView/server/venv/lib/python3.10/site-packages/rest_framework/serializers.py", line 253, in data
    self._data = self.get_initial()
  File "/home/rushikeshkadam/code_space/videoView/server/venv/lib/python3.10/site-packages/rest_framework/serializers.py", line 421, in get_initial
    for field in self.fields.values()
  File "/home/rushikeshkadam/code_space/videoView/server/venv/lib/python3.10/site-packages/django/utils/functional.py", line 47, in __get__
    res = instance.__dict__[self.name] = self.func(instance)
  File "/home/rushikeshkadam/code_space/videoView/server/venv/lib/python3.10/site-packages/rest_framework/serializers.py", line 372, in fields
    for key, value in self.get_fields().items():
  File "/home/rushikeshkadam/code_space/videoView/server/venv/lib/python3.10/site-packages/rest_framework/serializers.py", line 1103, in get_fields
    field_class, field_kwargs = self.build_field(
  File "/home/rushikeshkadam/code_space/videoView/server/venv/lib/python3.10/site-packages/rest_framework/serializers.py", line 1249, in build_field
    return self.build_unknown_field(field_name, model_class)
  File "/home/rushikeshkadam/code_space/videoView/server/venv/lib/python3.10/site-packages/rest_framework/serializers.py", line 1367, in build_unknown_field
    raise ImproperlyConfigured(
django.core.exceptions.ImproperlyConfigured: Field name `isPublish` is not valid for model `Videos` in `api.serializer.AllVideoSerializer`.
ERROR 2025-01-01 14:11:03,222 log.py log log_response 248: Internal Server Error: /api/v1/get_all_videos
Traceback (most recent call last):
  File "/home/rushikeshkadam/code_space/videoView/server/venv/lib/python3.10/site-packages/django/core/handlers/exception.py", line 55, in inner
    response = get_response(request)
  File "/home/rushikeshkadam/code_space/videoView/server/venv/lib/python3.10/site-packages/django/core/handlers/base.py", line 197, in _get_response
    response = wrapped_callback(request, *callback_args, **callback_kwargs)
  File "/home/rushikeshkadam/code_space/videoView/server/venv/lib/python3.10/site-packages/django/views/decorators/csrf.py", line 65, in _view_wrapper
    return view_func(request, *args, **kwargs)
  File "/home/rushikeshkadam/code_space/videoView/server/venv/lib/python3.10/site-packages/django/views/generic/base.py", line 104, in view
    return self.dispatch(request, *args, **kwargs)
  File "/home/rushikeshkadam/code_space/videoView/server/venv/lib/python3.10/site-packages/rest_framework/views.py", line 509, in dispatch
    response = self.handle_exception(exc)
  File "/home/rushikeshkadam/code_space/videoView/server/venv/lib/python3.10/site-packages/rest_framework/views.py", line 469, in handle_exception
    self.raise_uncaught_exception(exc)
  File "/home/rushikeshkadam/code_space/videoView/server/venv/lib/python3.10/site-packages/rest_framework/views.py", line 480, in raise_uncaught_exception
    raise exc
  File "/home/rushikeshkadam/code_space/videoView/server/venv/lib/python3.10/site-packages/rest_framework/views.py", line 506, in dispatch
    response = handler(request, *args, **kwargs)
  File "/home/rushikeshkadam/code_space/videoView/server/venv/lib/python3.10/site-packages/rest_framework/decorators.py", line 50, in handler
    return func(*args, **kwargs)
  File "/home/rushikeshkadam/code_space/videoView/server/videoView/api/Views/VideoView.py", line 45, in get_all_videos
    return Response(ApiResponse.success(200,"fetched all videos",response=serializer.data).__dict__,status=200)
  File "/home/rushikeshkadam/code_space/videoView/server/venv/lib/python3.10/site-packages/rest_framework/serializers.py", line 795, in data
    ret = super().data
  File "/home/rushikeshkadam/code_space/videoView/server/venv/lib/python3.10/site-packages/rest_framework/serializers.py", line 249, in data
    self._data = self.to_representation(self.instance)
  File "/home/rushikeshkadam/code_space/videoView/server/venv/lib/python3.10/site-packages/rest_framework/serializers.py", line 713, in to_representation
    return [
  File "/home/rushikeshkadam/code_space/videoView/server/venv/lib/python3.10/site-packages/rest_framework/serializers.py", line 714, in <listcomp>
    self.child.to_representation(item) for item in iterable
  File "/home/rushikeshkadam/code_space/videoView/server/venv/lib/python3.10/site-packages/rest_framework/serializers.py", line 523, in to_representation
    for field in fields:
  File "/home/rushikeshkadam/code_space/videoView/server/venv/lib/python3.10/site-packages/rest_framework/serializers.py", line 384, in _readable_fields
    for field in self.fields.values():
  File "/home/rushikeshkadam/code_space/videoView/server/venv/lib/python3.10/site-packages/django/utils/functional.py", line 47, in __get__
    res = instance.__dict__[self.name] = self.func(instance)
  File "/home/rushikeshkadam/code_space/videoView/server/venv/lib/python3.10/site-packages/rest_framework/serializers.py", line 372, in fields
    for key, value in self.get_fields().items():
  File "/home/rushikeshkadam/code_space/videoView/server/venv/lib/python3.10/site-packages/rest_framework/serializers.py", line 1103, in get_fields
    field_class, field_kwargs = self.build_field(
  File "/home/rushikeshkadam/code_space/videoView/server/venv/lib/python3.10/site-packages/rest_framework/serializers.py", line 1249, in build_field
    return self.build_unknown_field(field_name, model_class)
  File "/home/rushikeshkadam/code_space/videoView/server/venv/lib/python3.10/site-packages/rest_framework/serializers.py", line 1367, in build_unknown_field
    raise ImproperlyConfigured(
django.core.exceptions.ImproperlyConfigured: Field name `isPublish` is not valid for model `Videos` in `api.serializer.AllVideoSerializer`.
ERROR 2025-01-01 14:20:30,271 log.py log log_response 248: Internal Server Error: /api/v1/get_all_videos
Traceback (most recent call last):
  File "/home/rushikeshkadam/code_space/videoView/server/venv/lib/python3.10/site-packages/django/core/handlers/exception.py", line 55, in inner
    response = get_response(request)
  File "/home/rushikeshkadam/code_space/videoView/server/venv/lib/python3.10/site-packages/django/core/handlers/base.py", line 197, in _get_response
    response = wrapped_callback(request, *callback_args, **callback_kwargs)
  File "/home/rushikeshkadam/code_space/videoView/server/venv/lib/python3.10/site-packages/django/views/decorators/csrf.py", line 65, in _view_wrapper
    return view_func(request, *args, **kwargs)
  File "/home/rushikeshkadam/code_space/videoView/server/venv/lib/python3.10/site-packages/django/views/generic/base.py", line 104, in view
    return self.dispatch(request, *args, **kwargs)
  File "/home/rushikeshkadam/code_space/videoView/server/venv/lib/python3.10/site-packages/rest_framework/views.py", line 509, in dispatch
    response = self.handle_exception(exc)
  File "/home/rushikeshkadam/code_space/videoView/server/venv/lib/python3.10/site-packages/rest_framework/views.py", line 469, in handle_exception
    self.raise_uncaught_exception(exc)
  File "/home/rushikeshkadam/code_space/videoView/server/venv/lib/python3.10/site-packages/rest_framework/views.py", line 480, in raise_uncaught_exception
    raise exc
  File "/home/rushikeshkadam/code_space/videoView/server/venv/lib/python3.10/site-packages/rest_framework/views.py", line 506, in dispatch
    response = handler(request, *args, **kwargs)
  File "/home/rushikeshkadam/code_space/videoView/server/venv/lib/python3.10/site-packages/rest_framework/decorators.py", line 50, in handler
    return func(*args, **kwargs)
  File "/home/rushikeshkadam/code_space/videoView/server/videoView/api/Views/VideoView.py", line 45, in get_all_videos
    return Response(ApiResponse.success(200,"fetched all videos",response=serializer.data).__dict__,status=200)
  File "/home/rushikeshkadam/code_space/videoView/server/venv/lib/python3.10/site-packages/rest_framework/serializers.py", line 795, in data
    ret = super().data
  File "/home/rushikeshkadam/code_space/videoView/server/venv/lib/python3.10/site-packages/rest_framework/serializers.py", line 249, in data
    self._data = self.to_representation(self.instance)
  File "/home/rushikeshkadam/code_space/videoView/server/venv/lib/python3.10/site-packages/rest_framework/serializers.py", line 713, in to_representation
    return [
  File "/home/rushikeshkadam/code_space/videoView/server/venv/lib/python3.10/site-packages/rest_framework/serializers.py", line 714, in <listcomp>
    self.child.to_representation(item) for item in iterable
  File "/home/rushikeshkadam/code_space/videoView/server/venv/lib/python3.10/site-packages/rest_framework/serializers.py", line 538, in to_representation
    ret[field.field_name] = field.to_representation(attribute)
  File "/home/rushikeshkadam/code_space/videoView/server/venv/lib/python3.10/site-packages/rest_framework/serializers.py", line 523, in to_representation
    for field in fields:
  File "/home/rushikeshkadam/code_space/videoView/server/venv/lib/python3.10/site-packages/rest_framework/serializers.py", line 384, in _readable_fields
    for field in self.fields.values():
  File "/home/rushikeshkadam/code_space/videoView/server/venv/lib/python3.10/site-packages/django/utils/functional.py", line 47, in __get__
    res = instance.__dict__[self.name] = self.func(instance)
  File "/home/rushikeshkadam/code_space/videoView/server/venv/lib/python3.10/site-packages/rest_framework/serializers.py", line 372, in fields
    for key, value in self.get_fields().items():
  File "/home/rushikeshkadam/code_space/videoView/server/venv/lib/python3.10/site-packages/rest_framework/serializers.py", line 1103, in get_fields
    field_class, field_kwargs = self.build_field(
  File "/home/rushikeshkadam/code_space/videoView/server/venv/lib/python3.10/site-packages/rest_framework/serializers.py", line 1249, in build_field
    return self.build_unknown_field(field_name, model_class)
  File "/home/rushikeshkadam/code_space/videoView/server/venv/lib/python3.10/site-packages/rest_framework/serializers.py", line 1367, in build_unknown_field
    raise ImproperlyConfigured(
django.core.exceptions.ImproperlyConfigured: Field name `username` is not valid for model `Users` in `api.serializer.UserSerializer`.
ERROR 2025-01-01 14:32:46,404 log.py log log_response 248: Internal Server Error: /api/v1/get_all_videos
Traceback (most recent call last):
  File "/home/rushikeshkadam/code_space/videoView/server/venv/lib/python3.10/site-packages/django/core/handlers/exception.py", line 55, in inner
    response = get_response(request)
  File "/home/rushikeshkadam/code_space/videoView/server/venv/lib/python3.10/site-packages/django/core/handlers/base.py", line 220, in _get_response
    response = response.render()
  File "/home/rushikeshkadam/code_space/videoView/server/venv/lib/python3.10/site-packages/django/template/response.py", line 114, in render
    self.content = self.rendered_content
  File "/home/rushikeshkadam/code_space/videoView/server/venv/lib/python3.10/site-packages/rest_framework/response.py", line 74, in rendered_content
    ret = renderer.render(self.data, accepted_media_type, context)
  File "/home/rushikeshkadam/code_space/videoView/server/venv/lib/python3.10/site-packages/rest_framework/renderers.py", line 100, in render
    ret = json.dumps(
  File "/home/rushikeshkadam/code_space/videoView/server/venv/lib/python3.10/site-packages/rest_framework/utils/json.py", line 25, in dumps
    return json.dumps(*args, **kwargs)
  File "/usr/lib/python3.10/json/__init__.py", line 238, in dumps
    **kw).encode(obj)
  File "/usr/lib/python3.10/json/encoder.py", line 199, in encode
    chunks = self.iterencode(o, _one_shot=True)
  File "/usr/lib/python3.10/json/encoder.py", line 257, in iterencode
    return _iterencode(o, 0)
  File "/home/rushikeshkadam/code_space/videoView/server/venv/lib/python3.10/site-packages/rest_framework/utils/encoders.py", line 67, in default
    return super().default(obj)
  File "/usr/lib/python3.10/json/encoder.py", line 179, in default
    raise TypeError(f'Object of type {o.__class__.__name__} '
TypeError: Object of type ApiResponse is not JSON serializable
WARNING 2025-01-12 06:36:13,109 log.py log log_response 248: Not Found: /api/v1/get_all_video/:id
WARNING 2025-01-12 06:36:24,901 log.py log log_response 248: Not Found: /api/v1/get_all_video
WARNING 2025-01-12 06:36:27,987 log.py log log_response 248: Not Found: /api/v1/get_all_video
ERROR 2025-01-12 06:37:12,352 log.py log log_response 248: Internal Server Error: /api/v1/get_video_by_videoId/600ac1bb-4047-40a2-8aa3-bb4135870516
Traceback (most recent call last):
  File "/home/rushikeshkadam/code_space/videoView/server/venv/lib/python3.10/site-packages/django/core/handlers/exception.py", line 55, in inner
    response = get_response(request)
  File "/home/rushikeshkadam/code_space/videoView/server/venv/lib/python3.10/site-packages/django/core/handlers/base.py", line 197, in _get_response
    response = wrapped_callback(request, *callback_args, **callback_kwargs)
  File "/home/rushikeshkadam/code_space/videoView/server/venv/lib/python3.10/site-packages/django/views/decorators/csrf.py", line 65, in _view_wrapper
    return view_func(request, *args, **kwargs)
  File "/home/rushikeshkadam/code_space/videoView/server/venv/lib/python3.10/site-packages/django/views/generic/base.py", line 104, in view
    return self.dispatch(request, *args, **kwargs)
  File "/home/rushikeshkadam/code_space/videoView/server/venv/lib/python3.10/site-packages/rest_framework/views.py", line 509, in dispatch
    response = self.handle_exception(exc)
  File "/home/rushikeshkadam/code_space/videoView/server/venv/lib/python3.10/site-packages/rest_framework/views.py", line 469, in handle_exception
    self.raise_uncaught_exception(exc)
  File "/home/rushikeshkadam/code_space/videoView/server/venv/lib/python3.10/site-packages/rest_framework/views.py", line 480, in raise_uncaught_exception
    raise exc
  File "/home/rushikeshkadam/code_space/videoView/server/venv/lib/python3.10/site-packages/rest_framework/views.py", line 506, in dispatch
    response = handler(request, *args, **kwargs)
  File "/home/rushikeshkadam/code_space/videoView/server/venv/lib/python3.10/site-packages/rest_framework/decorators.py", line 50, in handler
    return func(*args, **kwargs)
TypeError: get_video_by_videoId() got an unexpected keyword argument 'id'
ERROR 2025-01-12 06:37:59,785 log.py log log_response 248: Internal Server Error: /api/v1/get_video_by_videoId/600ac1bb-4047-40a2-8aa3-bb4135870516
Traceback (most recent call last):
  File "/home/rushikeshkadam/code_space/videoView/server/venv/lib/python3.10/site-packages/django/core/handlers/exception.py", line 55, in inner
    response = get_response(request)
  File "/home/rushikeshkadam/code_space/videoView/server/venv/lib/python3.10/site-packages/django/core/handlers/base.py", line 197, in _get_response
    response = wrapped_callback(request, *callback_args, **callback_kwargs)
  File "/home/rushikeshkadam/code_space/videoView/server/venv/lib/python3.10/site-packages/django/views/decorators/csrf.py", line 65, in _view_wrapper
    return view_func(request, *args, **kwargs)
  File "/home/rushikeshkadam/code_space/videoView/server/venv/lib/python3.10/site-packages/django/views/generic/base.py", line 104, in view
    return self.dispatch(request, *args, **kwargs)
  File "/home/rushikeshkadam/code_space/videoView/server/venv/lib/python3.10/site-packages/rest_framework/views.py", line 509, in dispatch
    response = self.handle_exception(exc)
  File "/home/rushikeshkadam/code_space/videoView/server/venv/lib/python3.10/site-packages/rest_framework/views.py", line 469, in handle_exception
    self.raise_uncaught_exception(exc)
  File "/home/rushikeshkadam/code_space/videoView/server/venv/lib/python3.10/site-packages/rest_framework/views.py", line 480, in raise_uncaught_exception
    raise exc
  File "/home/rushikeshkadam/code_space/videoView/server/venv/lib/python3.10/site-packages/rest_framework/views.py", line 506, in dispatch
    response = handler(request, *args, **kwargs)
  File "/home/rushikeshkadam/code_space/videoView/server/venv/lib/python3.10/site-packages/rest_framework/decorators.py", line 50, in handler
    return func(*args, **kwargs)
TypeError: get_video_by_videoId() got an unexpected keyword argument 'id'
ERROR 2025-01-12 06:38:04,318 log.py log log_response 248: Internal Server Error: /api/v1/get_video_by_videoId/600ac1bb-4047-40a2-8aa3-bb4135870516
Traceback (most recent call last):
  File "/home/rushikeshkadam/code_space/videoView/server/venv/lib/python3.10/site-packages/django/core/handlers/exception.py", line 55, in inner
    response = get_response(request)
  File "/home/rushikeshkadam/code_space/videoView/server/venv/lib/python3.10/site-packages/django/core/handlers/base.py", line 197, in _get_response
    response = wrapped_callback(request, *callback_args, **callback_kwargs)
  File "/home/rushikeshkadam/code_space/videoView/server/venv/lib/python3.10/site-packages/django/views/decorators/csrf.py", line 65, in _view_wrapper
    return view_func(request, *args, **kwargs)
  File "/home/rushikeshkadam/code_space/videoView/server/venv/lib/python3.10/site-packages/django/views/generic/base.py", line 104, in view
    return self.dispatch(request, *args, **kwargs)
  File "/home/rushikeshkadam/code_space/videoView/server/venv/lib/python3.10/site-packages/rest_framework/views.py", line 509, in dispatch
    response = self.handle_exception(exc)
  File "/home/rushikeshkadam/code_space/videoView/server/venv/lib/python3.10/site-packages/rest_framework/views.py", line 469, in handle_exception
    self.raise_uncaught_exception(exc)
  File "/home/rushikeshkadam/code_space/videoView/server/venv/lib/python3.10/site-packages/rest_framework/views.py", line 480, in raise_uncaught_exception
    raise exc
  File "/home/rushikeshkadam/code_space/videoView/server/venv/lib/python3.10/site-packages/rest_framework/views.py", line 506, in dispatch
    response = handler(request, *args, **kwargs)
  File "/home/rushikeshkadam/code_space/videoView/server/venv/lib/python3.10/site-packages/rest_framework/decorators.py", line 50, in handler
    return func(*args, **kwargs)
TypeError: get_video_by_videoId() got an unexpected keyword argument 'id'
ERROR 2025-01-12 06:38:06,445 log.py log log_response 248: Internal Server Error: /api/v1/get_video_by_videoId/600ac1bb-4047-40a2-8aa3-bb4135870516
Traceback (most recent call last):
  File "/home/rushikeshkadam/code_space/videoView/server/venv/lib/python3.10/site-packages/django/core/handlers/exception.py", line 55, in inner
    response = get_response(request)
  File "/home/rushikeshkadam/code_space/videoView/server/venv/lib/python3.10/site-packages/django/core/handlers/base.py", line 197, in _get_response
    response = wrapped_callback(request, *callback_args, **callback_kwargs)
  File "/home/rushikeshkadam/code_space/videoView/server/venv/lib/python3.10/site-packages/django/views/decorators/csrf.py", line 65, in _view_wrapper
    return view_func(request, *args, **kwargs)
  File "/home/rushikeshkadam/code_space/videoView/server/venv/lib/python3.10/site-packages/django/views/generic/base.py", line 104, in view
    return self.dispatch(request, *args, **kwargs)
  File "/home/rushikeshkadam/code_space/videoView/server/venv/lib/python3.10/site-packages/rest_framework/views.py", line 509, in dispatch
    response = self.handle_exception(exc)
  File "/home/rushikeshkadam/code_space/videoView/server/venv/lib/python3.10/site-packages/rest_framework/views.py", line 469, in handle_exception
    self.raise_uncaught_exception(exc)
  File "/home/rushikeshkadam/code_space/videoView/server/venv/lib/python3.10/site-packages/rest_framework/views.py", line 480, in raise_uncaught_exception
    raise exc
  File "/home/rushikeshkadam/code_space/videoView/server/venv/lib/python3.10/site-packages/rest_framework/views.py", line 506, in dispatch
    response = handler(request, *args, **kwargs)
  File "/home/rushikeshkadam/code_space/videoView/server/venv/lib/python3.10/site-packages/rest_framework/decorators.py", line 50, in handler
    return func(*args, **kwargs)
TypeError: get_video_by_videoId() got an unexpected keyword argument 'id'
ERROR 2025-01-12 06:40:03,199 log.py log log_response 248: Internal Server Error: /api/v1/get_video_by_videoId/600ac1bb-4047-40a2-8aa3-bb4135870516/
Traceback (most recent call last):
  File "/home/rushikeshkadam/code_space/videoView/server/venv/lib/python3.10/site-packages/django/core/handlers/exception.py", line 55, in inner
    response = get_response(request)
  File "/home/rushikeshkadam/code_space/videoView/server/venv/lib/python3.10/site-packages/django/core/handlers/base.py", line 197, in _get_response
    response = wrapped_callback(request, *callback_args, **callback_kwargs)
  File "/home/rushikeshkadam/code_space/videoView/server/venv/lib/python3.10/site-packages/django/views/decorators/csrf.py", line 65, in _view_wrapper
    return view_func(request, *args, **kwargs)
  File "/home/rushikeshkadam/code_space/videoView/server/venv/lib/python3.10/site-packages/django/views/generic/base.py", line 104, in view
    return self.dispatch(request, *args, **kwargs)
  File "/home/rushikeshkadam/code_space/videoView/server/venv/lib/python3.10/site-packages/rest_framework/views.py", line 509, in dispatch
    response = self.handle_exception(exc)
  File "/home/rushikeshkadam/code_space/videoView/server/venv/lib/python3.10/site-packages/rest_framework/views.py", line 469, in handle_exception
    self.raise_uncaught_exception(exc)
  File "/home/rushikeshkadam/code_space/videoView/server/venv/lib/python3.10/site-packages/rest_framework/views.py", line 480, in raise_uncaught_exception
    raise exc
  File "/home/rushikeshkadam/code_space/videoView/server/venv/lib/python3.10/site-packages/rest_framework/views.py", line 506, in dispatch
    response = handler(request, *args, **kwargs)
  File "/home/rushikeshkadam/code_space/videoView/server/venv/lib/python3.10/site-packages/rest_framework/decorators.py", line 50, in handler
    return func(*args, **kwargs)
TypeError: get_video_by_videoId() got an unexpected keyword argument 'id'
ERROR 2025-01-12 06:41:34,911 log.py log log_response 248: Internal Server Error: /api/v1/get_video_by_videoId/600ac1bb-4047-40a2-8aa3-bb4135870516/
Traceback (most recent call last):
  File "/home/rushikeshkadam/code_space/videoView/server/venv/lib/python3.10/site-packages/django/core/handlers/exception.py", line 55, in inner
    response = get_response(request)
  File "/home/rushikeshkadam/code_space/videoView/server/venv/lib/python3.10/site-packages/django/core/handlers/base.py", line 220, in _get_response
    response = response.render()
  File "/home/rushikeshkadam/code_space/videoView/server/venv/lib/python3.10/site-packages/django/template/response.py", line 114, in render
    self.content = self.rendered_content
  File "/home/rushikeshkadam/code_space/videoView/server/venv/lib/python3.10/site-packages/rest_framework/response.py", line 74, in rendered_content
    ret = renderer.render(self.data, accepted_media_type, context)
  File "/home/rushikeshkadam/code_space/videoView/server/venv/lib/python3.10/site-packages/rest_framework/renderers.py", line 100, in render
    ret = json.dumps(
  File "/home/rushikeshkadam/code_space/videoView/server/venv/lib/python3.10/site-packages/rest_framework/utils/json.py", line 25, in dumps
    return json.dumps(*args, **kwargs)
  File "/usr/lib/python3.10/json/__init__.py", line 238, in dumps
    **kw).encode(obj)
  File "/usr/lib/python3.10/json/encoder.py", line 199, in encode
    chunks = self.iterencode(o, _one_shot=True)
  File "/usr/lib/python3.10/json/encoder.py", line 257, in iterencode
    return _iterencode(o, 0)
  File "/home/rushikeshkadam/code_space/videoView/server/venv/lib/python3.10/site-packages/rest_framework/utils/encoders.py", line 67, in default
    return super().default(obj)
  File "/usr/lib/python3.10/json/encoder.py", line 179, in default
    raise TypeError(f'Object of type {o.__class__.__name__} '
TypeError: Object of type Videos is not JSON serializable
ERROR 2025-01-12 06:42:27,259 log.py log log_response 248: Internal Server Error: /api/v1/get_video_by_videoId/600ac1bb-4047-40a2-8aa3-bb4135870516/
Traceback (most recent call last):
  File "/home/rushikeshkadam/code_space/videoView/server/venv/lib/python3.10/site-packages/django/core/handlers/exception.py", line 55, in inner
    response = get_response(request)
  File "/home/rushikeshkadam/code_space/videoView/server/venv/lib/python3.10/site-packages/django/core/handlers/base.py", line 220, in _get_response
    response = response.render()
  File "/home/rushikeshkadam/code_space/videoView/server/venv/lib/python3.10/site-packages/django/template/response.py", line 114, in render
    self.content = self.rendered_content
  File "/home/rushikeshkadam/code_space/videoView/server/venv/lib/python3.10/site-packages/rest_framework/response.py", line 74, in rendered_content
    ret = renderer.render(self.data, accepted_media_type, context)
  File "/home/rushikeshkadam/code_space/videoView/server/venv/lib/python3.10/site-packages/rest_framework/renderers.py", line 100, in render
    ret = json.dumps(
  File "/home/rushikeshkadam/code_space/videoView/server/venv/lib/python3.10/site-packages/rest_framework/utils/json.py", line 25, in dumps
    return json.dumps(*args, **kwargs)
  File "/usr/lib/python3.10/json/__init__.py", line 238, in dumps
    **kw).encode(obj)
  File "/usr/lib/python3.10/json/encoder.py", line 199, in encode
    chunks = self.iterencode(o, _one_shot=True)
  File "/usr/lib/python3.10/json/encoder.py", line 257, in iterencode
    return _iterencode(o, 0)
  File "/home/rushikeshkadam/code_space/videoView/server/venv/lib/python3.10/site-packages/rest_framework/utils/encoders.py", line 67, in default
    return super().default(obj)
  File "/usr/lib/python3.10/json/encoder.py", line 179, in default
    raise TypeError(f'Object of type {o.__class__.__name__} '
TypeError: Object of type ApiResponse is not JSON serializable
ERROR 2025-01-12 06:46:14,373 log.py log log_response 248: Internal Server Error: /api/v1/get_video_by_videoId/600ac1bb-4047-40a2-aa3-bb4135870516/
Traceback (most recent call last):
  File "/home/rushikeshkadam/code_space/videoView/server/venv/lib/python3.10/site-packages/django/db/models/fields/__init__.py", line 2761, in to_python
    return uuid.UUID(**{input_form: value})
  File "/usr/lib/python3.10/uuid.py", line 177, in __init__
    raise ValueError('badly formed hexadecimal UUID string')
ValueError: badly formed hexadecimal UUID string

During handling of the above exception, another exception occurred:

Traceback (most recent call last):
  File "/home/rushikeshkadam/code_space/videoView/server/venv/lib/python3.10/site-packages/django/core/handlers/exception.py", line 55, in inner
    response = get_response(request)
  File "/home/rushikeshkadam/code_space/videoView/server/venv/lib/python3.10/site-packages/django/core/handlers/base.py", line 197, in _get_response
    response = wrapped_callback(request, *callback_args, **callback_kwargs)
  File "/home/rushikeshkadam/code_space/videoView/server/venv/lib/python3.10/site-packages/django/views/decorators/csrf.py", line 65, in _view_wrapper
    return view_func(request, *args, **kwargs)
  File "/home/rushikeshkadam/code_space/videoView/server/venv/lib/python3.10/site-packages/django/views/generic/base.py", line 104, in view
    return self.dispatch(request, *args, **kwargs)
  File "/home/rushikeshkadam/code_space/videoView/server/venv/lib/python3.10/site-packages/rest_framework/views.py", line 509, in dispatch
    response = self.handle_exception(exc)
  File "/home/rushikeshkadam/code_space/videoView/server/venv/lib/python3.10/site-packages/rest_framework/views.py", line 469, in handle_exception
    self.raise_uncaught_exception(exc)
  File "/home/rushikeshkadam/code_space/videoView/server/venv/lib/python3.10/site-packages/rest_framework/views.py", line 480, in raise_uncaught_exception
    raise exc
  File "/home/rushikeshkadam/code_space/videoView/server/venv/lib/python3.10/site-packages/rest_framework/views.py", line 506, in dispatch
    response = handler(request, *args, **kwargs)
  File "/home/rushikeshkadam/code_space/videoView/server/venv/lib/python3.10/site-packages/rest_framework/decorators.py", line 50, in handler
    return func(*args, **kwargs)
  File "/home/rushikeshkadam/code_space/videoView/server/videoView/api/Views/VideoView.py", line 51, in get_video_by_videoId
    video_data=Videos.objects.get(id=id)
  File "/home/rushikeshkadam/code_space/videoView/server/venv/lib/python3.10/site-packages/django/db/models/manager.py", line 87, in manager_method
    return getattr(self.get_queryset(), name)(*args, **kwargs)
  File "/home/rushikeshkadam/code_space/videoView/server/venv/lib/python3.10/site-packages/django/db/models/query.py", line 635, in get
    clone = self._chain() if self.query.combinator else self.filter(*args, **kwargs)
  File "/home/rushikeshkadam/code_space/videoView/server/venv/lib/python3.10/site-packages/django/db/models/query.py", line 1476, in filter
    return self._filter_or_exclude(False, args, kwargs)
  File "/home/rushikeshkadam/code_space/videoView/server/venv/lib/python3.10/site-packages/django/db/models/query.py", line 1494, in _filter_or_exclude
    clone._filter_or_exclude_inplace(negate, args, kwargs)
  File "/home/rushikeshkadam/code_space/videoView/server/venv/lib/python3.10/site-packages/django/db/models/query.py", line 1501, in _filter_or_exclude_inplace
    self._query.add_q(Q(*args, **kwargs))
  File "/home/rushikeshkadam/code_space/videoView/server/venv/lib/python3.10/site-packages/django/db/models/sql/query.py", line 1609, in add_q
    clause, _ = self._add_q(q_object, self.used_aliases)
  File "/home/rushikeshkadam/code_space/videoView/server/venv/lib/python3.10/site-packages/django/db/models/sql/query.py", line 1641, in _add_q
    child_clause, needed_inner = self.build_filter(
  File "/home/rushikeshkadam/code_space/videoView/server/venv/lib/python3.10/site-packages/django/db/models/sql/query.py", line 1555, in build_filter
    condition = self.build_lookup(lookups, col, value)
  File "/home/rushikeshkadam/code_space/videoView/server/venv/lib/python3.10/site-packages/django/db/models/sql/query.py", line 1385, in build_lookup
    lookup = lookup_class(lhs, rhs)
  File "/home/rushikeshkadam/code_space/videoView/server/venv/lib/python3.10/site-packages/django/db/models/lookups.py", line 30, in __init__
    self.rhs = self.get_prep_lookup()
  File "/home/rushikeshkadam/code_space/videoView/server/venv/lib/python3.10/site-packages/django/db/models/lookups.py", line 369, in get_prep_lookup
    return super().get_prep_lookup()
  File "/home/rushikeshkadam/code_space/videoView/server/venv/lib/python3.10/site-packages/django/db/models/lookups.py", line 88, in get_prep_lookup
    return self.lhs.output_field.get_prep_value(self.rhs)
  File "/home/rushikeshkadam/code_space/videoView/server/venv/lib/python3.10/site-packages/django/db/models/fields/__init__.py", line 2745, in get_prep_value
    return self.to_python(value)
  File "/home/rushikeshkadam/code_space/videoView/server/venv/lib/python3.10/site-packages/django/db/models/fields/__init__.py", line 2763, in to_python
    raise exceptions.ValidationError(
django.core.exceptions.ValidationError: ['“600ac1bb-4047-40a2-aa3-bb4135870516” is not a valid UUID.']
DEBUG 2025-01-12 06:48:17,175 VideoView.py VideoView get_video_by_videoId 59: Error as occurred : ['“600ac1bb-4047-40a2-aa3-bb4135870516” is not a valid UUID.']
WARNING 2025-01-12 06:48:17,176 log.py log log_response 248: Unauthorized: /api/v1/get_video_by_videoId/600ac1bb-4047-40a2-aa3-bb4135870516/
WARNING 2025-01-15 17:12:39,772 log.py log log_response 248: Unauthorized: /api/v1/upload_video
WARNING 2025-01-15 17:13:45,601 log.py log log_response 248: Not Found: /api/v1/update_video
WARNING 2025-01-15 17:16:12,051 log.py log log_response 248: Not Found: /api/v1/update_video
WARNING 2025-01-15 17:17:30,661 log.py log log_response 248: Not Found: /api/v1/update_video
WARNING 2025-01-15 17:17:35,770 log.py log log_response 248: Not Found: /api/v1/update_video
WARNING 2025-01-15 17:18:02,644 log.py log log_response 248: Not Found: /api/v1/get_all_video/:id
ERROR 2025-01-15 17:19:57,505 log.py log log_response 248: Internal Server Error: /api/v1/update_video/600ac1bb-4047-40a2-8aa3-bb4135870516
Traceback (most recent call last):
  File "/home/rushikeshkadam/code_space/videoView/server/venv/lib/python3.10/site-packages/django/core/handlers/exception.py", line 55, in inner
    response = get_response(request)
  File "/home/rushikeshkadam/code_space/videoView/server/venv/lib/python3.10/site-packages/django/utils/deprecation.py", line 131, in __call__
    response = self.process_response(request, response)
  File "/home/rushikeshkadam/code_space/videoView/server/venv/lib/python3.10/site-packages/django/middleware/common.py", line 108, in process_response
    return self.response_redirect_class(self.get_full_path_with_slash(request))
  File "/home/rushikeshkadam/code_space/videoView/server/venv/lib/python3.10/site-packages/django/middleware/common.py", line 87, in get_full_path_with_slash
    raise RuntimeError(
RuntimeError: You called this URL via PATCH, but the URL doesn't end in a slash and you have APPEND_SLASH set. Django can't redirect to the slash URL while maintaining PATCH data. Change your form to point to 127.0.0.1:8000/api/v1/update_video/600ac1bb-4047-40a2-8aa3-bb4135870516/ (note the trailing slash), or set APPEND_SLASH=False in your Django settings.
WARNING 2025-01-15 17:23:23,406 log.py log log_response 248: Unauthorized: /api/v1/update_video/600ac1bb-4047-40a2-8aa3-bb4135870516/
WARNING 2025-01-15 17:23:59,766 log.py log log_response 248: Unauthorized: /api/v1/update_video/600ac1bb-4047-40a2-8aa3-bb4135870516/
ERROR 2025-01-15 17:24:21,891 log.py log log_response 248: Internal Server Error: /api/v1/update_video/600ac1bb-4047-40a2-8aa3-bb4135870516/
Traceback (most recent call last):
  File "/home/rushikeshkadam/code_space/videoView/server/venv/lib/python3.10/site-packages/django/core/handlers/exception.py", line 55, in inner
    response = get_response(request)
  File "/home/rushikeshkadam/code_space/videoView/server/venv/lib/python3.10/site-packages/django/core/handlers/base.py", line 220, in _get_response
    response = response.render()
  File "/home/rushikeshkadam/code_space/videoView/server/venv/lib/python3.10/site-packages/django/template/response.py", line 114, in render
    self.content = self.rendered_content
  File "/home/rushikeshkadam/code_space/videoView/server/venv/lib/python3.10/site-packages/rest_framework/response.py", line 74, in rendered_content
    ret = renderer.render(self.data, accepted_media_type, context)
  File "/home/rushikeshkadam/code_space/videoView/server/venv/lib/python3.10/site-packages/rest_framework/renderers.py", line 100, in render
    ret = json.dumps(
  File "/home/rushikeshkadam/code_space/videoView/server/venv/lib/python3.10/site-packages/rest_framework/utils/json.py", line 25, in dumps
    return json.dumps(*args, **kwargs)
  File "/usr/lib/python3.10/json/__init__.py", line 238, in dumps
    **kw).encode(obj)
  File "/usr/lib/python3.10/json/encoder.py", line 199, in encode
    chunks = self.iterencode(o, _one_shot=True)
  File "/usr/lib/python3.10/json/encoder.py", line 257, in iterencode
    return _iterencode(o, 0)
  File "/home/rushikeshkadam/code_space/videoView/server/venv/lib/python3.10/site-packages/rest_framework/utils/encoders.py", line 52, in default
    return obj.decode()
UnicodeDecodeError: 'utf-8' codec can't decode byte 0x90 in position 20: invalid start byte
ERROR 2025-01-15 17:24:47,332 log.py log log_response 248: Internal Server Error: /api/v1/update_video/600ac1bb-4047-40a2-8aa3-bb4135870516/
Traceback (most recent call last):
  File "/home/rushikeshkadam/code_space/videoView/server/venv/lib/python3.10/site-packages/django/core/handlers/exception.py", line 55, in inner
    response = get_response(request)
  File "/home/rushikeshkadam/code_space/videoView/server/venv/lib/python3.10/site-packages/django/core/handlers/base.py", line 220, in _get_response
    response = response.render()
  File "/home/rushikeshkadam/code_space/videoView/server/venv/lib/python3.10/site-packages/django/template/response.py", line 114, in render
    self.content = self.rendered_content
  File "/home/rushikeshkadam/code_space/videoView/server/venv/lib/python3.10/site-packages/rest_framework/response.py", line 74, in rendered_content
    ret = renderer.render(self.data, accepted_media_type, context)
  File "/home/rushikeshkadam/code_space/videoView/server/venv/lib/python3.10/site-packages/rest_framework/renderers.py", line 100, in render
    ret = json.dumps(
  File "/home/rushikeshkadam/code_space/videoView/server/venv/lib/python3.10/site-packages/rest_framework/utils/json.py", line 25, in dumps
    return json.dumps(*args, **kwargs)
  File "/usr/lib/python3.10/json/__init__.py", line 238, in dumps
    **kw).encode(obj)
  File "/usr/lib/python3.10/json/encoder.py", line 199, in encode
    chunks = self.iterencode(o, _one_shot=True)
  File "/usr/lib/python3.10/json/encoder.py", line 257, in iterencode
    return _iterencode(o, 0)
  File "/home/rushikeshkadam/code_space/videoView/server/venv/lib/python3.10/site-packages/rest_framework/utils/encoders.py", line 52, in default
    return obj.decode()
UnicodeDecodeError: 'utf-8' codec can't decode byte 0x90 in position 20: invalid start byte
ERROR 2025-01-15 17:27:33,625 log.py log log_response 248: Internal Server Error: /api/v1/update_video/600ac1bb-4047-40a2-8aa3-bb4135870516/
Traceback (most recent call last):
  File "/home/rushikeshkadam/code_space/videoView/server/venv/lib/python3.10/site-packages/django/core/handlers/exception.py", line 55, in inner
    response = get_response(request)
  File "/home/rushikeshkadam/code_space/videoView/server/venv/lib/python3.10/site-packages/django/core/handlers/base.py", line 220, in _get_response
    response = response.render()
  File "/home/rushikeshkadam/code_space/videoView/server/venv/lib/python3.10/site-packages/django/template/response.py", line 114, in render
    self.content = self.rendered_content
  File "/home/rushikeshkadam/code_space/videoView/server/venv/lib/python3.10/site-packages/rest_framework/response.py", line 74, in rendered_content
    ret = renderer.render(self.data, accepted_media_type, context)
  File "/home/rushikeshkadam/code_space/videoView/server/venv/lib/python3.10/site-packages/rest_framework/renderers.py", line 100, in render
    ret = json.dumps(
  File "/home/rushikeshkadam/code_space/videoView/server/venv/lib/python3.10/site-packages/rest_framework/utils/json.py", line 25, in dumps
    return json.dumps(*args, **kwargs)
  File "/usr/lib/python3.10/json/__init__.py", line 238, in dumps
    **kw).encode(obj)
  File "/usr/lib/python3.10/json/encoder.py", line 199, in encode
    chunks = self.iterencode(o, _one_shot=True)
  File "/usr/lib/python3.10/json/encoder.py", line 257, in iterencode
    return _iterencode(o, 0)
  File "/home/rushikeshkadam/code_space/videoView/server/venv/lib/python3.10/site-packages/rest_framework/utils/encoders.py", line 52, in default
    return obj.decode()
UnicodeDecodeError: 'utf-8' codec can't decode byte 0xff in position 0: invalid start byte
ERROR 2025-01-15 17:27:58,712 log.py log log_response 248: Internal Server Error: /api/v1/update_video/600ac1bb-4047-40a2-8aa3-bb4135870516/
Traceback (most recent call last):
  File "/home/rushikeshkadam/code_space/videoView/server/venv/lib/python3.10/site-packages/django/core/handlers/exception.py", line 55, in inner
    response = get_response(request)
  File "/home/rushikeshkadam/code_space/videoView/server/venv/lib/python3.10/site-packages/django/core/handlers/base.py", line 220, in _get_response
    response = response.render()
  File "/home/rushikeshkadam/code_space/videoView/server/venv/lib/python3.10/site-packages/django/template/response.py", line 114, in render
    self.content = self.rendered_content
  File "/home/rushikeshkadam/code_space/videoView/server/venv/lib/python3.10/site-packages/rest_framework/response.py", line 74, in rendered_content
    ret = renderer.render(self.data, accepted_media_type, context)
  File "/home/rushikeshkadam/code_space/videoView/server/venv/lib/python3.10/site-packages/rest_framework/renderers.py", line 100, in render
    ret = json.dumps(
  File "/home/rushikeshkadam/code_space/videoView/server/venv/lib/python3.10/site-packages/rest_framework/utils/json.py", line 25, in dumps
    return json.dumps(*args, **kwargs)
  File "/usr/lib/python3.10/json/__init__.py", line 238, in dumps
    **kw).encode(obj)
  File "/usr/lib/python3.10/json/encoder.py", line 199, in encode
    chunks = self.iterencode(o, _one_shot=True)
  File "/usr/lib/python3.10/json/encoder.py", line 257, in iterencode
    return _iterencode(o, 0)
  File "/home/rushikeshkadam/code_space/videoView/server/venv/lib/python3.10/site-packages/rest_framework/utils/encoders.py", line 52, in default
    return obj.decode()
UnicodeDecodeError: 'utf-8' codec can't decode byte 0xff in position 0: invalid start byte
ERROR 2025-01-15 17:29:28,919 log.py log log_response 248: Internal Server Error: /api/v1/update_video/600ac1bb-4047-40a2-8aa3-bb4135870516/
Traceback (most recent call last):
  File "/home/rushikeshkadam/code_space/videoView/server/venv/lib/python3.10/site-packages/django/core/handlers/exception.py", line 55, in inner
    response = get_response(request)
  File "/home/rushikeshkadam/code_space/videoView/server/venv/lib/python3.10/site-packages/django/core/handlers/base.py", line 220, in _get_response
    response = response.render()
  File "/home/rushikeshkadam/code_space/videoView/server/venv/lib/python3.10/site-packages/django/template/response.py", line 114, in render
    self.content = self.rendered_content
  File "/home/rushikeshkadam/code_space/videoView/server/venv/lib/python3.10/site-packages/rest_framework/response.py", line 74, in rendered_content
    ret = renderer.render(self.data, accepted_media_type, context)
  File "/home/rushikeshkadam/code_space/videoView/server/venv/lib/python3.10/site-packages/rest_framework/renderers.py", line 100, in render
    ret = json.dumps(
  File "/home/rushikeshkadam/code_space/videoView/server/venv/lib/python3.10/site-packages/rest_framework/utils/json.py", line 25, in dumps
    return json.dumps(*args, **kwargs)
  File "/usr/lib/python3.10/json/__init__.py", line 238, in dumps
    **kw).encode(obj)
  File "/usr/lib/python3.10/json/encoder.py", line 199, in encode
    chunks = self.iterencode(o, _one_shot=True)
  File "/usr/lib/python3.10/json/encoder.py", line 257, in iterencode
    return _iterencode(o, 0)
  File "/home/rushikeshkadam/code_space/videoView/server/venv/lib/python3.10/site-packages/rest_framework/utils/encoders.py", line 52, in default
    return obj.decode()
UnicodeDecodeError: 'utf-8' codec can't decode byte 0xff in position 0: invalid start byte
ERROR 2025-01-15 17:33:04,759 log.py log log_response 248: Internal Server Error: /api/v1/update_video/600ac1bb-4047-40a2-8aa3-bb4135870516/
Traceback (most recent call last):
  File "/home/rushikeshkadam/code_space/videoView/server/venv/lib/python3.10/site-packages/django/core/handlers/exception.py", line 55, in inner
    response = get_response(request)
  File "/home/rushikeshkadam/code_space/videoView/server/venv/lib/python3.10/site-packages/django/core/handlers/base.py", line 220, in _get_response
    response = response.render()
  File "/home/rushikeshkadam/code_space/videoView/server/venv/lib/python3.10/site-packages/django/template/response.py", line 114, in render
    self.content = self.rendered_content
  File "/home/rushikeshkadam/code_space/videoView/server/venv/lib/python3.10/site-packages/rest_framework/response.py", line 74, in rendered_content
    ret = renderer.render(self.data, accepted_media_type, context)
  File "/home/rushikeshkadam/code_space/videoView/server/venv/lib/python3.10/site-packages/rest_framework/renderers.py", line 100, in render
    ret = json.dumps(
  File "/home/rushikeshkadam/code_space/videoView/server/venv/lib/python3.10/site-packages/rest_framework/utils/json.py", line 25, in dumps
    return json.dumps(*args, **kwargs)
  File "/usr/lib/python3.10/json/__init__.py", line 238, in dumps
    **kw).encode(obj)
  File "/usr/lib/python3.10/json/encoder.py", line 199, in encode
    chunks = self.iterencode(o, _one_shot=True)
  File "/usr/lib/python3.10/json/encoder.py", line 257, in iterencode
    return _iterencode(o, 0)
  File "/home/rushikeshkadam/code_space/videoView/server/venv/lib/python3.10/site-packages/rest_framework/utils/encoders.py", line 52, in default
    return obj.decode()
UnicodeDecodeError: 'utf-8' codec can't decode byte 0xff in position 0: invalid start byte
ERROR 2025-01-15 17:33:23,738 log.py log log_response 248: Internal Server Error: /api/v1/update_video/600ac1bb-4047-40a2-8aa3-bb4135870516/
Traceback (most recent call last):
  File "/home/rushikeshkadam/code_space/videoView/server/venv/lib/python3.10/site-packages/django/core/handlers/exception.py", line 55, in inner
    response = get_response(request)
  File "/home/rushikeshkadam/code_space/videoView/server/venv/lib/python3.10/site-packages/django/core/handlers/base.py", line 220, in _get_response
    response = response.render()
  File "/home/rushikeshkadam/code_space/videoView/server/venv/lib/python3.10/site-packages/django/template/response.py", line 114, in render
    self.content = self.rendered_content
  File "/home/rushikeshkadam/code_space/videoView/server/venv/lib/python3.10/site-packages/rest_framework/response.py", line 74, in rendered_content
    ret = renderer.render(self.data, accepted_media_type, context)
  File "/home/rushikeshkadam/code_space/videoView/server/venv/lib/python3.10/site-packages/rest_framework/renderers.py", line 100, in render
    ret = json.dumps(
  File "/home/rushikeshkadam/code_space/videoView/server/venv/lib/python3.10/site-packages/rest_framework/utils/json.py", line 25, in dumps
    return json.dumps(*args, **kwargs)
  File "/usr/lib/python3.10/json/__init__.py", line 238, in dumps
    **kw).encode(obj)
  File "/usr/lib/python3.10/json/encoder.py", line 199, in encode
    chunks = self.iterencode(o, _one_shot=True)
  File "/usr/lib/python3.10/json/encoder.py", line 257, in iterencode
    return _iterencode(o, 0)
  File "/home/rushikeshkadam/code_space/videoView/server/venv/lib/python3.10/site-packages/rest_framework/utils/encoders.py", line 52, in default
    return obj.decode()
UnicodeDecodeError: 'utf-8' codec can't decode byte 0xff in position 0: invalid start byte
ERROR 2025-01-15 17:34:02,772 log.py log log_response 248: Internal Server Error: /api/v1/update_video/600ac1bb-4047-40a2-8aa3-bb4135870516/
Traceback (most recent call last):
  File "/home/rushikeshkadam/code_space/videoView/server/venv/lib/python3.10/site-packages/django/core/handlers/exception.py", line 55, in inner
    response = get_response(request)
  File "/home/rushikeshkadam/code_space/videoView/server/venv/lib/python3.10/site-packages/django/core/handlers/base.py", line 220, in _get_response
    response = response.render()
  File "/home/rushikeshkadam/code_space/videoView/server/venv/lib/python3.10/site-packages/django/template/response.py", line 114, in render
    self.content = self.rendered_content
  File "/home/rushikeshkadam/code_space/videoView/server/venv/lib/python3.10/site-packages/rest_framework/response.py", line 74, in rendered_content
    ret = renderer.render(self.data, accepted_media_type, context)
  File "/home/rushikeshkadam/code_space/videoView/server/venv/lib/python3.10/site-packages/rest_framework/renderers.py", line 100, in render
    ret = json.dumps(
  File "/home/rushikeshkadam/code_space/videoView/server/venv/lib/python3.10/site-packages/rest_framework/utils/json.py", line 25, in dumps
    return json.dumps(*args, **kwargs)
  File "/usr/lib/python3.10/json/__init__.py", line 238, in dumps
    **kw).encode(obj)
  File "/usr/lib/python3.10/json/encoder.py", line 199, in encode
    chunks = self.iterencode(o, _one_shot=True)
  File "/usr/lib/python3.10/json/encoder.py", line 257, in iterencode
    return _iterencode(o, 0)
  File "/home/rushikeshkadam/code_space/videoView/server/venv/lib/python3.10/site-packages/rest_framework/utils/encoders.py", line 52, in default
    return obj.decode()
UnicodeDecodeError: 'utf-8' codec can't decode byte 0xff in position 0: invalid start byte
ERROR 2025-01-15 17:34:24,767 log.py log log_response 248: Internal Server Error: /api/v1/update_video/600ac1bb-4047-40a2-8aa3-bb4135870516/
Traceback (most recent call last):
  File "/home/rushikeshkadam/code_space/videoView/server/venv/lib/python3.10/site-packages/django/core/handlers/exception.py", line 55, in inner
    response = get_response(request)
  File "/home/rushikeshkadam/code_space/videoView/server/venv/lib/python3.10/site-packages/django/core/handlers/base.py", line 220, in _get_response
    response = response.render()
  File "/home/rushikeshkadam/code_space/videoView/server/venv/lib/python3.10/site-packages/django/template/response.py", line 114, in render
    self.content = self.rendered_content
  File "/home/rushikeshkadam/code_space/videoView/server/venv/lib/python3.10/site-packages/rest_framework/response.py", line 74, in rendered_content
    ret = renderer.render(self.data, accepted_media_type, context)
  File "/home/rushikeshkadam/code_space/videoView/server/venv/lib/python3.10/site-packages/rest_framework/renderers.py", line 100, in render
    ret = json.dumps(
  File "/home/rushikeshkadam/code_space/videoView/server/venv/lib/python3.10/site-packages/rest_framework/utils/json.py", line 25, in dumps
    return json.dumps(*args, **kwargs)
  File "/usr/lib/python3.10/json/__init__.py", line 238, in dumps
    **kw).encode(obj)
  File "/usr/lib/python3.10/json/encoder.py", line 199, in encode
    chunks = self.iterencode(o, _one_shot=True)
  File "/usr/lib/python3.10/json/encoder.py", line 257, in iterencode
    return _iterencode(o, 0)
  File "/home/rushikeshkadam/code_space/videoView/server/venv/lib/python3.10/site-packages/rest_framework/utils/encoders.py", line 52, in default
    return obj.decode()
UnicodeDecodeError: 'utf-8' codec can't decode byte 0xff in position 0: invalid start byte
ERROR 2025-01-15 17:34:53,683 log.py log log_response 248: Internal Server Error: /api/v1/update_video/600ac1bb-4047-40a2-8aa3-bb4135870516/
Traceback (most recent call last):
  File "/home/rushikeshkadam/code_space/videoView/server/venv/lib/python3.10/site-packages/django/core/handlers/exception.py", line 55, in inner
    response = get_response(request)
  File "/home/rushikeshkadam/code_space/videoView/server/venv/lib/python3.10/site-packages/django/core/handlers/base.py", line 220, in _get_response
    response = response.render()
  File "/home/rushikeshkadam/code_space/videoView/server/venv/lib/python3.10/site-packages/django/template/response.py", line 114, in render
    self.content = self.rendered_content
  File "/home/rushikeshkadam/code_space/videoView/server/venv/lib/python3.10/site-packages/rest_framework/response.py", line 74, in rendered_content
    ret = renderer.render(self.data, accepted_media_type, context)
  File "/home/rushikeshkadam/code_space/videoView/server/venv/lib/python3.10/site-packages/rest_framework/renderers.py", line 100, in render
    ret = json.dumps(
  File "/home/rushikeshkadam/code_space/videoView/server/venv/lib/python3.10/site-packages/rest_framework/utils/json.py", line 25, in dumps
    return json.dumps(*args, **kwargs)
  File "/usr/lib/python3.10/json/__init__.py", line 238, in dumps
    **kw).encode(obj)
  File "/usr/lib/python3.10/json/encoder.py", line 199, in encode
    chunks = self.iterencode(o, _one_shot=True)
  File "/usr/lib/python3.10/json/encoder.py", line 257, in iterencode
    return _iterencode(o, 0)
  File "/home/rushikeshkadam/code_space/videoView/server/venv/lib/python3.10/site-packages/rest_framework/utils/encoders.py", line 52, in default
    return obj.decode()
UnicodeDecodeError: 'utf-8' codec can't decode byte 0xff in position 0: invalid start byte
ERROR 2025-01-15 17:35:17,507 log.py log log_response 248: Internal Server Error: /api/v1/update_video/600ac1bb-4047-40a2-8aa3-bb4135870516/
Traceback (most recent call last):
  File "/home/rushikeshkadam/code_space/videoView/server/venv/lib/python3.10/site-packages/django/core/handlers/exception.py", line 55, in inner
    response = get_response(request)
  File "/home/rushikeshkadam/code_space/videoView/server/venv/lib/python3.10/site-packages/django/core/handlers/base.py", line 220, in _get_response
    response = response.render()
  File "/home/rushikeshkadam/code_space/videoView/server/venv/lib/python3.10/site-packages/django/template/response.py", line 114, in render
    self.content = self.rendered_content
  File "/home/rushikeshkadam/code_space/videoView/server/venv/lib/python3.10/site-packages/rest_framework/response.py", line 74, in rendered_content
    ret = renderer.render(self.data, accepted_media_type, context)
  File "/home/rushikeshkadam/code_space/videoView/server/venv/lib/python3.10/site-packages/rest_framework/renderers.py", line 100, in render
    ret = json.dumps(
  File "/home/rushikeshkadam/code_space/videoView/server/venv/lib/python3.10/site-packages/rest_framework/utils/json.py", line 25, in dumps
    return json.dumps(*args, **kwargs)
  File "/usr/lib/python3.10/json/__init__.py", line 238, in dumps
    **kw).encode(obj)
  File "/usr/lib/python3.10/json/encoder.py", line 199, in encode
    chunks = self.iterencode(o, _one_shot=True)
  File "/usr/lib/python3.10/json/encoder.py", line 257, in iterencode
    return _iterencode(o, 0)
  File "/home/rushikeshkadam/code_space/videoView/server/venv/lib/python3.10/site-packages/rest_framework/utils/encoders.py", line 52, in default
    return obj.decode()
UnicodeDecodeError: 'utf-8' codec can't decode byte 0xff in position 0: invalid start byte
WARNING 2025-01-16 04:22:45,246 log.py log log_response 248: Not Found: /api/v1/update_video/
WARNING 2025-01-16 04:23:23,277 log.py log log_response 248: Not Found: /api/v1/update_video/
WARNING 2025-01-16 04:23:43,287 log.py log log_response 248: Not Found: /api/v1/update_video/
WARNING 2025-01-16 04:24:10,940 log.py log log_response 248: Not Found: /api/v1/update_video/
ERROR 2025-01-16 04:25:22,148 log.py log log_response 248: Internal Server Error: /api/v1/update_video/600ac1bb-4047-40a2-8aa3-bb4135870516/
Traceback (most recent call last):
  File "/home/rushikeshkadam/code_space/videoView/server/venv/lib/python3.10/site-packages/django/core/handlers/exception.py", line 55, in inner
    response = get_response(request)
  File "/home/rushikeshkadam/code_space/videoView/server/venv/lib/python3.10/site-packages/django/core/handlers/base.py", line 220, in _get_response
    response = response.render()
  File "/home/rushikeshkadam/code_space/videoView/server/venv/lib/python3.10/site-packages/django/template/response.py", line 114, in render
    self.content = self.rendered_content
  File "/home/rushikeshkadam/code_space/videoView/server/venv/lib/python3.10/site-packages/rest_framework/response.py", line 74, in rendered_content
    ret = renderer.render(self.data, accepted_media_type, context)
  File "/home/rushikeshkadam/code_space/videoView/server/venv/lib/python3.10/site-packages/rest_framework/renderers.py", line 100, in render
    ret = json.dumps(
  File "/home/rushikeshkadam/code_space/videoView/server/venv/lib/python3.10/site-packages/rest_framework/utils/json.py", line 25, in dumps
    return json.dumps(*args, **kwargs)
  File "/usr/lib/python3.10/json/__init__.py", line 238, in dumps
    **kw).encode(obj)
  File "/usr/lib/python3.10/json/encoder.py", line 199, in encode
    chunks = self.iterencode(o, _one_shot=True)
  File "/usr/lib/python3.10/json/encoder.py", line 257, in iterencode
    return _iterencode(o, 0)
  File "/home/rushikeshkadam/code_space/videoView/server/venv/lib/python3.10/site-packages/rest_framework/utils/encoders.py", line 52, in default
    return obj.decode()
UnicodeDecodeError: 'utf-8' codec can't decode byte 0xff in position 0: invalid start byte
DEBUG 2025-01-16 04:26:01,336 VideoView.py VideoView update_video 69: https://res.cloudinary.com/das30jn7u/image/upload/v1735723183/dymvpuh72cp4bgv1sh7a.png
ERROR 2025-01-16 04:26:01,402 log.py log log_response 248: Internal Server Error: /api/v1/update_video/600ac1bb-4047-40a2-8aa3-bb4135870516/
Traceback (most recent call last):
  File "/home/rushikeshkadam/code_space/videoView/server/venv/lib/python3.10/site-packages/django/core/handlers/exception.py", line 55, in inner
    response = get_response(request)
  File "/home/rushikeshkadam/code_space/videoView/server/venv/lib/python3.10/site-packages/django/core/handlers/base.py", line 220, in _get_response
    response = response.render()
  File "/home/rushikeshkadam/code_space/videoView/server/venv/lib/python3.10/site-packages/django/template/response.py", line 114, in render
    self.content = self.rendered_content
  File "/home/rushikeshkadam/code_space/videoView/server/venv/lib/python3.10/site-packages/rest_framework/response.py", line 74, in rendered_content
    ret = renderer.render(self.data, accepted_media_type, context)
  File "/home/rushikeshkadam/code_space/videoView/server/venv/lib/python3.10/site-packages/rest_framework/renderers.py", line 100, in render
    ret = json.dumps(
  File "/home/rushikeshkadam/code_space/videoView/server/venv/lib/python3.10/site-packages/rest_framework/utils/json.py", line 25, in dumps
    return json.dumps(*args, **kwargs)
  File "/usr/lib/python3.10/json/__init__.py", line 238, in dumps
    **kw).encode(obj)
  File "/usr/lib/python3.10/json/encoder.py", line 199, in encode
    chunks = self.iterencode(o, _one_shot=True)
  File "/usr/lib/python3.10/json/encoder.py", line 257, in iterencode
    return _iterencode(o, 0)
  File "/home/rushikeshkadam/code_space/videoView/server/venv/lib/python3.10/site-packages/rest_framework/utils/encoders.py", line 52, in default
    return obj.decode()
UnicodeDecodeError: 'utf-8' codec can't decode byte 0xff in position 0: invalid start byte
ERROR 2025-01-16 04:26:37,420 log.py log log_response 248: Internal Server Error: /api/v1/update_video/600ac1bb-4047-40a2-8aa3-bb4135870516/
Traceback (most recent call last):
  File "/home/rushikeshkadam/code_space/videoView/server/venv/lib/python3.10/site-packages/django/core/handlers/exception.py", line 55, in inner
    response = get_response(request)
  File "/home/rushikeshkadam/code_space/videoView/server/venv/lib/python3.10/site-packages/django/core/handlers/base.py", line 220, in _get_response
    response = response.render()
  File "/home/rushikeshkadam/code_space/videoView/server/venv/lib/python3.10/site-packages/django/template/response.py", line 114, in render
    self.content = self.rendered_content
  File "/home/rushikeshkadam/code_space/videoView/server/venv/lib/python3.10/site-packages/rest_framework/response.py", line 74, in rendered_content
    ret = renderer.render(self.data, accepted_media_type, context)
  File "/home/rushikeshkadam/code_space/videoView/server/venv/lib/python3.10/site-packages/rest_framework/renderers.py", line 100, in render
    ret = json.dumps(
  File "/home/rushikeshkadam/code_space/videoView/server/venv/lib/python3.10/site-packages/rest_framework/utils/json.py", line 25, in dumps
    return json.dumps(*args, **kwargs)
  File "/usr/lib/python3.10/json/__init__.py", line 238, in dumps
    **kw).encode(obj)
  File "/usr/lib/python3.10/json/encoder.py", line 199, in encode
    chunks = self.iterencode(o, _one_shot=True)
  File "/usr/lib/python3.10/json/encoder.py", line 257, in iterencode
    return _iterencode(o, 0)
  File "/home/rushikeshkadam/code_space/videoView/server/venv/lib/python3.10/site-packages/rest_framework/utils/encoders.py", line 52, in default
    return obj.decode()
UnicodeDecodeError: 'utf-8' codec can't decode byte 0xff in position 0: invalid start byte
DEBUG 2025-01-16 05:12:40,296 VideoView.py VideoView get_video_by_videoId 60: Error as occurred : type object 'super' has no attribute 'to_representation'
WARNING 2025-01-16 05:12:40,296 log.py log log_response 248: Unauthorized: /api/v1/get_video_by_videoId/600ac1bb-4047-40a2-8aa3-bb4135870516/
DEBUG 2025-01-16 05:15:05,520 VideoView.py VideoView get_video_by_videoId 60: Error as occurred : type object 'super' has no attribute 'to_representation'
WARNING 2025-01-16 05:15:05,520 log.py log log_response 248: Unauthorized: /api/v1/get_video_by_videoId/600ac1bb-4047-40a2-8aa3-bb4135870516/
DEBUG 2025-01-16 05:15:29,080 VideoView.py VideoView get_video_by_videoId 60: Error as occurred : type object 'super' has no attribute 'to_representation'
WARNING 2025-01-16 05:15:29,081 log.py log log_response 248: Unauthorized: /api/v1/get_video_by_videoId/600ac1bb-4047-40a2-8aa3-bb4135870516/
DEBUG 2025-01-16 05:16:16,620 VideoView.py VideoView get_video_by_videoId 52: 600ac1bb-4047-40a2-8aa3-bb4135870516
DEBUG 2025-01-16 05:16:16,625 VideoView.py VideoView get_video_by_videoId 61: Error as occurred : type object 'super' has no attribute 'to_representation'
WARNING 2025-01-16 05:16:16,626 log.py log log_response 248: Unauthorized: /api/v1/get_video_by_videoId/600ac1bb-4047-40a2-8aa3-bb4135870516/
DEBUG 2025-01-16 05:17:56,452 VideoView.py VideoView get_video_by_videoId 64: Error as occurred : type object 'super' has no attribute 'to_representation'
WARNING 2025-01-16 05:17:56,453 log.py log log_response 248: Unauthorized: /api/v1/get_video_by_videoId/600ac1bb-4047-40a2-8aa3-bb4135870516/
DEBUG 2025-01-16 05:20:19,245 VideoView.py VideoView get_video_by_videoId 64: Error as occurred : super(type, obj): obj must be an instance or subtype of type
WARNING 2025-01-16 05:20:19,245 log.py log log_response 248: Unauthorized: /api/v1/get_video_by_videoId/600ac1bb-4047-40a2-8aa3-bb4135870516/
DEBUG 2025-01-16 05:28:14,897 VideoView.py VideoView get_video_by_videoId 64: Error as occurred : 'NoneType' object has no attribute 'watchHistory'
WARNING 2025-01-16 05:28:14,898 log.py log log_response 248: Unauthorized: /api/v1/get_video_by_videoId/600ac1bb-4047-40a2-8aa3-bb4135870516/
DEBUG 2025-01-16 05:29:44,643 VideoView.py VideoView get_video_by_videoId 64: Error as occurred : Users matching query does not exist.
WARNING 2025-01-16 05:29:44,643 log.py log log_response 248: Unauthorized: /api/v1/get_video_by_videoId/600ac1bb-4047-40a2-8aa3-bb4135870516/
DEBUG 2025-01-16 05:30:13,126 VideoView.py VideoView get_video_by_videoId 64: Error as occurred : Users matching query does not exist.
WARNING 2025-01-16 05:30:13,126 log.py log log_response 248: Unauthorized: /api/v1/get_video_by_videoId/600ac1bb-4047-40a2-8aa3-bb4135870516/
DEBUG 2025-01-16 05:30:30,346 VideoView.py VideoView get_video_by_videoId 64: Error as occurred : Users matching query does not exist.
WARNING 2025-01-16 05:30:30,348 log.py log log_response 248: Unauthorized: /api/v1/get_video_by_videoId/600ac1bb-4047-40a2-8aa3-bb4135870516/
DEBUG 2025-01-16 05:30:50,962 VideoView.py VideoView get_video_by_videoId 64: Error as occurred : Users matching query does not exist.
WARNING 2025-01-16 05:30:50,963 log.py log log_response 248: Unauthorized: /api/v1/get_video_by_videoId/600ac1bb-4047-40a2-8aa3-bb4135870516/
DEBUG 2025-01-16 05:31:05,403 VideoView.py VideoView get_video_by_videoId 64: Error as occurred : Users matching query does not exist.
WARNING 2025-01-16 05:31:05,403 log.py log log_response 248: Unauthorized: /api/v1/get_video_by_videoId/600ac1bb-4047-40a2-8aa3-bb4135870516/
DEBUG 2025-01-16 05:32:36,311 VideoView.py VideoView get_video_by_videoId 66: Error as occurred : Users matching query does not exist.
WARNING 2025-01-16 05:32:36,312 log.py log log_response 248: Unauthorized: /api/v1/get_video_by_videoId/600ac1bb-4047-40a2-8aa3-bb4135870516/
DEBUG 2025-01-16 05:32:51,015 VideoView.py VideoView get_video_by_videoId 66: Error as occurred : Users matching query does not exist.
WARNING 2025-01-16 05:32:51,016 log.py log log_response 248: Unauthorized: /api/v1/get_video_by_videoId/600ac1bb-4047-40a2-8aa3-bb4135870516/
DEBUG 2025-01-16 05:35:41,167 VideoView.py VideoView get_video_by_videoId 66: Error as occurred : name 'user' is not defined
WARNING 2025-01-16 05:35:41,167 log.py log log_response 248: Unauthorized: /api/v1/get_video_by_videoId/600ac1bb-4047-40a2-8aa3-bb4135870516/
DEBUG 2025-01-16 05:38:33,942 serializer.py serializer to_representation 200: 600ac1bb-4047-40a2-8aa3-bb4135870516
DEBUG 2025-01-16 05:39:11,776 VideoView.py VideoView get_video_by_videoId 66: Error as occurred : 'Videos' object has no attribute 'Videos'
WARNING 2025-01-16 05:39:11,777 log.py log log_response 248: Unauthorized: /api/v1/get_video_by_videoId/600ac1bb-4047-40a2-8aa3-bb4135870516/
DEBUG 2025-01-16 05:39:36,360 serializer.py serializer to_representation 200: api.Users.None
DEBUG 2025-01-16 05:40:03,148 VideoView.py VideoView get_video_by_videoId 66: Error as occurred : 'ManyRelatedManager' object has no attribute 'fullName'
WARNING 2025-01-16 05:40:03,149 log.py log log_response 248: Unauthorized: /api/v1/get_video_by_videoId/600ac1bb-4047-40a2-8aa3-bb4135870516/
DEBUG 2025-01-16 05:40:16,917 serializer.py serializer to_representation 200: api.Users.None
DEBUG 2025-01-16 05:45:30,931 serializer.py serializer to_representation 201: checking........None
DEBUG 2025-01-16 05:46:54,696 serializer.py serializer to_representation 201: checking........api.Users.None
DEBUG 2025-01-17 16:14:32,355 VideoView.py VideoView get_video_by_videoId 67: Error as occurred : When a serializer is passed a `data` keyword argument you must call `.is_valid()` before attempting to access the serialized `.data` representation.
You should either call `.is_valid()` first, or access `.initial_data` instead.
WARNING 2025-01-17 16:14:32,355 log.py log log_response 248: Unauthorized: /api/v1/get_video_by_videoId/600ac1bb-4047-40a2-8aa3-bb4135870516/
DEBUG 2025-01-17 16:24:20,491 VideoView.py VideoView get_video_by_videoId 63: checking..........{}
DEBUG 2025-01-17 16:24:24,799 VideoView.py VideoView get_video_by_videoId 63: checking..........{}
DEBUG 2025-01-17 16:24:40,908 VideoView.py VideoView get_video_by_videoId 63: checking..........{}
DEBUG 2025-01-17 16:24:41,720 VideoView.py VideoView get_video_by_videoId 63: checking..........{}
DEBUG 2025-01-17 16:24:42,441 VideoView.py VideoView get_video_by_videoId 63: checking..........{}
DEBUG 2025-01-17 16:24:43,240 VideoView.py VideoView get_video_by_videoId 63: checking..........{}
DEBUG 2025-01-17 16:25:35,096 VideoView.py VideoView get_video_by_videoId 67: Error as occurred : Cannot call `.is_valid()` as no `data=` keyword argument was passed when instantiating the serializer instance.
WARNING 2025-01-17 16:25:35,096 log.py log log_response 248: Unauthorized: /api/v1/get_video_by_videoId/600ac1bb-4047-40a2-8aa3-bb4135870516/
DEBUG 2025-01-17 16:25:51,705 VideoView.py VideoView get_video_by_videoId 63: checking..........{'id': '600ac1bb-4047-40a2-8aa3-bb4135870516', 'videoFile': 'https://res.cloudinary.com/das30jn7u/video/upload/v1735723199/k9lnoob0onluxttai59v.mp4', 'thumbnail': '4482736.png', 'owner': {'id': '4ee934b7-161c-4392-ae2f-2d74587d6d44', 'fullName': 'rushi', 'email': 'rushi@124gmail.com', 'avatar': 'https://res.cloudinary.com/das30jn7u/image/upload/v1735723073/nxxcfzveixpcpoznse4x.png', 'coverImage': None}, 'title': 'test101', 'description': 'description', 'duration': 10, 'views': 14, 'isPublished': True, 'created_at': '2025-01-01T09:20:00.581499Z', 'updated_at': '2025-01-17T16:25:51.695796Z'}
DEBUG 2025-01-17 16:25:55,956 VideoView.py VideoView get_video_by_videoId 63: checking..........{'id': '600ac1bb-4047-40a2-8aa3-bb4135870516', 'videoFile': 'https://res.cloudinary.com/das30jn7u/video/upload/v1735723199/k9lnoob0onluxttai59v.mp4', 'thumbnail': '4482736.png', 'owner': {'id': '4ee934b7-161c-4392-ae2f-2d74587d6d44', 'fullName': 'rushi', 'email': 'rushi@124gmail.com', 'avatar': 'https://res.cloudinary.com/das30jn7u/image/upload/v1735723073/nxxcfzveixpcpoznse4x.png', 'coverImage': None}, 'title': 'test101', 'description': 'description', 'duration': 10, 'views': 15, 'isPublished': True, 'created_at': '2025-01-01T09:20:00.581499Z', 'updated_at': '2025-01-17T16:25:55.950413Z'}
ERROR 2025-01-17 16:49:19,956 log.py log log_response 248: Internal Server Error: /api/v1/delete_video/600ac1bb-4047-40a2-8aa3-bb4135870516/
ERROR 2025-01-17 16:50:15,367 log.py log log_response 248: Internal Server Error: /api/v1/delete_video/600ac1bb-4047-40a2-8aa3-bb4135870516/
DEBUG 2025-01-17 16:55:52,555 VideoView.py VideoView get_video_by_videoId 67: Error as occurred : local variable 'video_data' referenced before assignment
WARNING 2025-01-17 16:55:52,555 log.py log log_response 248: Unauthorized: /api/v1/get_video_by_videoId/600ac1bb-4047-40a2-8aa3-bb4135870516/
WARNING 2025-01-17 17:02:23,990 log.py log log_response 248: Method Not Allowed: /api/v1/is_published/600ac1bb-4047-40a2-8aa3-bb4135870516/
ERROR 2025-01-17 17:02:57,398 log.py log log_response 248: Internal Server Error: /api/v1/is_published/600ac1bb-4047-40a2-8aa3-bb4135870516/
ERROR 2025-01-17 17:05:17,309 log.py log log_response 248: Internal Server Error: /api/v1/is_published/600ac1bb-4047-40a2-8aa3-bb4135870516/
ERROR 2025-01-17 17:06:32,429 log.py log log_response 248: Internal Server Error: /api/v1/is_published/4ea48abe-cec6-4b37-ab9c-37e253412416/
Traceback (most recent call last):
  File "/home/rushikeshkadam/code_space/videoView/server/venv/lib/python3.10/site-packages/django/core/handlers/exception.py", line 55, in inner
    response = get_response(request)
  File "/home/rushikeshkadam/code_space/videoView/server/venv/lib/python3.10/site-packages/django/core/handlers/base.py", line 220, in _get_response
    response = response.render()
  File "/home/rushikeshkadam/code_space/videoView/server/venv/lib/python3.10/site-packages/django/template/response.py", line 114, in render
    self.content = self.rendered_content
  File "/home/rushikeshkadam/code_space/videoView/server/venv/lib/python3.10/site-packages/rest_framework/response.py", line 74, in rendered_content
    ret = renderer.render(self.data, accepted_media_type, context)
  File "/home/rushikeshkadam/code_space/videoView/server/venv/lib/python3.10/site-packages/rest_framework/renderers.py", line 100, in render
    ret = json.dumps(
  File "/home/rushikeshkadam/code_space/videoView/server/venv/lib/python3.10/site-packages/rest_framework/utils/json.py", line 25, in dumps
    return json.dumps(*args, **kwargs)
  File "/usr/lib/python3.10/json/__init__.py", line 238, in dumps
    **kw).encode(obj)
  File "/usr/lib/python3.10/json/encoder.py", line 199, in encode
    chunks = self.iterencode(o, _one_shot=True)
  File "/usr/lib/python3.10/json/encoder.py", line 257, in iterencode
    return _iterencode(o, 0)
  File "/home/rushikeshkadam/code_space/videoView/server/venv/lib/python3.10/site-packages/rest_framework/utils/encoders.py", line 67, in default
    return super().default(obj)
  File "/usr/lib/python3.10/json/encoder.py", line 179, in default
    raise TypeError(f'Object of type {o.__class__.__name__} '
TypeError: Object of type Videos is not JSON serializable
ERROR 2025-01-17 17:06:54,138 log.py log log_response 248: Internal Server Error: /api/v1/is_published/4ea48abe-cec6-4b37-ab9c-37e253412416/
Traceback (most recent call last):
  File "/home/rushikeshkadam/code_space/videoView/server/venv/lib/python3.10/site-packages/django/core/handlers/exception.py", line 55, in inner
    response = get_response(request)
  File "/home/rushikeshkadam/code_space/videoView/server/venv/lib/python3.10/site-packages/django/core/handlers/base.py", line 220, in _get_response
    response = response.render()
  File "/home/rushikeshkadam/code_space/videoView/server/venv/lib/python3.10/site-packages/django/template/response.py", line 114, in render
    self.content = self.rendered_content
  File "/home/rushikeshkadam/code_space/videoView/server/venv/lib/python3.10/site-packages/rest_framework/response.py", line 74, in rendered_content
    ret = renderer.render(self.data, accepted_media_type, context)
  File "/home/rushikeshkadam/code_space/videoView/server/venv/lib/python3.10/site-packages/rest_framework/renderers.py", line 100, in render
    ret = json.dumps(
  File "/home/rushikeshkadam/code_space/videoView/server/venv/lib/python3.10/site-packages/rest_framework/utils/json.py", line 25, in dumps
    return json.dumps(*args, **kwargs)
  File "/usr/lib/python3.10/json/__init__.py", line 238, in dumps
    **kw).encode(obj)
  File "/usr/lib/python3.10/json/encoder.py", line 199, in encode
    chunks = self.iterencode(o, _one_shot=True)
  File "/usr/lib/python3.10/json/encoder.py", line 257, in iterencode
    return _iterencode(o, 0)
  File "/home/rushikeshkadam/code_space/videoView/server/venv/lib/python3.10/site-packages/rest_framework/utils/encoders.py", line 67, in default
    return super().default(obj)
  File "/usr/lib/python3.10/json/encoder.py", line 179, in default
    raise TypeError(f'Object of type {o.__class__.__name__} '
TypeError: Object of type ModelState is not JSON serializable
ERROR 2025-01-17 17:08:29,845 log.py log log_response 248: Internal Server Error: /api/v1/is_published/4ea48abe-cec6-4b37-ab9c-37e253412416/
ERROR 2025-01-17 17:08:43,463 log.py log log_response 248: Internal Server Error: /api/v1/is_published/4ea48abe-cec6-4b37-ab9c-37e253412416/
DEBUG 2025-01-17 17:11:51,130 VideoView.py VideoView get_video_by_videoId 63: checking..........{'id': '4ea48abe-cec6-4b37-ab9c-37e253412416', 'videoFile': 'https://res.cloudinary.com/das30jn7u/video/upload/v1736961185/yd7svebhffp8e1nhbz2r.mp4', 'thumbnail': 'https://res.cloudinary.com/das30jn7u/image/upload/v1736961175/n196naoywz58y3iuvgu5.png', 'owner': {'id': '4ee934b7-161c-4392-ae2f-2d74587d6d44', 'fullName': 'rushi', 'email': 'rushi@124gmail.com', 'avatar': 'https://res.cloudinary.com/das30jn7u/image/upload/v1735723073/nxxcfzveixpcpoznse4x.png', 'coverImage': None}, 'title': 'test', 'description': 'test', 'duration': 10, 'views': 1, 'isPublished': False, 'created_at': '2025-01-15T17:13:05.828791Z', 'updated_at': '2025-01-17T17:11:51.122809Z'}
