Health check endpoint accessed
Health check endpoint accessed
Health check endpoint accessed
Health check endpoint accessed
Health check endpoint accessed
Health check endpoint accessed
Health check endpoint accessed
Health check endpoint accessed
Health check endpoint accessed
Health check endpoint accessed
Health check endpoint accessed
INFO 2024-12-28 07:31:48,870 autoreload autoreload.py run_with_reloader 668: Watching for file changes with StatReloader
INFO 2024-12-28 07:31:50,868 autoreload autoreload.py run_with_reloader 668: Watching for file changes with StatReloader
DEBUG 2024-12-28 07:31:52,398 UserViews UserViews.py health_check 10: Health check endpoint accessed
INFO 2024-12-28 07:31:52,399 basehttp basehttp.py log_message 213: "GET /api/v1/healthcheck HTTP/1.1" 200 16
INFO 2024-12-28 07:32:42,473 autoreload autoreload.py trigger_reload 266: /home/rushikeshkadam/code_space/videoView/server/videoView/videoView/settings.py changed, reloading.
DEBUG 2024-12-28 07:32:48,853 UserViews.py UserViews health_check 10: Health check endpoint accessed
WARNING 2024-12-28 08:19:56,988 log.py log log_response 248: Method Not Allowed: /api/v1/healthcheck
WARNING 2024-12-28 08:20:35,977 log.py log log_response 248: Method Not Allowed: /api/v1/healthcheck
WARNING 2024-12-28 08:21:19,898 log.py log log_response 248: Method Not Allowed: /api/v1/healthcheck
ERROR 2024-12-28 08:21:45,976 log.py log log_response 248: Internal Server Error: /api/v1/signup
Traceback (most recent call last):
  File "/home/rushikeshkadam/code_space/videoView/server/venv/lib/python3.10/site-packages/django/core/handlers/exception.py", line 55, in inner
    response = get_response(request)
  File "/home/rushikeshkadam/code_space/videoView/server/venv/lib/python3.10/site-packages/django/core/handlers/base.py", line 197, in _get_response
    response = wrapped_callback(request, *callback_args, **callback_kwargs)
  File "/home/rushikeshkadam/code_space/videoView/server/venv/lib/python3.10/site-packages/django/views/decorators/csrf.py", line 65, in _view_wrapper
    return view_func(request, *args, **kwargs)
  File "/home/rushikeshkadam/code_space/videoView/server/venv/lib/python3.10/site-packages/django/views/generic/base.py", line 104, in view
    return self.dispatch(request, *args, **kwargs)
  File "/home/rushikeshkadam/code_space/videoView/server/venv/lib/python3.10/site-packages/rest_framework/views.py", line 511, in dispatch
    self.response = self.finalize_response(request, response, *args, **kwargs)
  File "/home/rushikeshkadam/code_space/videoView/server/venv/lib/python3.10/site-packages/rest_framework/views.py", line 423, in finalize_response
    assert isinstance(response, HttpResponseBase), (
AssertionError: Expected a `Response`, `HttpResponse` or `StreamingHttpResponse` to be returned from the view, but received a `<class 'dict'>`
ERROR 2024-12-28 08:29:01,058 log.py log log_response 248: Internal Server Error: /api/v1/signup
Traceback (most recent call last):
  File "/home/rushikeshkadam/code_space/videoView/server/venv/lib/python3.10/site-packages/django/core/handlers/exception.py", line 55, in inner
    response = get_response(request)
  File "/home/rushikeshkadam/code_space/videoView/server/venv/lib/python3.10/site-packages/django/core/handlers/base.py", line 197, in _get_response
    response = wrapped_callback(request, *callback_args, **callback_kwargs)
  File "/home/rushikeshkadam/code_space/videoView/server/venv/lib/python3.10/site-packages/django/views/decorators/csrf.py", line 65, in _view_wrapper
    return view_func(request, *args, **kwargs)
  File "/home/rushikeshkadam/code_space/videoView/server/venv/lib/python3.10/site-packages/django/views/generic/base.py", line 104, in view
    return self.dispatch(request, *args, **kwargs)
  File "/home/rushikeshkadam/code_space/videoView/server/venv/lib/python3.10/site-packages/rest_framework/views.py", line 509, in dispatch
    response = self.handle_exception(exc)
  File "/home/rushikeshkadam/code_space/videoView/server/venv/lib/python3.10/site-packages/rest_framework/views.py", line 469, in handle_exception
    self.raise_uncaught_exception(exc)
  File "/home/rushikeshkadam/code_space/videoView/server/venv/lib/python3.10/site-packages/rest_framework/views.py", line 480, in raise_uncaught_exception
    raise exc
  File "/home/rushikeshkadam/code_space/videoView/server/venv/lib/python3.10/site-packages/rest_framework/views.py", line 506, in dispatch
    response = handler(request, *args, **kwargs)
  File "/home/rushikeshkadam/code_space/videoView/server/venv/lib/python3.10/site-packages/rest_framework/decorators.py", line 50, in handler
    return func(*args, **kwargs)
  File "/home/rushikeshkadam/code_space/videoView/server/videoView/api/Views/UserViews.py", line 29, in signup
    data=User.objects.all()
NameError: name 'User' is not defined
ERROR 2024-12-28 08:33:58,483 log.py log log_response 248: Internal Server Error: /api/v1/signup
Traceback (most recent call last):
  File "/home/rushikeshkadam/code_space/videoView/server/venv/lib/python3.10/site-packages/django/core/handlers/exception.py", line 55, in inner
    response = get_response(request)
  File "/home/rushikeshkadam/code_space/videoView/server/venv/lib/python3.10/site-packages/django/core/handlers/base.py", line 197, in _get_response
    response = wrapped_callback(request, *callback_args, **callback_kwargs)
  File "/home/rushikeshkadam/code_space/videoView/server/venv/lib/python3.10/site-packages/django/views/decorators/csrf.py", line 65, in _view_wrapper
    return view_func(request, *args, **kwargs)
  File "/home/rushikeshkadam/code_space/videoView/server/venv/lib/python3.10/site-packages/django/views/generic/base.py", line 104, in view
    return self.dispatch(request, *args, **kwargs)
  File "/home/rushikeshkadam/code_space/videoView/server/venv/lib/python3.10/site-packages/rest_framework/views.py", line 509, in dispatch
    response = self.handle_exception(exc)
  File "/home/rushikeshkadam/code_space/videoView/server/venv/lib/python3.10/site-packages/rest_framework/views.py", line 469, in handle_exception
    self.raise_uncaught_exception(exc)
  File "/home/rushikeshkadam/code_space/videoView/server/venv/lib/python3.10/site-packages/rest_framework/views.py", line 480, in raise_uncaught_exception
    raise exc
  File "/home/rushikeshkadam/code_space/videoView/server/venv/lib/python3.10/site-packages/rest_framework/views.py", line 506, in dispatch
    response = handler(request, *args, **kwargs)
  File "/home/rushikeshkadam/code_space/videoView/server/venv/lib/python3.10/site-packages/rest_framework/decorators.py", line 50, in handler
    return func(*args, **kwargs)
  File "/home/rushikeshkadam/code_space/videoView/server/videoView/api/Views/UserViews.py", line 29, in signup
    data=User.objects.all()
NameError: name 'User' is not defined
ERROR 2024-12-28 08:34:22,582 log.py log log_response 248: Internal Server Error: /api/v1/signup
Traceback (most recent call last):
  File "/home/rushikeshkadam/code_space/videoView/server/venv/lib/python3.10/site-packages/django/core/handlers/exception.py", line 55, in inner
    response = get_response(request)
  File "/home/rushikeshkadam/code_space/videoView/server/venv/lib/python3.10/site-packages/django/core/handlers/base.py", line 197, in _get_response
    response = wrapped_callback(request, *callback_args, **callback_kwargs)
  File "/home/rushikeshkadam/code_space/videoView/server/venv/lib/python3.10/site-packages/django/views/decorators/csrf.py", line 65, in _view_wrapper
    return view_func(request, *args, **kwargs)
  File "/home/rushikeshkadam/code_space/videoView/server/venv/lib/python3.10/site-packages/django/views/generic/base.py", line 104, in view
    return self.dispatch(request, *args, **kwargs)
  File "/home/rushikeshkadam/code_space/videoView/server/venv/lib/python3.10/site-packages/rest_framework/views.py", line 509, in dispatch
    response = self.handle_exception(exc)
  File "/home/rushikeshkadam/code_space/videoView/server/venv/lib/python3.10/site-packages/rest_framework/views.py", line 469, in handle_exception
    self.raise_uncaught_exception(exc)
  File "/home/rushikeshkadam/code_space/videoView/server/venv/lib/python3.10/site-packages/rest_framework/views.py", line 480, in raise_uncaught_exception
    raise exc
  File "/home/rushikeshkadam/code_space/videoView/server/venv/lib/python3.10/site-packages/rest_framework/views.py", line 506, in dispatch
    response = handler(request, *args, **kwargs)
  File "/home/rushikeshkadam/code_space/videoView/server/venv/lib/python3.10/site-packages/rest_framework/decorators.py", line 50, in handler
    return func(*args, **kwargs)
  File "/home/rushikeshkadam/code_space/videoView/server/videoView/api/Views/UserViews.py", line 30, in signup
    return JsonResponse({"message":"saved successfully","data":data})
  File "/home/rushikeshkadam/code_space/videoView/server/venv/lib/python3.10/site-packages/django/http/response.py", line 733, in __init__
    data = json.dumps(data, cls=encoder, **json_dumps_params)
  File "/usr/lib/python3.10/json/__init__.py", line 238, in dumps
    **kw).encode(obj)
  File "/usr/lib/python3.10/json/encoder.py", line 199, in encode
    chunks = self.iterencode(o, _one_shot=True)
  File "/usr/lib/python3.10/json/encoder.py", line 257, in iterencode
    return _iterencode(o, 0)
  File "/home/rushikeshkadam/code_space/videoView/server/venv/lib/python3.10/site-packages/django/core/serializers/json.py", line 106, in default
    return super().default(o)
  File "/usr/lib/python3.10/json/encoder.py", line 179, in default
    raise TypeError(f'Object of type {o.__class__.__name__} '
TypeError: Object of type QuerySet is not JSON serializable
ERROR 2024-12-28 08:35:24,465 log.py log log_response 248: Internal Server Error: /api/v1/signup
Traceback (most recent call last):
  File "/home/rushikeshkadam/code_space/videoView/server/venv/lib/python3.10/site-packages/rest_framework/fields.py", line 437, in get_attribute
    return get_attribute(instance, self.source_attrs)
  File "/home/rushikeshkadam/code_space/videoView/server/venv/lib/python3.10/site-packages/rest_framework/fields.py", line 104, in get_attribute
    instance = getattr(instance, attr)
AttributeError: type object 'User' has no attribute 'fullName'

During handling of the above exception, another exception occurred:

Traceback (most recent call last):
  File "/home/rushikeshkadam/code_space/videoView/server/venv/lib/python3.10/site-packages/django/core/handlers/exception.py", line 55, in inner
    response = get_response(request)
  File "/home/rushikeshkadam/code_space/videoView/server/venv/lib/python3.10/site-packages/django/core/handlers/base.py", line 197, in _get_response
    response = wrapped_callback(request, *callback_args, **callback_kwargs)
  File "/home/rushikeshkadam/code_space/videoView/server/venv/lib/python3.10/site-packages/django/views/decorators/csrf.py", line 65, in _view_wrapper
    return view_func(request, *args, **kwargs)
  File "/home/rushikeshkadam/code_space/videoView/server/venv/lib/python3.10/site-packages/django/views/generic/base.py", line 104, in view
    return self.dispatch(request, *args, **kwargs)
  File "/home/rushikeshkadam/code_space/videoView/server/venv/lib/python3.10/site-packages/rest_framework/views.py", line 509, in dispatch
    response = self.handle_exception(exc)
  File "/home/rushikeshkadam/code_space/videoView/server/venv/lib/python3.10/site-packages/rest_framework/views.py", line 469, in handle_exception
    self.raise_uncaught_exception(exc)
  File "/home/rushikeshkadam/code_space/videoView/server/venv/lib/python3.10/site-packages/rest_framework/views.py", line 480, in raise_uncaught_exception
    raise exc
  File "/home/rushikeshkadam/code_space/videoView/server/venv/lib/python3.10/site-packages/rest_framework/views.py", line 506, in dispatch
    response = handler(request, *args, **kwargs)
  File "/home/rushikeshkadam/code_space/videoView/server/venv/lib/python3.10/site-packages/rest_framework/decorators.py", line 50, in handler
    return func(*args, **kwargs)
  File "/home/rushikeshkadam/code_space/videoView/server/videoView/api/Views/UserViews.py", line 30, in signup
    return JsonResponse({"message":"saved successfully","data":serializers.data})
  File "/home/rushikeshkadam/code_space/videoView/server/venv/lib/python3.10/site-packages/rest_framework/serializers.py", line 571, in data
    ret = super().data
  File "/home/rushikeshkadam/code_space/videoView/server/venv/lib/python3.10/site-packages/rest_framework/serializers.py", line 249, in data
    self._data = self.to_representation(self.instance)
  File "/home/rushikeshkadam/code_space/videoView/server/venv/lib/python3.10/site-packages/rest_framework/serializers.py", line 525, in to_representation
    attribute = field.get_attribute(instance)
  File "/home/rushikeshkadam/code_space/videoView/server/venv/lib/python3.10/site-packages/rest_framework/fields.py", line 470, in get_attribute
    raise type(exc)(msg)
AttributeError: Got AttributeError when attempting to get a value for field `fullName` on serializer `UsersRegistrationSerializer`.
The serializer field might be named incorrectly and not match any attribute or key on the `ModelBase` instance.
Original exception text was: type object 'User' has no attribute 'fullName'.
ERROR 2024-12-28 08:38:19,109 log.py log log_response 248: Internal Server Error: /api/v1/signup
Traceback (most recent call last):
  File "/home/rushikeshkadam/code_space/videoView/server/venv/lib/python3.10/site-packages/django/core/handlers/exception.py", line 55, in inner
    response = get_response(request)
  File "/home/rushikeshkadam/code_space/videoView/server/venv/lib/python3.10/site-packages/django/core/handlers/base.py", line 197, in _get_response
    response = wrapped_callback(request, *callback_args, **callback_kwargs)
  File "/home/rushikeshkadam/code_space/videoView/server/venv/lib/python3.10/site-packages/django/views/decorators/csrf.py", line 65, in _view_wrapper
    return view_func(request, *args, **kwargs)
  File "/home/rushikeshkadam/code_space/videoView/server/venv/lib/python3.10/site-packages/django/views/generic/base.py", line 104, in view
    return self.dispatch(request, *args, **kwargs)
  File "/home/rushikeshkadam/code_space/videoView/server/venv/lib/python3.10/site-packages/rest_framework/views.py", line 509, in dispatch
    response = self.handle_exception(exc)
  File "/home/rushikeshkadam/code_space/videoView/server/venv/lib/python3.10/site-packages/rest_framework/views.py", line 469, in handle_exception
    self.raise_uncaught_exception(exc)
  File "/home/rushikeshkadam/code_space/videoView/server/venv/lib/python3.10/site-packages/rest_framework/views.py", line 480, in raise_uncaught_exception
    raise exc
  File "/home/rushikeshkadam/code_space/videoView/server/venv/lib/python3.10/site-packages/rest_framework/views.py", line 506, in dispatch
    response = handler(request, *args, **kwargs)
  File "/home/rushikeshkadam/code_space/videoView/server/venv/lib/python3.10/site-packages/rest_framework/decorators.py", line 50, in handler
    return func(*args, **kwargs)
  File "/home/rushikeshkadam/code_space/videoView/server/videoView/api/Views/UserViews.py", line 30, in signup
    return JsonResponse({"message":"saved successfully","data":user})
  File "/home/rushikeshkadam/code_space/videoView/server/venv/lib/python3.10/site-packages/django/http/response.py", line 733, in __init__
    data = json.dumps(data, cls=encoder, **json_dumps_params)
  File "/usr/lib/python3.10/json/__init__.py", line 238, in dumps
    **kw).encode(obj)
  File "/usr/lib/python3.10/json/encoder.py", line 199, in encode
    chunks = self.iterencode(o, _one_shot=True)
  File "/usr/lib/python3.10/json/encoder.py", line 257, in iterencode
    return _iterencode(o, 0)
  File "/home/rushikeshkadam/code_space/videoView/server/venv/lib/python3.10/site-packages/django/core/serializers/json.py", line 106, in default
    return super().default(o)
  File "/usr/lib/python3.10/json/encoder.py", line 179, in default
    raise TypeError(f'Object of type {o.__class__.__name__} '
TypeError: Object of type ModelBase is not JSON serializable
ERROR 2024-12-28 08:38:41,904 log.py log log_response 248: Internal Server Error: /api/v1/signup
Traceback (most recent call last):
  File "/home/rushikeshkadam/code_space/videoView/server/venv/lib/python3.10/site-packages/rest_framework/fields.py", line 437, in get_attribute
    return get_attribute(instance, self.source_attrs)
  File "/home/rushikeshkadam/code_space/videoView/server/venv/lib/python3.10/site-packages/rest_framework/fields.py", line 104, in get_attribute
    instance = getattr(instance, attr)
AttributeError: 'UsersRegistrationSerializer' object has no attribute 'fullName'

During handling of the above exception, another exception occurred:

Traceback (most recent call last):
  File "/home/rushikeshkadam/code_space/videoView/server/venv/lib/python3.10/site-packages/django/core/handlers/exception.py", line 55, in inner
    response = get_response(request)
  File "/home/rushikeshkadam/code_space/videoView/server/venv/lib/python3.10/site-packages/django/core/handlers/base.py", line 197, in _get_response
    response = wrapped_callback(request, *callback_args, **callback_kwargs)
  File "/home/rushikeshkadam/code_space/videoView/server/venv/lib/python3.10/site-packages/django/views/decorators/csrf.py", line 65, in _view_wrapper
    return view_func(request, *args, **kwargs)
  File "/home/rushikeshkadam/code_space/videoView/server/venv/lib/python3.10/site-packages/django/views/generic/base.py", line 104, in view
    return self.dispatch(request, *args, **kwargs)
  File "/home/rushikeshkadam/code_space/videoView/server/venv/lib/python3.10/site-packages/rest_framework/views.py", line 509, in dispatch
    response = self.handle_exception(exc)
  File "/home/rushikeshkadam/code_space/videoView/server/venv/lib/python3.10/site-packages/rest_framework/views.py", line 469, in handle_exception
    self.raise_uncaught_exception(exc)
  File "/home/rushikeshkadam/code_space/videoView/server/venv/lib/python3.10/site-packages/rest_framework/views.py", line 480, in raise_uncaught_exception
    raise exc
  File "/home/rushikeshkadam/code_space/videoView/server/venv/lib/python3.10/site-packages/rest_framework/views.py", line 506, in dispatch
    response = handler(request, *args, **kwargs)
  File "/home/rushikeshkadam/code_space/videoView/server/venv/lib/python3.10/site-packages/rest_framework/decorators.py", line 50, in handler
    return func(*args, **kwargs)
  File "/home/rushikeshkadam/code_space/videoView/server/videoView/api/Views/UserViews.py", line 30, in signup
    return JsonResponse({"message":"saved successfully","data":UsersRegistrationSerializer(serializers).data})
  File "/home/rushikeshkadam/code_space/videoView/server/venv/lib/python3.10/site-packages/rest_framework/serializers.py", line 571, in data
    ret = super().data
  File "/home/rushikeshkadam/code_space/videoView/server/venv/lib/python3.10/site-packages/rest_framework/serializers.py", line 249, in data
    self._data = self.to_representation(self.instance)
  File "/home/rushikeshkadam/code_space/videoView/server/venv/lib/python3.10/site-packages/rest_framework/serializers.py", line 525, in to_representation
    attribute = field.get_attribute(instance)
  File "/home/rushikeshkadam/code_space/videoView/server/venv/lib/python3.10/site-packages/rest_framework/fields.py", line 470, in get_attribute
    raise type(exc)(msg)
AttributeError: Got AttributeError when attempting to get a value for field `fullName` on serializer `UsersRegistrationSerializer`.
The serializer field might be named incorrectly and not match any attribute or key on the `UsersRegistrationSerializer` instance.
Original exception text was: 'UsersRegistrationSerializer' object has no attribute 'fullName'.
ERROR 2024-12-28 08:40:58,314 log.py log log_response 248: Internal Server Error: /api/v1/signup
Traceback (most recent call last):
  File "/home/rushikeshkadam/code_space/videoView/server/venv/lib/python3.10/site-packages/rest_framework/fields.py", line 437, in get_attribute
    return get_attribute(instance, self.source_attrs)
  File "/home/rushikeshkadam/code_space/videoView/server/venv/lib/python3.10/site-packages/rest_framework/fields.py", line 104, in get_attribute
    instance = getattr(instance, attr)
AttributeError: 'UsersRegistrationSerializer' object has no attribute 'fullName'

During handling of the above exception, another exception occurred:

Traceback (most recent call last):
  File "/home/rushikeshkadam/code_space/videoView/server/venv/lib/python3.10/site-packages/django/core/handlers/exception.py", line 55, in inner
    response = get_response(request)
  File "/home/rushikeshkadam/code_space/videoView/server/venv/lib/python3.10/site-packages/django/core/handlers/base.py", line 197, in _get_response
    response = wrapped_callback(request, *callback_args, **callback_kwargs)
  File "/home/rushikeshkadam/code_space/videoView/server/venv/lib/python3.10/site-packages/django/views/decorators/csrf.py", line 65, in _view_wrapper
    return view_func(request, *args, **kwargs)
  File "/home/rushikeshkadam/code_space/videoView/server/venv/lib/python3.10/site-packages/django/views/generic/base.py", line 104, in view
    return self.dispatch(request, *args, **kwargs)
  File "/home/rushikeshkadam/code_space/videoView/server/venv/lib/python3.10/site-packages/rest_framework/views.py", line 509, in dispatch
    response = self.handle_exception(exc)
  File "/home/rushikeshkadam/code_space/videoView/server/venv/lib/python3.10/site-packages/rest_framework/views.py", line 469, in handle_exception
    self.raise_uncaught_exception(exc)
  File "/home/rushikeshkadam/code_space/videoView/server/venv/lib/python3.10/site-packages/rest_framework/views.py", line 480, in raise_uncaught_exception
    raise exc
  File "/home/rushikeshkadam/code_space/videoView/server/venv/lib/python3.10/site-packages/rest_framework/views.py", line 506, in dispatch
    response = handler(request, *args, **kwargs)
  File "/home/rushikeshkadam/code_space/videoView/server/venv/lib/python3.10/site-packages/rest_framework/decorators.py", line 50, in handler
    return func(*args, **kwargs)
  File "/home/rushikeshkadam/code_space/videoView/server/videoView/api/Views/UserViews.py", line 30, in signup
    return JsonResponse({"message":"saved successfully","data":UsersRegistrationSerializer(serializers).data})
  File "/home/rushikeshkadam/code_space/videoView/server/venv/lib/python3.10/site-packages/rest_framework/serializers.py", line 571, in data
    ret = super().data
  File "/home/rushikeshkadam/code_space/videoView/server/venv/lib/python3.10/site-packages/rest_framework/serializers.py", line 249, in data
    self._data = self.to_representation(self.instance)
  File "/home/rushikeshkadam/code_space/videoView/server/venv/lib/python3.10/site-packages/rest_framework/serializers.py", line 525, in to_representation
    attribute = field.get_attribute(instance)
  File "/home/rushikeshkadam/code_space/videoView/server/venv/lib/python3.10/site-packages/rest_framework/fields.py", line 470, in get_attribute
    raise type(exc)(msg)
AttributeError: Got AttributeError when attempting to get a value for field `fullName` on serializer `UsersRegistrationSerializer`.
The serializer field might be named incorrectly and not match any attribute or key on the `UsersRegistrationSerializer` instance.
Original exception text was: 'UsersRegistrationSerializer' object has no attribute 'fullName'.
ERROR 2024-12-28 08:43:37,492 log.py log log_response 248: Internal Server Error: /api/v1/signup
Traceback (most recent call last):
  File "/home/rushikeshkadam/code_space/videoView/server/venv/lib/python3.10/site-packages/rest_framework/fields.py", line 437, in get_attribute
    return get_attribute(instance, self.source_attrs)
  File "/home/rushikeshkadam/code_space/videoView/server/venv/lib/python3.10/site-packages/rest_framework/fields.py", line 104, in get_attribute
    instance = getattr(instance, attr)
AttributeError: 'UsersRegistrationSerializer' object has no attribute 'fullName'

During handling of the above exception, another exception occurred:

Traceback (most recent call last):
  File "/home/rushikeshkadam/code_space/videoView/server/venv/lib/python3.10/site-packages/django/core/handlers/exception.py", line 55, in inner
    response = get_response(request)
  File "/home/rushikeshkadam/code_space/videoView/server/venv/lib/python3.10/site-packages/django/core/handlers/base.py", line 197, in _get_response
    response = wrapped_callback(request, *callback_args, **callback_kwargs)
  File "/home/rushikeshkadam/code_space/videoView/server/venv/lib/python3.10/site-packages/django/views/decorators/csrf.py", line 65, in _view_wrapper
    return view_func(request, *args, **kwargs)
  File "/home/rushikeshkadam/code_space/videoView/server/venv/lib/python3.10/site-packages/django/views/generic/base.py", line 104, in view
    return self.dispatch(request, *args, **kwargs)
  File "/home/rushikeshkadam/code_space/videoView/server/venv/lib/python3.10/site-packages/rest_framework/views.py", line 509, in dispatch
    response = self.handle_exception(exc)
  File "/home/rushikeshkadam/code_space/videoView/server/venv/lib/python3.10/site-packages/rest_framework/views.py", line 469, in handle_exception
    self.raise_uncaught_exception(exc)
  File "/home/rushikeshkadam/code_space/videoView/server/venv/lib/python3.10/site-packages/rest_framework/views.py", line 480, in raise_uncaught_exception
    raise exc
  File "/home/rushikeshkadam/code_space/videoView/server/venv/lib/python3.10/site-packages/rest_framework/views.py", line 506, in dispatch
    response = handler(request, *args, **kwargs)
  File "/home/rushikeshkadam/code_space/videoView/server/venv/lib/python3.10/site-packages/rest_framework/decorators.py", line 50, in handler
    return func(*args, **kwargs)
  File "/home/rushikeshkadam/code_space/videoView/server/videoView/api/Views/UserViews.py", line 30, in signup
    return JsonResponse({"message":"saved successfully","data":UsersRegistrationSerializer(serializers).data})
  File "/home/rushikeshkadam/code_space/videoView/server/venv/lib/python3.10/site-packages/rest_framework/serializers.py", line 571, in data
    ret = super().data
  File "/home/rushikeshkadam/code_space/videoView/server/venv/lib/python3.10/site-packages/rest_framework/serializers.py", line 249, in data
    self._data = self.to_representation(self.instance)
  File "/home/rushikeshkadam/code_space/videoView/server/venv/lib/python3.10/site-packages/rest_framework/serializers.py", line 525, in to_representation
    attribute = field.get_attribute(instance)
  File "/home/rushikeshkadam/code_space/videoView/server/venv/lib/python3.10/site-packages/rest_framework/fields.py", line 470, in get_attribute
    raise type(exc)(msg)
AttributeError: Got AttributeError when attempting to get a value for field `fullName` on serializer `UsersRegistrationSerializer`.
The serializer field might be named incorrectly and not match any attribute or key on the `UsersRegistrationSerializer` instance.
Original exception text was: 'UsersRegistrationSerializer' object has no attribute 'fullName'.
ERROR 2024-12-28 08:45:31,625 log.py log log_response 248: Internal Server Error: /api/v1/signup
Traceback (most recent call last):
  File "/home/rushikeshkadam/code_space/videoView/server/venv/lib/python3.10/site-packages/django/core/handlers/exception.py", line 55, in inner
    response = get_response(request)
  File "/home/rushikeshkadam/code_space/videoView/server/venv/lib/python3.10/site-packages/django/core/handlers/base.py", line 197, in _get_response
    response = wrapped_callback(request, *callback_args, **callback_kwargs)
  File "/home/rushikeshkadam/code_space/videoView/server/venv/lib/python3.10/site-packages/django/views/decorators/csrf.py", line 65, in _view_wrapper
    return view_func(request, *args, **kwargs)
  File "/home/rushikeshkadam/code_space/videoView/server/venv/lib/python3.10/site-packages/django/views/generic/base.py", line 104, in view
    return self.dispatch(request, *args, **kwargs)
  File "/home/rushikeshkadam/code_space/videoView/server/venv/lib/python3.10/site-packages/rest_framework/views.py", line 509, in dispatch
    response = self.handle_exception(exc)
  File "/home/rushikeshkadam/code_space/videoView/server/venv/lib/python3.10/site-packages/rest_framework/views.py", line 469, in handle_exception
    self.raise_uncaught_exception(exc)
  File "/home/rushikeshkadam/code_space/videoView/server/venv/lib/python3.10/site-packages/rest_framework/views.py", line 480, in raise_uncaught_exception
    raise exc
  File "/home/rushikeshkadam/code_space/videoView/server/venv/lib/python3.10/site-packages/rest_framework/views.py", line 506, in dispatch
    response = handler(request, *args, **kwargs)
  File "/home/rushikeshkadam/code_space/videoView/server/venv/lib/python3.10/site-packages/rest_framework/decorators.py", line 50, in handler
    return func(*args, **kwargs)
  File "/home/rushikeshkadam/code_space/videoView/server/videoView/api/Views/UserViews.py", line 27, in signup
    if serializers.is_valid():
NameError: name 'serializers' is not defined
ERROR 2024-12-28 08:52:42,625 log.py log log_response 248: Internal Server Error: /api/v1/signup
Traceback (most recent call last):
  File "/home/rushikeshkadam/code_space/videoView/server/venv/lib/python3.10/site-packages/django/core/handlers/exception.py", line 55, in inner
    response = get_response(request)
  File "/home/rushikeshkadam/code_space/videoView/server/venv/lib/python3.10/site-packages/django/core/handlers/base.py", line 197, in _get_response
    response = wrapped_callback(request, *callback_args, **callback_kwargs)
  File "/home/rushikeshkadam/code_space/videoView/server/venv/lib/python3.10/site-packages/django/views/decorators/csrf.py", line 65, in _view_wrapper
    return view_func(request, *args, **kwargs)
  File "/home/rushikeshkadam/code_space/videoView/server/venv/lib/python3.10/site-packages/django/views/generic/base.py", line 104, in view
    return self.dispatch(request, *args, **kwargs)
  File "/home/rushikeshkadam/code_space/videoView/server/venv/lib/python3.10/site-packages/rest_framework/views.py", line 509, in dispatch
    response = self.handle_exception(exc)
  File "/home/rushikeshkadam/code_space/videoView/server/venv/lib/python3.10/site-packages/rest_framework/views.py", line 469, in handle_exception
    self.raise_uncaught_exception(exc)
  File "/home/rushikeshkadam/code_space/videoView/server/venv/lib/python3.10/site-packages/rest_framework/views.py", line 480, in raise_uncaught_exception
    raise exc
  File "/home/rushikeshkadam/code_space/videoView/server/venv/lib/python3.10/site-packages/rest_framework/views.py", line 506, in dispatch
    response = handler(request, *args, **kwargs)
  File "/home/rushikeshkadam/code_space/videoView/server/venv/lib/python3.10/site-packages/rest_framework/decorators.py", line 50, in handler
    return func(*args, **kwargs)
  File "/home/rushikeshkadam/code_space/videoView/server/videoView/api/Views/UserViews.py", line 27, in signup
    if serializer.validate_email():
TypeError: UsersRegistrationSerializer.validate_email() missing 1 required positional argument: 'value'
